Workbook

Sheet Weekly Data
A1: DataPath — Weekly Performance Tracker (2025–2026)
A2: One row per week. Blue text = enter from dashboard. Monthly subtotal rows auto-calculate. Filter by Year/Month columns. Freeze panes set on row 4.
F3: ConnectWise | G3: ConnectWise | H3: ConnectWise | I3: ConnectWise | J3: ConnectWise | K3: Computed | L3: ConnectWise | M3: ConnectWise | N3: ConnectWise | O3: ConnectWise | P3: ConnectWise | Q3: ConnectWise | R3: ConnectWise | S3: Sage | T3: Sage | U3: Sage | V3: Computed | W3: Computed | X3: Sage | Y3: Computed | Z3: Sage | AA3: Sage | AB3: Computed | AC3: ConnectWise | AD3: ConnectWise | AE3: ConnectWise | AF3: ConnectWise | AG3: ConnectWise | AH3: ConnectWise | AI3: ConnectWise | AJ3: ConnectWise | AK3: HubSpot | AL3: HubSpot | AM3: HubSpot | AN3: HubSpot
A4: Year | B4: Month | C4: Wk # | D4: Week Range | E4: Date Key | F4: Total Rev Won | G4: NRR | H4: Recur Rev (Mo) | I4: Recur Rev (Ann) | J4: Target | K4: % of Target | L4: Joel Walker | M4: Nathan La Fleche | N4: Dan Sturdivant | O4: Jay Harvey | P4: Ricky Maestas | Q4: Maria Martinez | R4: Julissa Martinez | S4: P&L Gross Sales | T4: P&L COGS | U4: P&L Gross Margin | V4: P&L GM % | W4: Won vs Billed Gap | X4: Cash on Hand | Y4: DSO | Z4: AR Total | AA4: AP Total | AB4: Payroll % Rev | AC4: Tickets Created | AD4: Tickets Resolved | AE4: Open Tickets | AF4: Avg Resolution (hrs) | AG4: SLA Compliance % | AH4: Svc Util (THUNDR) | AI4: Proj Util (TopGun) | AJ4: Company Util | AK4: Pipeline Value | AL4: Proposals Sent | AM4: Win Rate % | AN4: Opportunities
A5: 2025 | B5: Jan | C5: 1 | D5: Jan 06 – Jan 10 | E5: 2025-01-06 | K5: =IF(AND(F5<>"",J5<>"",J5<>0),F5/J5*100,"") | U5: =IF(AND(S5<>"",T5<>""),S5-T5,"") | V5: =IF(AND(U5<>"",S5<>"",S5<>0),U5/S5*100,"") | W5: =IF(AND(F5<>"",S5<>""),F5-S5,"")
A6: 2025 | B6: Jan | C6: 2 | D6: Jan 13 – Jan 17 | E6: 2025-01-13 | K6: =IF(AND(F6<>"",J6<>"",J6<>0),F6/J6*100,"") | U6: =IF(AND(S6<>"",T6<>""),S6-T6,"") | V6: =IF(AND(U6<>"",S6<>"",S6<>0),U6/S6*100,"") | W6: =IF(AND(F6<>"",S6<>""),F6-S6,"")
A7: 2025 | B7: Jan | C7: 3 | D7: Jan 20 – Jan 24 | E7: 2025-01-20 | K7: =IF(AND(F7<>"",J7<>"",J7<>0),F7/J7*100,"") | U7: =IF(AND(S7<>"",T7<>""),S7-T7,"") | V7: =IF(AND(U7<>"",S7<>"",S7<>0),U7/S7*100,"") | W7: =IF(AND(F7<>"",S7<>""),F7-S7,"")
A8: 2025 | B8: Jan | C8: 4 | D8: Jan 27 – Jan 31 | E8: 2025-01-27 | K8: =IF(AND(F8<>"",J8<>"",J8<>0),F8/J8*100,"") | U8: =IF(AND(S8<>"",T8<>""),S8-T8,"") | V8: =IF(AND(U8<>"",S8<>"",S8<>0),U8/S8*100,"") | W8: =IF(AND(F8<>"",S8<>""),F8-S8,"")
A9: 2025 | B9: Jan | D9: Jan 2025 TOTAL | F9: =IFERROR(SUM(F5:F8),"") -> 0 | G9: =IFERROR(SUM(G5:G8),"") -> 0 | H9: =IFERROR(LOOKUP(2,1/(H5:H8<>""),H5:H8),"") | I9: =IFERROR(LOOKUP(2,1/(I5:I8<>""),I5:I8),"") | J9: =IFERROR(LOOKUP(2,1/(J5:J8<>""),J5:J8),"") | K9: =IFERROR(LOOKUP(2,1/(K5:K8<>""),K5:K8),"") | L9: =IFERROR(SUM(L5:L8),"") -> 0 | M9: =IFERROR(SUM(M5:M8),"") -> 0 | N9: =IFERROR(SUM(N5:N8),"") -> 0 | O9: =IFERROR(SUM(O5:O8),"") -> 0 | P9: =IFERROR(SUM(P5:P8),"") -> 0 | Q9: =IFERROR(SUM(Q5:Q8),"") -> 0 | R9: =IFERROR(SUM(R5:R8),"") -> 0 | S9: =IFERROR(LOOKUP(2,1/(S5:S8<>""),S5:S8),"") | T9: =IFERROR(LOOKUP(2,1/(T5:T8<>""),T5:T8),"") | U9: =IFERROR(LOOKUP(2,1/(U5:U8<>""),U5:U8),"") | V9: =IFERROR(LOOKUP(2,1/(V5:V8<>""),V5:V8),"") | W9: =IFERROR(LOOKUP(2,1/(W5:W8<>""),W5:W8),"") | X9: =IFERROR(LOOKUP(2,1/(X5:X8<>""),X5:X8),"") | Y9: =IFERROR(LOOKUP(2,1/(Y5:Y8<>""),Y5:Y8),"") | Z9: =IFERROR(LOOKUP(2,1/(Z5:Z8<>""),Z5:Z8),"") | ... AB9: =IFERROR(LOOKUP(2,1/(AB5:AB8<>""),AB5:AB8),"") | AC9: =IFERROR(SUM(AC5:AC8),"") -> 0 | AD9: =IFERROR(SUM(AD5:AD8),"") -> 0 | AE9: =IFERROR(LOOKUP(2,1/(AE5:AE8<>""),AE5:AE8),"") | AF9: =IFERROR(LOOKUP(2,1/(AF5:AF8<>""),AF5:AF8),"") | AG9: =IFERROR(LOOKUP(2,1/(AG5:AG8<>""),AG5:AG8),"") | AH9: =IFERROR(LOOKUP(2,1/(AH5:AH8<>""),AH5:AH8),"") | AI9: =IFERROR(LOOKUP(2,1/(AI5:AI8<>""),AI5:AI8),"") | AJ9: =IFERROR(LOOKUP(2,1/(AJ5:AJ8<>""),AJ5:AJ8),"") | AK9: =IFERROR(LOOKUP(2,1/(AK5:AK8<>""),AK5:AK8),"") | AL9: =IFERROR(LOOKUP(2,1/(AL5:AL8<>""),AL5:AL8),"") | ... AN9: =IFERROR(LOOKUP(2,1/(AN5:AN8<>""),AN5:AN8),"")
A10: 2025 | B10: Feb | C10: 5 | D10: Feb 03 – Feb 07 | E10: 2025-02-03 | K10: =IF(AND(F10<>"",J10<>"",J10<>0),F10/J10*100,"") | U10: =IF(AND(S10<>"",T10<>""),S10-T10,"") | V10: =IF(AND(U10<>"",S10<>"",S10<>0),U10/S10*100,"") | W10: =IF(AND(F10<>"",S10<>""),F10-S10,"")
A11: 2025 | B11: Feb | C11: 6 | D11: Feb 10 – Feb 14 | E11: 2025-02-10 | K11: =IF(AND(F11<>"",J11<>"",J11<>0),F11/J11*100,"") | U11: =IF(AND(S11<>"",T11<>""),S11-T11,"") | V11: =IF(AND(U11<>"",S11<>"",S11<>0),U11/S11*100,"") | W11: =IF(AND(F11<>"",S11<>""),F11-S11,"")
A12: 2025 | B12: Feb | C12: 7 | D12: Feb 17 – Feb 21 | E12: 2025-02-17 | K12: =IF(AND(F12<>"",J12<>"",J12<>0),F12/J12*100,"") | U12: =IF(AND(S12<>"",T12<>""),S12-T12,"") | V12: =IF(AND(U12<>"",S12<>"",S12<>0),U12/S12*100,"") | W12: =IF(AND(F12<>"",S12<>""),F12-S12,"")
A13: 2025 | B13: Feb | C13: 8 | D13: Feb 24 – Feb 28 | E13: 2025-02-24 | K13: =IF(AND(F13<>"",J13<>"",J13<>0),F13/J13*100,"") | U13: =IF(AND(S13<>"",T13<>""),S13-T13,"") | V13: =IF(AND(U13<>"",S13<>"",S13<>0),U13/S13*100,"") | W13: =IF(AND(F13<>"",S13<>""),F13-S13,"")
A14: 2025 | B14: Feb | D14: Feb 2025 TOTAL | F14: =IFERROR(SUM(F10:F13),"") -> 0 | G14: =IFERROR(SUM(G10:G13),"") -> 0 | H14: =IFERROR(LOOKUP(2,1/(H10:H13<>""),H10:H13),"") | I14: =IFERROR(LOOKUP(2,1/(I10:I13<>""),I10:I13),"") | J14: =IFERROR(LOOKUP(2,1/(J10:J13<>""),J10:J13),"") | K14: =IFERROR(LOOKUP(2,1/(K10:K13<>""),K10:K13),"") | L14: =IFERROR(SUM(L10:L13),"") -> 0 | M14: =IFERROR(SUM(M10:M13),"") -> 0 | N14: =IFERROR(SUM(N10:N13),"") -> 0 | O14: =IFERROR(SUM(O10:O13),"") -> 0 | P14: =IFERROR(SUM(P10:P13),"") -> 0 | Q14: =IFERROR(SUM(Q10:Q13),"") -> 0 | R14: =IFERROR(SUM(R10:R13),"") -> 0 | S14: =IFERROR(LOOKUP(2,1/(S10:S13<>""),S10:S13),"") | T14: =IFERROR(LOOKUP(2,1/(T10:T13<>""),T10:T13),"") | U14: =IFERROR(LOOKUP(2,1/(U10:U13<>""),U10:U13),"") | V14: =IFERROR(LOOKUP(2,1/(V10:V13<>""),V10:V13),"") | W14: =IFERROR(LOOKUP(2,1/(W10:W13<>""),W10:W13),"") | X14: =IFERROR(LOOKUP(2,1/(X10:X13<>""),X10:X13),"") | Y14: =IFERROR(LOOKUP(2,1/(Y10:Y13<>""),Y10:Y13),"") | Z14: =IFERROR(LOOKUP(2,1/(Z10:Z13<>""),Z10:Z13),"") | ... AB14: =IFERROR(LOOKUP(2,1/(AB10:AB13<>""),AB10:AB13),"") | AC14: =IFERROR(SUM(AC10:AC13),"") -> 0 | AD14: =IFERROR(SUM(AD10:AD13),"") -> 0 | AE14: =IFERROR(LOOKUP(2,1/(AE10:AE13<>""),AE10:AE13),"") | AF14: =IFERROR(LOOKUP(2,1/(AF10:AF13<>""),AF10:AF13),"") | AG14: =IFERROR(LOOKUP(2,1/(AG10:AG13<>""),AG10:AG13),"") | AH14: =IFERROR(LOOKUP(2,1/(AH10:AH13<>""),AH10:AH13),"") | AI14: =IFERROR(LOOKUP(2,1/(AI10:AI13<>""),AI10:AI13),"") | AJ14: =IFERROR(LOOKUP(2,1/(AJ10:AJ13<>""),AJ10:AJ13),"") | AK14: =IFERROR(LOOKUP(2,1/(AK10:AK13<>""),AK10:AK13),"") | AL14: =IFERROR(LOOKUP(2,1/(AL10:AL13<>""),AL10:AL13),"") | ... AN14: =IFERROR(LOOKUP(2,1/(AN10:AN13<>""),AN10:AN13),"")
A15: 2025 | B15: Mar | C15: 9 | D15: Mar 03 – Mar 07 | E15: 2025-03-03 | K15: =IF(AND(F15<>"",J15<>"",J15<>0),F15/J15*100,"") | U15: =IF(AND(S15<>"",T15<>""),S15-T15,"") | V15: =IF(AND(U15<>"",S15<>"",S15<>0),U15/S15*100,"") | W15: =IF(AND(F15<>"",S15<>""),F15-S15,"")
A16: 2025 | B16: Mar | C16: 10 | D16: Mar 10 – Mar 14 | E16: 2025-03-10 | K16: =IF(AND(F16<>"",J16<>"",J16<>0),F16/J16*100,"") | U16: =IF(AND(S16<>"",T16<>""),S16-T16,"") | V16: =IF(AND(U16<>"",S16<>"",S16<>0),U16/S16*100,"") | W16: =IF(AND(F16<>"",S16<>""),F16-S16,"")
A17: 2025 | B17: Mar | C17: 11 | D17: Mar 17 – Mar 21 | E17: 2025-03-17 | K17: =IF(AND(F17<>"",J17<>"",J17<>0),F17/J17*100,"") | U17: =IF(AND(S17<>"",T17<>""),S17-T17,"") | V17: =IF(AND(U17<>"",S17<>"",S17<>0),U17/S17*100,"") | W17: =IF(AND(F17<>"",S17<>""),F17-S17,"")
A18: 2025 | B18: Mar | C18: 12 | D18: Mar 24 – Mar 28 | E18: 2025-03-24 | K18: =IF(AND(F18<>"",J18<>"",J18<>0),F18/J18*100,"") | U18: =IF(AND(S18<>"",T18<>""),S18-T18,"") | V18: =IF(AND(U18<>"",S18<>"",S18<>0),U18/S18*100,"") | W18: =IF(AND(F18<>"",S18<>""),F18-S18,"")
A19: 2025 | B19: Mar | C19: 13 | D19: Mar 31 – Apr 04 | E19: 2025-03-31 | K19: =IF(AND(F19<>"",J19<>"",J19<>0),F19/J19*100,"") | U19: =IF(AND(S19<>"",T19<>""),S19-T19,"") | V19: =IF(AND(U19<>"",S19<>"",S19<>0),U19/S19*100,"") | W19: =IF(AND(F19<>"",S19<>""),F19-S19,"")
A20: 2025 | B20: Mar | D20: Mar 2025 TOTAL | F20: =IFERROR(SUM(F15:F19),"") -> 0 | G20: =IFERROR(SUM(G15:G19),"") -> 0 | H20: =IFERROR(LOOKUP(2,1/(H15:H19<>""),H15:H19),"") | I20: =IFERROR(LOOKUP(2,1/(I15:I19<>""),I15:I19),"") | J20: =IFERROR(LOOKUP(2,1/(J15:J19<>""),J15:J19),"") | K20: =IFERROR(LOOKUP(2,1/(K15:K19<>""),K15:K19),"") | L20: =IFERROR(SUM(L15:L19),"") -> 0 | M20: =IFERROR(SUM(M15:M19),"") -> 0 | N20: =IFERROR(SUM(N15:N19),"") -> 0 | O20: =IFERROR(SUM(O15:O19),"") -> 0 | P20: =IFERROR(SUM(P15:P19),"") -> 0 | Q20: =IFERROR(SUM(Q15:Q19),"") -> 0 | R20: =IFERROR(SUM(R15:R19),"") -> 0 | S20: =IFERROR(LOOKUP(2,1/(S15:S19<>""),S15:S19),"") | T20: =IFERROR(LOOKUP(2,1/(T15:T19<>""),T15:T19),"") | U20: =IFERROR(LOOKUP(2,1/(U15:U19<>""),U15:U19),"") | V20: =IFERROR(LOOKUP(2,1/(V15:V19<>""),V15:V19),"") | W20: =IFERROR(LOOKUP(2,1/(W15:W19<>""),W15:W19),"") | X20: =IFERROR(LOOKUP(2,1/(X15:X19<>""),X15:X19),"") | Y20: =IFERROR(LOOKUP(2,1/(Y15:Y19<>""),Y15:Y19),"") | Z20: =IFERROR(LOOKUP(2,1/(Z15:Z19<>""),Z15:Z19),"") | ... AB20: =IFERROR(LOOKUP(2,1/(AB15:AB19<>""),AB15:AB19),"") | AC20: =IFERROR(SUM(AC15:AC19),"") -> 0 | AD20: =IFERROR(SUM(AD15:AD19),"") -> 0 | AE20: =IFERROR(LOOKUP(2,1/(AE15:AE19<>""),AE15:AE19),"") | AF20: =IFERROR(LOOKUP(2,1/(AF15:AF19<>""),AF15:AF19),"") | AG20: =IFERROR(LOOKUP(2,1/(AG15:AG19<>""),AG15:AG19),"") | AH20: =IFERROR(LOOKUP(2,1/(AH15:AH19<>""),AH15:AH19),"") | AI20: =IFERROR(LOOKUP(2,1/(AI15:AI19<>""),AI15:AI19),"") | AJ20: =IFERROR(LOOKUP(2,1/(AJ15:AJ19<>""),AJ15:AJ19),"") | AK20: =IFERROR(LOOKUP(2,1/(AK15:AK19<>""),AK15:AK19),"") | AL20: =IFERROR(LOOKUP(2,1/(AL15:AL19<>""),AL15:AL19),"") | ... AN20: =IFERROR(LOOKUP(2,1/(AN15:AN19<>""),AN15:AN19),"")
A21: 2025 | B21: Apr | C21: 14 | D21: Apr 07 – Apr 11 | E21: 2025-04-07 | K21: =IF(AND(F21<>"",J21<>"",J21<>0),F21/J21*100,"") | U21: =IF(AND(S21<>"",T21<>""),S21-T21,"") | V21: =IF(AND(U21<>"",S21<>"",S21<>0),U21/S21*100,"") | W21: =IF(AND(F21<>"",S21<>""),F21-S21,"")
A22: 2025 | B22: Apr | C22: 15 | D22: Apr 14 – Apr 18 | E22: 2025-04-14 | K22: =IF(AND(F22<>"",J22<>"",J22<>0),F22/J22*100,"") | U22: =IF(AND(S22<>"",T22<>""),S22-T22,"") | V22: =IF(AND(U22<>"",S22<>"",S22<>0),U22/S22*100,"") | W22: =IF(AND(F22<>"",S22<>""),F22-S22,"")
A23: 2025 | B23: Apr | C23: 16 | D23: Apr 21 – Apr 25 | E23: 2025-04-21 | K23: =IF(AND(F23<>"",J23<>"",J23<>0),F23/J23*100,"") | U23: =IF(AND(S23<>"",T23<>""),S23-T23,"") | V23: =IF(AND(U23<>"",S23<>"",S23<>0),U23/S23*100,"") | W23: =IF(AND(F23<>"",S23<>""),F23-S23,"")
A24: 2025 | B24: Apr | C24: 17 | D24: Apr 28 – May 02 | E24: 2025-04-28 | K24: =IF(AND(F24<>"",J24<>"",J24<>0),F24/J24*100,"") | U24: =IF(AND(S24<>"",T24<>""),S24-T24,"") | V24: =IF(AND(U24<>"",S24<>"",S24<>0),U24/S24*100,"") | W24: =IF(AND(F24<>"",S24<>""),F24-S24,"")
A25: 2025 | B25: Apr | D25: Apr 2025 TOTAL | F25: =IFERROR(SUM(F21:F24),"") -> 0 | G25: =IFERROR(SUM(G21:G24),"") -> 0 | H25: =IFERROR(LOOKUP(2,1/(H21:H24<>""),H21:H24),"") | I25: =IFERROR(LOOKUP(2,1/(I21:I24<>""),I21:I24),"") | J25: =IFERROR(LOOKUP(2,1/(J21:J24<>""),J21:J24),"") | K25: =IFERROR(LOOKUP(2,1/(K21:K24<>""),K21:K24),"") | L25: =IFERROR(SUM(L21:L24),"") -> 0 | M25: =IFERROR(SUM(M21:M24),"") -> 0 | N25: =IFERROR(SUM(N21:N24),"") -> 0 | O25: =IFERROR(SUM(O21:O24),"") -> 0 | P25: =IFERROR(SUM(P21:P24),"") -> 0 | Q25: =IFERROR(SUM(Q21:Q24),"") -> 0 | R25: =IFERROR(SUM(R21:R24),"") -> 0 | S25: =IFERROR(LOOKUP(2,1/(S21:S24<>""),S21:S24),"") | T25: =IFERROR(LOOKUP(2,1/(T21:T24<>""),T21:T24),"") | U25: =IFERROR(LOOKUP(2,1/(U21:U24<>""),U21:U24),"") | V25: =IFERROR(LOOKUP(2,1/(V21:V24<>""),V21:V24),"") | W25: =IFERROR(LOOKUP(2,1/(W21:W24<>""),W21:W24),"") | X25: =IFERROR(LOOKUP(2,1/(X21:X24<>""),X21:X24),"") | Y25: =IFERROR(LOOKUP(2,1/(Y21:Y24<>""),Y21:Y24),"") | Z25: =IFERROR(LOOKUP(2,1/(Z21:Z24<>""),Z21:Z24),"") | ... AB25: =IFERROR(LOOKUP(2,1/(AB21:AB24<>""),AB21:AB24),"") | AC25: =IFERROR(SUM(AC21:AC24),"") -> 0 | AD25: =IFERROR(SUM(AD21:AD24),"") -> 0 | AE25: =IFERROR(LOOKUP(2,1/(AE21:AE24<>""),AE21:AE24),"") | AF25: =IFERROR(LOOKUP(2,1/(AF21:AF24<>""),AF21:AF24),"") | AG25: =IFERROR(LOOKUP(2,1/(AG21:AG24<>""),AG21:AG24),"") | AH25: =IFERROR(LOOKUP(2,1/(AH21:AH24<>""),AH21:AH24),"") | AI25: =IFERROR(LOOKUP(2,1/(AI21:AI24<>""),AI21:AI24),"") | AJ25: =IFERROR(LOOKUP(2,1/(AJ21:AJ24<>""),AJ21:AJ24),"") | AK25: =IFERROR(LOOKUP(2,1/(AK21:AK24<>""),AK21:AK24),"") | AL25: =IFERROR(LOOKUP(2,1/(AL21:AL24<>""),AL21:AL24),"") | ... AN25: =IFERROR(LOOKUP(2,1/(AN21:AN24<>""),AN21:AN24),"")
A26: 2025 | B26: May | C26: 18 | D26: May 05 – May 09 | E26: 2025-05-05 | K26: =IF(AND(F26<>"",J26<>"",J26<>0),F26/J26*100,"") | U26: =IF(AND(S26<>"",T26<>""),S26-T26,"") | V26: =IF(AND(U26<>"",S26<>"",S26<>0),U26/S26*100,"") | W26: =IF(AND(F26<>"",S26<>""),F26-S26,"")
A27: 2025 | B27: May | C27: 19 | D27: May 12 – May 16 | E27: 2025-05-12 | K27: =IF(AND(F27<>"",J27<>"",J27<>0),F27/J27*100,"") | U27: =IF(AND(S27<>"",T27<>""),S27-T27,"") | V27: =IF(AND(U27<>"",S27<>"",S27<>0),U27/S27*100,"") | W27: =IF(AND(F27<>"",S27<>""),F27-S27,"")
A28: 2025 | B28: May | C28: 20 | D28: May 19 – May 23 | E28: 2025-05-19 | K28: =IF(AND(F28<>"",J28<>"",J28<>0),F28/J28*100,"") | U28: =IF(AND(S28<>"",T28<>""),S28-T28,"") | V28: =IF(AND(U28<>"",S28<>"",S28<>0),U28/S28*100,"") | W28: =IF(AND(F28<>"",S28<>""),F28-S28,"")
A29: 2025 | B29: May | C29: 21 | D29: May 26 – May 30 | E29: 2025-05-26 | K29: =IF(AND(F29<>"",J29<>"",J29<>0),F29/J29*100,"") | U29: =IF(AND(S29<>"",T29<>""),S29-T29,"") | V29: =IF(AND(U29<>"",S29<>"",S29<>0),U29/S29*100,"") | W29: =IF(AND(F29<>"",S29<>""),F29-S29,"")
A30: 2025 | B30: May | D30: May 2025 TOTAL | F30: =IFERROR(SUM(F26:F29),"") -> 0 | G30: =IFERROR(SUM(G26:G29),"") -> 0 | H30: =IFERROR(LOOKUP(2,1/(H26:H29<>""),H26:H29),"") | I30: =IFERROR(LOOKUP(2,1/(I26:I29<>""),I26:I29),"") | J30: =IFERROR(LOOKUP(2,1/(J26:J29<>""),J26:J29),"") | K30: =IFERROR(LOOKUP(2,1/(K26:K29<>""),K26:K29),"") | L30: =IFERROR(SUM(L26:L29),"") -> 0 | M30: =IFERROR(SUM(M26:M29),"") -> 0 | N30: =IFERROR(SUM(N26:N29),"") -> 0 | O30: =IFERROR(SUM(O26:O29),"") -> 0 | P30: =IFERROR(SUM(P26:P29),"") -> 0 | Q30: =IFERROR(SUM(Q26:Q29),"") -> 0 | R30: =IFERROR(SUM(R26:R29),"") -> 0 | S30: =IFERROR(LOOKUP(2,1/(S26:S29<>""),S26:S29),"") | T30: =IFERROR(LOOKUP(2,1/(T26:T29<>""),T26:T29),"") | U30: =IFERROR(LOOKUP(2,1/(U26:U29<>""),U26:U29),"") | V30: =IFERROR(LOOKUP(2,1/(V26:V29<>""),V26:V29),"") | W30: =IFERROR(LOOKUP(2,1/(W26:W29<>""),W26:W29),"") | X30: =IFERROR(LOOKUP(2,1/(X26:X29<>""),X26:X29),"") | Y30: =IFERROR(LOOKUP(2,1/(Y26:Y29<>""),Y26:Y29),"") | Z30: =IFERROR(LOOKUP(2,1/(Z26:Z29<>""),Z26:Z29),"") | ... AB30: =IFERROR(LOOKUP(2,1/(AB26:AB29<>""),AB26:AB29),"") | AC30: =IFERROR(SUM(AC26:AC29),"") -> 0 | AD30: =IFERROR(SUM(AD26:AD29),"") -> 0 | AE30: =IFERROR(LOOKUP(2,1/(AE26:AE29<>""),AE26:AE29),"") | AF30: =IFERROR(LOOKUP(2,1/(AF26:AF29<>""),AF26:AF29),"") | AG30: =IFERROR(LOOKUP(2,1/(AG26:AG29<>""),AG26:AG29),"") | AH30: =IFERROR(LOOKUP(2,1/(AH26:AH29<>""),AH26:AH29),"") | AI30: =IFERROR(LOOKUP(2,1/(AI26:AI29<>""),AI26:AI29),"") | AJ30: =IFERROR(LOOKUP(2,1/(AJ26:AJ29<>""),AJ26:AJ29),"") | AK30: =IFERROR(LOOKUP(2,1/(AK26:AK29<>""),AK26:AK29),"") | AL30: =IFERROR(LOOKUP(2,1/(AL26:AL29<>""),AL26:AL29),"") | ... AN30: =IFERROR(LOOKUP(2,1/(AN26:AN29<>""),AN26:AN29),"")
A31: 2025 | B31: Jun | C31: 22 | D31: Jun 02 – Jun 06 | E31: 2025-06-02 | K31: =IF(AND(F31<>"",J31<>"",J31<>0),F31/J31*100,"") | U31: =IF(AND(S31<>"",T31<>""),S31-T31,"") | V31: =IF(AND(U31<>"",S31<>"",S31<>0),U31/S31*100,"") | W31: =IF(AND(F31<>"",S31<>""),F31-S31,"")
A32: 2025 | B32: Jun | C32: 23 | D32: Jun 09 – Jun 13 | E32: 2025-06-09 | K32: =IF(AND(F32<>"",J32<>"",J32<>0),F32/J32*100,"") | U32: =IF(AND(S32<>"",T32<>""),S32-T32,"") | V32: =IF(AND(U32<>"",S32<>"",S32<>0),U32/S32*100,"") | W32: =IF(AND(F32<>"",S32<>""),F32-S32,"")
A33: 2025 | B33: Jun | C33: 24 | D33: Jun 16 – Jun 20 | E33: 2025-06-16 | K33: =IF(AND(F33<>"",J33<>"",J33<>0),F33/J33*100,"") | U33: =IF(AND(S33<>"",T33<>""),S33-T33,"") | V33: =IF(AND(U33<>"",S33<>"",S33<>0),U33/S33*100,"") | W33: =IF(AND(F33<>"",S33<>""),F33-S33,"")
A34: 2025 | B34: Jun | C34: 25 | D34: Jun 23 – Jun 27 | E34: 2025-06-23 | K34: =IF(AND(F34<>"",J34<>"",J34<>0),F34/J34*100,"") | U34: =IF(AND(S34<>"",T34<>""),S34-T34,"") | V34: =IF(AND(U34<>"",S34<>"",S34<>0),U34/S34*100,"") | W34: =IF(AND(F34<>"",S34<>""),F34-S34,"")
A35: 2025 | B35: Jun | C35: 26 | D35: Jun 30 – Jul 04 | E35: 2025-06-30 | K35: =IF(AND(F35<>"",J35<>"",J35<>0),F35/J35*100,"") | U35: =IF(AND(S35<>"",T35<>""),S35-T35,"") | V35: =IF(AND(U35<>"",S35<>"",S35<>0),U35/S35*100,"") | W35: =IF(AND(F35<>"",S35<>""),F35-S35,"")
A36: 2025 | B36: Jun | D36: Jun 2025 TOTAL | F36: =IFERROR(SUM(F31:F35),"") -> 0 | G36: =IFERROR(SUM(G31:G35),"") -> 0 | H36: =IFERROR(LOOKUP(2,1/(H31:H35<>""),H31:H35),"") | I36: =IFERROR(LOOKUP(2,1/(I31:I35<>""),I31:I35),"") | J36: =IFERROR(LOOKUP(2,1/(J31:J35<>""),J31:J35),"") | K36: =IFERROR(LOOKUP(2,1/(K31:K35<>""),K31:K35),"") | L36: =IFERROR(SUM(L31:L35),"") -> 0 | M36: =IFERROR(SUM(M31:M35),"") -> 0 | N36: =IFERROR(SUM(N31:N35),"") -> 0 | O36: =IFERROR(SUM(O31:O35),"") -> 0 | P36: =IFERROR(SUM(P31:P35),"") -> 0 | Q36: =IFERROR(SUM(Q31:Q35),"") -> 0 | R36: =IFERROR(SUM(R31:R35),"") -> 0 | S36: =IFERROR(LOOKUP(2,1/(S31:S35<>""),S31:S35),"") | T36: =IFERROR(LOOKUP(2,1/(T31:T35<>""),T31:T35),"") | U36: =IFERROR(LOOKUP(2,1/(U31:U35<>""),U31:U35),"") | V36: =IFERROR(LOOKUP(2,1/(V31:V35<>""),V31:V35),"") | W36: =IFERROR(LOOKUP(2,1/(W31:W35<>""),W31:W35),"") | X36: =IFERROR(LOOKUP(2,1/(X31:X35<>""),X31:X35),"") | Y36: =IFERROR(LOOKUP(2,1/(Y31:Y35<>""),Y31:Y35),"") | Z36: =IFERROR(LOOKUP(2,1/(Z31:Z35<>""),Z31:Z35),"") | ... AB36: =IFERROR(LOOKUP(2,1/(AB31:AB35<>""),AB31:AB35),"") | AC36: =IFERROR(SUM(AC31:AC35),"") -> 0 | AD36: =IFERROR(SUM(AD31:AD35),"") -> 0 | AE36: =IFERROR(LOOKUP(2,1/(AE31:AE35<>""),AE31:AE35),"") | AF36: =IFERROR(LOOKUP(2,1/(AF31:AF35<>""),AF31:AF35),"") | AG36: =IFERROR(LOOKUP(2,1/(AG31:AG35<>""),AG31:AG35),"") | AH36: =IFERROR(LOOKUP(2,1/(AH31:AH35<>""),AH31:AH35),"") | AI36: =IFERROR(LOOKUP(2,1/(AI31:AI35<>""),AI31:AI35),"") | AJ36: =IFERROR(LOOKUP(2,1/(AJ31:AJ35<>""),AJ31:AJ35),"") | AK36: =IFERROR(LOOKUP(2,1/(AK31:AK35<>""),AK31:AK35),"") | AL36: =IFERROR(LOOKUP(2,1/(AL31:AL35<>""),AL31:AL35),"") | ... AN36: =IFERROR(LOOKUP(2,1/(AN31:AN35<>""),AN31:AN35),"")
A37: 2025 | B37: Jul | C37: 27 | D37: Jul 07 – Jul 11 | E37: 2025-07-07 | K37: =IF(AND(F37<>"",J37<>"",J37<>0),F37/J37*100,"") | U37: =IF(AND(S37<>"",T37<>""),S37-T37,"") | V37: =IF(AND(U37<>"",S37<>"",S37<>0),U37/S37*100,"") | W37: =IF(AND(F37<>"",S37<>""),F37-S37,"")
A38: 2025 | B38: Jul | C38: 28 | D38: Jul 14 – Jul 18 | E38: 2025-07-14 | K38: =IF(AND(F38<>"",J38<>"",J38<>0),F38/J38*100,"") | U38: =IF(AND(S38<>"",T38<>""),S38-T38,"") | V38: =IF(AND(U38<>"",S38<>"",S38<>0),U38/S38*100,"") | W38: =IF(AND(F38<>"",S38<>""),F38-S38,"")
A39: 2025 | B39: Jul | C39: 29 | D39: Jul 21 – Jul 25 | E39: 2025-07-21 | K39: =IF(AND(F39<>"",J39<>"",J39<>0),F39/J39*100,"") | U39: =IF(AND(S39<>"",T39<>""),S39-T39,"") | V39: =IF(AND(U39<>"",S39<>"",S39<>0),U39/S39*100,"") | W39: =IF(AND(F39<>"",S39<>""),F39-S39,"")
A40: 2025 | B40: Jul | C40: 30 | D40: Jul 28 – Aug 01 | E40: 2025-07-28 | K40: =IF(AND(F40<>"",J40<>"",J40<>0),F40/J40*100,"") | U40: =IF(AND(S40<>"",T40<>""),S40-T40,"") | V40: =IF(AND(U40<>"",S40<>"",S40<>0),U40/S40*100,"") | W40: =IF(AND(F40<>"",S40<>""),F40-S40,"")
...

Sheet Monthly Dashboard
A1: DataPath — Monthly Dashboard (Auto-Populated from Weekly Data)
A2: All values auto-calculated from Weekly Data sheet. Cumulative metrics (revenue, tickets) are summed; snapshot metrics (cash, utilization) use end-of-month value.
A4: ── 2025 ──
A5: Metric | B5: Jan | C5: Feb | D5: Mar | E5: Apr | F5: May | G5: Jun | H5: Jul | I5: Aug | J5: Sep | K5: Oct | L5: Nov | M5: Dec | N5: YTD
A6: Total Revenue Won | B6: ='Weekly Data'!F9 -> 0 | C6: ='Weekly Data'!F14 -> 0 | D6: ='Weekly Data'!F20 -> 0 | E6: ='Weekly Data'!F25 -> 0 | F6: ='Weekly Data'!F30 -> 0 | G6: ='Weekly Data'!F36 -> 0 | H6: ='Weekly Data'!F41 -> 0 | I6: ='Weekly Data'!F46 -> 0 | J6: ='Weekly Data'!F52 -> 0 | K6: ='Weekly Data'!F57 -> 0 | L6: ='Weekly Data'!F62 -> 0 | N6: =SUM(B6:M6) -> 0
A7: NRR | B7: ='Weekly Data'!G9 -> 0 | C7: ='Weekly Data'!G14 -> 0 | D7: ='Weekly Data'!G20 -> 0 | E7: ='Weekly Data'!G25 -> 0 | F7: ='Weekly Data'!G30 -> 0 | G7: ='Weekly Data'!G36 -> 0 | H7: ='Weekly Data'!G41 -> 0 | I7: ='Weekly Data'!G46 -> 0 | J7: ='Weekly Data'!G52 -> 0 | K7: ='Weekly Data'!G57 -> 0 | L7: ='Weekly Data'!G62 -> 0 | N7: =SUM(B7:M7) -> 0
A8: Recurring Revenue (Mo) | B8: ='Weekly Data'!H9 | C8: ='Weekly Data'!H14 | D8: ='Weekly Data'!H20 | E8: ='Weekly Data'!H25 | F8: ='Weekly Data'!H30 | G8: ='Weekly Data'!H36 | H8: ='Weekly Data'!H41 | I8: ='Weekly Data'!H46 | J8: ='Weekly Data'!H52 | K8: ='Weekly Data'!H57 | L8: ='Weekly Data'!H62 | N8: =IFERROR(LOOKUP(2,1/(B8:M8<>""),B8:M8),"")
A9: P&L Gross Sales | B9: ='Weekly Data'!S9 | C9: ='Weekly Data'!S14 | D9: ='Weekly Data'!S20 | E9: ='Weekly Data'!S25 | F9: ='Weekly Data'!S30 | G9: ='Weekly Data'!S36 | H9: ='Weekly Data'!S41 | I9: ='Weekly Data'!S46 | J9: ='Weekly Data'!S52 | K9: ='Weekly Data'!S57 | L9: ='Weekly Data'!S62 | N9: =IFERROR(LOOKUP(2,1/(B9:M9<>""),B9:M9),"")
A10: P&L Gross Margin | B10: ='Weekly Data'!U9 | C10: ='Weekly Data'!U14 | D10: ='Weekly Data'!U20 | E10: ='Weekly Data'!U25 | F10: ='Weekly Data'!U30 | G10: ='Weekly Data'!U36 | H10: ='Weekly Data'!U41 | I10: ='Weekly Data'!U46 | J10: ='Weekly Data'!U52 | K10: ='Weekly Data'!U57 | L10: ='Weekly Data'!U62 | N10: =IFERROR(LOOKUP(2,1/(B10:M10<>""),B10:M10),"")
A11: P&L GM % | B11: ='Weekly Data'!V9 | C11: ='Weekly Data'!V14 | D11: ='Weekly Data'!V20 | E11: ='Weekly Data'!V25 | F11: ='Weekly Data'!V30 | G11: ='Weekly Data'!V36 | H11: ='Weekly Data'!V41 | I11: ='Weekly Data'!V46 | J11: ='Weekly Data'!V52 | K11: ='Weekly Data'!V57 | L11: ='Weekly Data'!V62 | N11: =IFERROR(AVERAGE(B11:M11),"")
A12: Won vs Billed Gap | B12: ='Weekly Data'!W9 | C12: ='Weekly Data'!W14 | D12: ='Weekly Data'!W20 | E12: ='Weekly Data'!W25 | F12: ='Weekly Data'!W30 | G12: ='Weekly Data'!W36 | H12: ='Weekly Data'!W41 | I12: ='Weekly Data'!W46 | J12: ='Weekly Data'!W52 | K12: ='Weekly Data'!W57 | L12: ='Weekly Data'!W62 | N12: =IFERROR(LOOKUP(2,1/(B12:M12<>""),B12:M12),"")
A13: Cash on Hand | B13: ='Weekly Data'!X9 | C13: ='Weekly Data'!X14 | D13: ='Weekly Data'!X20 | E13: ='Weekly Data'!X25 | F13: ='Weekly Data'!X30 | G13: ='Weekly Data'!X36 | H13: ='Weekly Data'!X41 | I13: ='Weekly Data'!X46 | J13: ='Weekly Data'!X52 -> 296137 | K13: ='Weekly Data'!X57 -> 1392460 | L13: ='Weekly Data'!X62 -> 2992325 | N13: =IFERROR(LOOKUP(2,1/(B13:M13<>""),B13:M13),"") -> 2992325
A14: DSO | B14: ='Weekly Data'!Y9 | C14: ='Weekly Data'!Y14 | D14: ='Weekly Data'!Y20 | E14: ='Weekly Data'!Y25 | F14: ='Weekly Data'!Y30 | G14: ='Weekly Data'!Y36 | H14: ='Weekly Data'!Y41 | I14: ='Weekly Data'!Y46 | J14: ='Weekly Data'!Y52 | K14: ='Weekly Data'!Y57 | L14: ='Weekly Data'!Y62 | N14: =IFERROR(LOOKUP(2,1/(B14:M14<>""),B14:M14),"")
A15: AR Total | B15: ='Weekly Data'!Z9 | C15: ='Weekly Data'!Z14 | D15: ='Weekly Data'!Z20 | E15: ='Weekly Data'!Z25 | F15: ='Weekly Data'!Z30 | G15: ='Weekly Data'!Z36 | H15: ='Weekly Data'!Z41 | I15: ='Weekly Data'!Z46 | J15: ='Weekly Data'!Z52 | K15: ='Weekly Data'!Z57 | L15: ='Weekly Data'!Z62 | N15: =IFERROR(LOOKUP(2,1/(B15:M15<>""),B15:M15),"")
A16: AP Total | B16: ='Weekly Data'!AA9 | C16: ='Weekly Data'!AA14 | D16: ='Weekly Data'!AA20 | E16: ='Weekly Data'!AA25 | F16: ='Weekly Data'!AA30 | G16: ='Weekly Data'!AA36 | H16: ='Weekly Data'!AA41 | I16: ='Weekly Data'!AA46 | J16: ='Weekly Data'!AA52 | K16: ='Weekly Data'!AA57 | L16: ='Weekly Data'!AA62 | N16: =IFERROR(LOOKUP(2,1/(B16:M16<>""),B16:M16),"")
A17: Payroll % Revenue | B17: ='Weekly Data'!AB9 | C17: ='Weekly Data'!AB14 | D17: ='Weekly Data'!AB20 | E17: ='Weekly Data'!AB25 | F17: ='Weekly Data'!AB30 | G17: ='Weekly Data'!AB36 | H17: ='Weekly Data'!AB41 | I17: ='Weekly Data'!AB46 | J17: ='Weekly Data'!AB52 | K17: ='Weekly Data'!AB57 | L17: ='Weekly Data'!AB62 | N17: =IFERROR(AVERAGE(B17:M17),"")
A18: Tickets Created | B18: ='Weekly Data'!AC9 -> 0 | C18: ='Weekly Data'!AC14 -> 0 | D18: ='Weekly Data'!AC20 -> 0 | E18: ='Weekly Data'!AC25 -> 0 | F18: ='Weekly Data'!AC30 -> 0 | G18: ='Weekly Data'!AC36 -> 0 | H18: ='Weekly Data'!AC41 -> 0 | I18: ='Weekly Data'!AC46 -> 0 | J18: ='Weekly Data'!AC52 -> 0 | K18: ='Weekly Data'!AC57 -> 0 | L18: ='Weekly Data'!AC62 -> 0 | N18: =SUM(B18:M18) -> 0
A19: Tickets Resolved | B19: ='Weekly Data'!AD9 -> 0 | C19: ='Weekly Data'!AD14 -> 0 | D19: ='Weekly Data'!AD20 -> 0 | E19: ='Weekly Data'!AD25 -> 0 | F19: ='Weekly Data'!AD30 -> 0 | G19: ='Weekly Data'!AD36 -> 0 | H19: ='Weekly Data'!AD41 -> 0 | I19: ='Weekly Data'!AD46 -> 0 | J19: ='Weekly Data'!AD52 -> 0 | K19: ='Weekly Data'!AD57 -> 0 | L19: ='Weekly Data'!AD62 -> 0 | N19: =SUM(B19:M19) -> 0
A20: Avg Resolution (hrs) | B20: ='Weekly Data'!AF9 | C20: ='Weekly Data'!AF14 | D20: ='Weekly Data'!AF20 | E20: ='Weekly Data'!AF25 | F20: ='Weekly Data'!AF30 | G20: ='Weekly Data'!AF36 | H20: ='Weekly Data'!AF41 | I20: ='Weekly Data'!AF46 | J20: ='Weekly Data'!AF52 | K20: ='Weekly Data'!AF57 | L20: ='Weekly Data'!AF62 | N20: =IFERROR(AVERAGE(B20:M20),"")
A21: Company Utilization % | B21: ='Weekly Data'!AJ9 | C21: ='Weekly Data'!AJ14 | D21: ='Weekly Data'!AJ20 | E21: ='Weekly Data'!AJ25 | F21: ='Weekly Data'!AJ30 | G21: ='Weekly Data'!AJ36 | H21: ='Weekly Data'!AJ41 | I21: ='Weekly Data'!AJ46 | J21: ='Weekly Data'!AJ52 | K21: ='Weekly Data'!AJ57 | L21: ='Weekly Data'!AJ62 | N21: =IFERROR(AVERAGE(B21:M21),"")
A22: Pipeline Value | B22: ='Weekly Data'!AK9 | C22: ='Weekly Data'!AK14 | D22: ='Weekly Data'!AK20 | E22: ='Weekly Data'!AK25 | F22: ='Weekly Data'!AK30 | G22: ='Weekly Data'!AK36 | H22: ='Weekly Data'!AK41 | I22: ='Weekly Data'!AK46 | J22: ='Weekly Data'!AK52 | K22: ='Weekly Data'!AK57 | L22: ='Weekly Data'!AK62 | N22: =IFERROR(LOOKUP(2,1/(B22:M22<>""),B22:M22),"")
A23: Win Rate % | B23: ='Weekly Data'!AM9 | C23: ='Weekly Data'!AM14 | D23: ='Weekly Data'!AM20 | E23: ='Weekly Data'!AM25 | F23: ='Weekly Data'!AM30 | G23: ='Weekly Data'!AM36 | H23: ='Weekly Data'!AM41 | I23: ='Weekly Data'!AM46 | J23: ='Weekly Data'!AM52 | K23: ='Weekly Data'!AM57 | L23: ='Weekly Data'!AM62 | N23: =IFERROR(AVERAGE(B23:M23),"")
A25: Revenue Won by Rep — 2025
A26: Joel Walker | B26: ='Weekly Data'!L9 -> 0 | C26: ='Weekly Data'!L14 -> 0 | D26: ='Weekly Data'!L20 -> 0 | E26: ='Weekly Data'!L25 -> 0 | F26: ='Weekly Data'!L30 -> 0 | G26: ='Weekly Data'!L36 -> 0 | H26: ='Weekly Data'!L41 -> 0 | I26: ='Weekly Data'!L46 -> 0 | J26: ='Weekly Data'!L52 -> 0 | K26: ='Weekly Data'!L57 -> 0 | L26: ='Weekly Data'!L62 -> 0 | N26: =SUM(B26:M26) -> 0
A27: Nathan La Fleche | B27: ='Weekly Data'!M9 -> 0 | C27: ='Weekly Data'!M14 -> 0 | D27: ='Weekly Data'!M20 -> 0 | E27: ='Weekly Data'!M25 -> 0 | F27: ='Weekly Data'!M30 -> 0 | G27: ='Weekly Data'!M36 -> 0 | H27: ='Weekly Data'!M41 -> 0 | I27: ='Weekly Data'!M46 -> 0 | J27: ='Weekly Data'!M52 -> 0 | K27: ='Weekly Data'!M57 -> 0 | L27: ='Weekly Data'!M62 -> 0 | N27: =SUM(B27:M27) -> 0
A28: Dan Sturdivant | B28: ='Weekly Data'!N9 -> 0 | C28: ='Weekly Data'!N14 -> 0 | D28: ='Weekly Data'!N20 -> 0 | E28: ='Weekly Data'!N25 -> 0 | F28: ='Weekly Data'!N30 -> 0 | G28: ='Weekly Data'!N36 -> 0 | H28: ='Weekly Data'!N41 -> 0 | I28: ='Weekly Data'!N46 -> 0 | J28: ='Weekly Data'!N52 -> 0 | K28: ='Weekly Data'!N57 -> 0 | L28: ='Weekly Data'!N62 -> 0 | N28: =SUM(B28:M28) -> 0
A29: Jay Harvey | B29: ='Weekly Data'!O9 -> 0 | C29: ='Weekly Data'!O14 -> 0 | D29: ='Weekly Data'!O20 -> 0 | E29: ='Weekly Data'!O25 -> 0 | F29: ='Weekly Data'!O30 -> 0 | G29: ='Weekly Data'!O36 -> 0 | H29: ='Weekly Data'!O41 -> 0 | I29: ='Weekly Data'!O46 -> 0 | J29: ='Weekly Data'!O52 -> 0 | K29: ='Weekly Data'!O57 -> 0 | L29: ='Weekly Data'!O62 -> 0 | N29: =SUM(B29:M29) -> 0
A30: Ricky Maestas | B30: ='Weekly Data'!P9 -> 0 | C30: ='Weekly Data'!P14 -> 0 | D30: ='Weekly Data'!P20 -> 0 | E30: ='Weekly Data'!P25 -> 0 | F30: ='Weekly Data'!P30 -> 0 | G30: ='Weekly Data'!P36 -> 0 | H30: ='Weekly Data'!P41 -> 0 | I30: ='Weekly Data'!P46 -> 0 | J30: ='Weekly Data'!P52 -> 0 | K30: ='Weekly Data'!P57 -> 0 | L30: ='Weekly Data'!P62 -> 0 | N30: =SUM(B30:M30) -> 0
A31: Maria Martinez | B31: ='Weekly Data'!Q9 -> 0 | C31: ='Weekly Data'!Q14 -> 0 | D31: ='Weekly Data'!Q20 -> 0 | E31: ='Weekly Data'!Q25 -> 0 | F31: ='Weekly Data'!Q30 -> 0 | G31: ='Weekly Data'!Q36 -> 0 | H31: ='Weekly Data'!Q41 -> 0 | I31: ='Weekly Data'!Q46 -> 0 | J31: ='Weekly Data'!Q52 -> 0 | K31: ='Weekly Data'!Q57 -> 0 | L31: ='Weekly Data'!Q62 -> 0 | N31: =SUM(B31:M31) -> 0
A32: Julissa Martinez | B32: ='Weekly Data'!R9 -> 0 | C32: ='Weekly Data'!R14 -> 0 | D32: ='Weekly Data'!R20 -> 0 | E32: ='Weekly Data'!R25 -> 0 | F32: ='Weekly Data'!R30 -> 0 | G32: ='Weekly Data'!R36 -> 0 | H32: ='Weekly Data'!R41 -> 0 | I32: ='Weekly Data'!R46 -> 0 | J32: ='Weekly Data'!R52 -> 0 | K32: ='Weekly Data'!R57 -> 0 | L32: ='Weekly Data'!R62 -> 0 | N32: =SUM(B32:M32) -> 0
A33: TEAM TOTAL | B33: =SUM(B26:B32) -> 0 | C33: =SUM(C26:C32) -> 0 | D33: =SUM(D26:D32) -> 0 | E33: =SUM(E26:E32) -> 0 | F33: =SUM(F26:F32) -> 0 | G33: =SUM(G26:G32) -> 0 | H33: =SUM(H26:H32) -> 0 | I33: =SUM(I26:I32) -> 0 | ... N33: =SUM(N26:N32) -> 0
A35: ── 2026 ──
A36: Metric | B36: Jan | C36: Feb | D36: Mar | E36: Apr | F36: May | G36: Jun | H36: Jul | I36: Aug | J36: Sep | K36: Oct | L36: Nov | M36: Dec | N36: YTD
A37: Total Revenue Won | B37: ='Weekly Data'!F72 -> 0 | C37: ='Weekly Data'!F77 -> 782928 | D37: ='Weekly Data'!F83 -> 0 | E37: ='Weekly Data'!F88 -> 0 | F37: ='Weekly Data'!F93 -> 0 | G37: ='Weekly Data'!F99 -> 0 | H37: ='Weekly Data'!F104 -> 0 | I37: ='Weekly Data'!F110 -> 0 | J37: ='Weekly Data'!F115 -> 0 | K37: ='Weekly Data'!F120 -> 0 | L37: ='Weekly Data'!F126 -> 0 | M37: ='Weekly Data'!F131 -> 0 | N37: =SUM(B37:M37) -> 782928
A38: NRR | B38: ='Weekly Data'!G72 -> 0 | C38: ='Weekly Data'!G77 -> 384814 | D38: ='Weekly Data'!G83 -> 0 | E38: ='Weekly Data'!G88 -> 0 | F38: ='Weekly Data'!G93 -> 0 | G38: ='Weekly Data'!G99 -> 0 | H38: ='Weekly Data'!G104 -> 0 | I38: ='Weekly Data'!G110 -> 0 | J38: ='Weekly Data'!G115 -> 0 | K38: ='Weekly Data'!G120 -> 0 | L38: ='Weekly Data'!G126 -> 0 | M38: ='Weekly Data'!G131 -> 0 | N38: =SUM(B38:M38) -> 384814
A39: Recurring Revenue (Mo) | B39: ='Weekly Data'!H72 | C39: ='Weekly Data'!H77 -> 33176 | D39: ='Weekly Data'!H83 | E39: ='Weekly Data'!H88 | F39: ='Weekly Data'!H93 | G39: ='Weekly Data'!H99 | H39: ='Weekly Data'!H104 | I39: ='Weekly Data'!H110 | J39: ='Weekly Data'!H115 | K39: ='Weekly Data'!H120 | L39: ='Weekly Data'!H126 | M39: ='Weekly Data'!H131 | N39: =IFERROR(LOOKUP(2,1/(B39:M39<>""),B39:M39),"") -> 33176
A40: P&L Gross Sales | B40: ='Weekly Data'!S72 -> 1385716 | C40: ='Weekly Data'!S77 -> 1292505 | D40: ='Weekly Data'!S83 | E40: ='Weekly Data'!S88 | F40: ='Weekly Data'!S93 | G40: ='Weekly Data'!S99 | H40: ='Weekly Data'!S104 | I40: ='Weekly Data'!S110 | J40: ='Weekly Data'!S115 | K40: ='Weekly Data'!S120 | L40: ='Weekly Data'!S126 | M40: ='Weekly Data'!S131 | N40: =IFERROR(LOOKUP(2,1/(B40:M40<>""),B40:M40),"") -> 1292505
A41: P&L Gross Margin | B41: ='Weekly Data'!U72 -> 530251 | C41: ='Weekly Data'!U77 -> 613819 | D41: ='Weekly Data'!U83 | E41: ='Weekly Data'!U88 | F41: ='Weekly Data'!U93 | G41: ='Weekly Data'!U99 | H41: ='Weekly Data'!U104 | I41: ='Weekly Data'!U110 | J41: ='Weekly Data'!U115 | K41: ='Weekly Data'!U120 | L41: ='Weekly Data'!U126 | M41: ='Weekly Data'!U131 | N41: =IFERROR(LOOKUP(2,1/(B41:M41<>""),B41:M41),"") -> 613819
A42: P&L GM % | B42: ='Weekly Data'!V72 -> 38.265489 | C42: ='Weekly Data'!V77 -> 47.490648 | D42: ='Weekly Data'!V83 | E42: ='Weekly Data'!V88 | F42: ='Weekly Data'!V93 | G42: ='Weekly Data'!V99 | H42: ='Weekly Data'!V104 | I42: ='Weekly Data'!V110 | J42: ='Weekly Data'!V115 | K42: ='Weekly Data'!V120 | L42: ='Weekly Data'!V126 | M42: ='Weekly Data'!V131 | N42: =IFERROR(AVERAGE(B42:M42),"") -> 42.878068
A43: Won vs Billed Gap | B43: ='Weekly Data'!W72 | C43: ='Weekly Data'!W77 -> -509577 | D43: ='Weekly Data'!W83 | E43: ='Weekly Data'!W88 | F43: ='Weekly Data'!W93 | G43: ='Weekly Data'!W99 | H43: ='Weekly Data'!W104 | I43: ='Weekly Data'!W110 | J43: ='Weekly Data'!W115 | K43: ='Weekly Data'!W120 | L43: ='Weekly Data'!W126 | M43: ='Weekly Data'!W131 | N43: =IFERROR(LOOKUP(2,1/(B43:M43<>""),B43:M43),"") -> -509577
...

Sheet WoW Trends
A1: DataPath — Week-over-Week Change Tracker
A2: Auto-calculated deltas between consecutive weeks. Positive changes in green, negative in red (reversed for cost metrics).
A4: Metric | B4: Jan 05 | C4: Jan 12 | D4: Jan 19 | E4: Jan 26 | F4: Feb 02 | G4: Feb 09 | H4: Feb 16 | I4: Feb 23 | J4: Mar 02 | K4: Mar 09 | L4: Mar 16 | M4: Mar 23 | N4: Mar 30 | O4: Apr 06 | P4: Apr 13 | Q4: Apr 20 | R4: Apr 27 | S4: May 04 | T4: May 11 | U4: May 18 | V4: May 25 | W4: Jun 01 | X4: Jun 08 | Y4: Jun 15 | Z4: Jun 22 | AA4: Jun 29
A5: Total Rev Won (Δ) | B5: =IFERROR(INDEX('Weekly Data'!F:$F,MATCH("2026-01-05",'Weekly Data'!$E:$E,0)),"") -> 0 | C5: =IFERROR(INDEX('Weekly Data'!F:$F,MATCH("2026-01-12",'Weekly Data'!$E:$E,0))-INDEX('Weekly Data'!F:$F,MATCH("2026-01-05",'Weekly Data'!$E:$E,0)),"") -> 0 | D5: =IFERROR(INDEX('Weekly Data'!F:$F,MATCH("2026-01-19",'Weekly Data'!$E:$E,0))-INDEX('Weekly Data'!F:$F,MATCH("2026-01-12",'Weekly Data'!$E:$E,0)),"") -> 0 | E5: =IFERROR(INDEX('Weekly Data'!F:$F,MATCH("2026-01-26",'Weekly Data'!$E:$E,0))-INDEX('Weekly Data'!F:$F,MATCH("2026-01-19",'Weekly Data'!$E:$E,0)),"") -> 0 | F5: =IFERROR(INDEX('Weekly Data'!F:$F,MATCH("2026-02-02",'Weekly Data'!$E:$E,0))-INDEX('Weekly Data'!F:$F,MATCH("2026-01-26",'Weekly Data'!$E:$E,0)),"") -> 0 | G5: =IFERROR(INDEX('Weekly Data'!F:$F,MATCH("2026-02-09",'Weekly Data'!$E:$E,0))-INDEX('Weekly Data'!F:$F,MATCH("2026-02-02",'Weekly Data'!$E:$E,0)),"") -> 0 | H5: =IFERROR(INDEX('Weekly Data'!F:$F,MATCH("2026-02-16",'Weekly Data'!$E:$E,0))-INDEX('Weekly Data'!F:$F,MATCH("2026-02-09",'Weekly Data'!$E:$E,0)),"") -> 0 | I5: =IFERROR(INDEX('Weekly Data'!F:$F,MATCH("2026-02-23",'Weekly Data'!$E:$E,0))-INDEX('Weekly Data'!F:$F,MATCH("2026-02-16",'Weekly Data'!$E:$E,0)),"") -> 782928 | J5: =IFERROR(INDEX('Weekly Data'!F:$F,MATCH("2026-03-02",'Weekly Data'!$E:$E,0))-INDEX('Weekly Data'!F:$F,MATCH("2026-02-23",'Weekly Data'!$E:$E,0)),"") -> -782928 | K5: =IFERROR(INDEX('Weekly Data'!F:$F,MATCH("2026-03-09",'Weekly Data'!$E:$E,0))-INDEX('Weekly Data'!F:$F,MATCH("2026-03-02",'Weekly Data'!$E:$E,0)),"") -> 0 | L5: =IFERROR(INDEX('Weekly Data'!F:$F,MATCH("2026-03-16",'Weekly Data'!$E:$E,0))-INDEX('Weekly Data'!F:$F,MATCH("2026-03-09",'Weekly Data'!$E:$E,0)),"") -> 0 | M5: =IFERROR(INDEX('Weekly Data'!F:$F,MATCH("2026-03-23",'Weekly Data'!$E:$E,0))-INDEX('Weekly Data'!F:$F,MATCH("2026-03-16",'Weekly Data'!$E:$E,0)),"") -> 0 | N5: =IFERROR(INDEX('Weekly Data'!F:$F,MATCH("2026-03-30",'Weekly Data'!$E:$E,0))-INDEX('Weekly Data'!F:$F,MATCH("2026-03-23",'Weekly Data'!$E:$E,0)),"") -> 0 | O5: =IFERROR(INDEX('Weekly Data'!F:$F,MATCH("2026-04-06",'Weekly Data'!$E:$E,0))-INDEX('Weekly Data'!F:$F,MATCH("2026-03-30",'Weekly Data'!$E:$E,0)),"") -> 0 | P5: =IFERROR(INDEX('Weekly Data'!F:$F,MATCH("2026-04-13",'Weekly Data'!$E:$E,0))-INDEX('Weekly Data'!F:$F,MATCH("2026-04-06",'Weekly Data'!$E:$E,0)),"") -> 0 | Q5: =IFERROR(INDEX('Weekly Data'!F:$F,MATCH("2026-04-20",'Weekly Data'!$E:$E,0))-INDEX('Weekly Data'!F:$F,MATCH("2026-04-13",'Weekly Data'!$E:$E,0)),"") -> 0 | R5: =IFERROR(INDEX('Weekly Data'!F:$F,MATCH("2026-04-27",'Weekly Data'!$E:$E,0))-INDEX('Weekly Data'!F:$F,MATCH("2026-04-20",'Weekly Data'!$E:$E,0)),"") -> 0 | S5: =IFERROR(INDEX('Weekly Data'!F:$F,MATCH("2026-05-04",'Weekly Data'!$E:$E,0))-INDEX('Weekly Data'!F:$F,MATCH("2026-04-27",'Weekly Data'!$E:$E,0)),"") -> 0 | T5: =IFERROR(INDEX('Weekly Data'!F:$F,MATCH("2026-05-11",'Weekly Data'!$E:$E,0))-INDEX('Weekly Data'!F:$F,MATCH("2026-05-04",'Weekly Data'!$E:$E,0)),"") -> 0 | U5: =IFERROR(INDEX('Weekly Data'!F:$F,MATCH("2026-05-18",'Weekly Data'!$E:$E,0))-INDEX('Weekly Data'!F:$F,MATCH("2026-05-11",'Weekly Data'!$E:$E,0)),"") -> 0 | V5: =IFERROR(INDEX('Weekly Data'!F:$F,MATCH("2026-05-25",'Weekly Data'!$E:$E,0))-INDEX('Weekly Data'!F:$F,MATCH("2026-05-18",'Weekly Data'!$E:$E,0)),"") -> 0 | W5: =IFERROR(INDEX('Weekly Data'!F:$F,MATCH("2026-06-01",'Weekly Data'!$E:$E,0))-INDEX('Weekly Data'!F:$F,MATCH("2026-05-25",'Weekly Data'!$E:$E,0)),"") -> 0 | X5: =IFERROR(INDEX('Weekly Data'!F:$F,MATCH("2026-06-08",'Weekly Data'!$E:$E,0))-INDEX('Weekly Data'!F:$F,MATCH("2026-06-01",'Weekly Data'!$E:$E,0)),"") -> 0 | Y5: =IFERROR(INDEX('Weekly Data'!F:$F,MATCH("2026-06-15",'Weekly Data'!$E:$E,0))-INDEX('Weekly Data'!F:$F,MATCH("2026-06-08",'Weekly Data'!$E:$E,0)),"") -> 0 | Z5: =IFERROR(INDEX('Weekly Data'!F:$F,MATCH("2026-06-22",'Weekly Data'!$E:$E,0))-INDEX('Weekly Data'!F:$F,MATCH("2026-06-15",'Weekly Data'!$E:$E,0)),"") -> 0 | AA5: =IFERROR(INDEX('Weekly Data'!F:$F,MATCH("2026-06-29",'Weekly Data'!$E:$E,0))-INDEX('Weekly Data'!F:$F,MATCH("2026-06-22",'Weekly Data'!$E:$E,0)),"") -> 0
A6: P&L Gross Sales (Δ) | B6: =IFERROR(INDEX('Weekly Data'!S:$S,MATCH("2026-01-05",'Weekly Data'!$E:$E,0)),"") -> 0 | C6: =IFERROR(INDEX('Weekly Data'!S:$S,MATCH("2026-01-12",'Weekly Data'!$E:$E,0))-INDEX('Weekly Data'!S:$S,MATCH("2026-01-05",'Weekly Data'!$E:$E,0)),"") -> 0 | D6: =IFERROR(INDEX('Weekly Data'!S:$S,MATCH("2026-01-19",'Weekly Data'!$E:$E,0))-INDEX('Weekly Data'!S:$S,MATCH("2026-01-12",'Weekly Data'!$E:$E,0)),"") -> 0 | E6: =IFERROR(INDEX('Weekly Data'!S:$S,MATCH("2026-01-26",'Weekly Data'!$E:$E,0))-INDEX('Weekly Data'!S:$S,MATCH("2026-01-19",'Weekly Data'!$E:$E,0)),"") -> 1385716 | F6: =IFERROR(INDEX('Weekly Data'!S:$S,MATCH("2026-02-02",'Weekly Data'!$E:$E,0))-INDEX('Weekly Data'!S:$S,MATCH("2026-01-26",'Weekly Data'!$E:$E,0)),"") -> -1385716 | G6: =IFERROR(INDEX('Weekly Data'!S:$S,MATCH("2026-02-09",'Weekly Data'!$E:$E,0))-INDEX('Weekly Data'!S:$S,MATCH("2026-02-02",'Weekly Data'!$E:$E,0)),"") -> 0 | H6: =IFERROR(INDEX('Weekly Data'!S:$S,MATCH("2026-02-16",'Weekly Data'!$E:$E,0))-INDEX('Weekly Data'!S:$S,MATCH("2026-02-09",'Weekly Data'!$E:$E,0)),"") -> 0 | I6: =IFERROR(INDEX('Weekly Data'!S:$S,MATCH("2026-02-23",'Weekly Data'!$E:$E,0))-INDEX('Weekly Data'!S:$S,MATCH("2026-02-16",'Weekly Data'!$E:$E,0)),"") -> 1292505 | J6: =IFERROR(INDEX('Weekly Data'!S:$S,MATCH("2026-03-02",'Weekly Data'!$E:$E,0))-INDEX('Weekly Data'!S:$S,MATCH("2026-02-23",'Weekly Data'!$E:$E,0)),"") -> -1292505 | K6: =IFERROR(INDEX('Weekly Data'!S:$S,MATCH("2026-03-09",'Weekly Data'!$E:$E,0))-INDEX('Weekly Data'!S:$S,MATCH("2026-03-02",'Weekly Data'!$E:$E,0)),"") -> 0 | L6: =IFERROR(INDEX('Weekly Data'!S:$S,MATCH("2026-03-16",'Weekly Data'!$E:$E,0))-INDEX('Weekly Data'!S:$S,MATCH("2026-03-09",'Weekly Data'!$E:$E,0)),"") -> 0 | M6: =IFERROR(INDEX('Weekly Data'!S:$S,MATCH("2026-03-23",'Weekly Data'!$E:$E,0))-INDEX('Weekly Data'!S:$S,MATCH("2026-03-16",'Weekly Data'!$E:$E,0)),"") -> 0 | N6: =IFERROR(INDEX('Weekly Data'!S:$S,MATCH("2026-03-30",'Weekly Data'!$E:$E,0))-INDEX('Weekly Data'!S:$S,MATCH("2026-03-23",'Weekly Data'!$E:$E,0)),"") -> 0 | O6: =IFERROR(INDEX('Weekly Data'!S:$S,MATCH("2026-04-06",'Weekly Data'!$E:$E,0))-INDEX('Weekly Data'!S:$S,MATCH("2026-03-30",'Weekly Data'!$E:$E,0)),"") -> 0 | P6: =IFERROR(INDEX('Weekly Data'!S:$S,MATCH("2026-04-13",'Weekly Data'!$E:$E,0))-INDEX('Weekly Data'!S:$S,MATCH("2026-04-06",'Weekly Data'!$E:$E,0)),"") -> 0 | Q6: =IFERROR(INDEX('Weekly Data'!S:$S,MATCH("2026-04-20",'Weekly Data'!$E:$E,0))-INDEX('Weekly Data'!S:$S,MATCH("2026-04-13",'Weekly Data'!$E:$E,0)),"") -> 0 | R6: =IFERROR(INDEX('Weekly Data'!S:$S,MATCH("2026-04-27",'Weekly Data'!$E:$E,0))-INDEX('Weekly Data'!S:$S,MATCH("2026-04-20",'Weekly Data'!$E:$E,0)),"") -> 0 | S6: =IFERROR(INDEX('Weekly Data'!S:$S,MATCH("2026-05-04",'Weekly Data'!$E:$E,0))-INDEX('Weekly Data'!S:$S,MATCH("2026-04-27",'Weekly Data'!$E:$E,0)),"") -> 0 | T6: =IFERROR(INDEX('Weekly Data'!S:$S,MATCH("2026-05-11",'Weekly Data'!$E:$E,0))-INDEX('Weekly Data'!S:$S,MATCH("2026-05-04",'Weekly Data'!$E:$E,0)),"") -> 0 | U6: =IFERROR(INDEX('Weekly Data'!S:$S,MATCH("2026-05-18",'Weekly Data'!$E:$E,0))-INDEX('Weekly Data'!S:$S,MATCH("2026-05-11",'Weekly Data'!$E:$E,0)),"") -> 0 | V6: =IFERROR(INDEX('Weekly Data'!S:$S,MATCH("2026-05-25",'Weekly Data'!$E:$E,0))-INDEX('Weekly Data'!S:$S,MATCH("2026-05-18",'Weekly Data'!$E:$E,0)),"") -> 0 | W6: =IFERROR(INDEX('Weekly Data'!S:$S,MATCH("2026-06-01",'Weekly Data'!$E:$E,0))-INDEX('Weekly Data'!S:$S,MATCH("2026-05-25",'Weekly Data'!$E:$E,0)),"") -> 0 | X6: =IFERROR(INDEX('Weekly Data'!S:$S,MATCH("2026-06-08",'Weekly Data'!$E:$E,0))-INDEX('Weekly Data'!S:$S,MATCH("2026-06-01",'Weekly Data'!$E:$E,0)),"") -> 0 | Y6: =IFERROR(INDEX('Weekly Data'!S:$S,MATCH("2026-06-15",'Weekly Data'!$E:$E,0))-INDEX('Weekly Data'!S:$S,MATCH("2026-06-08",'Weekly Data'!$E:$E,0)),"") -> 0 | Z6: =IFERROR(INDEX('Weekly Data'!S:$S,MATCH("2026-06-22",'Weekly Data'!$E:$E,0))-INDEX('Weekly Data'!S:$S,MATCH("2026-06-15",'Weekly Data'!$E:$E,0)),"") -> 0 | AA6: =IFERROR(INDEX('Weekly Data'!S:$S,MATCH("2026-06-29",'Weekly Data'!$E:$E,0))-INDEX('Weekly Data'!S:$S,MATCH("2026-06-22",'Weekly Data'!$E:$E,0)),"") -> 0
A7: Cash on Hand (Δ) | B7: =IFERROR(INDEX('Weekly Data'!X:$X,MATCH("2026-01-05",'Weekly Data'!$E:$E,0)),"") -> 0 | C7: =IFERROR(INDEX('Weekly Data'!X:$X,MATCH("2026-01-12",'Weekly Data'!$E:$E,0))-INDEX('Weekly Data'!X:$X,MATCH("2026-01-05",'Weekly Data'!$E:$E,0)),"") -> 0 | D7: =IFERROR(INDEX('Weekly Data'!X:$X,MATCH("2026-01-19",'Weekly Data'!$E:$E,0))-INDEX('Weekly Data'!X:$X,MATCH("2026-01-12",'Weekly Data'!$E:$E,0)),"") -> 0 | E7: =IFERROR(INDEX('Weekly Data'!X:$X,MATCH("2026-01-26",'Weekly Data'!$E:$E,0))-INDEX('Weekly Data'!X:$X,MATCH("2026-01-19",'Weekly Data'!$E:$E,0)),"") -> 3133802 | F7: =IFERROR(INDEX('Weekly Data'!X:$X,MATCH("2026-02-02",'Weekly Data'!$E:$E,0))-INDEX('Weekly Data'!X:$X,MATCH("2026-01-26",'Weekly Data'!$E:$E,0)),"") -> -3133802 | G7: =IFERROR(INDEX('Weekly Data'!X:$X,MATCH("2026-02-09",'Weekly Data'!$E:$E,0))-INDEX('Weekly Data'!X:$X,MATCH("2026-02-02",'Weekly Data'!$E:$E,0)),"") -> 0 | H7: =IFERROR(INDEX('Weekly Data'!X:$X,MATCH("2026-02-16",'Weekly Data'!$E:$E,0))-INDEX('Weekly Data'!X:$X,MATCH("2026-02-09",'Weekly Data'!$E:$E,0)),"") -> 0 | I7: =IFERROR(INDEX('Weekly Data'!X:$X,MATCH("2026-02-23",'Weekly Data'!$E:$E,0))-INDEX('Weekly Data'!X:$X,MATCH("2026-02-16",'Weekly Data'!$E:$E,0)),"") -> 3076658 | J7: =IFERROR(INDEX('Weekly Data'!X:$X,MATCH("2026-03-02",'Weekly Data'!$E:$E,0))-INDEX('Weekly Data'!X:$X,MATCH("2026-02-23",'Weekly Data'!$E:$E,0)),"") -> -3076658 | K7: =IFERROR(INDEX('Weekly Data'!X:$X,MATCH("2026-03-09",'Weekly Data'!$E:$E,0))-INDEX('Weekly Data'!X:$X,MATCH("2026-03-02",'Weekly Data'!$E:$E,0)),"") -> 0 | L7: =IFERROR(INDEX('Weekly Data'!X:$X,MATCH("2026-03-16",'Weekly Data'!$E:$E,0))-INDEX('Weekly Data'!X:$X,MATCH("2026-03-09",'Weekly Data'!$E:$E,0)),"") -> 0 | M7: =IFERROR(INDEX('Weekly Data'!X:$X,MATCH("2026-03-23",'Weekly Data'!$E:$E,0))-INDEX('Weekly Data'!X:$X,MATCH("2026-03-16",'Weekly Data'!$E:$E,0)),"") -> 0 | N7: =IFERROR(INDEX('Weekly Data'!X:$X,MATCH("2026-03-30",'Weekly Data'!$E:$E,0))-INDEX('Weekly Data'!X:$X,MATCH("2026-03-23",'Weekly Data'!$E:$E,0)),"") -> 0 | O7: =IFERROR(INDEX('Weekly Data'!X:$X,MATCH("2026-04-06",'Weekly Data'!$E:$E,0))-INDEX('Weekly Data'!X:$X,MATCH("2026-03-30",'Weekly Data'!$E:$E,0)),"") -> 0 | P7: =IFERROR(INDEX('Weekly Data'!X:$X,MATCH("2026-04-13",'Weekly Data'!$E:$E,0))-INDEX('Weekly Data'!X:$X,MATCH("2026-04-06",'Weekly Data'!$E:$E,0)),"") -> 0 | Q7: =IFERROR(INDEX('Weekly Data'!X:$X,MATCH("2026-04-20",'Weekly Data'!$E:$E,0))-INDEX('Weekly Data'!X:$X,MATCH("2026-04-13",'Weekly Data'!$E:$E,0)),"") -> 0 | R7: =IFERROR(INDEX('Weekly Data'!X:$X,MATCH("2026-04-27",'Weekly Data'!$E:$E,0))-INDEX('Weekly Data'!X:$X,MATCH("2026-04-20",'Weekly Data'!$E:$E,0)),"") -> 0 | S7: =IFERROR(INDEX('Weekly Data'!X:$X,MATCH("2026-05-04",'Weekly Data'!$E:$E,0))-INDEX('Weekly Data'!X:$X,MATCH("2026-04-27",'Weekly Data'!$E:$E,0)),"") -> 0 | T7: =IFERROR(INDEX('Weekly Data'!X:$X,MATCH("2026-05-11",'Weekly Data'!$E:$E,0))-INDEX('Weekly Data'!X:$X,MATCH("2026-05-04",'Weekly Data'!$E:$E,0)),"") -> 0 | U7: =IFERROR(INDEX('Weekly Data'!X:$X,MATCH("2026-05-18",'Weekly Data'!$E:$E,0))-INDEX('Weekly Data'!X:$X,MATCH("2026-05-11",'Weekly Data'!$E:$E,0)),"") -> 0 | V7: =IFERROR(INDEX('Weekly Data'!X:$X,MATCH("2026-05-25",'Weekly Data'!$E:$E,0))-INDEX('Weekly Data'!X:$X,MATCH("2026-05-18",'Weekly Data'!$E:$E,0)),"") -> 0 | W7: =IFERROR(INDEX('Weekly Data'!X:$X,MATCH("2026-06-01",'Weekly Data'!$E:$E,0))-INDEX('Weekly Data'!X:$X,MATCH("2026-05-25",'Weekly Data'!$E:$E,0)),"") -> 0 | X7: =IFERROR(INDEX('Weekly Data'!X:$X,MATCH("2026-06-08",'Weekly Data'!$E:$E,0))-INDEX('Weekly Data'!X:$X,MATCH("2026-06-01",'Weekly Data'!$E:$E,0)),"") -> 0 | Y7: =IFERROR(INDEX('Weekly Data'!X:$X,MATCH("2026-06-15",'Weekly Data'!$E:$E,0))-INDEX('Weekly Data'!X:$X,MATCH("2026-06-08",'Weekly Data'!$E:$E,0)),"") -> 0 | Z7: =IFERROR(INDEX('Weekly Data'!X:$X,MATCH("2026-06-22",'Weekly Data'!$E:$E,0))-INDEX('Weekly Data'!X:$X,MATCH("2026-06-15",'Weekly Data'!$E:$E,0)),"") -> 0 | AA7: =IFERROR(INDEX('Weekly Data'!X:$X,MATCH("2026-06-29",'Weekly Data'!$E:$E,0))-INDEX('Weekly Data'!X:$X,MATCH("2026-06-22",'Weekly Data'!$E:$E,0)),"") -> 0
A8: DSO (Δ) | B8: =IFERROR(INDEX('Weekly Data'!Y:$Y,MATCH("2026-01-05",'Weekly Data'!$E:$E,0)),"") -> 0 | C8: =IFERROR(INDEX('Weekly Data'!Y:$Y,MATCH("2026-01-12",'Weekly Data'!$E:$E,0))-INDEX('Weekly Data'!Y:$Y,MATCH("2026-01-05",'Weekly Data'!$E:$E,0)),"") -> 0 | D8: =IFERROR(INDEX('Weekly Data'!Y:$Y,MATCH("2026-01-19",'Weekly Data'!$E:$E,0))-INDEX('Weekly Data'!Y:$Y,MATCH("2026-01-12",'Weekly Data'!$E:$E,0)),"") -> 0 | E8: =IFERROR(INDEX('Weekly Data'!Y:$Y,MATCH("2026-01-26",'Weekly Data'!$E:$E,0))-INDEX('Weekly Data'!Y:$Y,MATCH("2026-01-19",'Weekly Data'!$E:$E,0)),"") -> 0 | F8: =IFERROR(INDEX('Weekly Data'!Y:$Y,MATCH("2026-02-02",'Weekly Data'!$E:$E,0))-INDEX('Weekly Data'!Y:$Y,MATCH("2026-01-26",'Weekly Data'!$E:$E,0)),"") -> 0 | G8: =IFERROR(INDEX('Weekly Data'!Y:$Y,MATCH("2026-02-09",'Weekly Data'!$E:$E,0))-INDEX('Weekly Data'!Y:$Y,MATCH("2026-02-02",'Weekly Data'!$E:$E,0)),"") -> 0 | H8: =IFERROR(INDEX('Weekly Data'!Y:$Y,MATCH("2026-02-16",'Weekly Data'!$E:$E,0))-INDEX('Weekly Data'!Y:$Y,MATCH("2026-02-09",'Weekly Data'!$E:$E,0)),"") -> 0 | I8: =IFERROR(INDEX('Weekly Data'!Y:$Y,MATCH("2026-02-23",'Weekly Data'!$E:$E,0))-INDEX('Weekly Data'!Y:$Y,MATCH("2026-02-16",'Weekly Data'!$E:$E,0)),"") -> 40 | J8: =IFERROR(INDEX('Weekly Data'!Y:$Y,MATCH("2026-03-02",'Weekly Data'!$E:$E,0))-INDEX('Weekly Data'!Y:$Y,MATCH("2026-02-23",'Weekly Data'!$E:$E,0)),"") -> -40 | K8: =IFERROR(INDEX('Weekly Data'!Y:$Y,MATCH("2026-03-09",'Weekly Data'!$E:$E,0))-INDEX('Weekly Data'!Y:$Y,MATCH("2026-03-02",'Weekly Data'!$E:$E,0)),"") -> 0 | L8: =IFERROR(INDEX('Weekly Data'!Y:$Y,MATCH("2026-03-16",'Weekly Data'!$E:$E,0))-INDEX('Weekly Data'!Y:$Y,MATCH("2026-03-09",'Weekly Data'!$E:$E,0)),"") -> 0 | M8: =IFERROR(INDEX('Weekly Data'!Y:$Y,MATCH("2026-03-23",'Weekly Data'!$E:$E,0))-INDEX('Weekly Data'!Y:$Y,MATCH("2026-03-16",'Weekly Data'!$E:$E,0)),"") -> 0 | N8: =IFERROR(INDEX('Weekly Data'!Y:$Y,MATCH("2026-03-30",'Weekly Data'!$E:$E,0))-INDEX('Weekly Data'!Y:$Y,MATCH("2026-03-23",'Weekly Data'!$E:$E,0)),"") -> 0 | O8: =IFERROR(INDEX('Weekly Data'!Y:$Y,MATCH("2026-04-06",'Weekly Data'!$E:$E,0))-INDEX('Weekly Data'!Y:$Y,MATCH("2026-03-30",'Weekly Data'!$E:$E,0)),"") -> 0 | P8: =IFERROR(INDEX('Weekly Data'!Y:$Y,MATCH("2026-04-13",'Weekly Data'!$E:$E,0))-INDEX('Weekly Data'!Y:$Y,MATCH("2026-04-06",'Weekly Data'!$E:$E,0)),"") -> 0 | Q8: =IFERROR(INDEX('Weekly Data'!Y:$Y,MATCH("2026-04-20",'Weekly Data'!$E:$E,0))-INDEX('Weekly Data'!Y:$Y,MATCH("2026-04-13",'Weekly Data'!$E:$E,0)),"") -> 0 | R8: =IFERROR(INDEX('Weekly Data'!Y:$Y,MATCH("2026-04-27",'Weekly Data'!$E:$E,0))-INDEX('Weekly Data'!Y:$Y,MATCH("2026-04-20",'Weekly Data'!$E:$E,0)),"") -> 0 | S8: =IFERROR(INDEX('Weekly Data'!Y:$Y,MATCH("2026-05-04",'Weekly Data'!$E:$E,0))-INDEX('Weekly Data'!Y:$Y,MATCH("2026-04-27",'Weekly Data'!$E:$E,0)),"") -> 0 | T8: =IFERROR(INDEX('Weekly Data'!Y:$Y,MATCH("2026-05-11",'Weekly Data'!$E:$E,0))-INDEX('Weekly Data'!Y:$Y,MATCH("2026-05-04",'Weekly Data'!$E:$E,0)),"") -> 0 | U8: =IFERROR(INDEX('Weekly Data'!Y:$Y,MATCH("2026-05-18",'Weekly Data'!$E:$E,0))-INDEX('Weekly Data'!Y:$Y,MATCH("2026-05-11",'Weekly Data'!$E:$E,0)),"") -> 0 | V8: =IFERROR(INDEX('Weekly Data'!Y:$Y,MATCH("2026-05-25",'Weekly Data'!$E:$E,0))-INDEX('Weekly Data'!Y:$Y,MATCH("2026-05-18",'Weekly Data'!$E:$E,0)),"") -> 0 | W8: =IFERROR(INDEX('Weekly Data'!Y:$Y,MATCH("2026-06-01",'Weekly Data'!$E:$E,0))-INDEX('Weekly Data'!Y:$Y,MATCH("2026-05-25",'Weekly Data'!$E:$E,0)),"") -> 0 | X8: =IFERROR(INDEX('Weekly Data'!Y:$Y,MATCH("2026-06-08",'Weekly Data'!$E:$E,0))-INDEX('Weekly Data'!Y:$Y,MATCH("2026-06-01",'Weekly Data'!$E:$E,0)),"") -> 0 | Y8: =IFERROR(INDEX('Weekly Data'!Y:$Y,MATCH("2026-06-15",'Weekly Data'!$E:$E,0))-INDEX('Weekly Data'!Y:$Y,MATCH("2026-06-08",'Weekly Data'!$E:$E,0)),"") -> 0 | Z8: =IFERROR(INDEX('Weekly Data'!Y:$Y,MATCH("2026-06-22",'Weekly Data'!$E:$E,0))-INDEX('Weekly Data'!Y:$Y,MATCH("2026-06-15",'Weekly Data'!$E:$E,0)),"") -> 0 | AA8: =IFERROR(INDEX('Weekly Data'!Y:$Y,MATCH("2026-06-29",'Weekly Data'!$E:$E,0))-INDEX('Weekly Data'!Y:$Y,MATCH("2026-06-22",'Weekly Data'!$E:$E,0)),"") -> 0
A9: Tickets Created (Δ) | B9: =IFERROR(INDEX('Weekly Data'!AC:$AC,MATCH("2026-01-05",'Weekly Data'!$E:$E,0)),"") -> 0 | C9: =IFERROR(INDEX('Weekly Data'!AC:$AC,MATCH("2026-01-12",'Weekly Data'!$E:$E,0))-INDEX('Weekly Data'!AC:$AC,MATCH("2026-01-05",'Weekly Data'!$E:$E,0)),"") -> 0 | D9: =IFERROR(INDEX('Weekly Data'!AC:$AC,MATCH("2026-01-19",'Weekly Data'!$E:$E,0))-INDEX('Weekly Data'!AC:$AC,MATCH("2026-01-12",'Weekly Data'!$E:$E,0)),"") -> 0 | E9: =IFERROR(INDEX('Weekly Data'!AC:$AC,MATCH("2026-01-26",'Weekly Data'!$E:$E,0))-INDEX('Weekly Data'!AC:$AC,MATCH("2026-01-19",'Weekly Data'!$E:$E,0)),"") -> 0 | F9: =IFERROR(INDEX('Weekly Data'!AC:$AC,MATCH("2026-02-02",'Weekly Data'!$E:$E,0))-INDEX('Weekly Data'!AC:$AC,MATCH("2026-01-26",'Weekly Data'!$E:$E,0)),"") -> 0 | G9: =IFERROR(INDEX('Weekly Data'!AC:$AC,MATCH("2026-02-09",'Weekly Data'!$E:$E,0))-INDEX('Weekly Data'!AC:$AC,MATCH("2026-02-02",'Weekly Data'!$E:$E,0)),"") -> 0 | H9: =IFERROR(INDEX('Weekly Data'!AC:$AC,MATCH("2026-02-16",'Weekly Data'!$E:$E,0))-INDEX('Weekly Data'!AC:$AC,MATCH("2026-02-09",'Weekly Data'!$E:$E,0)),"") -> 0 | I9: =IFERROR(INDEX('Weekly Data'!AC:$AC,MATCH("2026-02-23",'Weekly Data'!$E:$E,0))-INDEX('Weekly Data'!AC:$AC,MATCH("2026-02-16",'Weekly Data'!$E:$E,0)),"") -> 0 | J9: =IFERROR(INDEX('Weekly Data'!AC:$AC,MATCH("2026-03-02",'Weekly Data'!$E:$E,0))-INDEX('Weekly Data'!AC:$AC,MATCH("2026-02-23",'Weekly Data'!$E:$E,0)),"") -> 532 | K9: =IFERROR(INDEX('Weekly Data'!AC:$AC,MATCH("2026-03-09",'Weekly Data'!$E:$E,0))-INDEX('Weekly Data'!AC:$AC,MATCH("2026-03-02",'Weekly Data'!$E:$E,0)),"") -> -532 | L9: =IFERROR(INDEX('Weekly Data'!AC:$AC,MATCH("2026-03-16",'Weekly Data'!$E:$E,0))-INDEX('Weekly Data'!AC:$AC,MATCH("2026-03-09",'Weekly Data'!$E:$E,0)),"") -> 0 | M9: =IFERROR(INDEX('Weekly Data'!AC:$AC,MATCH("2026-03-23",'Weekly Data'!$E:$E,0))-INDEX('Weekly Data'!AC:$AC,MATCH("2026-03-16",'Weekly Data'!$E:$E,0)),"") -> 0 | N9: =IFERROR(INDEX('Weekly Data'!AC:$AC,MATCH("2026-03-30",'Weekly Data'!$E:$E,0))-INDEX('Weekly Data'!AC:$AC,MATCH("2026-03-23",'Weekly Data'!$E:$E,0)),"") -> 0 | O9: =IFERROR(INDEX('Weekly Data'!AC:$AC,MATCH("2026-04-06",'Weekly Data'!$E:$E,0))-INDEX('Weekly Data'!AC:$AC,MATCH("2026-03-30",'Weekly Data'!$E:$E,0)),"") -> 0 | P9: =IFERROR(INDEX('Weekly Data'!AC:$AC,MATCH("2026-04-13",'Weekly Data'!$E:$E,0))-INDEX('Weekly Data'!AC:$AC,MATCH("2026-04-06",'Weekly Data'!$E:$E,0)),"") -> 0 | Q9: =IFERROR(INDEX('Weekly Data'!AC:$AC,MATCH("2026-04-20",'Weekly Data'!$E:$E,0))-INDEX('Weekly Data'!AC:$AC,MATCH("2026-04-13",'Weekly Data'!$E:$E,0)),"") -> 0 | R9: =IFERROR(INDEX('Weekly Data'!AC:$AC,MATCH("2026-04-27",'Weekly Data'!$E:$E,0))-INDEX('Weekly Data'!AC:$AC,MATCH("2026-04-20",'Weekly Data'!$E:$E,0)),"") -> 0 | S9: =IFERROR(INDEX('Weekly Data'!AC:$AC,MATCH("2026-05-04",'Weekly Data'!$E:$E,0))-INDEX('Weekly Data'!AC:$AC,MATCH("2026-04-27",'Weekly Data'!$E:$E,0)),"") -> 0 | T9: =IFERROR(INDEX('Weekly Data'!AC:$AC,MATCH("2026-05-11",'Weekly Data'!$E:$E,0))-INDEX('Weekly Data'!AC:$AC,MATCH("2026-05-04",'Weekly Data'!$E:$E,0)),"") -> 0 | U9: =IFERROR(INDEX('Weekly Data'!AC:$AC,MATCH("2026-05-18",'Weekly Data'!$E:$E,0))-INDEX('Weekly Data'!AC:$AC,MATCH("2026-05-11",'Weekly Data'!$E:$E,0)),"") -> 0 | V9: =IFERROR(INDEX('Weekly Data'!AC:$AC,MATCH("2026-05-25",'Weekly Data'!$E:$E,0))-INDEX('Weekly Data'!AC:$AC,MATCH("2026-05-18",'Weekly Data'!$E:$E,0)),"") -> 0 | W9: =IFERROR(INDEX('Weekly Data'!AC:$AC,MATCH("2026-06-01",'Weekly Data'!$E:$E,0))-INDEX('Weekly Data'!AC:$AC,MATCH("2026-05-25",'Weekly Data'!$E:$E,0)),"") -> 0 | X9: =IFERROR(INDEX('Weekly Data'!AC:$AC,MATCH("2026-06-08",'Weekly Data'!$E:$E,0))-INDEX('Weekly Data'!AC:$AC,MATCH("2026-06-01",'Weekly Data'!$E:$E,0)),"") -> 0 | Y9: =IFERROR(INDEX('Weekly Data'!AC:$AC,MATCH("2026-06-15",'Weekly Data'!$E:$E,0))-INDEX('Weekly Data'!AC:$AC,MATCH("2026-06-08",'Weekly Data'!$E:$E,0)),"") -> 0 | Z9: =IFERROR(INDEX('Weekly Data'!AC:$AC,MATCH("2026-06-22",'Weekly Data'!$E:$E,0))-INDEX('Weekly Data'!AC:$AC,MATCH("2026-06-15",'Weekly Data'!$E:$E,0)),"") -> 0 | AA9: =IFERROR(INDEX('Weekly Data'!AC:$AC,MATCH("2026-06-29",'Weekly Data'!$E:$E,0))-INDEX('Weekly Data'!AC:$AC,MATCH("2026-06-22",'Weekly Data'!$E:$E,0)),"") -> 0
A10: Tickets Resolved (Δ) | B10: =IFERROR(INDEX('Weekly Data'!AD:$AD,MATCH("2026-01-05",'Weekly Data'!$E:$E,0)),"") -> 0 | C10: =IFERROR(INDEX('Weekly Data'!AD:$AD,MATCH("2026-01-12",'Weekly Data'!$E:$E,0))-INDEX('Weekly Data'!AD:$AD,MATCH("2026-01-05",'Weekly Data'!$E:$E,0)),"") -> 0 | D10: =IFERROR(INDEX('Weekly Data'!AD:$AD,MATCH("2026-01-19",'Weekly Data'!$E:$E,0))-INDEX('Weekly Data'!AD:$AD,MATCH("2026-01-12",'Weekly Data'!$E:$E,0)),"") -> 0 | E10: =IFERROR(INDEX('Weekly Data'!AD:$AD,MATCH("2026-01-26",'Weekly Data'!$E:$E,0))-INDEX('Weekly Data'!AD:$AD,MATCH("2026-01-19",'Weekly Data'!$E:$E,0)),"") -> 0 | F10: =IFERROR(INDEX('Weekly Data'!AD:$AD,MATCH("2026-02-02",'Weekly Data'!$E:$E,0))-INDEX('Weekly Data'!AD:$AD,MATCH("2026-01-26",'Weekly Data'!$E:$E,0)),"") -> 0 | G10: =IFERROR(INDEX('Weekly Data'!AD:$AD,MATCH("2026-02-09",'Weekly Data'!$E:$E,0))-INDEX('Weekly Data'!AD:$AD,MATCH("2026-02-02",'Weekly Data'!$E:$E,0)),"") -> 0 | H10: =IFERROR(INDEX('Weekly Data'!AD:$AD,MATCH("2026-02-16",'Weekly Data'!$E:$E,0))-INDEX('Weekly Data'!AD:$AD,MATCH("2026-02-09",'Weekly Data'!$E:$E,0)),"") -> 0 | I10: =IFERROR(INDEX('Weekly Data'!AD:$AD,MATCH("2026-02-23",'Weekly Data'!$E:$E,0))-INDEX('Weekly Data'!AD:$AD,MATCH("2026-02-16",'Weekly Data'!$E:$E,0)),"") -> 0 | J10: =IFERROR(INDEX('Weekly Data'!AD:$AD,MATCH("2026-03-02",'Weekly Data'!$E:$E,0))-INDEX('Weekly Data'!AD:$AD,MATCH("2026-02-23",'Weekly Data'!$E:$E,0)),"") -> 532 | K10: =IFERROR(INDEX('Weekly Data'!AD:$AD,MATCH("2026-03-09",'Weekly Data'!$E:$E,0))-INDEX('Weekly Data'!AD:$AD,MATCH("2026-03-02",'Weekly Data'!$E:$E,0)),"") -> -532 | L10: =IFERROR(INDEX('Weekly Data'!AD:$AD,MATCH("2026-03-16",'Weekly Data'!$E:$E,0))-INDEX('Weekly Data'!AD:$AD,MATCH("2026-03-09",'Weekly Data'!$E:$E,0)),"") -> 0 | M10: =IFERROR(INDEX('Weekly Data'!AD:$AD,MATCH("2026-03-23",'Weekly Data'!$E:$E,0))-INDEX('Weekly Data'!AD:$AD,MATCH("2026-03-16",'Weekly Data'!$E:$E,0)),"") -> 0 | N10: =IFERROR(INDEX('Weekly Data'!AD:$AD,MATCH("2026-03-30",'Weekly Data'!$E:$E,0))-INDEX('Weekly Data'!AD:$AD,MATCH("2026-03-23",'Weekly Data'!$E:$E,0)),"") -> 0 | O10: =IFERROR(INDEX('Weekly Data'!AD:$AD,MATCH("2026-04-06",'Weekly Data'!$E:$E,0))-INDEX('Weekly Data'!AD:$AD,MATCH("2026-03-30",'Weekly Data'!$E:$E,0)),"") -> 0 | P10: =IFERROR(INDEX('Weekly Data'!AD:$AD,MATCH("2026-04-13",'Weekly Data'!$E:$E,0))-INDEX('Weekly Data'!AD:$AD,MATCH("2026-04-06",'Weekly Data'!$E:$E,0)),"") -> 0 | Q10: =IFERROR(INDEX('Weekly Data'!AD:$AD,MATCH("2026-04-20",'Weekly Data'!$E:$E,0))-INDEX('Weekly Data'!AD:$AD,MATCH("2026-04-13",'Weekly Data'!$E:$E,0)),"") -> 0 | R10: =IFERROR(INDEX('Weekly Data'!AD:$AD,MATCH("2026-04-27",'Weekly Data'!$E:$E,0))-INDEX('Weekly Data'!AD:$AD,MATCH("2026-04-20",'Weekly Data'!$E:$E,0)),"") -> 0 | S10: =IFERROR(INDEX('Weekly Data'!AD:$AD,MATCH("2026-05-04",'Weekly Data'!$E:$E,0))-INDEX('Weekly Data'!AD:$AD,MATCH("2026-04-27",'Weekly Data'!$E:$E,0)),"") -> 0 | T10: =IFERROR(INDEX('Weekly Data'!AD:$AD,MATCH("2026-05-11",'Weekly Data'!$E:$E,0))-INDEX('Weekly Data'!AD:$AD,MATCH("2026-05-04",'Weekly Data'!$E:$E,0)),"") -> 0 | U10: =IFERROR(INDEX('Weekly Data'!AD:$AD,MATCH("2026-05-18",'Weekly Data'!$E:$E,0))-INDEX('Weekly Data'!AD:$AD,MATCH("2026-05-11",'Weekly Data'!$E:$E,0)),"") -> 0 | V10: =IFERROR(INDEX('Weekly Data'!AD:$AD,MATCH("2026-05-25",'Weekly Data'!$E:$E,0))-INDEX('Weekly Data'!AD:$AD,MATCH("2026-05-18",'Weekly Data'!$E:$E,0)),"") -> 0 | W10: =IFERROR(INDEX('Weekly Data'!AD:$AD,MATCH("2026-06-01",'Weekly Data'!$E:$E,0))-INDEX('Weekly Data'!AD:$AD,MATCH("2026-05-25",'Weekly Data'!$E:$E,0)),"") -> 0 | X10: =IFERROR(INDEX('Weekly Data'!AD:$AD,MATCH("2026-06-08",'Weekly Data'!$E:$E,0))-INDEX('Weekly Data'!AD:$AD,MATCH("2026-06-01",'Weekly Data'!$E:$E,0)),"") -> 0 | Y10: =IFERROR(INDEX('Weekly Data'!AD:$AD,MATCH("2026-06-15",'Weekly Data'!$E:$E,0))-INDEX('Weekly Data'!AD:$AD,MATCH("2026-06-08",'Weekly Data'!$E:$E,0)),"") -> 0 | Z10: =IFERROR(INDEX('Weekly Data'!AD:$AD,MATCH("2026-06-22",'Weekly Data'!$E:$E,0))-INDEX('Weekly Data'!AD:$AD,MATCH("2026-06-15",'Weekly Data'!$E:$E,0)),"") -> 0 | AA10: =IFERROR(INDEX('Weekly Data'!AD:$AD,MATCH("2026-06-29",'Weekly Data'!$E:$E,0))-INDEX('Weekly Data'!AD:$AD,MATCH("2026-06-22",'Weekly Data'!$E:$E,0)),"") -> 0
