Workbook

Sheet Combined Company
B1: Month 1 ($) | C1: Month 1 (%) | D1: Month 2 ($) | E1: Month 2 (%) | F1: Month 3 ($) | G1: Month 3 (%) | H1: Month 4 ($) | I1: Month 4 (%) | J1: Month 5 ($) | K1: Month 5 (%) | L1: Month 6 ($) | M1: Month 6 (%) | N1: Month 7 ($) | O1: Month 7 (%) | P1: Month 8 ($) | Q1: Month 8 (%) | R1: Month 9 ($) | S1: Month 9 (%) | T1: Month 10 ($) | U1: Month 10 (%) | V1: Month 11 ($) | W1: Month 11 (%) | X1: Month 12 ($) | Y1: Month 12 (%) | Z1: 12 Month Totals | AE1: Last 3 Months Average | AF1: Last 3 Months Sparkline
A2: Location | B2: All Locations | D2: All Locations | F2: All Locations | H2: All Locations | I2: All Locations | J2: All Locations | L2: All Locations | N2: All Locations | P2: All Locations | R2: All Locations | T2: All Locations | V2: All Locations | X2: All Locations | Y2: All Locations | Z2: All Locations
A3: Month | B3: 01/31/2023 | D3: 02/28/2023 | F3: 03/31/2023 | H3: 45046 | J3: 45077 | L3: 45107 | N3: 45138 | P3: 45169 | R3: 45199 | T3: 45230 | V3: 45260 | X3: 45291
A4: Days in Month | B4: 31 | D4: 28 | F4: 31 | H4: 30 | J4: 31 | L4: 30 | N4: 31 | P4: 31 | R4: 30 | T4: 31 | V4: 30 | X4: 31
A5: Quarter | B5: 1 | D5: 1 | F5: 1 | H5: 2 | J5: 2 | L5: 2 | N5: 3 | P5: 3 | R5: 3 | T5: 4 | V5: 4 | X5: 4
A6: Year | B6: 2023 | D6: 2023 | F6: 2023 | H6: 2023 | J6: 2023 | L6: 2023 | N6: 2023 | P6: 2023 | R6: 2023 | T6: 2023 | V6: 2023 | X6: 2023
A8: Revenue
A9: Managed IT Services (Recurring IT & Security) | B9: 618563 | C9: =B9/B$17 -> 0.22468648 | D9: 622840 | E9: =D9/D$17 -> 0.30671741 | F9: 676399 | G9: =F9/F$17 -> 0.33281178 | H9: 804317 | I9: =H9/H$17 -> 0.40143331 | J9: 771921 | K9: =J9/J$17 -> 0.31925728 | L9: 816214 | M9: =L9/L$17 -> 0.38111759 | N9: 723940 | O9: =N9/N$17 -> 0.31939286 | P9: 716281 | Q9: =P9/P$17 -> 0.23202932 | R9: 633625 | S9: =R9/R$17 -> 0.24088304 | T9: 592078 | U9: =T9/T$17 -> 0.31310444 | V9: 635168 | W9: =V9/V$17 -> 0.23958921 | X9: 464521 | Y9: =X9/X$17 -> 0.24529537 | Z9: =SUM(B9,D9,F9,H9,J9,L9,N9,P9,R9,T9,V9,X9) -> 8075867 | AE9: =IFERROR(AVERAGE(R9,T9,V9),0) -> 620290.33
A10: Cloud (Private Cloud Only as of 4/1/23) | B10: 482810 | C10: =B10/B$17 -> 0.17537563 | D10: 477754 | E10: =D10/D$17 -> 0.23526984 | F10: 507829 | G10: =F10/F$17 -> 0.24986949 | H10: 70464 | I10: =H10/H$17 -> 0.035168468 | J10: 70467 | K10: =J10/J$17 -> 0.029144307 | L10: 68677 | M10: =L10/L$17 -> 0.032067586 | N10: 63312 | O10: =N10/N$17 -> 0.027932426 | P10: 58680 | Q10: =P10/P$17 -> 0.019008574 | R10: 49426 | S10: =R10/R$17 -> 0.018790112 | T10: 33323 | U10: =T10/T$17 -> 0.017621968 | V10: 34007 | W10: =V10/V$17 -> 0.012827646 | X10: 19383 | Y10: =X10/X$17 -> 0.010235404 | Z10: =SUM(B10,D10,F10,H10,J10,L10,N10,P10,R10,T10,V10,X10) -> 1936132 | AE10: =IFERROR(AVERAGE(R10,T10,V10),0) -> 38918.667
A11: Recurring Resale (Includes previouse Cloud sales) | C11: =B11/B$17 -> 0 | E11: =D11/D$17 -> 0 | G11: =F11/F$17 -> 0 | H11: 251582 | I11: =H11/H$17 -> 0.12556417 | J11: 298554 | K11: =J11/J$17 -> 0.12347836 | L11: 299810 | M11: =L11/L$17 -> 0.13999131 | N11: 289268 | O11: =N11/N$17 -> 0.12762126 | P11: 291785 | Q11: =P11/P$17 -> 0.094519713 | R11: 270887 | S11: =R11/R$17 -> 0.10298218 | T11: 267726 | U11: =T11/T$17 -> 0.14157966 | V11: 242938 | W11: =V11/V$17 -> 0.091637682 | X11: 213581 | Y11: =X11/X$17 -> 0.11278377 | Z11: =SUM(B11,D11,F11,H11,J11,L11,N11,P11,R11,T11,V11,X11) -> 2426131 | AE11: =IFERROR(AVERAGE(R11,T11,V11),0) -> 260517
A12: Project Services | B12: 98569 | C12: =B12/B$17 -> 0.035804149 | D12: 139411 | E12: =D12/D$17 -> 0.068652914 | F12: 106978 | G12: =F12/F$17 -> 0.052636888 | H12: 87200 | I12: =H12/H$17 -> 0.043521379 | J12: 157359 | K12: =J12/J$17 -> 0.065081797 | L12: 58967 | M12: =L12/L$17 -> 0.027533662 | N12: 180502 | O12: =N12/N$17 -> 0.079635121 | P12: 176019 | Q12: =P12/P$17 -> 0.057018919 | R12: 124873 | S12: =R12/R$17 -> 0.047472539 | T12: 84028 | U12: =T12/T$17 -> 0.044435936 | V12: 39227 | W12: =V12/V$17 -> 0.014796661 | X12: 57136 | Y12: =X12/X$17 -> 0.030171287 | Z12: =SUM(B12,D12,F12,H12,J12,L12,N12,P12,R12,T12,V12,X12) -> 1310269 | AE12: =IFERROR(AVERAGE(R12,T12,V12),0) -> 82709.333
A13: Subcontracted Services | B13: 63823 | C13: =B13/B$17 -> 0.023183031 | D13: 78469 | E13: =D13/D$17 -> 0.03864204 | F13: 40805 | G13: =F13/F$17 -> 0.020077476 | H13: 30033 | I13: =H13/H$17 -> 0.014989422 | J13: 36525 | K13: =J13/J$17 -> 0.015106302 | L13: 26588 | M13: =L13/L$17 -> 0.012414826 | N13: 162366 | O13: =N13/N$17 -> 0.071633755 | P13: 60247 | Q13: =P13/P$17 -> 0.019516182 | R13: 28290 | S13: =R13/R$17 -> 0.010754912 | T13: 30162 | U13: =T13/T$17 -> 0.015950358 | V13: 18990 | W13: =V13/V$17 -> 0.0071631427 | X13: 2427 | Y13: =X13/X$17 -> 0.0012816038 | Z13: =SUM(B13,D13,F13,H13,J13,L13,N13,P13,R13,T13,V13,X13) -> 578725 | AE13: =IFERROR(AVERAGE(R13,T13,V13),0) -> 25814
A14: Product Sales | B14: 1465094 | C14: =B14/B$17 -> 0.53217993 | D14: 681484 | E14: =D14/D$17 -> 0.33559663 | F14: 671999 | G14: =F14/F$17 -> 0.33064682 | H14: 746285 | I14: =H14/H$17 -> 0.37246963 | J14: 1072158 | K14: =J14/J$17 -> 0.44343171 | L14: 854343 | M14: =L14/L$17 -> 0.39892129 | N14: 835308 | O14: =N14/N$17 -> 0.36852696 | P14: 1773163 | Q14: =P14/P$17 -> 0.57439162 | R14: 1500169 | S14: =R14/R$17 -> 0.57031409 | T14: 873395 | U14: =T14/T$17 -> 0.46187134 | V14: 1659476 | W14: =V14/V$17 -> 0.62596437 | X14: 1123606 | Y14: =X14/X$17 -> 0.59333239 | Z14: =SUM(B14,D14,F14,H14,J14,L14,N14,P14,R14,T14,V14,X14) -> 13256480 | AE14: =IFERROR(AVERAGE(R14,T14,V14),0) -> 1344346.7
A15: Commissions | B15: 24146 | C15: =B15/B$17 -> 0.0087707796 | D15: 30706 | E15: =D15/D$17 -> 0.015121162 | F15: 28436 | G15: =F15/F$17 -> 0.013991499 | H15: 13732 | I15: =H15/H$17 -> 0.0068536189 | J15: 10881 | K15: =J15/J$17 -> 0.0045002513 | L15: 17034 | M15: =L15/L$17 -> 0.0079537437 | N15: 11917 | O15: =N15/N$17 -> 0.0052576245 | P15: 10853 | Q15: =P15/P$17 -> 0.0035156792 | R15: 23156 | S15: =R15/R$17 -> 0.0088031368 | T15: 10280 | U15: =T15/T$17 -> 0.0054363001 | V15: 21265 | W15: =V15/V$17 -> 0.0080212865 | X15: 13067 | Y15: =X15/X$17 -> 0.0069001717 | Z15: =SUM(B15,D15,F15,H15,J15,L15,N15,P15,R15,T15,V15,X15) -> 215473 | AE15: =IFERROR(AVERAGE(R15,T15,V15),0) -> 18233.667
A16: Sales Returns and Discounts | B16: 0 | C16: =B16/B$17 -> 0 | D16: 0 | E16: =D16/D$17 -> 0 | F16: 69 | G16: =F16/F$17 -> 3.3950394e-05 | H16: 0 | I16: =H16/H$17 -> 0 | J16: 0 | K16: =J16/J$17 -> 0 | L16: 0 | M16: =L16/L$17 -> 0 | N16: 0 | O16: =N16/N$17 -> 0 | P16: 0 | Q16: =P16/P$17 -> 0 | R16: 0 | S16: =R16/R$17 -> 0 | T16: 0 | U16: =T16/T$17 -> 0 | V16: 0 | W16: =V16/V$17 -> 0 | Y16: =X16/X$17 -> 0 | Z16: =SUM(B16,D16,F16,H16,J16,L16,N16,P16,R16,T16,V16,X16) -> 69 | AE16: =IFERROR(AVERAGE(R16,T16,V16),0) -> 0
A17: Total Revenue | B17: 2753005 | C17: =B17/B$17 -> 1 | D17: 2030664 | E17: =D17/D$17 -> 1 | F17: 2032377 | G17: =F17/F$17 -> 1 | H17: 2003613 | I17: =H17/H$17 -> 1 | J17: =SUM(J9:J16) -> 2417865 | K17: =J17/J$17 -> 1 | L17: =SUM(L9:L16) -> 2141633 | M17: =L17/L$17 -> 1 | N17: =SUM(N9:N16) -> 2266613 | O17: =N17/N$17 -> 1 | P17: =SUM(P9:P16) -> 3087028 | Q17: =P17/P$17 -> 1 | R17: =SUM(R9:R16) -> 2630426 | S17: =R17/R$17 -> 1 | T17: =SUM(T9:T16) -> 1890992 | U17: =T17/T$17 -> 1 | V17: =SUM(V9:V16) -> 2651071 | W17: =V17/V$17 -> 1 | X17: =SUM(X9:X16) -> 1893721 | Y17: =X17/X$17 -> 1 | Z17: =SUM(B17,D17,F17,H17,J17,L17,N17,P17,R17,T17,V17,X17) -> 27799008 | AE17: =IFERROR(AVERAGE(R17:V17),0) -> 1434498.2
A20: Cost of Goods and Services
A21: Managed IT Service Costs | B21: 61481 | C21: =B21/B$17 -> 0.022332324 | D21: 87723 | E21: =D21/D$17 -> 0.04319917 | F21: 99230 | G21: =F21/F$17 -> 0.048824603 | H21: 27668 | I21: =H21/H$17 -> 0.013809054 | J21: 29657 | K21: =J21/J$17 -> 0.01226578 | L21: 20710 | M21: =L21/L$17 -> 0.0096701909 | N21: 25579 | O21: =N21/N$17 -> 0.01128512 | P21: 40069 | Q21: =P21/P$17 -> 0.012979798 | R21: 9079 | S21: =R21/R$17 -> 0.0034515322 | T21: 18714 | U21: =T21/T$17 -> 0.009896393 | V21: 19429 | W21: =V21/V$17 -> 0.0073287362 | X21: 19840 | Y21: =X21/X$17 -> 0.010476728 | Z21: =SUM(F21,H21,J21,L21,N21,P21,R21,T21,V21,X21) -> 309975 | AE21: =IFERROR(AVERAGE(R21:V21),0) -> 9444.4027
A22: Cloud Service Costs | B22: 147592 | C22: =B22/B$17 -> 0.053611236 | D22: 152612 | E22: =D22/D$17 -> 0.075153743 | F22: 153032 | G22: =F22/F$17 -> 0.075297054 | H22: 39868 | I22: =H22/H$17 -> 0.019898054 | J22: 40621 | K22: =J22/J$17 -> 0.016800359 | L22: 52167 | M22: =L22/L$17 -> 0.024358515 | N22: 42698 | O22: =N22/N$17 -> 0.018837799 | P22: 26890 | Q22: =P22/P$17 -> 0.0087106434 | R22: 42899 | S22: =R22/R$17 -> 0.016308765 | T22: 12623 | U22: =T22/T$17 -> 0.0066753323 | V22: 17899 | W22: =V22/V$17 -> 0.006751611 | X22: 13321 | Y22: =X22/X$17 -> 0.0070342991 | Z22: =SUM(F22,H22,J22,L22,N22,P22,R22,T22,V22,X22) -> 442018 | AE22: =IFERROR(AVERAGE(R22:V22),0) -> 14684.205
A23: Recurring Resale Costs | C23: =B23/B$17 -> 0 | E23: =D23/D$17 -> 0 | G23: =F23/F$17 -> 0 | H23: 190790 | I23: =H23/H$17 -> 0.09522298 | J23: 179145 | K23: =J23/J$17 -> 0.074092226 | L23: 212008 | M23: =L23/L$17 -> 0.098993618 | N23: 146217 | O23: =N23/N$17 -> 0.064509027 | P23: 204709 | Q23: =P23/P$17 -> 0.066312648 | R23: 179856 | S23: =R23/R$17 -> 0.068375237 | T23: 181262 | U23: =T23/T$17 -> 0.095855509 | V23: 167095 | W23: =V23/V$17 -> 0.063029244 | X23: 148195 | Y23: =X23/X$17 -> 0.078255984 | Z23: =SUM(F23,H23,J23,L23,N23,P23,R23,T23,V23,X23) -> 1609277
A24: Project Service Costs | B24: 0 | C24: =B24/B$17 -> 0 | D24: 942 | E24: =D24/D$17 -> 0.00046388767 | F24: 1071 | G24: =F24/F$17 -> 0.00052696916 | H24: 0 | I24: =H24/H$17 -> 0 | J24: 0 | K24: =J24/J$17 -> 0 | L24: 0 | M24: =L24/L$17 -> 0 | N24: 0 | O24: =N24/N$17 -> 0 | P24: 525 | Q24: =P24/P$17 -> 0.00017006648 | R24: 5449 | S24: =R24/R$17 -> 0.0020715276 | T24: 2916 | U24: =T24/T$17 -> 0.0015420478 | V24: 0 | W24: =V24/V$17 -> 0 | X24: 0 | Y24: =X24/X$17 -> 0 | Z24: =SUM(F24,H24,J24,L24,N24,P24,R24,T24,V24,X24) -> 9961 | AE24: =IFERROR(AVERAGE(R24:V24),0) -> 1673.0007
A25: Subcontractor Service Costs | B25: 53982 | C25: =B25/B$17 -> 0.019608392 | D25: 66267 | E25: =D25/D$17 -> 0.032633168 | F25: 33571 | G25: =F25/F$17 -> 0.016518097 | H25: 25077 | I25: =H25/H$17 -> 0.01251589 | J25: 30438 | K25: =J25/J$17 -> 0.012588792 | L25: 22057 | M25: =L25/L$17 -> 0.01029915 | N25: 138134 | O25: =N25/N$17 -> 0.060942914 | P25: 50205 | Q25: =P25/P$17 -> 0.016263215 | R25: 30005 | S25: =R25/R$17 -> 0.011406898 | T25: 24662 | U25: =T25/T$17 -> 0.013041832 | V25: 15781 | W25: =V25/V$17 -> 0.0059526886 | X25: 1290 | Y25: =X25/X$17 -> 0.00068119855 | Z25: =SUM(F25,H25,J25,L25,N25,P25,R25,T25,V25,X25) -> 371220 | AE25: =IFERROR(AVERAGE(R25:V25),0) -> 14089.605
A26: Product Sales Costs | B26: 1229969 | C26: =B26/B$17 -> 0.44677325 | D26: 544122 | E26: =D26/D$17 -> 0.26795275 | F26: 544407 | G26: =F26/F$17 -> 0.26786713 | H26: 631866 | I26: =H26/H$17 -> 0.3153633 | J26: 905546 | K26: =J26/J$17 -> 0.37452298 | L26: 727333 | M26: =L26/L$17 -> 0.33961608 | N26: 731290 | O26: =N26/N$17 -> 0.32263558 | P26: 1462308 | Q26: =P26/P$17 -> 0.47369444 | R26: 1269641 | S26: =R26/R$17 -> 0.48267505 | T26: 702933 | U26: =T26/T$17 -> 0.37172711 | V26: 1400739 | W26: =V26/V$17 -> 0.52836721 | X26: 943687 | Y26: =X26/X$17 -> 0.4983242 | Z26: =SUM(F26,H26,J26,L26,N26,P26,R26,T26,V26,X26) -> 9319750 | AE26: =IFERROR(AVERAGE(R26:V26),0) -> 674662.77
A27: Total COGS | B27: 1493024 | C27: =B27/B$17 -> 0.5423252 | D27: 851666 | E27: =D27/D$17 -> 0.41940272 | F27: 831311 | G27: =F27/F$17 -> 0.40903386 | H27: 915269 | I27: =H27/H$17 -> 0.45680927 | J27: =SUM(J21:J26) -> 1185407 | K27: =J27/J$17 -> 0.49027014 | L27: =SUM(L21:L26) -> 1034275 | M27: =L27/L$17 -> 0.48293755 | N27: =SUM(N21:N26) -> 1083918 | O27: =N27/N$17 -> 0.47821044 | P27: =SUM(P21:P26) -> 1784706 | Q27: =P27/P$17 -> 0.57813081 | R27: =SUM(R21:R26) -> 1536929 | S27: =R27/R$17 -> 0.58428901 | T27: =SUM(T21:T26) -> 943110 | U27: =T27/T$17 -> 0.49873823 | V27: =SUM(V21:V26) -> 1620943 | W27: =V27/V$17 -> 0.61142949 | X27: =SUM(X21:X26) -> 1126333 | Y27: =X27/X$17 -> 0.59477241 | Z27: =SUM(F27,H27,J27,L27,N27,P27,R27,T27,V27,X27) -> 12062201 | AE27: =IFERROR(AVERAGE(R27:V27),0) -> 820196.62
Z28: =SUM(F28,H28,J28,L28,N28,P28,R28,T28,V28,X28) -> 0
A29: Gross Profit | B29: 1259981 | C29: =B29/B$17 -> 0.4576748 | D29: 1178998 | E29: =D29/D$17 -> 0.58059728 | F29: 1201066 | G29: =F29/F$17 -> 0.59096614 | H29: 1088344 | I29: =H29/H$17 -> 0.54319073 | J29: =+J17-J27 -> 1232458 | K29: =J29/J$17 -> 0.50972986 | L29: =+L17-L27 -> 1107358 | M29: =L29/L$17 -> 0.51706245 | N29: =+N17-N27 -> 1182695 | O29: =N29/N$17 -> 0.52178956 | P29: =+P17-P27 -> 1302322 | Q29: =P29/P$17 -> 0.42186919 | R29: =+R17-R27 -> 1093497 | S29: =R29/R$17 -> 0.41571099 | T29: =+T17-T27 -> 947882 | U29: =T29/T$17 -> 0.50126177 | V29: =+V17-V27 -> 1030128 | W29: =V29/V$17 -> 0.38857051 | X29: =+X17-X27 -> 767388 | Y29: =X29/X$17 -> 0.40522759 | Z29: =SUM(F29,H29,J29,L29,N29,P29,R29,T29,V29,X29) -> 10953138 | AE29: =IFERROR(AVERAGE(R29:V29),0) -> 614301.58
A30: Gross Profit % | B30: 0.4576748 | C30: =C29/C17 -> 0.4576748 | D30: 0.58059728 | E30: =E29/E17 -> 0.58059728 | F30: 0.59096614 | G30: =G29/G17 -> 0.59096614 | H30: 0.54319073 | I30: =I29/I17 -> 0.54319073 | J30: =J29/J17 -> 0.50972986 | K30: =K29/K17 -> 0.50972986 | L30: =L29/L17 -> 0.51706245 | M30: =M29/M17 -> 0.51706245 | N30: =N29/N17 -> 0.52178956 | O30: =O29/O17 -> 0.52178956 | P30: =P29/P17 -> 0.42186919 | ... Z30: =Z29/Z17 -> 0.39401183
A32: Operating Expenses
A33: General & Admin Expenses
A34: Charitable Contributions | B34: 1000 | C34: =B34/B$17 -> 0.00036323944 | D34: 1515 | E34: =D34/D$17 -> 0.00074606139 | F34: 2250 | G34: =F34/F$17 -> 0.0011070781 | H34: 5500 | I34: =H34/H$17 -> 0.0027450411 | J34: 3195 | K34: =J34/J$17 -> 0.0013214137 | L34: 5733 | M34: =L34/L$17 -> 0.0026769292 | N34: 2000 | O34: =N34/N$17 -> 0.00088237383 | P34: 2906 | Q34: =P34/P$17 -> 0.00094135848 | R34: 1990 | S34: =R34/R$17 -> 0.00075653145 | T34: 4549 | U34: =T34/T$17 -> 0.0024056157 | V34: 0 | W34: =V34/V$17 -> 0 | X34: 2120 | Y34: =X34/X$17 -> 0.0011194891 | Z34: =SUM(B34,D34,F34,H34,J34,L34,N34,P34,R34,T34,V34,X34) -> 32758 | AE34: =IFERROR(AVERAGE(R34:V34),0) -> 1307.8006
A35: Education | B35: 384 | C35: =B35/B$17 -> 0.00013948395 | D35: 747 | E35: =D35/D$17 -> 0.00036785997 | F35: 551 | G35: =F35/F$17 -> 0.00027111112 | H35: 30 | I35: =H35/H$17 -> 1.4972951e-05 | J35: 195 | K35: =J35/J$17 -> 8.0649664e-05 | L35: 3530 | M35: =L35/L$17 -> 0.0016482749 | N35: 580 | O35: =N35/N$17 -> 0.00025588841 | P35: 741 | Q35: =P35/P$17 -> 0.0002400367 | R35: 288 | S35: =R35/R$17 -> 0.00010948797 | T35: 393 | U35: =T35/T$17 -> 0.00020782743 | V35: 613 | W35: =V35/V$17 -> 0.0002312273 | X35: 386 | Y35: =X35/X$17 -> 0.0002038315 | Z35: =SUM(B35,D35,F35,H35,J35,L35,N35,P35,R35,T35,V35,X35) -> 8438 | AE35: =IFERROR(AVERAGE(R35:V35),0) -> 258.80006
A36: Finance Charges | B36: 5925 | C36: =B36/B$17 -> 0.0021521937 | D36: 10413 | E36: =D36/D$17 -> 0.0051278794 | F36: 5218 | G36: =F36/F$17 -> 0.002567437 | H36: 5293 | I36: =H36/H$17 -> 0.0026417277 | J36: 4211 | K36: =J36/J$17 -> 0.0017416192 | L36: 6331 | M36: =L36/L$17 -> 0.0029561554 | N36: 3452 | O36: =N36/N$17 -> 0.0015229772 | P36: 6117 | Q36: =P36/P$17 -> 0.0019815175 | R36: 3960 | S36: =R36/R$17 -> 0.0015054596 | T36: 4108 | U36: =T36/T$17 -> 0.0021724047 | V36: 7324 | W36: =V36/V$17 -> 0.0027626571 | X36: 4182 | Y36: =X36/X$17 -> 0.0022083506 | Z36: =SUM(B36,D36,F36,H36,J36,L36,N36,P36,R36,T36,V36,X36) -> 66534 | AE36: =IFERROR(AVERAGE(R36:V36),0) -> 3078.4007
A37: Travel, Meals and Entertainment | B37: 6909 | C37: =B37/B$17 -> 0.0025096213 | D37: 22230 | E37: =D37/D$17 -> 0.010947158 | F37: 23841 | G37: =F37/F$17 -> 0.011730599 | H37: 9221 | I37: =H37/H$17 -> 0.0046021862 | J37: 14196 | K37: =J37/J$17 -> 0.0058712955 | L37: 12582 | M37: =L37/L$17 -> 0.0058749562 | N37: 8217 | O37: =N37/N$17 -> 0.0036252329 | P37: 8361 | Q37: =P37/P$17 -> 0.0027084302 | R37: 16892 | S37: =R37/R$17 -> 0.0064217735 | T37: 16986 | U37: =T37/T$17 -> 0.0089825869 | V37: 22674 | W37: =V37/V$17 -> 0.0085527698 | X37: 9671 | Y37: =X37/X$17 -> 0.0051068769 | Z37: =SUM(B37,D37,F37,H37,J37,L37,N37,P37,R37,T37,V37,X37) -> 171780 | AE37: =IFERROR(AVERAGE(R37:V37),0) -> 11310.403
A38: Office Supplies | B38: 11061 | C38: =B38/B$17 -> 0.0040177915 | D38: 15433 | E38: =D38/D$17 -> 0.0075999772 | F38: 25552 | G38: =F38/F$17 -> 0.012572471 | H38: 5873 | I38: =H38/H$17 -> 0.0029312048 | J38: 10971 | K38: =J38/J$17 -> 0.0045374742 | L38: 9129 | M38: =L38/L$17 -> 0.0042626351 | N38: 6500 | O38: =N38/N$17 -> 0.002867715 | P38: 12606 | Q38: =P38/P$17 -> 0.0040835392 | R38: 10500 | S38: =R38/R$17 -> 0.0039917489 | T38: 8851 | U38: =T38/T$17 -> 0.0046806121 | V38: 9384 | W38: =V38/V$17 -> 0.0035397015 | X38: 12390 | Y38: =X38/X$17 -> 0.0065426744 | Z38: =SUM(B38,D38,F38,H38,J38,L38,N38,P38,R38,T38,V38,X38) -> 138250 | AE38: =IFERROR(AVERAGE(R38:V38),0) -> 5747.0017
A39: Total General and Admin Expenses | B39: 25279 | C39: =B39/B$17 -> 0.0091823299 | D39: 50338 | E39: =D39/D$17 -> 0.024788936 | F39: 57412 | G39: =F39/F$17 -> 0.028248696 | H39: 25917 | I39: =H39/H$17 -> 0.012935133 | J39: 32768 | K39: =J39/J$17 -> 0.013552452 | L39: 37305 | M39: =L39/L$17 -> 0.017418951 | N39: 20749 | O39: =N39/N$17 -> 0.0091541873 | P39: 30731 | Q39: =P39/P$17 -> 0.0099548822 | R39: 33630 | S39: =R39/R$17 -> 0.012785001 | T39: 34886 | U39: =T39/T$17 -> 0.018448518 | V39: 39995 | W39: =V39/V$17 -> 0.015086356 | X39: 28749 | Y39: =X39/X$17 -> 0.015181223 | Z39: =SUM(B39,D39,F39,H39,J39,L39,N39,P39,R39,T39,V39,X39) -> 417759 | AE39: =IFERROR(AVERAGE(R39:V39),0) -> 21702.206
A41: Marketing and Advertising Expenses | B41: 430 | C41: =B41/B$17 -> 0.00015619296 | D41: 6417 | E41: =D41/D$17 -> 0.0031600501 | F41: 1910 | G41: =F41/F$17 -> 0.00093978627 | H41: 4000 | I41: =H41/H$17 -> 0.0019963935 | J41: 5896 | K41: =J41/J$17 -> 0.002438515 | L41: 5720 | M41: =L41/L$17 -> 0.0026708591 | N41: 7191 | O41: =N41/N$17 -> 0.0031725751 | P41: 7283 | Q41: =P41/P$17 -> 0.0023592271 | R41: 8952 | S41: =R41/R$17 -> 0.003403251 | T41: 15252 | U41: =T41/T$17 -> 0.0080656079 | V41: 6862 | W41: =V41/V$17 -> 0.0025883879 | X41: 5872 | Y41: =X41/X$17 -> 0.0031007736 | Z41: =SUM(B41,D41,F41,H41,J41,L41,N41,P41,R41,T41,V41,X41) -> 75785 | AE41: =IFERROR(AVERAGE(R41:V41),0) -> 6213.2023
A43: Payroll and Related Expenses | B43: 541229 | C43: =B43/B$17 -> 0.19659572 | D43: 580256 | E43: =D43/D$17 -> 0.28574693 | F43: 696257 | G43: =F43/F$17 -> 0.3425826 | H43: 604704 | I43: =H43/H$17 -> 0.30180679 | J43: 653761 | K43: =J43/J$17 -> 0.27038772 | L43: 653739 | M43: =L43/L$17 -> 0.30525258 | N43: 626338 | O43: =N43/N$17 -> 0.27633213 | P43: 621699 | Q43: =P43/P$17 -> 0.20139079 | R43: 601845 | S43: =R43/R$17 -> 0.22880134 | T43: 581106 | U43: =T43/T$17 -> 0.3073022 | V43: 577214 | W43: =V43/V$17 -> 0.21772861 | X43: 228687 | Y43: =X43/X$17 -> 0.12076066 | Z43: =SUM(B43,D43,F43,H43,J43,L43,N43,P43,R43,T43,V43,X43) -> 6966835 | AE43: =IFERROR(AVERAGE(R43:V43),0) -> 352033.11
A45: Utilities and Facilities | B45: 36312 | C45: =B45/B$17 -> 0.013189951 | D45: 38163 | E45: =D45/D$17 -> 0.01879336 | F45: 34502 | G45: =F45/F$17 -> 0.016976181 | H45: 35778 | I45: =H45/H$17 -> 0.017856742 | K45: =J45/J$17 -> 0 | L45: 38163 | M45: =L45/L$17 -> 0.01781958 | N45: 28934 | O45: =N45/N$17 -> 0.012765302 | P45: 37666 | Q45: =P45/P$17 -> 0.012201379 | R45: 45659 | S45: =R45/R$17 -> 0.017358025 | T45: 36689 | U45: =T45/T$17 -> 0.019401986 | V45: 21278 | W45: =V45/V$17 -> 0.0080261902 | X45: 9891 | Y45: =X45/X$17 -> 0.0052230503 | Z45: =SUM(B45,D45,F45,H45,J45,L45,N45,P45,R45,T45,V45,X45) -> 363035 | AE45: =IFERROR(AVERAGE(R45:V45),0) -> 20725.207
A47: Ops and Maint. Expenses
A48: Automobile Expenses | C48: =B48/B$17 -> 0 | E48: =D48/D$17 -> 0 | G48: =F48/F$17 -> 0 | H48: 13580 | I48: =H48/H$17 -> 0.006777756 | K48: =J48/J$17 -> 0 | M48: =L48/L$17 -> 0 | O48: =N48/N$17 -> 0 | P48: 17399 | Q48: =P48/P$17 -> 0.0056361653 | R48: 14359 | S48: =R48/R$17 -> 0.0054588116 | T48: 16439 | U48: =T48/T$17 -> 0.0086933208 | V48: 15551 | W48: =V48/V$17 -> 0.0058659312 | X48: 18765 | Y48: =X48/X$17 -> 0.0099090626 | Z48: =SUM(B48,D48,F48,H48,J48,L48,N48,P48,R48,T48,V48,X48) -> 96093 | AE48: =IFERROR(AVERAGE(R48:V48),0) -> 9269.8028
...

Sheet Ohio
B1: Month 1 ($) | C1: Month 1 (%) | D1: Month 2 ($) | E1: Month 2 (%) | F1: Month 3 ($) | G1: Month 3 (%) | H1: Month 4 ($) | I1: Month 4 (%) | J1: Month 5 ($) | K1: Month 5 (%) | L1: Month 6 ($) | M1: Month 6 (%) | N1: Month 7 ($) | O1: Month 7 (%) | P1: Month 8 ($) | Q1: Month 8 (%) | R1: Month 9 ($) | S1: Month 9 (%) | T1: Month 10 ($) | U1: Month 10 (%) | V1: Month 11 ($) | W1: Month 11 (%) | X1: Month 12 ($) | Y1: Month 12 (%) | Z1: 12 Month Totals | AA1: 12 Month Average | AB1: 3 Month Average | AD1: 10 Month Sparkline | AE1: Last 3 Months Average | AF1: Last 3 Months Sparkline | AG1: Target $ | AH1: Target % | AI1: Swag for Neutral | AJ1: Dashboard | AK1: Annual Budget Q1 * 4 | AL1: Monthly Budget | AM1: Notes:
A2: Location | B2: Ohio | D2: Ohio | F2: Ohio | H2: Ohio | J2: Ohio | L2: Ohio | N2: Ohio | P2: Ohio | R2: Ohio | T2: Ohio | V2: Ohio | X2: Ohio | Y2: All Locations | Z2: Ohio | AA2: Ohio | AB2: Ohio
A3: Month | B3: ='Combined Company'!B3 -> 01/31/2023 | D3: ='Combined Company'!D3 -> 02/28/2023 | F3: ='Combined Company'!F3 -> 03/31/2023 | H3: ='Combined Company'!H3 -> 45046 | J3: ='Combined Company'!J3 -> 45077 | L3: ='Combined Company'!L3 -> 45107 | N3: ='Combined Company'!N3 -> 45138 | P3: ='Combined Company'!P3 -> 45169 | R3: ='Combined Company'!R3 -> 45199 | T3: ='Combined Company'!T3 -> 45230 | V3: ='Combined Company'!V3 -> 45260 | X3: ='Combined Company'!X3 -> 45291
A4: Days in Month | B4: ='Combined Company'!B4 -> 31 | D4: ='Combined Company'!D4 -> 28 | F4: ='Combined Company'!F4 -> 31 | H4: ='Combined Company'!H4 -> 30 | J4: ='Combined Company'!J4 -> 31 | L4: ='Combined Company'!L4 -> 30 | N4: ='Combined Company'!N4 -> 31 | P4: ='Combined Company'!P4 -> 31 | R4: ='Combined Company'!R4 -> 30 | T4: ='Combined Company'!T4 -> 31 | V4: ='Combined Company'!V4 -> 30 | X4: ='Combined Company'!X4 -> 31
A5: Quarter | B5: ='Combined Company'!B5 -> 1 | D5: ='Combined Company'!D5 -> 1 | F5: ='Combined Company'!F5 -> 1 | H5: ='Combined Company'!H5 -> 2 | J5: ='Combined Company'!J5 -> 2 | L5: ='Combined Company'!L5 -> 2 | N5: ='Combined Company'!N5 -> 3 | P5: ='Combined Company'!P5 -> 3 | R5: ='Combined Company'!R5 -> 3 | T5: ='Combined Company'!T5 -> 4 | V5: ='Combined Company'!V5 -> 4 | X5: ='Combined Company'!X5 -> 4
A6: Year | B6: ='Combined Company'!B6 -> 2023 | D6: ='Combined Company'!D6 -> 2023 | F6: ='Combined Company'!F6 -> 2023 | H6: ='Combined Company'!H6 -> 2023 | J6: ='Combined Company'!J6 -> 2023 | L6: ='Combined Company'!L6 -> 2023 | N6: ='Combined Company'!N6 -> 2023 | P6: ='Combined Company'!P6 -> 2023 | R6: ='Combined Company'!R6 -> 2023 | T6: ='Combined Company'!T6 -> 2023 | V6: ='Combined Company'!V6 -> 2023 | X6: ='Combined Company'!X6 -> 2023
A8: Revenue
A9: Managed IT Services (Recurring IT & Security) | B9: 102223 | C9: =B9/B$17 -> 0.35615909 | D9: 101637 | E9: =D9/D$17 -> 0.152503 | F9: 133979 | G9: =F9/F$17 -> 0.34186427 | H9: 157213 | I9: =H9/H$17 -> 0.26697404 | J9: 99474 | K9: =J9/J$17 -> 0.096427377 | L9: 109822 | M9: =L9/L$17 -> 0.23772745 | N9: 97176 | O9: =N9/N$17 -> 0.11439563 | P9: 121475 | Q9: =P9/P$17 -> 0.10535103 | R9: 103635 | S9: =R9/R$17 -> 0.11605744 | T9: 115881 | U9: =T9/T$17 -> 0.16262904 | V9: 113271 | W9: =V9/V$17 -> 0.33496571 | X9: 115351 | Y9: =X9/X$17 -> 0.15040048 | Z9: =SUM(B9,D9,F9,H9,J9,L9,N9,P9,R9,T9,V9,X9) -> 1371137 | AA9: =IFERROR(AVERAGE(B9,D9,F9,H9,J9,L9,N9,P9,R9,T9,V9,X9),0) -> 114261.42 | AB9: =IFERROR(AVERAGE(T9,V9,X9),0) -> 114834.33 | AE9: =IFERROR(AVERAGE(R9,T9,V9),0) -> 110929 | AK9: =SUM(T9,V9,X9)*4 -> 1378012 | AL9: =AK9/12 -> 114834.33
A10: Cloud (Private Cloud Only as of 4/1/23) | B10: 43961 | C10: =B10/B$17 -> 0.15316621 | D10: 7683 | E10: =D10/D$17 -> 0.011528091 | F10: 31895 | G10: =F10/F$17 -> 0.081384104 | H10: 161 | I10: =H10/H$17 -> 0.000273405 | J10: 184 | K10: =J10/J$17 -> 0.00017836457 | L10: 177 | M10: =L10/L$17 -> 0.00038314508 | N10: 161 | O10: =N10/N$17 -> 0.00018952927 | P10: 0 | Q10: =P10/P$17 -> 0 | R10: 0 | S10: =R10/R$17 -> 0 | T10: 0 | U10: =T10/T$17 -> 0 | V10: 0 | W10: =V10/V$17 -> 0 | X10: 0 | Y10: =X10/X$17 -> 0 | Z10: =SUM(B10,D10,F10,H10,J10,L10,N10,P10,R10,T10,V10,X10) -> 84222 | AA10: =IFERROR(AVERAGE(B10,D10,F10,H10,J10,L10,N10,P10,R10,T10,V10,X10),0) -> 7018.5 | AB10: =IFERROR(AVERAGE(T10,V10,X10),0) -> 0 | AE10: =IFERROR(AVERAGE(R10,T10,V10),0) -> 0 | AK10: =SUM(T10,V10,X10)*4 -> 0 | AL10: =AK10/12 -> 0
A11: Recurring Resale (Includes previouse Cloud sales) | C11: =B11/B$17 -> 0 | E11: =D11/D$17 -> 0 | G11: =F11/F$17 -> 0 | H11: 13167 | I11: =H11/H$17 -> 0.022359774 | J11: 12214 | K11: =J11/J$17 -> 0.011839918 | L11: 13079 | M11: =L11/L$17 -> 0.028311607 | N11: 6002 | O11: =N11/N$17 -> 0.0070655571 | P11: 11891 | Q11: =P11/P$17 -> 0.010312649 | R11: 13655 | S11: =R11/R$17 -> 0.015291787 | T11: 17769 | U11: =T11/T$17 -> 0.024937267 | V11: 17622 | W11: =V11/V$17 -> 0.052111889 | X11: 17987 | Y11: =X11/X$17 -> 0.023452362 | Z11: =SUM(B11,D11,F11,H11,J11,L11,N11,P11,R11,T11,V11,X11) -> 123386 | AA11: =IFERROR(AVERAGE(B11,D11,F11,H11,J11,L11,N11,P11,R11,T11,V11,X11),0) -> 13709.556 | AB11: =IFERROR(AVERAGE(T11,V11,X11),0) -> 17792.667 | AK11: =(X11*3)*4 -> 215844 | AL11: =AK11/12 -> 17987 | AM11: *Just started tracking in April - Use (April * 3) * 4
A12: Project Services | B12: 59765 | C12: =B12/B$17 -> 0.20822954 | D12: 113090 | E12: =D12/D$17 -> 0.16968786 | F12: 72796 | G12: =F12/F$17 -> 0.18574815 | H12: 11734 | I12: =H12/H$17 -> 0.0199263 | J12: 80606 | K12: =J12/J$17 -> 0.078137253 | L12: 42267 | M12: =L12/L$17 -> 0.091493746 | N12: 92912 | O12: =N12/N$17 -> 0.10937605 | P12: 108496 | Q12: =P12/P$17 -> 0.094094792 | R12: 75466 | S12: =R12/R$17 -> 0.0845119 | T12: 71848 | U12: =T12/T$17 -> 0.10083251 | V12: 11245 | W12: =V12/V$17 -> 0.033253784 | X12: 31148 | Y12: =X12/X$17 -> 0.04061234 | Z12: =SUM(B12,D12,F12,H12,J12,L12,N12,P12,R12,T12,V12,X12) -> 771373 | AA12: =IFERROR(AVERAGE(B12,D12,F12,H12,J12,L12,N12,P12,R12,T12,V12,X12),0) -> 64281.083 | AB12: =IFERROR(AVERAGE(T12,V12,X12),0) -> 38080.333 | AE12: =IFERROR(AVERAGE(R12,T12,V12),0) -> 52853 | AK12: =SUM(T12,V12,X12)*4 -> 456964 | AL12: =AK12/12 -> 38080.333
A13: Subcontracted Services | B13: 0 | C13: =B13/B$17 -> 0 | D13: 1592 | E13: =D13/D$17 -> 0.0023887441 | F13: 145 | G13: =F13/F$17 -> 0.00036998574 | H13: 987 | I13: =H13/H$17 -> 0.0016760915 | J13: 0 | K13: =J13/J$17 -> 0 | L13: 0 | M13: =L13/L$17 -> 0 | N13: 0 | O13: =N13/N$17 -> 0 | P13: 0 | Q13: =P13/P$17 -> 0 | R13: 5929 | S13: =R13/R$17 -> 0.0066396928 | T13: 1108 | U13: =T13/T$17 -> 0.001554983 | V13: 1820 | W13: =V13/V$17 -> 0.0053821154 | X13: 2427 | Y13: =X13/X$17 -> 0.0031644456 | Z13: =SUM(B13,D13,F13,H13,J13,L13,N13,P13,R13,T13,V13,X13) -> 14008 | AA13: =IFERROR(AVERAGE(B13,D13,F13,H13,J13,L13,N13,P13,R13,T13,V13,X13),0) -> 1167.3333 | AB13: =IFERROR(AVERAGE(T13,V13,X13),0) -> 1785 | AE13: =IFERROR(AVERAGE(R13,T13,V13),0) -> 2952.3333 | AK13: =SUM(T13,V13,X13)*4 -> 21420 | AL13: =AK13/12 -> 1785
A14: Product Sales | B14: 81066 | C14: =B14/B$17 -> 0.28244517 | D14: 442457 | E14: =D14/D$17 -> 0.6638923 | F14: 153161 | G14: =F14/F$17 -> 0.39080955 | H14: 405608 | I14: =H14/H$17 -> 0.6887904 | J14: 839117 | K14: =J14/J$17 -> 0.81341709 | L14: 296621 | M14: =L14/L$17 -> 0.64208405 | N14: 653222 | O14: =N14/N$17 -> 0.76897323 | P14: 911188 | Q14: =P14/P$17 -> 0.79024153 | R14: 685651 | S14: =R14/R$17 -> 0.76783809 | T14: 499231 | U14: =T14/T$17 -> 0.70062789 | V14: 187218 | W14: =V14/V$17 -> 0.55364224 | X14: 591430 | Y14: =X14/X$17 -> 0.7711364 | Z14: =SUM(B14,D14,F14,H14,J14,L14,N14,P14,R14,T14,V14,X14) -> 5745970 | AA14: =IFERROR(AVERAGE(B14,D14,F14,H14,J14,L14,N14,P14,R14,T14,V14,X14),0) -> 478830.83 | AB14: =IFERROR(AVERAGE(T14,V14,X14),0) -> 425959.67 | AE14: =IFERROR(AVERAGE(R14,T14,V14),0) -> 457366.67 | AK14: =SUM(T14,V14,X14)*4 -> 5111516 | AL14: =AK14/12 -> 425959.67
A15: Commissions | B15: 0 | C15: =B15/B$17 -> 0 | D15: 0 | E15: =D15/D$17 -> 0 | F15: 0 | G15: =F15/F$17 -> 0 | H15: 0 | I15: =H15/H$17 -> 0 | J15: 0 | K15: =J15/J$17 -> 0 | L15: 0 | M15: =L15/L$17 -> 0 | N15: 0 | O15: =N15/N$17 -> 0 | Q15: =P15/P$17 -> 0 | R15: 8627 | S15: =R15/R$17 -> 0.0096610946 | T15: 6711 | U15: =T15/T$17 -> 0.0094183129 | V15: 6981 | W15: =V15/V$17 -> 0.020644257 | X15: 8616 | Y15: =X15/X$17 -> 0.011233977 | Z15: =SUM(B15,D15,F15,H15,J15,L15,N15,P15,R15,T15,V15,X15) -> 30935 | AA15: =IFERROR(AVERAGE(B15,D15,F15,H15,J15,L15,N15,P15,R15,T15,V15,X15),0) -> 2812.2727 | AB15: =IFERROR(AVERAGE(T15,V15,X15),0) -> 7436 | AE15: =IFERROR(AVERAGE(R15,T15,V15),0) -> 7439.6667 | AK15: =SUM(T15,V15,X15)*4 -> 89232 | AL15: =AK15/12 -> 7436
A16: Sales Returns and Discounts | C16: =B16/B$17 -> 0 | E16: =D16/D$17 -> 0 | F16: 69 | G16: =F16/F$17 -> 0.00017606218 | H16: 0 | I16: =H16/H$17 -> 0 | J16: 0 | K16: =J16/J$17 -> 0 | L16: 0 | M16: =L16/L$17 -> 0 | N16: 0 | O16: =N16/N$17 -> 0 | Q16: =P16/P$17 -> 0 | R16: 0 | S16: =R16/R$17 -> 0 | T16: 0 | U16: =T16/T$17 -> 0 | V16: 0 | W16: =V16/V$17 -> 0 | X16: 0 | Y16: =X16/X$17 -> 0 | Z16: =SUM(B16,D16,F16,H16,J16,L16,N16,P16,R16,T16,V16,X16) -> 69 | AA16: =IFERROR(AVERAGE(B16,D16,F16,H16,J16,L16,N16,P16,R16,T16,V16,X16),0) -> 7.6666667 | AB16: =IFERROR(AVERAGE(T16,V16,X16),0) -> 0 | AE16: =IFERROR(AVERAGE(R16,T16,V16),0) -> 0 | AK16: =SUM(T16,V16,X16)*4 -> 0 | AL16: =AK16/12 -> 0
A17: Total Revenue | B17: 287015 | C17: =B17/B$17 -> 1 | D17: 666459 | E17: =D17/D$17 -> 1 | F17: 391907 | G17: =F17/F$17 -> 1 | H17: 588870 | I17: =H17/H$17 -> 1 | J17: =SUM(J9:J16) -> 1031595 | K17: =J17/J$17 -> 1 | L17: =SUM(L9:L16) -> 461966 | M17: =L17/L$17 -> 1 | N17: =SUM(N9:N16) -> 849473 | O17: =N17/N$17 -> 1 | P17: =SUM(P9:P16) -> 1153050 | Q17: =P17/P$17 -> 1 | R17: =SUM(R9:R16) -> 892963 | S17: =R17/R$17 -> 1 | T17: =SUM(T9:T16) -> 712548 | U17: =T17/T$17 -> 1 | V17: =SUM(V9:V16) -> 338157 | W17: =V17/V$17 -> 1 | X17: =SUM(X9:X16) -> 766959 | Y17: =X17/X$17 -> 1 | Z17: =SUM(B17,D17,F17,H17,J17,L17,N17,P17,R17,T17,V17,X17) -> 8140962 | AA17: =IFERROR(AVERAGE(B17,D17,F17,H17,J17,L17,N17,P17,R17,T17,V17,X17),0) -> 678413.5 | AB17: =IFERROR(AVERAGE(T17,V17,X17),0) -> 605888 | AE17: =IFERROR(AVERAGE(R17:V17),0) -> 388734 | AK17: =SUM(T17,V17,X17)*4 -> 7270656 | AL17: =AK17/12 -> 605888
A20: Cost of Goods and Services
A21: Managed IT Service Costs | B21: 18619 | C21: =B21/B$17 -> 0.064871174 | D21: 24994 | E21: =D21/D$17 -> 0.037502682 | F21: 45087 | G21: =F21/F$17 -> 0.11504515 | H21: 6029 | I21: =H21/H$17 -> 0.010238253 | J21: 6080 | K21: =J21/J$17 -> 0.0058937858 | L21: 1069 | M21: =L21/L$17 -> 0.0023140231 | N21: 6052 | O21: =N21/N$17 -> 0.0071244171 | P21: 11012 | Q21: =P21/P$17 -> 0.0095503231 | R21: 1382 | S21: =R21/R$17 -> 0.0015476565 | T21: 5640 | U21: =T21/T$17 -> 0.0079152562 | V21: 6486 | W21: =V21/V$17 -> 0.01918044 | X21: 5547 | Y21: =X21/X$17 -> 0.0072324596 | Z21: =SUM(F21,H21,J21,L21,N21,P21,R21,T21,V21,X21) -> 94384 | AA21: =IFERROR(AVERAGE(B21,D21,F21,H21,J21,L21,N21,P21,R21,T21,V21,X21),0) -> 11499.75 | AB21: =IFERROR(AVERAGE(T21,V21,X21),0) -> 5891 | AE21: =IFERROR(AVERAGE(R21:V21),0) -> 2701.6019 | AK21: =SUM(T21,V21,X21)*4 -> 70692 | AL21: =AK21/12 -> 5891
A22: Cloud Service Costs | B22: 4135 | C22: =B22/B$17 -> 0.014406913 | D22: 2185 | E22: =D22/D$17 -> 0.0032785213 | F22: 5390 | G22: =F22/F$17 -> 0.013753263 | H22: 109 | I22: =H22/H$17 -> 0.00018510028 | J22: 407 | K22: =J22/J$17 -> 0.00039453468 | L22: 246 | M22: =L22/L$17 -> 0.00053250672 | N22: 105 | O22: =N22/N$17 -> 0.00012360605 | P22: 17 | Q22: =P22/P$17 -> 1.4743506e-05 | R22: 17 | S22: =R22/R$17 -> 1.9037743e-05 | T22: 17 | U22: =T22/T$17 -> 2.3858042e-05 | V22: 17 | W22: =V22/V$17 -> 5.0272507e-05 | X22: 17 | Y22: =X22/X$17 -> 2.2165461e-05 | Z22: =SUM(F22,H22,J22,L22,N22,P22,R22,T22,V22,X22) -> 6342 | AA22: =IFERROR(AVERAGE(B22,D22,F22,H22,J22,L22,N22,P22,R22,T22,V22,X22),0) -> 1055.1667 | AB22: =IFERROR(AVERAGE(T22,V22,X22),0) -> 17 | AE22: =IFERROR(AVERAGE(R22:V22),0) -> 10.200009 | AK22: =SUM(T22,V22,X22)*4 -> 204 | AL22: =AK22/12 -> 17
A23: Recurring Resale Costs | C23: =B23/B$17 -> 0 | E23: =D23/D$17 -> 0 | G23: =F23/F$17 -> 0 | H23: 5031 | I23: =H23/H$17 -> 0.0085434816 | J23: 6543 | K23: =J23/J$17 -> 0.0063426054 | L23: 7471 | M23: =L23/L$17 -> 0.016172186 | N23: 4127 | O23: =N23/N$17 -> 0.0048583063 | P23: 5998 | Q23: =P23/P$17 -> 0.0052018559 | R23: 7779 | S23: =R23/R$17 -> 0.0087114472 | T23: 10243 | U23: =T23/T$17 -> 0.014375172 | V23: 9387 | W23: =V23/V$17 -> 0.027759295 | X23: 9666 | Y23: =X23/X$17 -> 0.012603021 | Z23: =SUM(F23,H23,J23,L23,N23,P23,R23,T23,V23,X23) -> 66245 | AA23: =IFERROR(AVERAGE(B23,D23,F23,H23,J23,L23,N23,P23,R23,T23,V23,X23),0) -> 7360.5556 | AB23: =IFERROR(AVERAGE(T23,V23,X23),0) -> 9765.3333 | AK23: =(X23*3)*4 -> 115992 | AL23: =AK23/12 -> 9666 | AM23: *Just started tracking in April - Use (April * 3) * 4
A24: Project Service Costs | C24: =B24/B$17 -> 0 | D24: 942 | E24: =D24/D$17 -> 0.0014134403 | F24: 1071 | G24: =F24/F$17 -> 0.0027327912 | H24: 0 | I24: =H24/H$17 -> 0 | J24: 0 | K24: =J24/J$17 -> 0 | L24: 0 | M24: =L24/L$17 -> 0 | N24: 0 | O24: =N24/N$17 -> 0 | P24: 525 | Q24: =P24/P$17 -> 0.00045531417 | R24: 5449 | S24: =R24/R$17 -> 0.0061021565 | T24: 877 | U24: =T24/T$17 -> 0.0012307943 | V24: 0 | W24: =V24/V$17 -> 0 | X24: 0 | Y24: =X24/X$17 -> 0 | Z24: =SUM(F24,H24,J24,L24,N24,P24,R24,T24,V24,X24) -> 7922 | AA24: =IFERROR(AVERAGE(B24,D24,F24,H24,J24,L24,N24,P24,R24,T24,V24,X24),0) -> 805.81818 | AB24: =IFERROR(AVERAGE(T24,V24,X24),0) -> 292.33333 | AE24: =IFERROR(AVERAGE(R24:V24),0) -> 1265.2015 | AK24: =SUM(T24,V24,X24)*4 -> 3508 | AL24: =AK24/12 -> 292.33333
A25: Subcontractor Service Costs | B25: 795 | C25: =B25/B$17 -> 0.0027698901 | D25: 2816 | E25: =D25/D$17 -> 0.0042253162 | F25: 102 | G25: =F25/F$17 -> 0.00026026583 | H25: 871 | I25: =H25/H$17 -> 0.001479104 | J25: 0 | K25: =J25/J$17 -> 0 | L25: 0 | M25: =L25/L$17 -> 0 | N25: 4 | O25: =N25/N$17 -> 4.7088018e-06 | P25: 0 | Q25: =P25/P$17 -> 0 | R25: 3321 | S25: =R25/R$17 -> 0.0037190791 | T25: 450 | U25: =T25/T$17 -> 0.0006315364 | V25: 1400 | W25: =V25/V$17 -> 0.0041400888 | X25: 1290 | Y25: =X25/X$17 -> 0.0016819674 | Z25: =SUM(F25,H25,J25,L25,N25,P25,R25,T25,V25,X25) -> 7438 | AA25: =IFERROR(AVERAGE(B25,D25,F25,H25,J25,L25,N25,P25,R25,T25,V25,X25),0) -> 920.75 | AB25: =IFERROR(AVERAGE(T25,V25,X25),0) -> 1046.6667 | AE25: =IFERROR(AVERAGE(R25:V25),0) -> 1034.2009 | AK25: =SUM(T25,V25,X25)*4 -> 12560 | AL25: =AK25/12 -> 1046.6667
A26: Product Sales Costs | B26: 68603 | C26: =B26/B$17 -> 0.23902235 | D26: 335871 | E26: =D26/D$17 -> 0.50396348 | F26: 128558 | G26: =F26/F$17 -> 0.32803191 | H26: 335659 | I26: =H26/H$17 -> 0.57000526 | J26: 707631 | K26: =J26/J$17 -> 0.68595815 | L26: 249562 | M26: =L26/L$17 -> 0.54021725 | N26: 567432 | O26: =N26/N$17 -> 0.66798121 | P26: 715251 | Q26: =P26/P$17 -> 0.62031222 | R26: 572663 | S26: =R26/R$17 -> 0.64130653 | T26: 400895 | U26: =T26/T$17 -> 0.56262175 | V26: 153639 | W26: =V26/V$17 -> 0.45434221 | X26: 493536 | Y26: =X26/X$17 -> 0.64349724 | Z26: =SUM(F26,H26,J26,L26,N26,P26,R26,T26,V26,X26) -> 4324826 | AA26: =IFERROR(AVERAGE(B26,D26,F26,H26,J26,L26,N26,P26,R26,T26,V26,X26),0) -> 394108.33 | AB26: =IFERROR(AVERAGE(T26,V26,X26),0) -> 349356.67 | AE26: =IFERROR(AVERAGE(R26:V26),0) -> 225439.64 | AK26: =SUM(T26,V26,X26)*4 -> 4192280 | AL26: =AK26/12 -> 349356.67
A27: Total COGS | B27: 92152 | C27: =B27/B$17 -> 0.32107033 | D27: 366808 | E27: =D27/D$17 -> 0.55038344 | F27: 180208 | G27: =F27/F$17 -> 0.45982338 | H27: 347699 | I27: =H27/H$17 -> 0.5904512 | J27: =SUM(J21:J26) -> 720661 | K27: =J27/J$17 -> 0.69858908 | L27: =SUM(L21:L26) -> 258348 | M27: =L27/L$17 -> 0.55923596 | N27: =SUM(N21:N26) -> 577720 | O27: =N27/N$17 -> 0.68009225 | P27: =SUM(P21:P26) -> 732803 | Q27: =P27/P$17 -> 0.63553445 | R27: =SUM(R21:R26) -> 590611 | S27: =R27/R$17 -> 0.6614059 | T27: =SUM(T21:T26) -> 418122 | U27: =T27/T$17 -> 0.58679836 | V27: =SUM(V21:V26) -> 170929 | W27: =V27/V$17 -> 0.50547231 | X27: =SUM(X21:X26) -> 510056 | Y27: =X27/X$17 -> 0.66503685 | Z27: =SUM(F27,H27,J27,L27,N27,P27,R27,T27,V27,X27) -> 4507157 | AA27: =IFERROR(AVERAGE(B27,D27,F27,H27,J27,L27,N27,P27,R27,T27,V27,X27),0) -> 413843.08 | AB27: =IFERROR(AVERAGE(T27,V27,X27),0) -> 366369 | AE27: =IFERROR(AVERAGE(R27:V27),0) -> 235932.65 | AK27: =SUM(T27,V27,X27)*4 -> 4396428 | AL27: =AK27/12 -> 366369
Z28: =SUM(F28,H28,J28,L28,N28,P28,R28,T28,V28,X28) -> 0 | AA28: =IFERROR(AVERAGE(F28,H28,J28,L28,N28,P28,R28,T28,V28,X28),0) -> 0 | AB28: =IFERROR(AVERAGE(T28,V28,X28),0) -> 0
A29: Gross Profit | B29: 194863 | C29: =B29/B$17 -> 0.67892967 | D29: 299651 | E29: =D29/D$17 -> 0.44961656 | F29: 211699 | G29: =F29/F$17 -> 0.54017662 | H29: 241171 | I29: =H29/H$17 -> 0.4095488 | J29: =+J17-J27 -> 310934 | K29: =J29/J$17 -> 0.30141092 | L29: =+L17-L27 -> 203618 | M29: =L29/L$17 -> 0.44076404 | N29: =+N17-N27 -> 271753 | O29: =N29/N$17 -> 0.31990775 | P29: =+P17-P27 -> 420247 | Q29: =P29/P$17 -> 0.36446555 | R29: =+R17-R27 -> 302352 | S29: =R29/R$17 -> 0.3385941 | T29: =+T17-T27 -> 294426 | U29: =T29/T$17 -> 0.41320164 | V29: =+V17-V27 -> 167228 | W29: =V29/V$17 -> 0.49452769 | X29: =+X17-X27 -> 256903 | Y29: =X29/X$17 -> 0.33496315 | Z29: =SUM(F29,H29,J29,L29,N29,P29,R29,T29,V29,X29) -> 2680331 | AA29: =IFERROR(AVERAGE(B29,D29,F29,H29,J29,L29,N29,P29,R29,T29,V29,X29),0) -> 264570.42 | AB29: =IFERROR(AVERAGE(T29,V29,X29),0) -> 239519 | AE29: =IFERROR(AVERAGE(R29:V29),0) -> 152801.35 | AK29: =SUM(T29,V29,X29)*4 -> 2874228 | AL29: =AK29/12 -> 239519
A30: Gross Profit % | B30: =B29/B17 -> 0.67892967 | C30: =C29/C17 -> 0.67892967 | D30: =D29/D17 -> 0.44961656 | E30: =E29/E17 -> 0.44961656 | F30: =F29/F17 -> 0.54017662 | G30: =G29/G17 -> 0.54017662 | H30: =H29/H17 -> 0.4095488 | I30: =I29/I17 -> 0.4095488 | ... AB30: =AB29/AB17 -> 0.39531894 | AH30: 0.55
A32: Operating Expenses
A33: General & Admin Expenses
A34: Charitable Contributions | C34: =B34/B$17 -> 0 | E34: =D34/D$17 -> 0 | G34: =F34/F$17 -> 0 | H34: 0 | I34: =H34/H$17 -> 0 | J34: 0 | K34: =J34/J$17 -> 0 | L34: 0 | M34: =L34/L$17 -> 0 | N34: 0 | O34: =N34/N$17 -> 0 | P34: 0 | Q34: =P34/P$17 -> 0 | R34: 0 | S34: =R34/R$17 -> 0 | T34: 0 | U34: =T34/T$17 -> 0 | V34: 0 | W34: =V34/V$17 -> 0 | X34: 0 | Y34: =X34/X$17 -> 0 | Z34: =SUM(B34,D34,F34,H34,J34,L34,N34,P34,R34,T34,V34,X34) -> 0 | AA34: =IFERROR(AVERAGE(B34,D34,F34,H34,J34,L34,N34,P34,R34,T34,V34,X34),0) -> 0 | AB34: =IFERROR(AVERAGE(T34,V34,X34),0) -> 0 | AE34: =IFERROR(AVERAGE(R34:V34),0) -> 0 | AK34: =SUM(T34,V34,X34)*4 -> 0 | AL34: =AK34/12 -> 0
A35: Education | C35: =B35/B$17 -> 0 | E35: =D35/D$17 -> 0 | G35: =F35/F$17 -> 0 | H35: 0 | I35: =H35/H$17 -> 0 | J35: 0 | K35: =J35/J$17 -> 0 | L35: 0 | M35: =L35/L$17 -> 0 | N35: 0 | O35: =N35/N$17 -> 0 | P35: 150 | Q35: =P35/P$17 -> 0.00013008976 | R35: 0 | S35: =R35/R$17 -> 0 | T35: 129 | U35: =T35/T$17 -> 0.00018104044 | V35: 471 | W35: =V35/V$17 -> 0.0013928442 | X35: 63 | Y35: =X35/X$17 -> 8.2142592e-05 | Z35: =SUM(B35,D35,F35,H35,J35,L35,N35,P35,R35,T35,V35,X35) -> 813 | AA35: =IFERROR(AVERAGE(B35,D35,F35,H35,J35,L35,N35,P35,R35,T35,V35,X35),0) -> 90.333333 | AB35: =IFERROR(AVERAGE(T35,V35,X35),0) -> 221 | AE35: =IFERROR(AVERAGE(R35:V35),0) -> 120.00004 | AK35: =SUM(T35,V35,X35)*4 -> 2652 | AL35: =AK35/12 -> 221
A36: Finance Charges | C36: =B36/B$17 -> 0 | E36: =D36/D$17 -> 0 | G36: =F36/F$17 -> 0 | H36: 0 | I36: =H36/H$17 -> 0 | J36: 0 | K36: =J36/J$17 -> 0 | L36: 775 | M36: =L36/L$17 -> 0.0016776126 | N36: 0 | O36: =N36/N$17 -> 0 | P36: 0 | Q36: =P36/P$17 -> 0 | R36: 0 | S36: =R36/R$17 -> 0 | T36: 0 | U36: =T36/T$17 -> 0 | V36: 0 | W36: =V36/V$17 -> 0 | X36: 205 | Y36: =X36/X$17 -> 0.00026728939 | Z36: =SUM(B36,D36,F36,H36,J36,L36,N36,P36,R36,T36,V36,X36) -> 980 | AA36: =IFERROR(AVERAGE(B36,D36,F36,H36,J36,L36,N36,P36,R36,T36,V36,X36),0) -> 108.88889 | AB36: =IFERROR(AVERAGE(T36,V36,X36),0) -> 68.333333 | AE36: =IFERROR(AVERAGE(R36:V36),0) -> 0 | AK36: =SUM(T36,V36,X36)*4 -> 820 | AL36: =AK36/12 -> 68.333333
A37: Travel, Meals and Entertainment | C37: =B37/B$17 -> 0 | E37: =D37/D$17 -> 0 | G37: =F37/F$17 -> 0 | H37: 836 | I37: =H37/H$17 -> 0.0014196682 | J37: 1101 | K37: =J37/J$17 -> 0.0010672793 | L37: 993 | M37: =L37/L$17 -> 0.0021495088 | N37: 3856 | O37: =N37/N$17 -> 0.0045392849 | P37: 477 | Q37: =P37/P$17 -> 0.00041368544 | R37: 5504 | S37: =R37/R$17 -> 0.0061637492 | T37: 1815 | U37: =T37/T$17 -> 0.0025471968 | V37: 6145 | W37: =V37/V$17 -> 0.018172033 | X37: 766 | Y37: =X37/X$17 -> 0.00099874961 | Z37: =SUM(B37,D37,F37,H37,J37,L37,N37,P37,R37,T37,V37,X37) -> 21493 | AA37: =IFERROR(AVERAGE(B37,D37,F37,H37,J37,L37,N37,P37,R37,T37,V37,X37),0) -> 2388.1111 | AB37: =IFERROR(AVERAGE(T37,V37,X37),0) -> 2908.6667 | AE37: =IFERROR(AVERAGE(R37:V37),0) -> 2692.8017 | AK37: =SUM(T37,V37,X37)*4 -> 34904 | AL37: =AK37/12 -> 2908.6667
A38: Office Supplies | C38: =B38/B$17 -> 0 | E38: =D38/D$17 -> 0 | G38: =F38/F$17 -> 0 | H38: 1364 | I38: =H38/H$17 -> 0.0023163007 | J38: 2208 | K38: =J38/J$17 -> 0.0021403749 | L38: 1838 | M38: =L38/L$17 -> 0.0039786478 | N38: 680 | O38: =N38/N$17 -> 0.00080049631 | P38: 3809 | Q38: =P38/P$17 -> 0.0033034127 | R38: 1162 | S38: =R38/R$17 -> 0.0013012857 | T38: 2234 | U38: =T38/T$17 -> 0.0031352274 | V38: 4125 | W38: =V38/V$17 -> 0.012198476 | X38: 1075 | Y38: =X38/X$17 -> 0.0014016395 | Z38: =SUM(B38,D38,F38,H38,J38,L38,N38,P38,R38,T38,V38,X38) -> 18495 | AA38: =IFERROR(AVERAGE(B38,D38,F38,H38,J38,L38,N38,P38,R38,T38,V38,X38),0) -> 2055 | AB38: =IFERROR(AVERAGE(T38,V38,X38),0) -> 2478 | AE38: =IFERROR(AVERAGE(R38:V38),0) -> 1504.2009 | AK38: =SUM(T38,V38,X38)*4 -> 29736 | AL38: =AK38/12 -> 2478
A39: Total General and Admin Expenses | B39: 2124 | C39: =B39/B$17 -> 0.0074003101 | D39: 6964 | E39: =D39/D$17 -> 0.010449255 | F39: 14713 | G39: =F39/F$17 -> 0.03754207 | H39: 2200 | I39: =H39/H$17 -> 0.0037359689 | J39: 3309 | K39: =J39/J$17 -> 0.0032076542 | L39: =SUM(L34:L38) -> 3606 | M39: =L39/L$17 -> 0.0078057693 | N39: =SUM(N34:N38) -> 4536 | O39: =N39/N$17 -> 0.0053397813 | P39: =SUM(P34:P38) -> 4436 | Q39: =P39/P$17 -> 0.0038471879 | R39: =SUM(R34:R38) -> 6666 | S39: =R39/R$17 -> 0.0074650349 | T39: 4178 | U39: =T39/T$17 -> 0.0058634646 | V39: 10741 | W39: =V39/V$17 -> 0.031763353 | X39: 2109 | Y39: =X39/X$17 -> 0.002749821 | Z39: =SUM(B39,D39,F39,H39,J39,L39,N39,P39,R39,T39,V39,X39) -> 65582 | AA39: =IFERROR(AVERAGE(B39,D39,F39,H39,J39,L39,N39,P39,R39,T39,V39,X39),0) -> 5465.1667 | AB39: =IFERROR(AVERAGE(T39,V39,X39),0) -> 5676 | AE39: =IFERROR(AVERAGE(R39:V39),0) -> 4317.0027 | AK39: =SUM(T39,V39,X39)*4 -> 68112 | AL39: =AK39/12 -> 5676
A41: Marketing and Advertising Expenses | B41: 0 | C41: =B41/B$17 -> 0 | D41: 881 | E41: =D41/D$17 -> 0.0013219118 | F41: 114 | G41: =F41/F$17 -> 0.00029088534 | H41: 0 | I41: =H41/H$17 -> 0 | J41: 552 | K41: =J41/J$17 -> 0.00053509371 | L41: 881 | M41: =L41/L$17 -> 0.0019070668 | N41: 0 | O41: =N41/N$17 -> 0 | P41: 0 | Q41: =P41/P$17 -> 0 | R41: 704 | S41: =R41/R$17 -> 0.00078838653 | T41: 0 | U41: =T41/T$17 -> 0 | V41: 1763 | W41: =V41/V$17 -> 0.0052135547 | X41: 0 | Y41: =X41/X$17 -> 0 | Z41: =SUM(B41,D41,F41,H41,J41,L41,N41,P41,R41,T41,V41,X41) -> 4895 | AA41: =IFERROR(AVERAGE(B41,D41,F41,H41,J41,L41,N41,P41,R41,T41,V41,X41),0) -> 407.91667 | AB41: =IFERROR(AVERAGE(T41,V41,X41),0) -> 587.66667 | AE41: =IFERROR(AVERAGE(R41:V41),0) -> 493.40016 | AK41: =SUM(T41,V41,X41)*4 -> 7052 | AL41: =AK41/12 -> 587.66667
A43: Payroll and Related Expenses | B43: 153559 | C43: =B43/B$17 -> 0.53502082 | D43: 162014 | E43: =D43/D$17 -> 0.24309672 | F43: 204141 | G43: =F43/F$17 -> 0.52089144 | H43: 175391 | I43: =H43/H$17 -> 0.29784333 | J43: 212999 | K43: =J43/J$17 -> 0.20647541 | L43: 196658 | M43: =L43/L$17 -> 0.425698 | N43: 204141 | O43: =N43/N$17 -> 0.24031488 | P43: 224572 | Q43: =P43/P$17 -> 0.19476345 | R43: 171146 | S43: =R43/R$17 -> 0.1916608 | T43: 186315 | U43: =T43/T$17 -> 0.26147712 | V43: 159037 | W43: =V43/V$17 -> 0.47030521 | X43: 228687 | Y43: =X43/X$17 -> 0.2981737 | Z43: =SUM(B43,D43,F43,H43,J43,L43,N43,P43,R43,T43,V43,X43) -> 2278660 | AA43: =IFERROR(AVERAGE(B43,D43,F43,H43,J43,L43,N43,P43,R43,T43,V43,X43),0) -> 189888.33 | AB43: =IFERROR(AVERAGE(T43,V43,X43),0) -> 191346.33 | AE43: =IFERROR(AVERAGE(R43:V43),0) -> 103299.69 | AK43: =SUM(T43,V43,X43)*4 -> 2296156 | AL43: =AK43/12 -> 191346.33
A45: Utilities and Facilities | B45: 11249 | C45: =B45/B$17 -> 0.039193074 | D45: 13838 | E45: =D45/D$17 -> 0.020763468 | F45: 11127 | G45: =F45/F$17 -> 0.02839194 | H45: 13009 | I45: =H45/H$17 -> 0.022091463 | J45: 11860 | K45: =J45/J$17 -> 0.01149676 | L45: 10344 | M45: =L45/L$17 -> 0.022391258 | N45: 5532 | O45: =N45/N$17 -> 0.0065122729 | P45: 11243 | Q45: =P45/P$17 -> 0.0097506613 | R45: 16607 | S45: =R45/R$17 -> 0.018597635 | T45: 8996 | U45: =T45/T$17 -> 0.012625114 | V45: 14349 | W45: =V45/V$17 -> 0.042432953 | X45: 9891 | Y45: =X45/X$17 -> 0.012896387 | Z45: =SUM(B45,D45,F45,H45,J45,L45,N45,P45,R45,T45,V45,X45) -> 138045 | AA45: =IFERROR(AVERAGE(B45,D45,F45,H45,J45,L45,N45,P45,R45,T45,V45,X45),0) -> 11503.75 | AB45: =IFERROR(AVERAGE(T45,V45,X45),0) -> 11078.667 | AE45: =IFERROR(AVERAGE(R45:V45),0) -> 7990.4062 | AK45: =SUM(T45,V45,X45)*4 -> 132944 | AL45: =AK45/12 -> 11078.667
A47: Ops and Maint. Expenses
A48: Automobile Expenses | C48: =B48/B$17 -> 0 | E48: =D48/D$17 -> 0 | G48: =F48/F$17 -> 0 | H48: 7044 | I48: =H48/H$17 -> 0.011961893 | J48: 9102 | K48: =J48/J$17 -> 0.00882323 | M48: =L48/L$17 -> 0 | O48: =N48/N$17 -> 0 | P48: 9019 | Q48: =P48/P$17 -> 0.0078218638 | R48: 7925 | S48: =R48/R$17 -> 0.0088749478 | T48: 7783 | U48: =T48/T$17 -> 0.010922773 | V48: 8157 | W48: =V48/V$17 -> 0.024121932 | X48: 10770 | Y48: =X48/X$17 -> 0.014042472 | Z48: =SUM(B48,D48,F48,H48,J48,L48,N48,P48,R48,T48,V48,X48) -> 59800 | AA48: =IFERROR(AVERAGE(B48,D48,F48,H48,J48,L48,N48,P48,R48,T48,V48,X48),0) -> 8542.8571 | AB48: =IFERROR(AVERAGE(T48,V48,X48),0) -> 8903.3333 | AE48: =IFERROR(AVERAGE(R48:V48),0) -> 4773.004 | AK48: =SUM(T48,V48,X48)*4 -> 106840 | AL48: =AK48/12 -> 8903.3333
...

Sheet California Calculated
B1: Month 1 ($) | C1: Month 1 (%) | D1: Month 2 ($) | E1: Month 2 (%) | F1: Month 3 ($) | G1: Month 3 (%) | H1: Month 4 ($) | I1: Month 4 (%) | J1: Month 5 ($) | K1: Month 5 (%) | L1: Month 6 ($) | M1: Month 6 (%) | N1: Month 7 ($) | O1: Month 7 (%) | P1: Month 8 ($) | Q1: Month 8 (%) | R1: Month 9 ($) | S1: Month 9 (%) | T1: Month 10 ($) | U1: Month 10 (%) | V1: Month 11 ($) | W1: Month 11 (%) | X1: Month 12 ($) | Y1: Month 12 (%) | Z1: 12 Month Totals | AA1: 12 Month Average | AB1: 3 Month Average | AD1: 9 Month Sparkline | AE1: Last 3 Months Average | AF1: Last 3 Months Sparkline | AG1: Target $ | AH1: Target % | AI1: Swag for Neutral | AJ1: Dashboard | AK1: Annual Budget Q1 * 4 | AL1: Monthly Budget | AM1: Notes:
A2: Location | B2: California | D2: California | F2: California | H2: California | J2: California | L2: California | N2: California | P2: California | Q2: All Locations | R2: California | T2: California | V2: California | X2: California | Y2: All Locations | Z2: All Locations | AA2: All Locations | AB2: All Locations
A3: Month | B3: =+'Combined Company'!B3 -> 01/31/2023 | D3: =+'Combined Company'!D3 -> 02/28/2023 | F3: =+'Combined Company'!F3 -> 03/31/2023 | H3: =+'Combined Company'!H3 -> 45046 | J3: =+'Combined Company'!J3 -> 45077 | L3: =+'Combined Company'!L3 -> 45107 | N3: =+'Combined Company'!N3 -> 45138 | P3: =+'Combined Company'!P3 -> 45169 | R3: =+'Combined Company'!R3 -> 45199 | T3: =+'Combined Company'!T3 -> 45230 | V3: =+'Combined Company'!V3 -> 45260 | X3: =+'Combined Company'!X3 -> 45291
A4: Days in Month | B4: =+'Combined Company'!B4 -> 31 | D4: =+'Combined Company'!D4 -> 28 | F4: =+'Combined Company'!F4 -> 31 | H4: =+'Combined Company'!H4 -> 30 | J4: =+'Combined Company'!J4 -> 31 | L4: =+'Combined Company'!L4 -> 30 | N4: =+'Combined Company'!N4 -> 31 | P4: =+'Combined Company'!P4 -> 31 | R4: =+'Combined Company'!R4 -> 30 | T4: =+'Combined Company'!T4 -> 31 | V4: =+'Combined Company'!V4 -> 30 | X4: =+'Combined Company'!X4 -> 31
A5: Quarter | B5: =+'Combined Company'!B5 -> 1 | D5: =+'Combined Company'!D5 -> 1 | F5: =+'Combined Company'!F5 -> 1 | H5: =+'Combined Company'!H5 -> 2 | J5: =+'Combined Company'!J5 -> 2 | L5: =+'Combined Company'!L5 -> 2 | N5: =+'Combined Company'!N5 -> 3 | P5: =+'Combined Company'!P5 -> 3 | R5: =+'Combined Company'!R5 -> 3 | T5: =+'Combined Company'!T5 -> 4 | V5: =+'Combined Company'!V5 -> 4 | X5: =+'Combined Company'!X5 -> 4
A6: Year | B6: =+'Combined Company'!B6 -> 2023 | D6: =+'Combined Company'!D6 -> 2023 | F6: =+'Combined Company'!F6 -> 2023 | H6: =+'Combined Company'!H6 -> 2023 | J6: =+'Combined Company'!J6 -> 2023 | L6: =+'Combined Company'!L6 -> 2023 | N6: =+'Combined Company'!N6 -> 2023 | P6: =+'Combined Company'!P6 -> 2023 | R6: =+'Combined Company'!R6 -> 2023 | T6: =+'Combined Company'!T6 -> 2023 | V6: =+'Combined Company'!V6 -> 2023 | X6: =+'Combined Company'!X6 -> 2023
A8: Revenue
A9: Managed IT Services (Recurring IT & Security) | B9: =+'Combined Company'!B9-Ohio!B9 -> 516340 | C9: =B9/B$17 -> 0.20938447 | D9: =+'Combined Company'!D9-Ohio!D9 -> 521203 | E9: =D9/D$17 -> 0.38205622 | F9: =+'Combined Company'!F9-Ohio!F9 -> 542420 | G9: =F9/F$17 -> 0.33064914 | H9: =+'Combined Company'!H9-Ohio!H9 -> 647104 | I9: =H9/H$17 -> 0.45740039 | J9: =+'Combined Company'!J9-Ohio!J9 -> 672447 | K9: =J9/J$17 -> 0.4850765 | L9: =+'Combined Company'!L9-Ohio!L9 -> 706392 | M9: =L9/L$17 -> 0.42055479 | N9: =+'Combined Company'!N9-Ohio!N9 -> 626764 | O9: =N9/N$17 -> 0.44227388 | P9: =+'Combined Company'!P9-Ohio!P9 -> 594806 | Q9: =P9/P$17 -> 0.30755572 | R9: =+'Combined Company'!R9-Ohio!R9 -> 529990 | S9: =R9/R$17 -> 0.30503671 | T9: =+'Combined Company'!T9-Ohio!T9 -> 476197 | U9: =T9/T$17 -> 0.40408963 | V9: =+'Combined Company'!V9-Ohio!V9 -> 521897 | W9: =V9/V$17 -> 0.22564479 | X9: =+'Combined Company'!X9-Ohio!X9 -> 349170 | Y9: =X9/X$17 -> 0.30988798 | Z9: =SUM(B9,D9,F9,H9,J9,L9,N9,P9,R9,T9,V9,X9) -> 6704730 | AA9: =IFERROR(AVERAGE(B9,D9,F9,H9,J9,L9,N9,P9,R9,T9,V9,X9),0) -> 558727.5 | AB9: =IFERROR(AVERAGE(T9,V9,X9),0) -> 449088 | AE9: =IFERROR(AVERAGE(R9,T9,V9),0) -> 509361.33 | AK9: =SUM(T9,V9,X9)*4 -> 5389056 | AL9: =AK9/12 -> 449088
A10: Cloud (Private Cloud Only as of 4/1/23) | B10: =+'Combined Company'!B10-Ohio!B10 -> 438849 | C10: =B10/B$17 -> 0.17796058 | D10: =+'Combined Company'!D10-Ohio!D10 -> 470071 | E10: =D10/D$17 -> 0.34457505 | F10: =+'Combined Company'!F10-Ohio!F10 -> 475934 | G10: =F10/F$17 -> 0.29012051 | H10: =+'Combined Company'!H10-Ohio!H10 -> 70303 | I10: =H10/H$17 -> 0.049693124 | J10: =+'Combined Company'!J10-Ohio!J10 -> 70283 | K10: =J10/J$17 -> 0.050699359 | L10: =+'Combined Company'!L10-Ohio!L10 -> 68500 | M10: =L10/L$17 -> 0.040781893 | N10: =+'Combined Company'!N10-Ohio!N10 -> 63151 | O10: =N10/N$17 -> 0.044562287 | P10: =+'Combined Company'!P10-Ohio!P10 -> 58680 | Q10: =P10/P$17 -> 0.030341607 | R10: =+'Combined Company'!R10-Ohio!R10 -> 49426 | S10: =R10/R$17 -> 0.028447224 | T10: =+'Combined Company'!T10-Ohio!T10 -> 33323 | U10: =T10/T$17 -> 0.028277118 | V10: =+'Combined Company'!V10-Ohio!V10 -> 34007 | W10: =V10/V$17 -> 0.014703097 | X10: =+'Combined Company'!X10-Ohio!X10 -> 19383 | Y10: =X10/X$17 -> 0.017202391 | Z10: =SUM(B10,D10,F10,H10,J10,L10,N10,P10,R10,T10,V10,X10) -> 1851910 | AA10: =IFERROR(AVERAGE(B10,D10,F10,H10,J10,L10,N10,P10,R10,T10,V10,X10),0) -> 154325.83 | AB10: =IFERROR(AVERAGE(T10,V10,X10),0) -> 28904.333 | AE10: =IFERROR(AVERAGE(R10,T10,V10),0) -> 38918.667 | AK10: =SUM(T10,V10,X10)*4 -> 346852 | AL10: =AK10/12 -> 28904.333
A11: Recurring Resale (Includes previouse Cloud sales) | B11: =+'Combined Company'!B11-Ohio!B11 -> 0 | C11: =B11/B$17 -> 0 | D11: =+'Combined Company'!D11-Ohio!D11 -> 0 | E11: =D11/D$17 -> 0 | F11: =+'Combined Company'!F11-Ohio!F11 -> 0 | G11: =F11/F$17 -> 0 | H11: =+'Combined Company'!H11-Ohio!H11 -> 238415 | I11: =H11/H$17 -> 0.16852177 | J11: =+'Combined Company'!J11-Ohio!J11 -> 286340 | K11: =J11/J$17 -> 0.20655428 | L11: =+'Combined Company'!L11-Ohio!L11 -> 286731 | M11: =L11/L$17 -> 0.17070705 | N11: =+'Combined Company'!N11-Ohio!N11 -> 283266 | O11: =N11/N$17 -> 0.19988569 | P11: =+'Combined Company'!P11-Ohio!P11 -> 279894 | Q11: =P11/P$17 -> 0.1447245 | R11: =+'Combined Company'!R11-Ohio!R11 -> 257232 | S11: =R11/R$17 -> 0.14805035 | T11: =+'Combined Company'!T11-Ohio!T11 -> 249957 | U11: =T11/T$17 -> 0.21210766 | V11: =+'Combined Company'!V11-Ohio!V11 -> 225316 | W11: =V11/V$17 -> 0.097416506 | X11: =+'Combined Company'!X11-Ohio!X11 -> 195594 | Y11: =X11/X$17 -> 0.17358945 | Z11: =SUM(B11,D11,F11,H11,J11,L11,N11,P11,R11,T11,V11,X11) -> 2302745 | AA11: =IFERROR(AVERAGE(B11,D11,F11,H11,J11,L11,N11,P11,R11,T11,V11,X11),0) -> 191895.42 | AB11: =IFERROR(AVERAGE(T11,V11,X11),0) -> 223622.33 | AE11: =IFERROR(AVERAGE(R11,T11,V11),0) -> 244168.33 | AK11: =SUM(T11,V11,X11)*4 -> 2683468 | AL11: =AK11/12 -> 223622.33 | AM11: *Just started tracking in April - Use April * 4
A12: Project Services | B12: =+'Combined Company'!B12-Ohio!B12 -> 38804 | C12: =B12/B$17 -> 0.015735668 | D12: =+'Combined Company'!D12-Ohio!D12 -> 26321 | E12: =D12/D$17 -> 0.019294021 | F12: =+'Combined Company'!F12-Ohio!F12 -> 34182 | G12: =F12/F$17 -> 0.020836711 | H12: =+'Combined Company'!H12-Ohio!H12 -> 75466 | I12: =H12/H$17 -> 0.053342551 | J12: =+'Combined Company'!J12-Ohio!J12 -> 76753 | K12: =J12/J$17 -> 0.055366559 | L12: =+'Combined Company'!L12-Ohio!L12 -> 16700 | M12: =L12/L$17 -> 0.0099424469 | N12: =+'Combined Company'!N12-Ohio!N12 -> 87590 | O12: =N12/N$17 -> 0.061807584 | P12: =+'Combined Company'!P12-Ohio!P12 -> 67523 | Q12: =P12/P$17 -> 0.034914048 | R12: =+'Combined Company'!R12-Ohio!R12 -> 49407 | S12: =R12/R$17 -> 0.028436289 | T12: =+'Combined Company'!T12-Ohio!T12 -> 12180 | U12: =T12/T$17 -> 0.010335663 | V12: =+'Combined Company'!V12-Ohio!V12 -> 27982 | W12: =V12/V$17 -> 0.012098158 | X12: =+'Combined Company'!X12-Ohio!X12 -> 25988 | Y12: =X12/X$17 -> 0.023064321 | Z12: =SUM(B12,D12,F12,H12,J12,L12,N12,P12,R12,T12,V12,X12) -> 538896 | AA12: =IFERROR(AVERAGE(B12,D12,F12,H12,J12,L12,N12,P12,R12,T12,V12,X12),0) -> 44908 | AB12: =IFERROR(AVERAGE(T12,V12,X12),0) -> 22050 | AE12: =IFERROR(AVERAGE(R12,T12,V12),0) -> 29856.333 | AK12: =SUM(T12,V12,X12)*4 -> 264600 | AL12: =AK12/12 -> 22050
A13: Subcontracted Services | B13: =+'Combined Company'!B13-Ohio!B13 -> 63823 | C13: =B13/B$17 -> 0.025881289 | D13: =+'Combined Company'!D13-Ohio!D13 -> 76877 | E13: =D13/D$17 -> 0.056352967 | F13: =+'Combined Company'!F13-Ohio!F13 -> 40660 | G13: =F13/F$17 -> 0.02478558 | H13: =+'Combined Company'!H13-Ohio!H13 -> 29046 | I13: =H13/H$17 -> 0.020530937 | J13: =+'Combined Company'!J13-Ohio!J13 -> 36525 | K13: =J13/J$17 -> 0.026347681 | L13: =+'Combined Company'!L13-Ohio!L13 -> 26588 | M13: =L13/L$17 -> 0.015829328 | N13: =+'Combined Company'!N13-Ohio!N13 -> 162366 | O13: =N13/N$17 -> 0.11457301 | P13: =+'Combined Company'!P13-Ohio!P13 -> 60247 | Q13: =P13/P$17 -> 0.031151854 | R13: =+'Combined Company'!R13-Ohio!R13 -> 22361 | S13: =R13/R$17 -> 0.012869914 | T13: =+'Combined Company'!T13-Ohio!T13 -> 29054 | U13: =T13/T$17 -> 0.024654544 | V13: =+'Combined Company'!V13-Ohio!V13 -> 17170 | W13: =V13/V$17 -> 0.0074235359 | X13: =+'Combined Company'!X13-Ohio!X13 -> 0 | Y13: =X13/X$17 -> 0 | Z13: =SUM(B13,D13,F13,H13,J13,L13,N13,P13,R13,T13,V13,X13) -> 564717 | AA13: =IFERROR(AVERAGE(B13,D13,F13,H13,J13,L13,N13,P13,R13,T13,V13,X13),0) -> 47059.75 | AB13: =IFERROR(AVERAGE(T13,V13,X13),0) -> 15408 | AE13: =IFERROR(AVERAGE(R13,T13,V13),0) -> 22861.667 | AK13: =SUM(T13,V13,X13)*4 -> 184896 | AL13: =AK13/12 -> 15408
A14: Product Sales | B14: =+'Combined Company'!B14-Ohio!B14 -> 1384028 | C14: =B14/B$17 -> 0.5612464 | D14: =+'Combined Company'!D14-Ohio!D14 -> 239027 | E14: =D14/D$17 -> 0.1752134 | F14: =+'Combined Company'!F14-Ohio!F14 -> 518838 | G14: =F14/F$17 -> 0.31627399 | H14: =+'Combined Company'!H14-Ohio!H14 -> 340677 | I14: =H14/H$17 -> 0.24080487 | J14: =+'Combined Company'!J14-Ohio!J14 -> 233041 | K14: =J14/J$17 -> 0.1681065 | L14: =+'Combined Company'!L14-Ohio!L14 -> 557722 | M14: =L14/L$17 -> 0.3320432 | N14: =+'Combined Company'!N14-Ohio!N14 -> 182086 | O14: =N14/N$17 -> 0.12848836 | P14: =+'Combined Company'!P14-Ohio!P14 -> 861975 | Q14: =P14/P$17 -> 0.44570052 | R14: =+'Combined Company'!R14-Ohio!R14 -> 814518 | S14: =R14/R$17 -> 0.46879732 | T14: =+'Combined Company'!T14-Ohio!T14 -> 374164 | U14: =T14/T$17 -> 0.31750681 | V14: =+'Combined Company'!V14-Ohio!V14 -> 1472258 | W14: =V14/V$17 -> 0.63653815 | X14: =+'Combined Company'!X14-Ohio!X14 -> 532176 | Y14: =X14/X$17 -> 0.4723056 | Z14: =SUM(B14,D14,F14,H14,J14,L14,N14,P14,R14,T14,V14,X14) -> 7510510 | AA14: =IFERROR(AVERAGE(B14,D14,F14,H14,J14,L14,N14,P14,R14,T14,V14,X14),0) -> 625875.83 | AB14: =IFERROR(AVERAGE(T14,V14,X14),0) -> 792866 | AE14: =IFERROR(AVERAGE(R14,T14,V14),0) -> 886980 | AK14: =SUM(T14,V14,X14)*4 -> 9514392 | AL14: =AK14/12 -> 792866
A15: Commissions | B15: =+'Combined Company'!B15-Ohio!B15 -> 24146 | C15: =B15/B$17 -> 0.009791605 | D15: =+'Combined Company'!D15-Ohio!D15 -> 30706 | E15: =D15/D$17 -> 0.022508347 | F15: =+'Combined Company'!F15-Ohio!F15 -> 28436 | G15: =F15/F$17 -> 0.017334057 | H15: =+'Combined Company'!H15-Ohio!H15 -> 13732 | I15: =H15/H$17 -> 0.0097063566 | J15: =+'Combined Company'!J15-Ohio!J15 -> 10881 | K15: =J15/J$17 -> 0.0078491203 | L15: =+'Combined Company'!L15-Ohio!L15 -> 17034 | M15: =L15/L$17 -> 0.010141296 | N15: =+'Combined Company'!N15-Ohio!N15 -> 11917 | O15: =N15/N$17 -> 0.0084091903 | P15: =+'Combined Company'!P15-Ohio!P15 -> 10853 | Q15: =P15/P$17 -> 0.0056117495 | R15: =+'Combined Company'!R15-Ohio!R15 -> 14529 | S15: =R15/R$17 -> 0.0083621925 | T15: =+'Combined Company'!T15-Ohio!T15 -> 3569 | U15: =T15/T$17 -> 0.0030285699 | V15: =+'Combined Company'!V15-Ohio!V15 -> 14284 | W15: =V15/V$17 -> 0.0061757592 | X15: =+'Combined Company'!X15-Ohio!X15 -> 4451 | Y15: =X15/X$17 -> 0.0039502575 | Z15: =SUM(B15,D15,F15,H15,J15,L15,N15,P15,R15,T15,V15,X15) -> 184538 | AA15: =IFERROR(AVERAGE(B15,D15,F15,H15,J15,L15,N15,P15,R15,T15,V15,X15),0) -> 15378.167 | AB15: =IFERROR(AVERAGE(T15,V15,X15),0) -> 7434.6667 | AE15: =IFERROR(AVERAGE(R15,T15,V15),0) -> 10794 | AK15: =SUM(T15,V15,X15)*4 -> 89216 | AL15: =AK15/12 -> 7434.6667
A16: Sales Returns and Discounts | B16: =+'Combined Company'!B16-Ohio!B16 -> 0 | C16: =B16/B$17 -> 0 | D16: =+'Combined Company'!D16-Ohio!D16 -> 0 | E16: =D16/D$17 -> 0 | F16: =+'Combined Company'!F16-Ohio!F16 -> 0 | G16: =F16/F$17 -> 0 | H16: =+'Combined Company'!H16-Ohio!H16 -> 0 | I16: =H16/H$17 -> 0 | J16: =+'Combined Company'!J16-Ohio!J16 -> 0 | K16: =J16/J$17 -> 0 | L16: =+'Combined Company'!L16-Ohio!L16 -> 0 | M16: =L16/L$17 -> 0 | N16: =+'Combined Company'!N16-Ohio!N16 -> 0 | O16: =N16/N$17 -> 0 | P16: =+'Combined Company'!P16-Ohio!P16 -> 0 | Q16: =P16/P$17 -> 0 | R16: =+'Combined Company'!R16-Ohio!R16 -> 0 | S16: =R16/R$17 -> 0 | T16: =+'Combined Company'!T16-Ohio!T16 -> 0 | U16: =T16/T$17 -> 0 | V16: =+'Combined Company'!V16-Ohio!V16 -> 0 | W16: =V16/V$17 -> 0 | X16: =+'Combined Company'!X16-Ohio!X16 -> 0 | Y16: =X16/X$17 -> 0 | Z16: =SUM(B16,D16,F16,H16,J16,L16,N16,P16,R16,T16,V16,X16) -> 0 | AA16: =IFERROR(AVERAGE(B16,D16,F16,H16,J16,L16,N16,P16,R16,T16,V16,X16),0) -> 0 | AB16: =IFERROR(AVERAGE(T16,V16,X16),0) -> 0 | AE16: =IFERROR(AVERAGE(R16,T16,V16),0) -> 0 | AK16: =SUM(T16,V16,X16)*4 -> 0 | AL16: =AK16/12 -> 0
