Workbook
Name NB_Monthly_Recurring_Private_Cloud_CA: #REF!
Name NB_Monthly_Recurring_Private_Cloud_OH: #REF!
Name NB_Monthly_Recurring_Resale_CA: #REF!
Name NB_Monthly_Recurring_Resale_OH: #REF!
Name NB_Monthly_Recurring_Services_CA: #REF!
Name NB_Monthly_Recurring_Services_OH: #REF!
Name WA_Monthly_Recurring_Private_Cloud_CA: #REF!
Name WA_Monthly_Recurring_Resale_CA: #REF!
Name WA_Monthly_Recurring_Resale_OH: #REF!
Name WA_Monthly_Recurring_Services_CA: #REF!
Name WA_Monthly_Recurring_Services_OH: #REF!

Sheet 2024 Bdg vs Actual All
I1: Budget Vs Actual | M1: Variance | N1: (Red) | O1: Over budget | Q1: Budget Vs Actual
I2: Income Statement - All | N2: Black | O2: Under budget | Q2: Income Statement - All
I3: 2024 | Q3: 2024
AB4: x
F7: Budget
F8: Year 1* | H8: January | L8: February | P8: March | T8: April | X8: May | AB8: June | AF8: July | AJ8: August | AN8: September | AR8: October | AV8: November | AZ8: December | BG8: YTD
A9: Year Ending | F9: 45657 | H9: Budget | I9: Actual | J9: Var | L9: Budget | M9: Actual | N9: Variance | O9: Notes | P9: Budget | Q9: Actual | R9: Variance | S9: Notes | T9: Budget | U9: Actual | V9: Variance | W9: Notes | X9: Budget | Y9: Actual | Z9: Variance | AA9: Notes | AB9: Budget | AC9: Actual | AD9: Variance | AE9: Notes | AF9: Budget | AG9: Actual | AH9: Variance | AI9: Notes | AJ9: Budget | AK9: Actual | AL9: Variance | AM9: Notes | AN9: Budget | AO9: Actual | AP9: Variance | AQ9: Notes | AR9: Budget | AS9: Actual | AT9: Variance | AU9: Notes | AV9: Budget | AW9: Actual | AX9: Variance | AY9: Notes | AZ9: Budget | BA9: Actual | BB9: Variance | BC9: Notes | BE9: Questions | BG9: Budget | BH9: Actual | BI9: Variance
N10: (Red) over budget
A11: **Gross Sales** | F11: =H11+L11+P11+T11+X11+AB11+AF11+AJ11+AN11+AR11+AV11+AZ11 -> 27189475 | H11: =SUM(H14:H23) -> 2263097.8 | I11: =SUM(I14:I23) -> 1375722.6 | J11: =+I11-H11 -> -887375.27 | L11: =SUM(L14:L23) -> 2193476.8 | M11: =SUM(M14:M23) -> 1708668 | N11: =+M11-L11 -> -484808.83 | P11: =SUM(P14:P23) -> 2167400 | Q11: =SUM(Q14:Q23) -> 1256746 | R11: =+Q11-P11 -> -910654 | T11: =SUM(T14:T23) -> 2193700 | U11: =SUM(U14:U23) -> 1740436 | V11: =+U11-T11 -> -453264 | X11: =SUM(X14:X23) -> 2215400 | Y11: =SUM(Y14:Y23) -> 1510467 | Z11: =+Y11-X11 -> -704933 | AB11: =SUM(AB14:AB23) -> 2258900 | AC11: =SUM(AC14:AC23) -> 2578281 | AD11: =+AC11-AB11 -> 319381 | AF11: =SUM(AF14:AF23) -> 2278300 | AG11: =SUM(AG14:AG23) -> 2399002 | AH11: =+AG11-AF11 -> 120702 | AJ11: =SUM(AJ14:AJ23) -> 2289100 | AK11: =SUM(AK14:AK23) -> 2786533 | AL11: =+AK11-AJ11 -> 497433 | AN11: =SUM(AN14:AN23) -> 2304800 | AO11: =SUM(AO14:AO23) -> 1407338 | AP11: =+AO11-AN11 -> -897462 | AR11: =SUM(AR14:AR23) -> 2324400 | AS11: =SUM(AS14:AS23) -> 1520174 | AT11: =+AS11-AR11 -> -804226 | AV11: =SUM(AV14:AV23) -> 2340800 | AW11: =SUM(AW14:AW23) -> 1802062 | AX11: =+AW11-AV11 -> -538738 | AZ11: =SUM(AZ14:AZ23) -> 2360100 | BA11: =SUM(BA14:BA23) -> 1196916 | BB11: =+BA11-AZ11 -> -1163184 | BG11: =+P11+L11+H11+T11+X11+AB11+AF11+AJ11+AN11+AR11+AV11+AZ11 -> 27189475 | BH11: =+Q11+M11+I11+U11+Y11+AC11+AG11+AK11+AO11+AS11+AW11+BA11 -> 21282346 | BI11: =+BH11-BG11 -> -5907129.1
A13: Services
A14: Monthly Recurring Services | F14: =H14+L14+P14+T14+X14+AB14+AF14+AJ14+AN14+AR14+AV14+AZ14 -> 7002838 | H14: =+'2024 Bdg vs Actual-CA'!O14+'2024 Bdg vs Actual -OH'!O14 -> 607265.97 | I14: 519442 | J14: =+I14-H14 -> -87823.971 | K14: How is recurring services so much less? It should be a repeat of December and IR was modeled out? | L14: =+'2024 Bdg vs Actual-CA'!S14+'2024 Bdg vs Actual -OH'!S14 -> 519372 | M14: 533709 | N14: =+M14-L14 -> 14337 | O14: Budget for February is updated based on actual MRR from last meeting D | P14: =ROUND(+'2024 Bdg vs Actual-CA'!W14+'2024 Bdg vs Actual -OH'!W14,-2) -> 516400 | Q14: 522308 | R14: =+Q14-P14 -> 5908 | S14: Budget for March is updated based on actual MRR from last meeting D | T14: =ROUND(+'2024 Bdg vs Actual-CA'!AA14+'2024 Bdg vs Actual -OH'!AA14,-2) -> 534200 | U14: 514855 | V14: =+U14-T14 -> -19345 | X14: =ROUND(+'2024 Bdg vs Actual-CA'!AE14+'2024 Bdg vs Actual -OH'!AE14,-2) -> 546000 | Y14: 444256 | Z14: =+Y14-X14 -> -101744 | AA14: See location for notes | AB14: =ROUND(+'2024 Bdg vs Actual-CA'!AI14+'2024 Bdg vs Actual -OH'!AI14,-2) -> 575100 | AC14: 513444 | AD14: =+AC14-AB14 -> -61656 | AE14: See location for notes | AF14: =ROUND(+'2024 Bdg vs Actual-CA'!AM14+'2024 Bdg vs Actual -OH'!AM14,-2) -> 590000 | AG14: 505165 | AH14: =+AG14-AF14 -> -84835 | AI14: See location for notes | AJ14: =ROUND(+'2024 Bdg vs Actual-CA'!AQ14+'2024 Bdg vs Actual -OH'!AQ14,-2) -> 596300 | AK14: 534210 | AL14: =+AK14-AJ14 -> -62090 | AM14: See location for notes | AN14: =ROUND(+'2024 Bdg vs Actual-CA'!AU14+'2024 Bdg vs Actual -OH'!AU14,-2) -> 608000 | AO14: 521714 | AP14: =+AO14-AN14 -> -86286 | AQ14: See location for notes | AR14: =ROUND(+'2024 Bdg vs Actual-CA'!AY14+'2024 Bdg vs Actual -OH'!AY14,-2) -> 623400 | AS14: 507617 | AT14: =+AS14-AR14 -> -115783 | AU14: See location for notes | AV14: =ROUND(+'2024 Bdg vs Actual-CA'!BC14+'2024 Bdg vs Actual -OH'!BC14,-2) -> 636300 | AW14: 551943 | AX14: =+AW14-AV14 -> -84357 | AZ14: =ROUND(+'2024 Bdg vs Actual-CA'!BG14+'2024 Bdg vs Actual -OH'!BG14,-2) -> 650500 | BA14: 577780 | BB14: =+BA14-AZ14 -> -72720 | BC14: See location for notes | BG14: =+P14+L14+H14+T14+X14+AB14+AF14+AJ14+AN14+AR14+AV14+AZ14 -> 7002838 | BH14: =+Q14+M14+I14+U14+Y14+AC14+AG14+AK14+AO14+AS14+AW14+BA14 -> 6246443 | BI14: =+BH14-BG14 -> -756394.97
A15: Monthly Recurring Private Cloud | F15: =H15+L15+P15+T15+X15+AB15+AF15+AJ15+AN15+AR15+AV15+AZ15 -> 255753.84 | H15: =+'2024 Bdg vs Actual-CA'!O15+'2024 Bdg vs Actual -OH'!O15 -> 26611.835 | I15: 21937 | J15: =+I15-H15 -> -4674.835 | L15: =+'2024 Bdg vs Actual-CA'!S15+'2024 Bdg vs Actual -OH'!S15 -> 18042 | M15: 24564 | N15: =+M15-L15 -> 6522 | P15: =ROUND(+'2024 Bdg vs Actual-CA'!W15+'2024 Bdg vs Actual -OH'!W15,-2) -> 18000 | Q15: 18807 | R15: =+Q15-P15 -> 807 | T15: =ROUND(+'2024 Bdg vs Actual-CA'!AA15+'2024 Bdg vs Actual -OH'!AA15,-2) -> 18500 | U15: 20511 | V15: =+U15-T15 -> 2011 | X15: =ROUND(+'2024 Bdg vs Actual-CA'!AE15+'2024 Bdg vs Actual -OH'!AE15,-2) -> 18000 | Y15: 20275 | Z15: =+Y15-X15 -> 2275 | AB15: =ROUND(+'2024 Bdg vs Actual-CA'!AI15+'2024 Bdg vs Actual -OH'!AI15,-2) -> 20900 | AC15: 18128 | AD15: =+AC15-AB15 -> -2772 | AF15: =ROUND(+'2024 Bdg vs Actual-CA'!AM15+'2024 Bdg vs Actual -OH'!AM15,-2) -> 21400 | AG15: 18272 | AH15: =+AG15-AF15 -> -3128 | AJ15: =ROUND(+'2024 Bdg vs Actual-CA'!AQ15+'2024 Bdg vs Actual -OH'!AQ15,-2) -> 21800 | AK15: 18250 | AL15: =+AK15-AJ15 -> -3550 | AN15: =ROUND(+'2024 Bdg vs Actual-CA'!AU15+'2024 Bdg vs Actual -OH'!AU15,-2) -> 22300 | AO15: 22059 | AP15: =+AO15-AN15 -> -241 | AR15: =ROUND(+'2024 Bdg vs Actual-CA'!AY15+'2024 Bdg vs Actual -OH'!AY15,-2) -> 22700 | AS15: 26554 | AT15: =+AS15-AR15 -> 3854 | AV15: =ROUND(+'2024 Bdg vs Actual-CA'!BC15+'2024 Bdg vs Actual -OH'!BC15,-2) -> 23200 | AW15: 17924 | AX15: =+AW15-AV15 -> -5276 | AZ15: =ROUND(+'2024 Bdg vs Actual-CA'!BG15+'2024 Bdg vs Actual -OH'!BG15,-2) -> 24300 | BA15: 21850 | BB15: =+BA15-AZ15 -> -2450 | BG15: =+P15+L15+H15+T15+X15+AB15+AF15+AJ15+AN15+AR15+AV15+AZ15 -> 255753.84 | BH15: =+Q15+M15+I15+U15+Y15+AC15+AG15+AK15+AO15+AS15+AW15+BA15 -> 249131 | BI15: =+BH15-BG15 -> -6622.835
A16: Monthly Recurring Resale | F16: =H16+L16+P16+T16+X16+AB16+AF16+AJ16+AN16+AR16+AV16+AZ16 -> 2768443.7 | H16: =+'2024 Bdg vs Actual-CA'!O16+'2024 Bdg vs Actual -OH'!O16 -> 199886.7 | I16: 226368 | J16: =+I16-H16 -> 26481.298 | L16: =+'2024 Bdg vs Actual-CA'!S16+'2024 Bdg vs Actual -OH'!S16 -> 216957 | M16: 220002 | N16: =+M16-L16 -> 3045 | P16: =ROUND(+'2024 Bdg vs Actual-CA'!W16+'2024 Bdg vs Actual -OH'!W16,-2) -> 203600 | Q16: 206276 | R16: =+Q16-P16 -> 2676 | T16: =ROUND(+'2024 Bdg vs Actual-CA'!AA16+'2024 Bdg vs Actual -OH'!AA16,-2) -> 211600 | U16: 218674 | V16: =+U16-T16 -> 7074 | X16: =ROUND(+'2024 Bdg vs Actual-CA'!AE16+'2024 Bdg vs Actual -OH'!AE16,-2) -> 222000 | Y16: 216193 | Z16: =+Y16-X16 -> -5807 | AB16: =ROUND(+'2024 Bdg vs Actual-CA'!AI16+'2024 Bdg vs Actual -OH'!AI16,-2) -> 233500 | AC16: 221605 | AD16: =+AC16-AB16 -> -11895 | AF16: =ROUND(+'2024 Bdg vs Actual-CA'!AM16+'2024 Bdg vs Actual -OH'!AM16,-2) -> 237500 | AG16: 221399 | AH16: =+AG16-AF16 -> -16101 | AJ16: =ROUND(+'2024 Bdg vs Actual-CA'!AQ16+'2024 Bdg vs Actual -OH'!AQ16,-2) -> 241600 | AK16: 219968 | AL16: =+AK16-AJ16 -> -21632 | AN16: =ROUND(+'2024 Bdg vs Actual-CA'!AU16+'2024 Bdg vs Actual -OH'!AU16,-2) -> 245100 | AO16: 225338 | AP16: =+AO16-AN16 -> -19762 | AR16: =ROUND(+'2024 Bdg vs Actual-CA'!AY16+'2024 Bdg vs Actual -OH'!AY16,-2) -> 248900 | AS16: 234350 | AT16: =+AS16-AR16 -> -14550 | AV16: =ROUND(+'2024 Bdg vs Actual-CA'!BC16+'2024 Bdg vs Actual -OH'!BC16,-2) -> 251900 | AW16: 238967 | AX16: =+AW16-AV16 -> -12933 | AZ16: =ROUND(+'2024 Bdg vs Actual-CA'!BG16+'2024 Bdg vs Actual -OH'!BG16,-2) -> 255900 | BA16: 241544 | BB16: =+BA16-AZ16 -> -14356 | BG16: =+P16+L16+H16+T16+X16+AB16+AF16+AJ16+AN16+AR16+AV16+AZ16 -> 2768443.7 | BH16: =+Q16+M16+I16+U16+Y16+AC16+AG16+AK16+AO16+AS16+AW16+BA16 -> 2690684 | BI16: =+BH16-BG16 -> -77759.702
A17: IT Project Services | F17: =H17+L17+P17+T17+X17+AB17+AF17+AJ17+AN17+AR17+AV17+AZ17 -> 1447392.5 | H17: =+'2024 Bdg vs Actual-CA'!O17+'2024 Bdg vs Actual -OH'!O17 -> 120784.5 | I17: 47765.57 | J17: =+I17-H17 -> -73018.93 | L17: =+'2024 Bdg vs Actual-CA'!S17+'2024 Bdg vs Actual -OH'!S17 -> 118608 | M17: 91984 | N17: =+M17-L17 -> -26624 | O17: No changes to project forecast | P17: =ROUND(+'2024 Bdg vs Actual-CA'!W17+'2024 Bdg vs Actual -OH'!W17,-2) -> 120800 | Q17: 85429 | R17: =+Q17-P17 -> -35371 | S17: No changes to project forecast | T17: =ROUND(+'2024 Bdg vs Actual-CA'!AA17+'2024 Bdg vs Actual -OH'!AA17,-2) -> 120800 | U17: 185976 | V17: =+U17-T17 -> 65176 | X17: =ROUND(+'2024 Bdg vs Actual-CA'!AE17+'2024 Bdg vs Actual -OH'!AE17,-2) -> 120800 | Y17: 173843 | Z17: =+Y17-X17 -> 53043 | AB17: =ROUND(+'2024 Bdg vs Actual-CA'!AI17+'2024 Bdg vs Actual -OH'!AI17,-2) -> 120800 | AC17: 148908 | AD17: =+AC17-AB17 -> 28108 | AF17: =ROUND(+'2024 Bdg vs Actual-CA'!AM17+'2024 Bdg vs Actual -OH'!AM17,-2) -> 120800 | AG17: 190189 | AH17: =+AG17-AF17 -> 69389 | AJ17: =ROUND(+'2024 Bdg vs Actual-CA'!AQ17+'2024 Bdg vs Actual -OH'!AQ17,-2) -> 120800 | AK17: 344196 | AL17: =+AK17-AJ17 -> 223396 | AN17: =ROUND(+'2024 Bdg vs Actual-CA'!AU17+'2024 Bdg vs Actual -OH'!AU17,-2) -> 120800 | AO17: 100536 | AP17: =+AO17-AN17 -> -20264 | AR17: =ROUND(+'2024 Bdg vs Actual-CA'!AY17+'2024 Bdg vs Actual -OH'!AY17,-2) -> 120800 | AS17: 90248 | AT17: =+AS17-AR17 -> -30552 | AV17: =ROUND(+'2024 Bdg vs Actual-CA'!BC17+'2024 Bdg vs Actual -OH'!BC17,-2) -> 120800 | AW17: 46132 | AX17: =+AW17-AV17 -> -74668 | AZ17: =ROUND(+'2024 Bdg vs Actual-CA'!BG17+'2024 Bdg vs Actual -OH'!BG17,-2) -> 120800 | BA17: 39163 | BB17: =+BA17-AZ17 -> -81637 | BG17: =+P17+L17+H17+T17+X17+AB17+AF17+AJ17+AN17+AR17+AV17+AZ17 -> 1447392.5 | BH17: =+Q17+M17+I17+U17+Y17+AC17+AG17+AK17+AO17+AS17+AW17+BA17 -> 1544369.6 | BI17: =+BH17-BG17 -> 96977.07
A18: Subcontracted Services | F18: =H18+L18+P18+T18+X18+AB18+AF18+AJ18+AN18+AR18+AV18+AZ18 -> 696225 | H18: =+'2024 Bdg vs Actual-CA'!O18+'2024 Bdg vs Actual -OH'!O18 -> 56763 | I18: 5809 | J18: =+I18-H18 -> -50954 | L18: =+'2024 Bdg vs Actual-CA'!S18+'2024 Bdg vs Actual -OH'!S18 -> 71462 | M18: 74654 | N18: =+M18-L18 -> 3192 | P18: =ROUND(+'2024 Bdg vs Actual-CA'!W18+'2024 Bdg vs Actual -OH'!W18,-2) -> 56800 | Q18: 16220 | R18: =+Q18-P18 -> -40580 | T18: =ROUND(+'2024 Bdg vs Actual-CA'!AA18+'2024 Bdg vs Actual -OH'!AA18,-2) -> 56800 | U18: 10805 | V18: =+U18-T18 -> -45995 | X18: =ROUND(+'2024 Bdg vs Actual-CA'!AE18+'2024 Bdg vs Actual -OH'!AE18,-2) -> 56800 | Y18: 14230 | Z18: =+Y18-X18 -> -42570 | AB18: =ROUND(+'2024 Bdg vs Actual-CA'!AI18+'2024 Bdg vs Actual -OH'!AI18,-2) -> 56800 | AC18: 19715 | AD18: =+AC18-AB18 -> -37085 | AF18: =ROUND(+'2024 Bdg vs Actual-CA'!AM18+'2024 Bdg vs Actual -OH'!AM18,-2) -> 56800 | AG18: 295714 | AH18: =+AG18-AF18 -> 238914 | AJ18: =ROUND(+'2024 Bdg vs Actual-CA'!AQ18+'2024 Bdg vs Actual -OH'!AQ18,-2) -> 56800 | AK18: 132645 | AL18: =+AK18-AJ18 -> 75845 | AN18: =ROUND(+'2024 Bdg vs Actual-CA'!AU18+'2024 Bdg vs Actual -OH'!AU18,-2) -> 56800 | AO18: 24969 | AP18: =+AO18-AN18 -> -31831 | AR18: =ROUND(+'2024 Bdg vs Actual-CA'!AY18+'2024 Bdg vs Actual -OH'!AY18,-2) -> 56800 | AS18: 32496 | AT18: =+AS18-AR18 -> -24304 | AV18: =ROUND(+'2024 Bdg vs Actual-CA'!BC18+'2024 Bdg vs Actual -OH'!BC18,-2) -> 56800 | AW18: 12751 | AX18: =+AW18-AV18 -> -44049 | AZ18: =ROUND(+'2024 Bdg vs Actual-CA'!BG18+'2024 Bdg vs Actual -OH'!BG18,-2) -> 56800 | BA18: 25687 | BB18: =+BA18-AZ18 -> -31113 | BG18: =+P18+L18+H18+T18+X18+AB18+AF18+AJ18+AN18+AR18+AV18+AZ18 -> 696225 | BH18: =+Q18+M18+I18+U18+Y18+AC18+AG18+AK18+AO18+AS18+AW18+BA18 -> 665695 | BI18: =+BH18-BG18 -> -30530
A21: Product Sales
A22: Product Resale | F22: =H22+L22+P22+T22+X22+AB22+AF22+AJ22+AN22+AR22+AV22+AZ22 -> 14789905 | H22: =+'2024 Bdg vs Actual-CA'!O22+'2024 Bdg vs Actual -OH'!O22 -> 1232452.5 | I22: 542234 | J22: =+I22-H22 -> -690218.5 | L22: =+'2024 Bdg vs Actual-CA'!S22+'2024 Bdg vs Actual -OH'!S22 -> 1232452.5 | M22: 756837 | N22: =+M22-L22 -> -475615.5 | O22: No changes yet to product forecast | P22: =ROUND(+'2024 Bdg vs Actual-CA'!W22+'2024 Bdg vs Actual -OH'!W22,-2) -> 1232500 | Q22: 392152 | R22: =+Q22-P22 -> -840348 | S22: No changes yet to product forecast | T22: =ROUND(+'2024 Bdg vs Actual-CA'!AA22+'2024 Bdg vs Actual -OH'!AA22,-2) -> 1232500 | U22: 784945 | V22: =+U22-T22 -> -447555 | X22: =ROUND(+'2024 Bdg vs Actual-CA'!AE22+'2024 Bdg vs Actual -OH'!AE22,-2) -> 1232500 | Y22: 629848 | Z22: =+Y22-X22 -> -602652 | AB22: =ROUND(+'2024 Bdg vs Actual-CA'!AI22+'2024 Bdg vs Actual -OH'!AI22,-2) -> 1232500 | AC22: 1645749 | AD22: =+AC22-AB22 -> 413249 | AF22: =ROUND(+'2024 Bdg vs Actual-CA'!AM22+'2024 Bdg vs Actual -OH'!AM22,-2) -> 1232500 | AG22: 1162232 | AH22: =+AG22-AF22 -> -70268 | AJ22: =ROUND(+'2024 Bdg vs Actual-CA'!AQ22+'2024 Bdg vs Actual -OH'!AQ22,-2) -> 1232500 | AK22: 1529705 | AL22: =+AK22-AJ22 -> 297205 | AN22: =ROUND(+'2024 Bdg vs Actual-CA'!AU22+'2024 Bdg vs Actual -OH'!AU22,-2) -> 1232500 | AO22: 494557 | AP22: =+AO22-AN22 -> -737943 | AR22: =ROUND(+'2024 Bdg vs Actual-CA'!AY22+'2024 Bdg vs Actual -OH'!AY22,-2) -> 1232500 | AS22: 621149 | AT22: =+AS22-AR22 -> -611351 | AV22: =ROUND(+'2024 Bdg vs Actual-CA'!BC22+'2024 Bdg vs Actual -OH'!BC22,-2) -> 1232500 | AW22: 927230 | AX22: =+AW22-AV22 -> -305270 | AZ22: =ROUND(+'2024 Bdg vs Actual-CA'!BG22+'2024 Bdg vs Actual -OH'!BG22,-2) -> 1232500 | BA22: 263714 | BB22: =+BA22-AZ22 -> -968786 | BG22: =+P22+L22+H22+T22+X22+AB22+AF22+AJ22+AN22+AR22+AV22+AZ22 -> 14789905 | BH22: =+Q22+M22+I22+U22+Y22+AC22+AG22+AK22+AO22+AS22+AW22+BA22 -> 9750352 | BI22: =+BH22-BG22 -> -5039553
A23: Other Revenue | F23: =H23+L23+P23+T23+X23+AB23+AF23+AJ23+AN23+AR23+AV23+AZ23 -> 228916.67 | H23: =+'2024 Bdg vs Actual-CA'!O23+'2024 Bdg vs Actual -OH'!O23 -> 19333.333 | I23: 12167 | J23: =+I23-H23 -> -7166.3333 | L23: =+'2024 Bdg vs Actual-CA'!S23+'2024 Bdg vs Actual -OH'!S23 -> 16583.333 | M23: 6918 | N23: =+M23-L23 -> -9665.3333 | P23: =ROUND(+'2024 Bdg vs Actual-CA'!W23+'2024 Bdg vs Actual -OH'!W23,-2) -> 19300 | Q23: 15554 | R23: =+Q23-P23 -> -3746 | T23: =ROUND(+'2024 Bdg vs Actual-CA'!AA23+'2024 Bdg vs Actual -OH'!AA23,-2) -> 19300 | U23: 4670 | V23: =+U23-T23 -> -14630 | X23: =ROUND(+'2024 Bdg vs Actual-CA'!AE23+'2024 Bdg vs Actual -OH'!AE23,-2) -> 19300 | Y23: =102670-90848 -> 11822 | Z23: =+Y23-X23 -> -7478 | AB23: =ROUND(+'2024 Bdg vs Actual-CA'!AI23+'2024 Bdg vs Actual -OH'!AI23,-2) -> 19300 | AC23: 10732 | AD23: =+AC23-AB23 -> -8568 | AF23: =ROUND(+'2024 Bdg vs Actual-CA'!AM23+'2024 Bdg vs Actual -OH'!AM23,-2) -> 19300 | AG23: 6031 | AH23: =+AG23-AF23 -> -13269 | AJ23: =ROUND(+'2024 Bdg vs Actual-CA'!AQ23+'2024 Bdg vs Actual -OH'!AQ23,-2) -> 19300 | AK23: 7559 | AL23: =+AK23-AJ23 -> -11741 | AN23: =ROUND(+'2024 Bdg vs Actual-CA'!AU23+'2024 Bdg vs Actual -OH'!AU23,-2) -> 19300 | AO23: 18165 | AP23: =+AO23-AN23 -> -1135 | AR23: =ROUND(+'2024 Bdg vs Actual-CA'!AY23+'2024 Bdg vs Actual -OH'!AY23,-2) -> 19300 | AS23: 7760 | AT23: =+AS23-AR23 -> -11540 | AV23: =ROUND(+'2024 Bdg vs Actual-CA'!BC23+'2024 Bdg vs Actual -OH'!BC23,-2) -> 19300 | AW23: 7115 | AX23: =+AW23-AV23 -> -12185 | AZ23: =ROUND(+'2024 Bdg vs Actual-CA'!BG23+'2024 Bdg vs Actual -OH'!BG23,-2) -> 19300 | BA23: 27178 | BB23: =+BA23-AZ23 -> 7878 | BG23: =+P23+L23+H23+T23+X23+AB23+AF23+AJ23+AN23+AR23+AV23+AZ23 -> 228916.67 | BH23: =+Q23+M23+I23+U23+Y23+AC23+AG23+AK23+AO23+AS23+AW23+BA23 -> 135671 | BI23: =+BH23-BG23 -> -93245.667
A25: Cost of Services- **
A26: Costs of Monthly Recurring Services | F26: =H26+L26+P26+T26+X26+AB26+AF26+AJ26+AN26+AR26+AV26+AZ26 -> 231439.78 | H26: =H14*0.033 -> 20039.777 | I26: 18726 | J26: =H26-I26 -> 1313.777 | L26: =+'2024 Bdg vs Actual-CA'!S26+'2024 Bdg vs Actual -OH'!S26 -> 17400 | M26: 21728 | N26: =L26-M26 -> -4328 | P26: =ROUND(+'2024 Bdg vs Actual-CA'!W26+'2024 Bdg vs Actual -OH'!W26,-2) -> 17200 | Q26: 23839 | R26: =P26-Q26 -> -6639 | T26: =ROUND('2024 Bdg vs Actual-CA'!AA26+'2024 Bdg vs Actual -OH'!AA26,-2) -> 17600 | U26: 31075 | V26: =T26-U26 -> -13475 | X26: =ROUND('2024 Bdg vs Actual-CA'!AE26+'2024 Bdg vs Actual -OH'!AE26,-2) -> 18000 | Y26: 21136 | Z26: =X26-Y26 -> -3136 | AB26: =ROUND('2024 Bdg vs Actual-CA'!AI26+'2024 Bdg vs Actual -OH'!AI26,-2) -> 19000 | AC26: 21363 | AD26: =AB26-AC26 -> -2363 | AF26: =ROUND('2024 Bdg vs Actual-CA'!AM26+'2024 Bdg vs Actual -OH'!AM26,-2) -> 19500 | AG26: 22325 | AH26: =AF26-AG26 -> -2825 | AJ26: =ROUND('2024 Bdg vs Actual-CA'!AQ26+'2024 Bdg vs Actual -OH'!AQ26,-2) -> 19700 | AK26: 16009 | AL26: =AJ26-AK26 -> 3691 | AN26: =ROUND('2024 Bdg vs Actual-CA'!AU26+'2024 Bdg vs Actual -OH'!AU26,-2) -> 20000 | AO26: 17427 | AP26: =AN26-AO26 -> 2573 | AR26: =ROUND('2024 Bdg vs Actual-CA'!AY26+'2024 Bdg vs Actual -OH'!AY26,-2) -> 20600 | AS26: 13618 | AT26: =AR26-AS26 -> 6982 | AV26: =ROUND('2024 Bdg vs Actual-CA'!BC26+'2024 Bdg vs Actual -OH'!BC26,-2) -> 21000 | AW26: 20756 | AX26: =AV26-AW26 -> 244 | AZ26: =ROUND('2024 Bdg vs Actual-CA'!BG26+'2024 Bdg vs Actual -OH'!BG26,-2) -> 21400 | BA26: 16438 | BB26: =AZ26-BA26 -> 4962 | BG26: =+P26+L26+H26+T26+X26+AB26+AF26+AJ26+AN26+AR26+AV26+AZ26 -> 231439.78 | BH26: =+Q26+M26+I26+U26+Y26+AC26+AG26+AK26+AO26+AS26+AW26+BA26 -> 244440 | BI26: =BG26-BH26 -> -13000.223
A27: Costs of Recur Private Cloud | F27: =H27+L27+P27+T27+X27+AB27+AF27+AJ27+AN27+AR27+AV27+AZ27 -> 185593.58 | H27: =H15*0.725 -> 19293.58 | I27: 13334 | J27: =H27-I27 -> 5959.5804 | L27: =+'2024 Bdg vs Actual-CA'!S27+'2024 Bdg vs Actual -OH'!S27 -> 13100 | M27: 12968 | N27: =L27-M27 -> 132 | P27: =ROUND(+'2024 Bdg vs Actual-CA'!W27+'2024 Bdg vs Actual -OH'!W27,-2) -> 13100 | Q27: 8745 | R27: =P27-Q27 -> 4355 | T27: =ROUND('2024 Bdg vs Actual-CA'!AA27+'2024 Bdg vs Actual -OH'!AA27,-2) -> 13400 | U27: 5436 | V27: =T27-U27 -> 7964 | X27: =ROUND('2024 Bdg vs Actual-CA'!AE27+'2024 Bdg vs Actual -OH'!AE27,-2) -> 13100 | Y27: 9138 | Z27: =X27-Y27 -> 3962 | AB27: =ROUND('2024 Bdg vs Actual-CA'!AI27+'2024 Bdg vs Actual -OH'!AI27,-2) -> 15200 | AC27: 7867 | AD27: =AB27-AC27 -> 7333 | AF27: =ROUND('2024 Bdg vs Actual-CA'!AM27+'2024 Bdg vs Actual -OH'!AM27,-2) -> 15500 | AG27: 8470 | AH27: =AF27-AG27 -> 7030 | AJ27: =ROUND('2024 Bdg vs Actual-CA'!AQ27+'2024 Bdg vs Actual -OH'!AQ27,-2) -> 15800 | AK27: 7841 | AL27: =AJ27-AK27 -> 7959 | AN27: =ROUND('2024 Bdg vs Actual-CA'!AU27+'2024 Bdg vs Actual -OH'!AU27,-2) -> 16200 | AO27: 9617 | AP27: =AN27-AO27 -> 6583 | AR27: =ROUND('2024 Bdg vs Actual-CA'!AY27+'2024 Bdg vs Actual -OH'!AY27,-2) -> 16500 | AS27: 10737 | AT27: =AR27-AS27 -> 5763 | AV27: =ROUND('2024 Bdg vs Actual-CA'!BC27+'2024 Bdg vs Actual -OH'!BC27,-2) -> 16800 | AW27: 7273 | AX27: =AV27-AW27 -> 9527 | AZ27: =ROUND('2024 Bdg vs Actual-CA'!BG27+'2024 Bdg vs Actual -OH'!BG27,-2) -> 17600 | BA27: 9786 | BB27: =AZ27-BA27 -> 7814 | BG27: =+P27+L27+H27+T27+X27+AB27+AF27+AJ27+AN27+AR27+AV27+AZ27 -> 185593.58 | BH27: =+Q27+M27+I27+U27+Y27+AC27+AG27+AK27+AO27+AS27+AW27+BA27 -> 111212 | BI27: =BG27-BH27 -> 74381.58
A28: Costs of Monthly Recurring Resale | F28: =H28+L28+P28+T28+X28+AB28+AF28+AJ28+AN28+AR28+AV28+AZ28 -> 1788426.7 | H28: =H16*0.647 -> 129326.7 | I28: 151839 | J28: =H28-I28 -> -22512.304 | L28: =+'2024 Bdg vs Actual-CA'!S28+'2024 Bdg vs Actual -OH'!S28 -> 139800 | M28: 162704 | N28: =L28-M28 -> -22904 | P28: =ROUND(+'2024 Bdg vs Actual-CA'!W28+'2024 Bdg vs Actual -OH'!W28,-2) -> 129600 | Q28: 153411 | R28: =P28-Q28 -> -23811 | T28: =ROUND('2024 Bdg vs Actual-CA'!AA28+'2024 Bdg vs Actual -OH'!AA28,-2) -> 136900 | U28: 150078 | V28: =T28-U28 -> -13178 | X28: =ROUND('2024 Bdg vs Actual-CA'!AE28+'2024 Bdg vs Actual -OH'!AE28,-2) -> 143600 | Y28: 150744 | Z28: =X28-Y28 -> -7144 | AB28: =ROUND('2024 Bdg vs Actual-CA'!AI28+'2024 Bdg vs Actual -OH'!AI28,-2) -> 151100 | AC28: 147044 | AD28: =AB28-AC28 -> 4056 | AF28: =ROUND('2024 Bdg vs Actual-CA'!AM28+'2024 Bdg vs Actual -OH'!AM28,-2) -> 153700 | AG28: 143293 | AH28: =AF28-AG28 -> 10407 | AJ28: =ROUND('2024 Bdg vs Actual-CA'!AQ28+'2024 Bdg vs Actual -OH'!AQ28,-2) -> 156300 | AK28: 145211 | AL28: =AJ28-AK28 -> 11089 | AN28: =ROUND('2024 Bdg vs Actual-CA'!AU28+'2024 Bdg vs Actual -OH'!AU28,-2) -> 158600 | AO28: 156493 | AP28: =AN28-AO28 -> 2107 | AR28: =ROUND('2024 Bdg vs Actual-CA'!AY28+'2024 Bdg vs Actual -OH'!AY28,-2) -> 161000 | AS28: 155761 | AT28: =AR28-AS28 -> 5239 | AV28: =ROUND('2024 Bdg vs Actual-CA'!BC28+'2024 Bdg vs Actual -OH'!BC28,-2) -> 163000 | AW28: 165048 | AX28: =AV28-AW28 -> -2048 | AZ28: =ROUND('2024 Bdg vs Actual-CA'!BG28+'2024 Bdg vs Actual -OH'!BG28,-2) -> 165500 | BA28: 166833 | BB28: =AZ28-BA28 -> -1333 | BG28: =+P28+L28+H28+T28+X28+AB28+AF28+AJ28+AN28+AR28+AV28+AZ28 -> 1788426.7 | BH28: =+Q28+M28+I28+U28+Y28+AC28+AG28+AK28+AO28+AS28+AW28+BA28 -> 1848459 | BI28: =BG28-BH28 -> -60032.304
A29: Costs of IT Project Services | F29: =H29+L29+P29+T29+X29+AB29+AF29+AJ29+AN29+AR29+AV29+AZ29 -> 16944.414 | H29: =H17*0.012 -> 1449.414 | I29: 2444 | J29: =H29-I29 -> -994.586 | L29: =+'2024 Bdg vs Actual-CA'!S29+'2024 Bdg vs Actual -OH'!S29 -> 1495 | M29: 371 | N29: =L29-M29 -> 1124 | P29: =ROUND(+'2024 Bdg vs Actual-CA'!W29+'2024 Bdg vs Actual -OH'!W29,-2) -> 1400 | Q29: 270 | R29: =P29-Q29 -> 1130 | T29: =ROUND('2024 Bdg vs Actual-CA'!AA29+'2024 Bdg vs Actual -OH'!AA29,-2) -> 1400 | U29: 3310 | V29: =T29-U29 -> -1910 | X29: =ROUND('2024 Bdg vs Actual-CA'!AE29+'2024 Bdg vs Actual -OH'!AE29,-2) -> 1400 | Y29: 367 | Z29: =X29-Y29 -> 1033 | AB29: =ROUND('2024 Bdg vs Actual-CA'!AI29+'2024 Bdg vs Actual -OH'!AI29,-2) -> 1400 | AC29: 19990 | AD29: =AB29-AC29 -> -18590 | AF29: =ROUND('2024 Bdg vs Actual-CA'!AM29+'2024 Bdg vs Actual -OH'!AM29,-2) -> 1400 | AG29: 794 | AH29: =AF29-AG29 -> 606 | AJ29: =ROUND('2024 Bdg vs Actual-CA'!AQ29+'2024 Bdg vs Actual -OH'!AQ29,-2) -> 1400 | AK29: 245 | AL29: =AJ29-AK29 -> 1155 | AN29: =ROUND('2024 Bdg vs Actual-CA'!AU29+'2024 Bdg vs Actual -OH'!AU29,-2) -> 1400 | AO29: 0 | AP29: =AN29-AO29 -> 1400 | AR29: =ROUND('2024 Bdg vs Actual-CA'!AY29+'2024 Bdg vs Actual -OH'!AY29,-2) -> 1400 | AS29: 0 | AT29: =AR29-AS29 -> 1400 | AV29: =ROUND('2024 Bdg vs Actual-CA'!BC29+'2024 Bdg vs Actual -OH'!BC29,-2) -> 1400 | AW29: 562 | AX29: =AV29-AW29 -> 838 | AZ29: =ROUND('2024 Bdg vs Actual-CA'!BG29+'2024 Bdg vs Actual -OH'!BG29,-2) -> 1400 | BA29: 0 | BB29: =AZ29-BA29 -> 1400 | BG29: =+P29+L29+H29+T29+X29+AB29+AF29+AJ29+AN29+AR29+AV29+AZ29 -> 16944.414 | BH29: =+Q29+M29+I29+U29+Y29+AC29+AG29+AK29+AO29+AS29+AW29+BA29 -> 28353 | BI29: =BG29-BH29 -> -11408.586
A30: Costs of Subcontracted Services | F30: =H30+L30+P30+T30+X30+AB30+AF30+AJ30+AN30+AR30+AV30+AZ30 -> 621646.12 | H30: =H18*0.894 -> 50746.122 | I30: 4581 | J30: =H30-I30 -> 46165.122 | L30: =+'2024 Bdg vs Actual-CA'!S30+'2024 Bdg vs Actual -OH'!S30 -> 63900 | M30: 62562 | N30: =L30-M30 -> 1338 | P30: =ROUND(+'2024 Bdg vs Actual-CA'!W30+'2024 Bdg vs Actual -OH'!W30,-2) -> 50700 | Q30: 13434 | R30: =P30-Q30 -> 37266 | T30: =ROUND('2024 Bdg vs Actual-CA'!AA30+'2024 Bdg vs Actual -OH'!AA30,-2) -> 50700 | U30: 9004 | V30: =T30-U30 -> 41696 | X30: =ROUND('2024 Bdg vs Actual-CA'!AE30+'2024 Bdg vs Actual -OH'!AE30,-2) -> 50700 | Y30: 11858 | Z30: =X30-Y30 -> 38842 | AB30: =ROUND('2024 Bdg vs Actual-CA'!AI30+'2024 Bdg vs Actual -OH'!AI30,-2) -> 50700 | AC30: 13738 | AD30: =AB30-AC30 -> 36962 | AF30: =ROUND('2024 Bdg vs Actual-CA'!AM30+'2024 Bdg vs Actual -OH'!AM30,-2) -> 50700 | AG30: 246428 | AH30: =AF30-AG30 -> -195728 | AJ30: =ROUND('2024 Bdg vs Actual-CA'!AQ30+'2024 Bdg vs Actual -OH'!AQ30,-2) -> 50700 | AK30: 111796 | AL30: =AJ30-AK30 -> -61096 | AN30: =ROUND('2024 Bdg vs Actual-CA'!AU30+'2024 Bdg vs Actual -OH'!AU30,-2) -> 50700 | AO30: 22771 | AP30: =AN30-AO30 -> 27929 | AR30: =ROUND('2024 Bdg vs Actual-CA'!AY30+'2024 Bdg vs Actual -OH'!AY30,-2) -> 50700 | AS30: 27250 | AT30: =AR30-AS30 -> 23450 | AV30: =ROUND('2024 Bdg vs Actual-CA'!BC30+'2024 Bdg vs Actual -OH'!BC30,-2) -> 50700 | AW30: 10575 | AX30: =AV30-AW30 -> 40125 | AZ30: =ROUND('2024 Bdg vs Actual-CA'!BG30+'2024 Bdg vs Actual -OH'!BG30,-2) -> 50700 | BA30: 22708 | BB30: =AZ30-BA30 -> 27992 | BG30: =+P30+L30+H30+T30+X30+AB30+AF30+AJ30+AN30+AR30+AV30+AZ30 -> 621646.12 | BH30: =+Q30+M30+I30+U30+Y30+AC30+AG30+AK30+AO30+AS30+AW30+BA30 -> 556705 | BI30: =BG30-BH30 -> 64941.122
A31: Costs of Product Resale | F31: =H31+L31+P31+T31+X31+AB31+AF31+AJ31+AN31+AR31+AV31+AZ31 -> 12571185 | H31: =H22*0.85 -> 1047584.6 | I31: 454504 | J31: =H31-I31 -> 593080.62 | L31: =+'2024 Bdg vs Actual-CA'!S31+'2024 Bdg vs Actual -OH'!S31 -> 1047600 | M31: 619534 | N31: =L31-M31 -> 428066 | P31: =ROUND(+'2024 Bdg vs Actual-CA'!W31+'2024 Bdg vs Actual -OH'!W31,-2) -> 1047600 | Q31: 322796 | R31: =P31-Q31 -> 724804 | T31: =ROUND('2024 Bdg vs Actual-CA'!AA31+'2024 Bdg vs Actual -OH'!AA31,-2) -> 1047600 | U31: 633077 | V31: =T31-U31 -> 414523 | X31: =ROUND('2024 Bdg vs Actual-CA'!AE31+'2024 Bdg vs Actual -OH'!AE31,-2) -> 1047600 | Y31: 529476 | Z31: =X31-Y31 -> 518124 | AB31: =ROUND('2024 Bdg vs Actual-CA'!AI31+'2024 Bdg vs Actual -OH'!AI31,-2) -> 1047600 | AC31: 1363102 | AD31: =AB31-AC31 -> -315502 | AF31: =ROUND('2024 Bdg vs Actual-CA'!AM31+'2024 Bdg vs Actual -OH'!AM31,-2) -> 1047600 | AG31: 980082 | AH31: =AF31-AG31 -> 67518 | AJ31: =ROUND('2024 Bdg vs Actual-CA'!AQ31+'2024 Bdg vs Actual -OH'!AQ31,-2) -> 1047600 | AK31: 1197545 | AL31: =AJ31-AK31 -> -149945 | AN31: =ROUND('2024 Bdg vs Actual-CA'!AU31+'2024 Bdg vs Actual -OH'!AU31,-2) -> 1047600 | AO31: 413028 | AP31: =AN31-AO31 -> 634572 | AR31: =ROUND('2024 Bdg vs Actual-CA'!AY31+'2024 Bdg vs Actual -OH'!AY31,-2) -> 1047600 | AS31: 521483 | AT31: =AR31-AS31 -> 526117 | AV31: =ROUND('2024 Bdg vs Actual-CA'!BC31+'2024 Bdg vs Actual -OH'!BC31,-2) -> 1047600 | AW31: 768618 | AX31: =AV31-AW31 -> 278982 | AZ31: =ROUND('2024 Bdg vs Actual-CA'!BG31+'2024 Bdg vs Actual -OH'!BG31,-2) -> 1047600 | BA31: 218840 | BB31: =AZ31-BA31 -> 828760 | BG31: =+P31+L31+H31+T31+X31+AB31+AF31+AJ31+AN31+AR31+AV31+AZ31 -> 12571185 | BH31: =+Q31+M31+I31+U31+Y31+AC31+AG31+AK31+AO31+AS31+AW31+BA31 -> 8022085 | BI31: =BG31-BH31 -> 4549099.6
A33: Direct Labor-Fully loaded(Support/Engineers) | F33: =H33+L33+P33+T33+X33+AB33+AF33+AJ33+AN33+AR33+AV33+AZ33 -> 4169565.2 | H33: ='2024 Bdg vs Actual-CA'!O33+'2024 Bdg vs Actual -OH'!O33 -> 361700 | I33: =313241+15170+3640+21873 -> 353924 | J33: =H33-I33 -> 7776 | L33: =+'2024 Bdg vs Actual-CA'!S33+'2024 Bdg vs Actual -OH'!S33 -> 348865.19 | M33: 333332 | N33: =L33-M33 -> 15533.193 | O33: Update budgetpayroll based on onboarding and off boardings notified of | P33: =ROUND(+'2024 Bdg vs Actual-CA'!W33+'2024 Bdg vs Actual -OH'!W33,-2) -> 345200 | Q33: 333234 | R33: =P33-Q33 -> 11966 | T33: =ROUND('2024 Bdg vs Actual-CA'!AA33+'2024 Bdg vs Actual -OH'!AA33,-2) -> 341000 | U33: 345633 | V33: =T33-U33 -> -4633 | X33: =ROUND('2024 Bdg vs Actual-CA'!AE33+'2024 Bdg vs Actual -OH'!AE33,-2) -> 346600 | Y33: 357329 | Z33: =X33-Y33 -> -10729 | AB33: =ROUND('2024 Bdg vs Actual-CA'!AI33+'2024 Bdg vs Actual -OH'!AI33,-2) -> 346600 | AC33: 346405 | AD33: =AB33-AC33 -> 195 | AF33: =ROUND('2024 Bdg vs Actual-CA'!AM33+'2024 Bdg vs Actual -OH'!AM33,-2) -> 346600 | AG33: 340442 | AH33: =AF33-AG33 -> 6158 | AJ33: =ROUND('2024 Bdg vs Actual-CA'!AQ33+'2024 Bdg vs Actual -OH'!AQ33,-2) -> 346600 | AK33: 349505 | AL33: =AJ33-AK33 -> -2905 | AN33: =ROUND('2024 Bdg vs Actual-CA'!AU33+'2024 Bdg vs Actual -OH'!AU33,-2) -> 346600 | AO33: 325154 | AP33: =AN33-AO33 -> 21446 | AR33: =ROUND('2024 Bdg vs Actual-CA'!AY33+'2024 Bdg vs Actual -OH'!AY33,-2) -> 346600 | AS33: 333772 | AT33: =AR33-AS33 -> 12828 | AV33: =ROUND('2024 Bdg vs Actual-CA'!BC33+'2024 Bdg vs Actual -OH'!BC33,-2) -> 346600 | AW33: 359057 | AX33: =AV33-AW33 -> -12457 | AZ33: =ROUND('2024 Bdg vs Actual-CA'!BG33+'2024 Bdg vs Actual -OH'!BG33,-2) -> 346600 | BA33: 333778 | BB33: =AZ33-BA33 -> 12822 | BG33: =+P33+L33+H33+T33+X33+AB33+AF33+AJ33+AN33+AR33+AV33+AZ33 -> 4169565.2 | BH33: =+Q33+M33+I33+U33+Y33+AC33+AG33+AK33+AO33+AS33+AW33+BA33 -> 4111565 | BI33: =BG33-BH33 -> 58000.192
A34: Total Cost of Good Sold** | F34: =H34+L34+P34+T34+X34+AB34+AF34+AJ34+AN34+AR34+AV34+AZ34 -> 19584800 | H34: =SUM(H26:H33) -> 1630140.2 | I34: =SUM(I26:I33) -> 999352 | J34: =H34-I34 -> 630788.21 | L34: =SUM(L26:L33) -> 1632160.2 | M34: =SUM(M26:M33) -> 1213199 | N34: =L34-M34 -> 418961.19 | P34: =SUM(P26:P33) -> 1604800 | Q34: =SUM(Q26:Q33) -> 855729 | R34: =P34-Q34 -> 749071 | T34: =SUM(T26:T33) -> 1608600 | U34: =SUM(U26:U33) -> 1177613 | V34: =T34-U34 -> 430987 | X34: =SUM(X26:X33) -> 1621000 | Y34: =SUM(Y26:Y33) -> 1080048 | Z34: =X34-Y34 -> 540952 | AB34: =SUM(AB26:AB33) -> 1631600 | AC34: =SUM(AC26:AC33) -> 1919509 | AD34: =AB34-AC34 -> -287909 | AF34: =SUM(AF26:AF33) -> 1635000 | AG34: =SUM(AG26:AG33) -> 1741834 | AH34: =AF34-AG34 -> -106834 | AJ34: =SUM(AJ26:AJ33) -> 1638100 | AK34: =SUM(AK26:AK33) -> 1828152 | AL34: =AJ34-AK34 -> -190052 | AN34: =SUM(AN26:AN33) -> 1641100 | AO34: =SUM(AO26:AO33) -> 944490 | AP34: =AN34-AO34 -> 696610 | AR34: =SUM(AR26:AR33) -> 1644400 | AS34: =SUM(AS26:AS33) -> 1062621 | AT34: =AR34-AS34 -> 581779 | AV34: =SUM(AV26:AV33) -> 1647100 | AW34: =SUM(AW26:AW33) -> 1331889 | AX34: =AV34-AW34 -> 315211 | AZ34: =SUM(AZ26:AZ33) -> 1650800 | BA34: =SUM(BA26:BA33) -> 768383 | BB34: =AZ34-BA34 -> 882417 | BG34: =+P34+L34+H34+T34+X34+AB34+AF34+AJ34+AN34+AR34+AV34+AZ34 -> 19584800 | BH34: =+Q34+M34+I34+U34+Y34+AC34+AG34+AK34+AO34+AS34+AW34+BA34 -> 14922819 | BI34: =BG34-BH34 -> 4661981.4
A35: Total Gross Margin | F35: =F11-F34 -> 7604674.3 | H35: =H11-H34 -> 632957.63 | I35: =I11-I34 -> 376370.57 | J35: =I35-H35 -> -256587.06 | L35: =L11-L34 -> 561316.64 | M35: =M11-M34 -> 495469 | N35: =M35-L35 -> -65847.641 | P35: =P11-P34 -> 562600 | Q35: =Q11-Q34 -> 401017 | R35: =Q35-P35 -> -161583 | T35: =T11-T34 -> 585100 | U35: =U11-U34 -> 562823 | V35: =U35-T35 -> -22277 | X35: =X11-X34 -> 594400 | Y35: =Y11-Y34 -> 430419 | Z35: =Y35-X35 -> -163981 | AB35: =AB11-AB34 -> 627300 | AC35: =AC11-AC34 -> 658772 | AD35: =AC35-AB35 -> 31472 | AF35: =AF11-AF34 -> 643300 | AG35: =AG11-AG34 -> 657168 | AH35: =AG35-AF35 -> 13868 | AJ35: =AJ11-AJ34 -> 651000 | AK35: =AK11-AK34 -> 958381 | AL35: =AK35-AJ35 -> 307381 | AN35: =AN11-AN34 -> 663700 | AO35: =AO11-AO34 -> 462848 | AP35: =AO35-AN35 -> -200852 | AR35: =AR11-AR34 -> 680000 | AS35: =AS11-AS34 -> 457553 | AT35: =AS35-AR35 -> -222447 | AV35: =AV11-AV34 -> 693700 | AW35: =AW11-AW34 -> 470173 | AX35: =AW35-AV35 -> -223527 | AZ35: =AZ11-AZ34 -> 709300 | BA35: =BA11-BA34 -> 428533 | BB35: =BA35-AZ35 -> -280767 | BG35: =BG11-BG34 -> 7604674.3 | BH35: =BH11-BH34 -> 6359526.6 | BI35: =BH35-BG35 -> -1245147.7
A37: Direct Selling Costs
A39: Commissions | F39: =H39+L39+P39+T39+X39+AB39+AF39+AJ39+AN39+AR39+AV39+AZ39 -> 603000 | H39: =+'2024 Bdg vs Actual-CA'!O39+'2024 Bdg vs Actual -OH'!O39 -> 66600 | I39: 2772 | J39: =H39-I39 -> 63828 | L39: =+'2024 Bdg vs Actual-CA'!S39+'2024 Bdg vs Actual -OH'!S39 -> 19300 | M39: 30348 | N39: =L39-M39 -> -11048 | O39: Paid out commissions from 4Q2024 | P39: =ROUND(+'2024 Bdg vs Actual-CA'!W39+'2024 Bdg vs Actual -OH'!W39,-2) -> 28900 | Q39: 0 | R39: =P39-Q39 -> 28900 | T39: =+'2024 Bdg vs Actual-CA'!AA39+'2024 Bdg vs Actual -OH'!AA39 -> 51700 | U39: 26145 | V39: =T39-U39 -> 25555 | X39: =+'2024 Bdg vs Actual-CA'!AE39+'2024 Bdg vs Actual -OH'!AE39 -> 51700 | Y39: 15741.92 | Z39: =X39-Y39 -> 35958.08 | AB39: =+'2024 Bdg vs Actual-CA'!AI39+'2024 Bdg vs Actual -OH'!AI39 -> 101600 | AC39: 31323 | AD39: =AB39-AC39 -> 70277 | AF39: =+'2024 Bdg vs Actual-CA'!AM39+'2024 Bdg vs Actual -OH'!AM39 -> 47200 | AG39: 22987 | AH39: =AF39-AG39 -> 24213 | AJ39: =+'2024 Bdg vs Actual-CA'!AQ39+'2024 Bdg vs Actual -OH'!AQ39 -> 47200 | AK39: =31335 -> 31335 | AL39: =AJ39-AK39 -> 15865 | AN39: =+'2024 Bdg vs Actual-CA'!AU39+'2024 Bdg vs Actual -OH'!AU39 -> 47200 | AO39: 29868 | AP39: =AN39-AO39 -> 17332 | AR39: =+'2024 Bdg vs Actual-CA'!AY39+'2024 Bdg vs Actual -OH'!AY39 -> 47200 | AS39: 41573 | AT39: =AR39-AS39 -> 5627 | AV39: =+'2024 Bdg vs Actual-CA'!BC39+'2024 Bdg vs Actual -OH'!BC39 -> 47200 | AW39: 22190 | AX39: =AV39-AW39 -> 25010 | AZ39: =+'2024 Bdg vs Actual-CA'!BG39+'2024 Bdg vs Actual -OH'!BG39 -> 47200 | BA39: 26793 | BB39: =AZ39-BA39 -> 20407 | BG39: =+P39+L39+H39+T39+X39+AB39+AF39+AJ39+AN39+AR39+AV39+AZ39 -> 603000 | BH39: =+Q39+M39+I39+U39+Y39+AC39+AG39+AK39+AO39+AS39+AW39+BA39 -> 281075.92 | BI39: =BG39-BH39 -> 321924.08
A40: Labor Selling - Loaded | F40: =H40+L40+P40+T40+X40+AB40+AF40+AJ40+AN40+AR40+AV40+AZ40 -> 1414731.5 | H40: ='2024 Bdg vs Actual-CA'!O40+'2024 Bdg vs Actual -OH'!O40 -> 110400 | I40: 118582 | J40: =H40-I40 -> -8182 | K40: I'm assuming these commissions are from December/prior, because they should be much less than budgeted with sales so low | L40: =+'2024 Bdg vs Actual-CA'!S40+'2024 Bdg vs Actual -OH'!S40 -> 130631.49 | M40: 127279 | N40: =L40-M40 -> 3352.49 | O40: Update budgetpayroll based on onboarding and off boardings notified of | P40: =ROUND(+'2024 Bdg vs Actual-CA'!W40+'2024 Bdg vs Actual -OH'!W40,-2) -> 130600 | Q40: 132452 | R40: =P40-Q40 -> -1852 | T40: =ROUND('2024 Bdg vs Actual-CA'!AA40+'2024 Bdg vs Actual -OH'!AA40,-2) -> 120700 | U40: =157259-26145 -> 131114 | V40: =T40-U40 -> -10414 | X40: =ROUND('2024 Bdg vs Actual-CA'!AE40+'2024 Bdg vs Actual -OH'!AE40,-2) -> 115300 | Y40: 147392 | Z40: =X40-Y40 -> -32092 | AB40: =ROUND('2024 Bdg vs Actual-CA'!AI40+'2024 Bdg vs Actual -OH'!AI40,-2) -> 115300 | AC40: =141685-31323 -> 110362 | AD40: =AB40-AC40 -> 4938 | AF40: =ROUND('2024 Bdg vs Actual-CA'!AM40+'2024 Bdg vs Actual -OH'!AM40,-2) -> 115300 | AG40: =108853+10617+2430+4607 -> 126507 | AH40: =AF40-AG40 -> -11207 | AJ40: =ROUND('2024 Bdg vs Actual-CA'!AQ40+'2024 Bdg vs Actual -OH'!AQ40,-2) -> 115300 | AK40: =130111-31335 -> 98776 | AL40: =AJ40-AK40 -> 16524 | AN40: =ROUND('2024 Bdg vs Actual-CA'!AU40+'2024 Bdg vs Actual -OH'!AU40,-2) -> 115300 | AO40: =119660-AO39 -> 89792 | AP40: =AN40-AO40 -> 25508 | AR40: =ROUND('2024 Bdg vs Actual-CA'!AY40+'2024 Bdg vs Actual -OH'!AY40,-2) -> 115300 | AS40: =115290+12667+1692+4023+6460 -> 140132 | AT40: =AR40-AS40 -> -24832 | AV40: =ROUND('2024 Bdg vs Actual-CA'!BC40+'2024 Bdg vs Actual -OH'!BC40,-2) -> 115300 | AW40: =84308+7906+1531+3339+6007 -> 103091 | AX40: =AV40-AW40 -> 12209 | AZ40: =ROUND('2024 Bdg vs Actual-CA'!BG40+'2024 Bdg vs Actual -OH'!BG40,-2) -> 115300 | BA40: =126880.26-26793 -> 100087.26 | BB40: =AZ40-BA40 -> 15212.74 | BG40: =+P40+L40+H40+T40+X40+AB40+AF40+AJ40+AN40+AR40+AV40+AZ40 -> 1414731.5 | BH40: =+Q40+M40+I40+U40+Y40+AC40+AG40+AK40+AO40+AS40+AW40+BA40 -> 1425566.3 | BI40: =BG40-BH40 -> -10834.77
A41: Contribution Margin | F41: =F35-F39-F40 -> 5586942.8 | H41: =H35-H39-H40 -> 455957.63 | I41: =I35-I39-I40 -> 255016.57 | J41: =I41-H41 -> -200941.06 | K41: *We need to have a way to project commissions and timing | L41: =L35-L39-L40 -> 411385.15 | M41: =M35-M39-M40 -> 337842 | N41: =M41-L41 -> -73543.151 | P41: =P35-P39-P40 -> 403100 | Q41: =Q35-Q39-Q40 -> 268565 | R41: =Q41-P41 -> -134535 | T41: =T35-T39-T40 -> 412700 | U41: =U35-U39-U40 -> 405564 | V41: =U41-T41 -> -7136 | X41: =X35-X39-X40 -> 427400 | Y41: =Y35-Y39-Y40 -> 267285.08 | Z41: =Y41-X41 -> -160114.92 | AB41: =AB35-AB39-AB40 -> 410400 | AC41: =AC35-AC39-AC40 -> 517087 | AD41: =AC41-AB41 -> 106687 | AF41: =AF35-AF39-AF40 -> 480800 | AG41: =AG35-AG39-AG40 -> 507674 | AH41: =AG41-AF41 -> 26874 | AJ41: =AJ35-AJ39-AJ40 -> 488500 | AK41: =AK35-AK39-AK40 -> 828270 | AL41: =AK41-AJ41 -> 339770 | AN41: =AN35-AN39-AN40 -> 501200 | AO41: =AO35-AO39-AO40 -> 343188 | AP41: =AO41-AN41 -> -158012 | AR41: =AR35-AR39-AR40 -> 517500 | AS41: =AS35-AS39-AS40 -> 275848 | AT41: =AS41-AR41 -> -241652 | AV41: =AV35-AV39-AV40 -> 531200 | AW41: =AW35-AW39-AW40 -> 344892 | AX41: =AW41-AV41 -> -186308 | AZ41: =AZ35-AZ39-AZ40 -> 546800 | BA41: =BA35-BA39-BA40 -> 301652.74 | BB41: =BA41-AZ41 -> -245147.26 | BG41: =BG35-BG39-BG40 -> 5586942.8 | BH41: =BH35-BH39-BH40 -> 4652884.4 | BI41: =BH41-BG41 -> -934058.39
A43: **Expenses**
A45: Payroll ***
A46: Exec/ Mgmnt/Admin- Fully Loaded | F46: =H46+L46+P46+T46+X46+AB46+AF46+AJ46+AN46+AR46+AV46+AZ46 -> 1395000 | H46: ='2024 Bdg vs Actual-CA'!O46+'2024 Bdg vs Actual -OH'!O46 -> 109100 | I46: 132611 | J46: =H46-I46 -> -23511 | L46: =+'2024 Bdg vs Actual-CA'!S46+'2024 Bdg vs Actual -OH'!S46 -> 109100 | M46: 111986 | N46: =L46-M46 -> -2886 | O46: Update budgetpayroll based on onboarding and off boardings notified of | P46: =ROUND(+'2024 Bdg vs Actual-CA'!W46+'2024 Bdg vs Actual -OH'!W46,-2) -> 110300 | Q46: 115934 | R46: =P46-Q46 -> -5634 | T46: =ROUND('2024 Bdg vs Actual-CA'!AA46+'2024 Bdg vs Actual -OH'!AA46,-2) -> 118500 | U46: 130035 | V46: =T46-U46 -> -11535 | X46: =ROUND('2024 Bdg vs Actual-CA'!AE46+'2024 Bdg vs Actual -OH'!AE46,-2) -> 118500 | Y46: 132946 | Z46: =X46-Y46 -> -14446 | AB46: =ROUND('2024 Bdg vs Actual-CA'!AI46+'2024 Bdg vs Actual -OH'!AI46,-2) -> 118500 | AC46: 110799 | AD46: =AB46-AC46 -> 7701 | AF46: =ROUND('2024 Bdg vs Actual-CA'!AM46+'2024 Bdg vs Actual -OH'!AM46,-2) -> 118500 | AG46: 104268 | AH46: =AF46-AG46 -> 14232 | AJ46: =ROUND('2024 Bdg vs Actual-CA'!AQ46+'2024 Bdg vs Actual -OH'!AQ46,-2) -> 118500 | AK46: 110147 | AL46: =AJ46-AK46 -> 8353 | AN46: =ROUND('2024 Bdg vs Actual-CA'!AU46+'2024 Bdg vs Actual -OH'!AU46,-2) -> 118500 | AO46: 105538 | AP46: =AN46-AO46 -> 12962 | AR46: =ROUND('2024 Bdg vs Actual-CA'!AY46+'2024 Bdg vs Actual -OH'!AY46,-2) -> 118500 | AS46: 117800 | AT46: =AR46-AS46 -> 700 | AV46: =ROUND('2024 Bdg vs Actual-CA'!BC46+'2024 Bdg vs Actual -OH'!BC46,-2) -> 118500 | AW46: 109515 | AX46: =AV46-AW46 -> 8985 | AZ46: =ROUND('2024 Bdg vs Actual-CA'!BG46+'2024 Bdg vs Actual -OH'!BG46,-2) -> 118500 | BA46: 149557 | BB46: =AZ46-BA46 -> -31057 | BG46: =+P46+L46+H46+T46+X46+AB46+AF46+AJ46+AN46+AR46+AV46+AZ46 -> 1395000 | BH46: =+Q46+M46+I46+U46+Y46+AC46+AG46+AK46+AO46+AS46+AW46+BA46 -> 1431136 | BI46: =BG46-BH46 -> -36136
A47: Workers Comp | F47: =H47+L47+P47+T47+X47+AB47+AF47+AJ47+AN47+AR47+AV47+AZ47 -> 9000 | H47: ='2024 Bdg vs Actual-CA'!O47+'2024 Bdg vs Actual -OH'!O47 -> 0 | I47: 0 | J47: =H47-I47 -> 0 | L47: ='2024 Bdg vs Actual-CA'!S47+'2024 Bdg vs Actual -OH'!S47 -> 0 | M47: 0 | N47: =L47-M47 -> 0 | P47: =ROUND(+'2024 Bdg vs Actual-CA'!W47+'2024 Bdg vs Actual -OH'!W47,-2) -> 3000 | Q47: 0 | R47: =P47-Q47 -> 3000 | T47: ='2024 Bdg vs Actual-CA'!AA47+'2024 Bdg vs Actual -OH'!AA47 -> 0 | V47: =T47-U47 -> 0 | X47: ='2024 Bdg vs Actual-CA'!AE47+'2024 Bdg vs Actual -OH'!AE47 -> 0 | Z47: =X47-Y47 -> 0 | AB47: ='2024 Bdg vs Actual-CA'!AI47+'2024 Bdg vs Actual -OH'!AI47 -> 3000 | AD47: =AB47-AC47 -> 3000 | AF47: ='2024 Bdg vs Actual-CA'!AM47+'2024 Bdg vs Actual -OH'!AM47 -> 0 | AH47: =AF47-AG47 -> 0 | AJ47: ='2024 Bdg vs Actual-CA'!AQ47+'2024 Bdg vs Actual -OH'!AQ47 -> 0 | AL47: =AJ47-AK47 -> 0 | AN47: ='2024 Bdg vs Actual-CA'!AU47+'2024 Bdg vs Actual -OH'!AU47 -> 0 | AP47: =AN47-AO47 -> 0 | AR47: ='2024 Bdg vs Actual-CA'!AY47+'2024 Bdg vs Actual -OH'!AY47 -> 3000 | AS47: 0 | AT47: =AR47-AS47 -> 3000 | AV47: ='2024 Bdg vs Actual-CA'!BC47+'2024 Bdg vs Actual -OH'!BC47 -> 0 | AX47: =AV47-AW47 -> 0 | AZ47: ='2024 Bdg vs Actual-CA'!BG47+'2024 Bdg vs Actual -OH'!BG47 -> 0 | BB47: =AZ47-BA47 -> 0 | BG47: =+P47+L47+H47+T47+X47+AB47+AF47+AJ47+AN47+AR47+AV47+AZ47 -> 9000 | BH47: =+Q47+M47+I47+U47+Y47+AC47+AG47+AK47+AO47+AS47+AW47+BA47 -> 0 | BI47: =BG47-BH47 -> 9000
A48: Total Payroll | F48: =SUM(H48:AZ48) -> 2689500 | H48: =H46+H47 -> 109100 | I48: =I46+I47 -> 132611 | J48: =H48-I48 -> -23511 | L48: =L46+L47 -> 109100 | M48: =M46+M47 -> 111986 | N48: =L48-M48 -> -2886 | P48: =P46+P47 -> 113300 | Q48: =Q46+Q47 -> 115934 | R48: =P48-Q48 -> -2634 | T48: =T46+T47 -> 118500 | U48: =U46+U47 -> 130035 | V48: =T48-U48 -> -11535 | X48: =X46+X47 -> 118500 | Y48: =Y46+Y47 -> 132946 | Z48: =X48-Y48 -> -14446 | AB48: =AB46+AB47 -> 121500 | AC48: =AC46+AC47 -> 110799 | AD48: =AB48-AC48 -> 10701 | AF48: =AF46+AF47 -> 118500 | AG48: =AG46+AG47 -> 104268 | AH48: =AF48-AG48 -> 14232 | AJ48: =AJ46+AJ47 -> 118500 | AK48: =AK46+AK47 -> 110147 | AL48: =AJ48-AK48 -> 8353 | AN48: =AN46+AN47 -> 118500 | AO48: =AO46+AO47 -> 105538 | AP48: =AN48-AO48 -> 12962 | AR48: =AR46+AR47 -> 121500 | AS48: =AS46+AS47 -> 117800 | AT48: =AR48-AS48 -> 3700 | AV48: =AV46+AV47 -> 118500 | AW48: =AW46+AW47 -> 109515 | AX48: =AV48-AW48 -> 8985 | AZ48: =AZ46+AZ47 -> 118500 | BA48: =BA46+BA47 -> 149557 | BB48: =AZ48-BA48 -> -31057 | BG48: =BG46+BG47 -> 1404000 | BH48: =BH46+BH47 -> 1431136 | BI48: =BG48-BH48 -> -27136
A51: Office Expenses****
A52: Office Lease | F52: =H52+L52+P52+T52+X52+AB52+AF52+AJ52+AN52+AR52+AV52+AZ52 -> 321500 | H52: ='2024 Bdg vs Actual-CA'!O52+'2024 Bdg vs Actual -OH'!O52 -> 26200 | I52: =27952-1700 -> 26252 | J52: =H52-I52 -> -52 | L52: =+'2024 Bdg vs Actual-CA'!S52+'2024 Bdg vs Actual -OH'!S52 -> 26200 | M52: 27157 | N52: =L52-M52 -> -957 | P52: =ROUND(+'2024 Bdg vs Actual-CA'!W52+'2024 Bdg vs Actual -OH'!W52,-2) -> 26600 | Q52: 31350 | R52: =P52-Q52 -> -4750 | T52: =+'2024 Bdg vs Actual-CA'!AA52+'2024 Bdg vs Actual -OH'!AA52 -> 26600 | U52: 26358 | V52: =T52-U52 -> 242 | X52: =+'2024 Bdg vs Actual-CA'!AE52+'2024 Bdg vs Actual -OH'!AE52 -> 26600 | Y52: 25407 | Z52: =X52-Y52 -> 1193 | AB52: =+'2024 Bdg vs Actual-CA'!AI52+'2024 Bdg vs Actual -OH'!AI52 -> 26600 | AC52: 25212 | AD52: =AB52-AC52 -> 1388 | AF52: =+'2024 Bdg vs Actual-CA'!AM52+'2024 Bdg vs Actual -OH'!AM52 -> 26700 | AG52: 27192 | AH52: =AF52-AG52 -> -492 | AJ52: =+'2024 Bdg vs Actual-CA'!AQ52+'2024 Bdg vs Actual -OH'!AQ52 -> 27200 | AK52: 26310 | AL52: =AJ52-AK52 -> 890 | AN52: =+'2024 Bdg vs Actual-CA'!AU52+'2024 Bdg vs Actual -OH'!AU52 -> 27200 | AO52: 28017 | AP52: =AN52-AO52 -> -817 | AR52: =+'2024 Bdg vs Actual-CA'!AY52+'2024 Bdg vs Actual -OH'!AY52 -> 27200 | AS52: 27465 | AT52: =AR52-AS52 -> -265 | AV52: =+'2024 Bdg vs Actual-CA'!BC52+'2024 Bdg vs Actual -OH'!BC52 -> 27200 | AW52: 26216 | AX52: =AV52-AW52 -> 984 | AZ52: =+'2024 Bdg vs Actual-CA'!BG52+'2024 Bdg vs Actual -OH'!BG52 -> 27200 | BA52: 26216 | BB52: =AZ52-BA52 -> 984 | BG52: =+P52+L52+H52+T52+X52+AB52+AF52+AJ52+AN52+AR52+AV52+AZ52 -> 321500 | BH52: =+Q52+M52+I52+U52+Y52+AC52+AG52+AK52+AO52+AS52+AW52+BA52 -> 323152 | BI52: =BG52-BH52 -> -1652
A53: Insurance | F53: =H53+L53+P53+T53+X53+AB53+AF53+AJ53+AN53+AR53+AV53+AZ53 -> 120000 | H53: ='2024 Bdg vs Actual-CA'!O53+'2024 Bdg vs Actual -OH'!O53 -> 9000 | I53: 7175 | J53: =H53-I53 -> 1825 | L53: =+'2024 Bdg vs Actual-CA'!S53+'2024 Bdg vs Actual -OH'!S53 -> 10000 | M53: =-32456+40000 -> 7544 | N53: =L53-M53 -> 2456 | P53: =ROUND(+'2024 Bdg vs Actual-CA'!W53+'2024 Bdg vs Actual -OH'!W53,-2) -> 10000 | Q53: 8116 | R53: =P53-Q53 -> 1884 | T53: =+'2024 Bdg vs Actual-CA'!AA53+'2024 Bdg vs Actual -OH'!AA53 -> 10000 | U53: 4860 | V53: =T53-U53 -> 5140 | X53: =+'2024 Bdg vs Actual-CA'!AE53+'2024 Bdg vs Actual -OH'!AE53 -> 10000 | Y53: 5589 | Z53: =X53-Y53 -> 4411 | AB53: =+'2024 Bdg vs Actual-CA'!AI53+'2024 Bdg vs Actual -OH'!AI53 -> 10000 | AC53: 7749 | AD53: =AB53-AC53 -> 2251 | AF53: =+'2024 Bdg vs Actual-CA'!AM53+'2024 Bdg vs Actual -OH'!AM53 -> 10000 | AG53: 5678 | AH53: =AF53-AG53 -> 4322 | AJ53: =+'2024 Bdg vs Actual-CA'!AQ53+'2024 Bdg vs Actual -OH'!AQ53 -> 10200 | AK53: 5936 | AL53: =AJ53-AK53 -> 4264 | AN53: =+'2024 Bdg vs Actual-CA'!AU53+'2024 Bdg vs Actual -OH'!AU53 -> 10200 | AO53: 5581 | AP53: =AN53-AO53 -> 4619 | AR53: =+'2024 Bdg vs Actual-CA'!AY53+'2024 Bdg vs Actual -OH'!AY53 -> 10200 | AS53: 7074 | AT53: =AR53-AS53 -> 3126 | AV53: =+'2024 Bdg vs Actual-CA'!BC53+'2024 Bdg vs Actual -OH'!BC53 -> 10200 | AW53: 6275 | AX53: =AV53-AW53 -> 3925 | AZ53: =+'2024 Bdg vs Actual-CA'!BG53+'2024 Bdg vs Actual -OH'!BG53 -> 10200 | BA53: 6513 | BB53: =AZ53-BA53 -> 3687 | BG53: =+P53+L53+H53+T53+X53+AB53+AF53+AJ53+AN53+AR53+AV53+AZ53 -> 120000 | BH53: =+Q53+M53+I53+U53+Y53+AC53+AG53+AK53+AO53+AS53+AW53+BA53 -> 78090 | BI53: =BG53-BH53 -> 41910
...

Sheet 2024  Bdg vs Actual-CA
M1: Financial Projections | P1: Budget Vs Actual | T1: Variance | U1: (Red) | V1: Over budget | X1: Budget Vs Actual
M2: Income Statement 2023-2028 | P2: Income Statement - California | U2: Black | V2: Under budget | X2: Income Statement - California
P3: 2024 | X3: 2024
E8: Year 1* | G8: Year 2 * | I8: Year 3* | K8: Year 4 * | M8: Year 5 * | O8: January | S8: Feburary | W8: March | AA8: April | AE8: May | AI8: June | AM8: July | AQ8: August | AU8: September | AY8: October | BC8: November | BG8: December | CG8: YTD
E9: 45657 | O9: Budget | P9: Actual | Q9: Var | R9: Notes | S9: Budget | T9: Actual | U9: Var | V9: Notes | W9: Budget | X9: Actual | Y9: Var $ | Z9: Notes | AA9: Budget | AB9: Actual | AC9: Variance | AD9: Notes | AE9: Budget | AF9: Actual | AG9: Variance | AH9: Notes | AI9: Budget | AJ9: Actual | AK9: Variance | AL9: Notes | AM9: Budget | AN9: Actual | AO9: Variance | AP9: Notes | AQ9: Budget | AR9: Actual | AS9: Variance | AT9: Notes | AU9: Budget | AV9: Actual | AW9: Variance | AX9: Notes | AY9: Budget | AZ9: Actual | BA9: Variance | BB9: Notes | BC9: Budget | BD9: Actual | BE9: Variance | BF9: Notes | BG9: Budget | BH9: Actual | BI9: Variance | BJ9: Notes | BK9: Variance | BL9: Notes | CG9: Budget | CH9: Actual | CI9: Variance
A11: **Gross Sales** | E11: =SUM(E14:E23) -> 18200700 | O11: =SUM(O14:O23) -> 1542999 | P11: =+'2024 Bdg vs Actual All'!I11-'2024 Bdg vs Actual -OH'!P11 -> 840269.57 | Q11: =+P11-O11 -> -702729.4 | S11: =SUM(S14:S23) -> 1478678.8 | T11: =+'2024 Bdg vs Actual All'!M11-'2024 Bdg vs Actual -OH'!T11 -> 1238032 | U11: =+T11-S11 -> -240646.83 | W11: =SUM(W14:W23) -> 1442217.2 | X11: =+'2024 Bdg vs Actual All'!Q11-'2024 Bdg vs Actual -OH'!X11 -> 837354 | Y11: =+X11-W11 -> -604863.23 | AA11: =SUM(AA14:AA23) -> 1455488.3 | AB11: =SUM(AB14:AB23) -> 947573 | AC11: =+AB11-AA11 -> -507915.33 | AE11: =SUM(AE14:AE23) -> 1469333.3 | AF11: =SUM(AF14:AF23) -> 851142 | AG11: =+AF11-AE11 -> -618191.33 | AI11: =SUM(AI14:AI23) -> 1519265 | AJ11: =SUM(AJ14:AJ23) -> 1863270 | AK11: =+AJ11-AI11 -> 344005.01 | AM11: =SUM(AM14:AM23) -> 1526715 | AN11: =SUM(AN14:AN23) -> 1324908 | AO11: =+AN11-AM11 -> -201806.99 | AQ11: =SUM(AQ14:AQ23) -> 1530165 | AR11: =SUM(AR14:AR23) -> 1360378 | AS11: =+AR11-AQ11 -> -169786.99 | AU11: =SUM(AU14:AU23) -> 1541615 | AV11: =SUM(AV14:AV23) -> 939557 | AW11: =+AV11-AU11 -> -602057.99 | AY11: =SUM(AY14:AY23) -> 1553065 | AZ11: =SUM(AZ14:AZ23) -> 914158 | BA11: =+AZ11-AY11 -> -638906.99 | BC11: =SUM(BC14:BC23) -> 1564515 | BD11: =SUM(BD14:BD23) -> 1324777 | BE11: =+BD11-BC11 -> -239737.99 | BG11: =SUM(BG14:BG23) -> 1576601.8 | BH11: =SUM(BH14:BH23) -> 839015 | BI11: =+BH11-BG11 -> -737586.83 | CG11: =+W11+S11+O11+AA11+AE11+AI11+AM11+AQ11+AU11+AY11+BC11+BG11 -> 18200658 | CH11: =+X11+T11+P11+AB11+AF11+AJ11+AN11+AR11+AV11+AZ11+BD11+BH11 -> 13280434 | CI11: =+CH11-CG11 -> -4920224.9
A13: Services | M13: Attrition
A14: Monthly Recurring Services | D14: New Business + Current Agreements | E14: =ROUND(O14+S14+W14+AA14+AE14+AI14+AM14+AQ14+AU14+AY14+BC14+BG14,-2) -> 5276000 | M14: 0.005 | O14: 484784.11 | P14: ='2024 Bdg vs Actual All'!I14-'2024 Bdg vs Actual -OH'!P14 -> 401933.48 | Q14: =P14-O14 -> -82850.635 | S14: 400334 | T14: ='2024 Bdg vs Actual All'!M14-'2024 Bdg vs Actual -OH'!T14 -> 404034 | U14: =T14-S14 -> 3700 | V14: Pinacle Minds new client that is not renewing | W14: 393866.89 | X14: ='2024 Bdg vs Actual All'!Q14-'2024 Bdg vs Actual -OH'!X14 -> 394718 | Y14: =X14-W14 -> 851.1092 | AA14: 400000 | AB14: ='2024 Bdg vs Actual All'!U14-'2024 Bdg vs Actual -OH'!AB14 -> 388414 | AC14: =AB14-AA14 -> -11586 | AD14: Credit of Agee double March invoice, new business budget is 7875 - actual new business is 1755 (TPC), Fabricated Extrusion credit for $1800 for overbilling for 2 months and reduced bill by 900 | AE14: 406000 | AF14: ='2024 Bdg vs Actual All'!Y14-'2024 Bdg vs Actual -OH'!AF14 -> 312110 | AG14: =AF14-AE14 -> -93890 | AH14: New Business was budgeted at 15,750 and new business was only 7,350. | AI14: 441000 | AJ14: ='2024 Bdg vs Actual All'!AC14-'2024 Bdg vs Actual -OH'!AJ14 -> 387467 | AK14: =AJ14-AI14 -> -53533 | AL14: New Business was budgeted at 50,575 and new business was only 9,210. Sunny Valley was 6k under, Thomason Tractor 7K under, (both cancelled) | AM14: 445000 | AN14: ='2024 Bdg vs Actual All'!AG14-'2024 Bdg vs Actual -OH'!AN14 -> 409430 | AO14: =AN14-AM14 -> -35570 | AP14: New Business was budgeted at 58K and new business was only 48K. (Clients that left- Lammersville, Thomas tractor, Chathom- (16.4k)) (Under budget Clients- Sunny Valley -(6.2K), Chathom (3.4k), Graceada (3K), River delta (2K), Project Hope Alliance had credit for overbilling Jan- June (3K), Sylvan USD was over budget by 5K. | AQ14: 445000 | AR14: ='2024 Bdg vs Actual All'!AK14-'2024 Bdg vs Actual -OH'!AR14 -> 383691 | AS14: =AR14-AQ14 -> -61309 | AT14: New Business is 36.5K under budget,Lost companies total 24K, Gratton Elementary $1K under budget (will be caught up in Sept) | AU14: 453000 | AV14: ='2024 Bdg vs Actual All'!AO14-'2024 Bdg vs Actual -OH'!AV14 -> 385274 | AW14: =AV14-AU14 -> -67726 | AX14: No New Business - See Agreement Revenue Comparison - Sept to Aug 2024 see supplemental report for breakdown | AY14: 461000 | AZ14: ='2024 Bdg vs Actual All'!AS14-'2024 Bdg vs Actual -OH'!AZ14 -> 386945 | BA14: =AZ14-AY14 -> -74055 | BB14: No New Business - See Agreement Revenue Comparison - Sept to Aug 2024 see supplemental report for breakdown | BC14: 469000 | BD14: ='2024 Bdg vs Actual All'!AW14-'2024 Bdg vs Actual -OH'!BD14 -> 414555 | BE14: =BD14-BC14 -> -54445 | BG14: 477000 | BH14: ='2024 Bdg vs Actual All'!BA14-'2024 Bdg vs Actual -OH'!BH14 -> 437673 | BI14: =BH14-BG14 -> -39327 | BJ14: see supplemental report for breakdown | CG14: =+W14+S14+O14+AA14+AE14+AI14+AM14+AQ14+AU14+AY14+BC14+BG14 -> 5275985 | CH14: =+X14+T14+P14+AB14+AF14+AJ14+AN14+AR14+AV14+AZ14+BD14+BH14 -> 4706244.5 | CI14: =CH14-CG14 -> -569740.53
A15: Monthly Recurring Private Cloud | D15: New Business + Current Agreements | E15: =ROUND(O15+S15+W15+AA15+AE15+AI15+AM15+AQ15+AU15+AY15+BC15+BG15,-2) -> 255800 | O15: 26611.835 | P15: ='2024 Bdg vs Actual All'!I15-'2024 Bdg vs Actual -OH'!P15 -> 21937 | Q15: =P15-O15 -> -4674.835 | S15: 18042 | T15: ='2024 Bdg vs Actual All'!M15-'2024 Bdg vs Actual -OH'!T15 -> 24564 | U15: =T15-S15 -> 6522 | V15: Pinacle Minds new client that is not renewing | W15: 18041.66 | X15: ='2024 Bdg vs Actual All'!Q15-'2024 Bdg vs Actual -OH'!X15 -> 18807 | Y15: =X15-W15 -> 765.34 | AA15: 18491.66 | AB15: ='2024 Bdg vs Actual All'!U15-'2024 Bdg vs Actual -OH'!AB15 -> 20511 | AC15: =AB15-AA15 -> 2019.34 | AE15: 18000 | AF15: ='2024 Bdg vs Actual All'!Y15-'2024 Bdg vs Actual -OH'!AF15 -> 20275 | AG15: =AF15-AE15 -> 2275 | AH15: New Business was budgeted at 900 we had 2,500 in new business | AI15: 20931.66 | AJ15: ='2024 Bdg vs Actual All'!AC15-'2024 Bdg vs Actual -OH'!AJ15 -> 18128 | AK15: =AJ15-AI15 -> -2803.66 | AL15: New Business was budgeted at 2,890- we had 2,500 in new business, Thomason Tractor 1.2k under SoCal addiction 236 under(cancelled), Capital Financial 500 under, Laguna tools 400 under | AM15: 21381.66 | AN15: ='2024 Bdg vs Actual All'!AG15-'2024 Bdg vs Actual -OH'!AN15 -> 18272 | AO15: =AN15-AM15 -> -3109.66 | AP15: New Business was budgeted at 3,340- we had 2,500 in new business, Thomason Tractor 1.2k under SoCal addiction 236 under(cancelled), Capital Financial 575 under, Laguna tools 400 under, City of Firbaigh 300 over | AQ15: 21831.66 | AR15: ='2024 Bdg vs Actual All'!AK15-'2024 Bdg vs Actual -OH'!AR15 -> 18250 | AS15: =AR15-AQ15 -> -3581.66 | AT15: New Business is 1.2K under budget, lost business 2.7K, | AU15: 22281.66 | AV15: ='2024 Bdg vs Actual All'!AO15-'2024 Bdg vs Actual -OH'!AV15 -> 22059 | AW15: =AV15-AU15 -> -222.66 | AY15: 22731.66 | AZ15: ='2024 Bdg vs Actual All'!AS15-'2024 Bdg vs Actual -OH'!AZ15 -> 26554 | BA15: =AZ15-AY15 -> 3822.34 | BC15: 23181.66 | BD15: ='2024 Bdg vs Actual All'!AW15-'2024 Bdg vs Actual -OH'!BD15 -> 17924 | BE15: =BD15-BC15 -> -5257.66 | BG15: 24268.5 | BH15: ='2024 Bdg vs Actual All'!BA15-'2024 Bdg vs Actual -OH'!BH15 -> 21850 | BI15: =BH15-BG15 -> -2418.5 | CG15: =+W15+S15+O15+AA15+AE15+AI15+AM15+AQ15+AU15+AY15+BC15+BG15 -> 255795.62 | CH15: =+X15+T15+P15+AB15+AF15+AJ15+AN15+AR15+AV15+AZ15+BD15+BH15 -> 249131 | CI15: =CH15-CG15 -> -6664.6151
A16: Monthly Recurring Resale | D16: New Business + Current Agreements | E16: =ROUND(O16+S16+W16+AA16+AE16+AI16+AM16+AQ16+AU16+AY16+BC16+BG16,-2) -> 2440300 | O16: 180269.69 | P16: ='2024 Bdg vs Actual All'!I16-'2024 Bdg vs Actual -OH'!P16 -> 199323.86 | Q16: =P16-O16 -> 19054.173 | S16: 196417 | T16: ='2024 Bdg vs Actual All'!M16-'2024 Bdg vs Actual -OH'!T16 -> 196648 | U16: =T16-S16 -> 231 | W16: 178975.34 | X16: ='2024 Bdg vs Actual All'!Q16-'2024 Bdg vs Actual -OH'!X16 -> 181582 | Y16: =X16-W16 -> 2606.6588 | Z16: Agee Construction up $1200- duplicate invoice- correction in April- New customer Carmel USD | AA16: 185663.34 | AB16: ='2024 Bdg vs Actual All'!U16-'2024 Bdg vs Actual -OH'!AB16 -> 195163 | AC16: =AB16-AA16 -> 9499.6588 | AD16: Lucia Mar New Business $4k, City of Selma new agreement increase 2.7K, Catch up billing Dehart, | AE16: 194000 | AF16: ='2024 Bdg vs Actual All'!Y16-'2024 Bdg vs Actual -OH'!AF16 -> 193173 | AG16: =AF16-AE16 -> -827 | AH16: New Business was budgeted at 5850.00 and we actually had 8,738 in new business- | AI16: 206000 | AJ16: ='2024 Bdg vs Actual All'!AC16-'2024 Bdg vs Actual -OH'!AJ16 -> 198029 | AK16: =AJ16-AI16 -> -7971 | AL16: New Business was budgeted at 18,785.00, new business was 2K, City of Selma 2.7K over budget, Dehart 1.7K over budget, Graceada 2K over budget, Lucia Mar 4.9K over budget, Trumark 2K over budget, John Potter 1K under budget, Thomaston 1.5K under budget, SunnyValley 1.9K under budget | AM16: 209000 | AN16: ='2024 Bdg vs Actual All'!AG16-'2024 Bdg vs Actual -OH'!AN16 -> 199828 | AO16: =AN16-AM16 -> -9172 | AP16: New Business was budgeted at 21,700.00, new business was 2.7K,(Over Budget -City of Selma 2.7Kt, Dehart 1.8K, Graceada 1.2K, Lucia Mar 6K, Trumark 1.5K,Cranbrook 750),- (Under budget- John Potter (1K), ThomasonTractor- left(1.5K), Learning Quest-left(1.1K), and Sylvan(875)). | AQ16: 212000 | AR16: ='2024 Bdg vs Actual All'!AK16-'2024 Bdg vs Actual -OH'!AR16 -> 197654 | AS16: =AR16-AQ16 -> -14346 | AT16: New Business is 24K under budget, lost business 4K, City of Selma 2.7K over budget, Dehart 1.7K over budget, Fabricated Extrusion 1K over budget, Lucia Mar 5K over budget | AU16: 215000 | AV16: ='2024 Bdg vs Actual All'!AO16-'2024 Bdg vs Actual -OH'!AV16 -> 205177 | AW16: =AV16-AU16 -> -9823 | AY16: 218000 | AZ16: ='2024 Bdg vs Actual All'!AS16-'2024 Bdg vs Actual -OH'!AZ16 -> 212080 | BA16: =AZ16-AY16 -> -5920 | BC16: 221000 | BD16: ='2024 Bdg vs Actual All'!AW16-'2024 Bdg vs Actual -OH'!BD16 -> 212141 | BE16: =BD16-BC16 -> -8859 | BG16: 224000 | BH16: ='2024 Bdg vs Actual All'!BA16-'2024 Bdg vs Actual -OH'!BH16 -> 217770 | BI16: =BH16-BG16 -> -6230 | CG16: =+W16+S16+O16+AA16+AE16+AI16+AM16+AQ16+AU16+AY16+BC16+BG16 -> 2440325.4 | CH16: =+X16+T16+P16+AB16+AF16+AJ16+AN16+AR16+AV16+AZ16+BD16+BH16 -> 2408568.9 | CI16: =CH16-CG16 -> -31756.509
A17: IT Project Services | D17: New Business | E17: =ROUND(O17+S17+W17+AA17+AE17+AI17+AM17+AQ17+AU17+AY17+BC17+BG17,-2) -> 618900 | O17: 51754.5 | P17: ='2024 Bdg vs Actual All'!I17-'2024 Bdg vs Actual -OH'!P17 -> 27228.23 | Q17: =P17-O17 -> -24526.27 | S17: 49608 | T17: ='2024 Bdg vs Actual All'!M17-'2024 Bdg vs Actual -OH'!T17 -> 49608 | U17: =T17-S17 -> 0 | W17: 51754.5 | X17: ='2024 Bdg vs Actual All'!Q17-'2024 Bdg vs Actual -OH'!X17 -> 44366 | Y17: =X17-W17 -> -7388.5 | AA17: 51754.5 | AB17: ='2024 Bdg vs Actual All'!U17-'2024 Bdg vs Actual -OH'!AB17 -> 131293 | AC17: =AB17-AA17 -> 79538.5 | AD17: Modesto City Project completed | AE17: 51754.5 | AF17: ='2024 Bdg vs Actual All'!Y17-'2024 Bdg vs Actual -OH'!AF17 -> 148275 | AG17: =AF17-AE17 -> 96520.5 | AH17: Empire USD $50K Final Billing | AI17: 51754.5 | AJ17: ='2024 Bdg vs Actual All'!AC17-'2024 Bdg vs Actual -OH'!AJ17 -> 71950 | AK17: =AJ17-AI17 -> 20195.5 | AM17: 51754.5 | AN17: ='2024 Bdg vs Actual All'!AG17-'2024 Bdg vs Actual -OH'!AN17 -> 23582 | AO17: =AN17-AM17 -> -28172.5 | AQ17: 51754.5 | AR17: ='2024 Bdg vs Actual All'!AK17-'2024 Bdg vs Actual -OH'!AR17 -> 171887 | AS17: =AR17-AQ17 -> 120132.5 | AT17: Lucia Mar 150K | AU17: 51754.5 | AV17: ='2024 Bdg vs Actual All'!AO17-'2024 Bdg vs Actual -OH'!AV17 -> 34501 | AW17: =AV17-AU17 -> -17253.5 | AX17: See Breakdown in Project and Product Sales Sept 2024 for details | AY17: 51754.5 | AZ17: ='2024 Bdg vs Actual All'!AS17-'2024 Bdg vs Actual -OH'!AZ17 -> 41200 | BA17: =AZ17-AY17 -> -10554.5 | BB17: See Breakdown in Project and Product Sales Sept 2024 for details | BC17: 51754.5 | BD17: ='2024 Bdg vs Actual All'!AW17-'2024 Bdg vs Actual -OH'!BD17 -> 30800 | BE17: =BD17-BC17 -> -20954.5 | BG17: 51754.5 | BH17: ='2024 Bdg vs Actual All'!BA17-'2024 Bdg vs Actual -OH'!BH17 -> 33100 | BI17: =BH17-BG17 -> -18654.5 | CG17: =+W17+S17+O17+AA17+AE17+AI17+AM17+AQ17+AU17+AY17+BC17+BG17 -> 618907.5 | CH17: =+X17+T17+P17+AB17+AF17+AJ17+AN17+AR17+AV17+AZ17+BD17+BH17 -> 807790.23 | CI17: =CH17-CG17 -> 188882.73
