Workbook
Name NB_Monthly_Recurring_Private_Cloud_CA: #REF!
Name NB_Monthly_Recurring_Private_Cloud_OH: #REF!
Name NB_Monthly_Recurring_Resale_CA: #REF!
Name NB_Monthly_Recurring_Resale_OH: #REF!
Name NB_Monthly_Recurring_Services_CA: #REF!
Name NB_Monthly_Recurring_Services_OH: #REF!
Name WA_Monthly_Recurring_Private_Cloud_CA: #REF!
Name WA_Monthly_Recurring_Private_Cloud_CA: #REF!
Name WA_Monthly_Recurring_Resale_CA: #REF!
Name WA_Monthly_Recurring_Resale_CA: #REF!
Name WA_Monthly_Recurring_Resale_OH: #REF!
Name WA_Monthly_Recurring_Services_CA: #REF!
Name WA_Monthly_Recurring_Services_CA: #REF!
Name WA_Monthly_Recurring_Services_OH: #REF!

Sheet P&L MTD with Previous Month Com
A1: Datapath | I1: *Need to get figures in separate tabs
A2: P&L MTD with Previous Month Comparison
A3: Reporting Book: | C3: ACCRUAL
A4: As of Date: | C4: 10/31/2025
A5: Location group: | C5: Modesto Fresno Ohio
P6: Actual Billings/In Period Receipts Posted
C7: DP California | D7: DP California | F7: DP Ohio | G7: DP Ohio | I7: Data Path - All Locations | J7: Data Path - All Locations | L7: DP California | M7: DP Ohio | N7: Data Path - All Locations | P7: DP California | R7: DP Ohio
C8: Month Ending | D8: Month Ending | F8: Month Ending | G8: Month Ending | I8: Month Ending | J8: Month Ending | L8: Year To Date | M8: Year To Date | N8: Year To Date | P8: Month Ending | R8: Month Ending
C9: 10/31/2025 | D9: 09/30/2025 | F9: 10/31/2025 | G9: 09/30/2025 | I9: 10/31/2025 | J9: 09/30/2025 | L9: 10/31/2025 | M9: 10/31/2025 | N9: 10/31/2025 | P9: 10/31/2025 | Q9: vs. Accrual | R9: 10/31/2025 | S9: vs. Accrual | T9: Notes
D10: Actual | E10: Variance | F10: Actual | G10: Actual | H10: Variance | I10: Actual | J10: Actual | K10: Variance | L10: Actual | M10: Actual | N10: Actual
A11: Net Income- With DL above the line | B11: Net | U11: =I11
A12: Operating Net Income- DL above the line | B12: Operating | U12: =I12
A13: Gross Profit with Direct Labor | B13: Gross | U13: =I13
A14: Revenue | B14: Revenue | U14: =I14
A15: Monthly Recurring Services | B15: Monthly | U15: =I15
A16: 40000 - Managed IT Revenue | B16: 40000 | C16: 456302 | D16: 424153 | E16: 32149 | F16: 92188 | G16: 91841 | H16: 347 | I16: 548490 | J16: 515994 | K16: 32496 | L16: 4326264 | M16: 979344 | N16: 5305607 | O16: CA: Irvine pickup from Sept. (No reversal in August performed). This is for billings but not yet earned. | P16: =IFERROR(-VLOOKUP(B16,'Actual Billings'!$A$8:$C$26,3,FALSE),0) -> 458920.03 | Q16: =C16-P16 -> -2618.03 | R16: =IFERROR(-VLOOKUP(B16,'Actual Billings'!$H$8:$J$24,3,FALSE),0) -> 92188.25 | S16: =F16-R16 -> -0.25 | U16: 548490 | V16: =U16-I16 -> 0
A17: 40100 - Managed Security Revenue | B17: 40100 | C17: 4729 | D17: 5055 | E17: -326 | F17: 0 | G17: 0 | H17: 0 | I17: 4729 | J17: 5056 | K17: -326 | L17: 68993 | M17: 0 | N17: 68993 | P17: =IFERROR(-VLOOKUP(B17,'Actual Billings'!$A$8:$C$17,3,FALSE),0) -> 5055.45 | Q17: =C17-P17 -> -326.45 | R17: =IFERROR(-VLOOKUP(B17,'Actual Billings'!$H$8:$J$24,3,FALSE),0) -> 0 | S17: =F17-R17 -> 0 | U17: 4729 | V17: =U17-I17 -> 0
A18: 40200 - Managed Voice Revenue | B18: 40200 | C18: 2826 | D18: 2953 | E18: -126 | F18: 5580 | G18: 5581 | H18: 0 | I18: 8407 | J18: 8532 | K18: -126 | L18: 41808 | M18: 61056 | N18: 102865 | P18: =IFERROR(-VLOOKUP(B18,'Actual Billings'!$A$8:$C$17,3,FALSE),0) -> 2826.33 | Q18: =C18-P18 -> -0.33 | R18: =IFERROR(-VLOOKUP(B18,'Actual Billings'!$H$8:$J$24,3,FALSE),0) -> 5580.2 | S18: =F18-R18 -> -0.2 | U18: 8407 | V18: =U18-I18 -> 0
A19: 41320 - Managed Back up Revenue | B19: 41320 | C19: 8758 | D19: 8987 | E19: -230 | F19: 2800 | G19: 2734 | H19: 65 | I19: 11556 | J19: 11722 | K19: -165 | L19: 91653 | M19: 31748 | N19: 123401 | P19: =IFERROR(-VLOOKUP(B19,'Actual Billings'!$A$8:$C$17,3,FALSE),0) -> 8757.36 | Q19: =C19-P19 -> 0.64 | R19: =IFERROR(-VLOOKUP(B19,'Actual Billings'!$H$8:$J$24,3,FALSE),0) -> 2799.25 | S19: =F19-R19 -> 0.75 | U19: 11556 | V19: =U19-I19 -> 0
A20: 41925 - USAC ERATE BM Revenue | B20: 41925 | C20: 0 | D20: 0 | E20: 0 | F20: 5774 | G20: 5913 | H20: -140 | I20: 5774 | J20: 5913 | K20: -140 | L20: 0 | M20: 84373 | N20: 84373 | P20: =IFERROR(-VLOOKUP(B20,'Actual Billings'!$A$8:$C$17,3,FALSE),0) -> 0 | Q20: =C20-P20 -> 0 | R20: =IFERROR(-VLOOKUP(B20,'Actual Billings'!$H$8:$J$24,3,FALSE),0) -> 5773.93 | S20: =F20-R20 -> 0.07 | U20: 5774 | V20: =U20-I20 -> 0
A21: Monthly Recurring Services | B21: Monthly | C21: 472615 | D21: 441148 | E21: 31467 | F21: 106342 | G21: 106069 | H21: 272 | I21: 578956 | J21: 547217 | K21: 31739 | L21: 4528718 | M21: 1156521 | N21: 5685239 | U21: 578956 | V21: =U21-I21 -> 0
A22: Monthly Recurring Private Cloud | B22: Monthly | V22: =U22-I22 -> #VALUE!
A23: 41360 - Public Cloud Revenue | B23: 41360 | C23: 1144 | D23: 1144 | E23: 0 | F23: 0 | G23: 0 | H23: 0 | I23: 1144 | J23: 1144 | K23: 0 | L23: 11440 | M23: 0 | N23: 11440 | P23: =IFERROR(-VLOOKUP(B23,'Actual Billings'!$A$8:$C$26,3,FALSE),0) -> 1144 | Q23: =C23-P23 -> 0 | R23: =IFERROR(-VLOOKUP(B23,'Actual Billings'!$H$8:$J$24,3,FALSE),0) -> 0 | S23: =F23-R23 -> 0 | U23: 1144 | V23: =U23-I23 -> 0
A24: 41365 - Private Cloud Revenue | B24: 41365 | C24: 25853 | D24: 20457 | E24: 5396 | F24: 0 | G24: 0 | H24: 0 | I24: 25853 | J24: 20457 | K24: 5396 | L24: 227591 | M24: 0 | N24: 227591 | O24: CA: Irvine pickup from Sept. (No reversal in August performed). This is for billings but not yet earned. | P24: =IFERROR(-VLOOKUP(B24,'Actual Billings'!$A$8:$C$26,3,FALSE),0) -> 25853.05 | Q24: =C24-P24 -> -0.05 | R24: =IFERROR(-VLOOKUP(B24,'Actual Billings'!$H$8:$J$24,3,FALSE),0) -> 0 | S24: =F24-R24 -> 0 | U24: 25853 | V24: =U24-I24 -> 0
A25: Monthly Recurring Private Cloud | B25: Monthly | C25: 26997 | D25: 21601 | E25: 5396 | F25: 0 | G25: 0 | H25: 0 | I25: 26997 | J25: 21601 | K25: 5396 | L25: 239031 | M25: 0 | N25: 239031 | U25: 26997 | V25: =U25-I25 -> 0
A26: Monthly Recurring Resale | B26: Monthly | V26: =U26-I26 -> #VALUE!
A27: 41200 - HaaS Revenue | B27: 41200 | C27: 26074 | D27: 20854 | E27: 5220 | F27: 315 | G27: 0 | H27: 315 | I27: 26390 | J27: 20854 | K27: 5536 | L27: 247116 | M27: 315 | N27: 247431 | O27: CA: Irvine pickup from Sept. (No reversal in August performed). This is for billings but not yet earned. | P27: =IFERROR(-VLOOKUP(B27,'Actual Billings'!$A$8:$C$26,3,FALSE),0) -> 26310.81 | Q27: =C27-P27 -> -236.81 | R27: =IFERROR(-VLOOKUP(B27,'Actual Billings'!$H$8:$J$24,3,FALSE),0) -> 315 | S27: =F27-R27 -> 0 | T27: Delta of zero because recurring reversal amount = same for Sept, Oct. Sept = artificially low. | U27: 26390 | V27: =U27-I27 -> 0
A28: 41250 - Chromebook ADP Revenue | B28: 41250 | C28: 0 | D28: 0 | E28: 0 | F28: 562 | G28: 563 | H28: 0 | I28: 562 | J28: 563 | K28: 0 | L28: 0 | M28: 5625 | N28: 5625 | P28: =IFERROR(-VLOOKUP(B28,'Actual Billings'!$A$8:$C$26,3,FALSE),0) -> 0 | Q28: =C28-P28 -> 0 | R28: =IFERROR(-VLOOKUP(B28,'Actual Billings'!$H$8:$J$24,3,FALSE),0) -> 562.5 | S28: =F28-R28 -> -0.5 | U28: 562 | V28: =U28-I28 -> 0
A29: 41300 - Cloud SAAS Revenue | B29: 41300 | C29: 49508 | D29: 43551 | E29: 5957 | F29: 2011 | G29: 2065 | H29: -54 | I29: 51519 | J29: 45616 | K29: 5902 | L29: 414124 | M29: 29568 | N29: 443692 | O29: CA: Irvine pickup from Sept. (No reversal in August performed). This is for billings but not yet earned. | P29: =IFERROR(-VLOOKUP(B29,'Actual Billings'!$A$8:$C$26,3,FALSE),0) -> 49744.37 | Q29: =C29-P29 -> -236.37 | R29: =IFERROR(-VLOOKUP(B29,'Actual Billings'!$H$8:$J$24,3,FALSE),0) -> 2010.85 | S29: =F29-R29 -> 0.15 | U29: 51519 | V29: =U29-I29 -> 0
A30: 41350 - Managed Spam Filtering Revenue | B30: 41350 | C30: 899 | D30: 954 | E30: -56 | F30: 0 | G30: 0 | H30: 0 | I30: 899 | J30: 954 | K30: -55 | L30: 9128 | M30: 0 | N30: 9127 | P30: =IFERROR(-VLOOKUP(B30,'Actual Billings'!$A$8:$C$26,3,FALSE),0) -> 898.87 | Q30: =C30-P30 -> 0.13 | R30: =IFERROR(-VLOOKUP(B30,'Actual Billings'!$H$8:$J$24,3,FALSE),0) -> 0 | S30: =F30-R30 -> 0 | U30: 899 | V30: =U30-I30 -> 0
A31: 41450 - Microsoft 365 Revenue | B31: 41450 | C31: 121163 | D31: 80884 | E31: 40279 | F31: 1377 | G31: 1311 | H31: 67 | I31: 122540 | J31: 82195 | K31: 40345 | L31: 893072 | M31: 12306 | N31: 905379 | O31: CA: Increase is primarily the result of a new 365 agreement for 24 Hour Home Care, $31k, as well as $11k Irvine pickup from Sept. (No reversal in August performed). This is for billings but not yet earned. | P31: =IFERROR(-VLOOKUP(B31,'Actual Billings'!$A$8:$C$26,3,FALSE),0) -> 121329.87 | Q31: =C31-P31 -> -166.87 | R31: =IFERROR(-VLOOKUP(B31,'Actual Billings'!$H$8:$J$24,3,FALSE),0) -> 1377.37 | S31: =F31-R31 -> -0.37 | T31: 24 hour | U31: 122540 | V31: =U31-I31 -> 0
A32: 42100 - Security Resale Revenue | B32: 42100 | C32: 134500 | D32: 129956 | E32: 4544 | F32: 14214 | G32: 13409 | H32: 805 | I32: 148714 | J32: 143365 | K32: 5349 | L32: 1113719 | M32: 119114 | N32: 1232833 | O32: CA: Irvine pickup from Sept. (No reversal in August performed). This is for billings but not yet earned. | P32: =IFERROR(-VLOOKUP(B32,'Actual Billings'!$A$8:$C$26,3,FALSE),0) -> 135011.8 | Q32: =C32-P32 -> -511.8 | R32: =IFERROR(-VLOOKUP(B32,'Actual Billings'!$H$8:$J$24,3,FALSE),0) -> 14214.1 | S32: =F32-R32 -> -0.1 | T32: 149216 | U32: 148714 | V32: =U32-I32 -> 0
A33: 42200 - Tool Resale Revenue | B33: 42200 | C33: 1898 | D33: 1898 | E33: 0 | F33: 1719 | G33: 1718 | H33: 0 | I33: 3616 | J33: 3616 | K33: 0 | L33: 19291 | M33: 21465 | N33: 40756 | P33: =IFERROR(-VLOOKUP(B33,'Actual Billings'!$A$8:$C$26,3,FALSE),0) -> 1898.23 | Q33: =C33-P33 -> -0.23 | R33: =IFERROR(-VLOOKUP(B33,'Actual Billings'!$H$8:$J$24,3,FALSE),0) -> 1718.1 | S33: =F33-R33 -> 0.9 | T33: 3616 | U33: 3616 | V33: =U33-I33 -> 0
A34: 42300 - Voice Resale Revenue | B34: 42300 | C34: 1792 | D34: 1792 | E34: 0 | F34: 754 | G34: 754 | H34: 0 | I34: 2546 | J34: 2546 | K34: 0 | L34: 16127 | M34: 5468 | N34: 21594 | P34: =IFERROR(-VLOOKUP(B34,'Actual Billings'!$A$8:$C$26,3,FALSE),0) -> 1791.81 | Q34: =C34-P34 -> 0.19 | R34: =IFERROR(-VLOOKUP(B34,'Actual Billings'!$H$8:$J$24,3,FALSE),0) -> 754 | S34: =F34-R34 -> 0 | T34: 2546 | U34: 2546 | V34: =U34-I34 -> 0
A35: Monthly Recurring Resale | B35: Monthly | C35: 335834 | D35: 279889 | E35: 55944 | F35: 20952 | G35: 19820 | H35: 1133 | I35: 356786 | J35: 299709 | K35: 57077 | L35: 2712577 | M35: 193861 | N35: 2906437 | T35: 357732 | U35: 356786 | V35: =U35-I35 -> 0
A36: Project Services | B36: Project | V36: =U36-I36 -> #VALUE!
A37: 41500 - Project Service Revenue | B37: 41500 | C37: 51320 | D37: 24527 | E37: 26794 | F37: 16234 | G37: 21545 | H37: -5311 | I37: 67554 | J37: 46071 | K37: 21483 | L37: 511189 | M37: 277231 | N37: 788421 | O37: CA: Increase primarily driven by the following: $11.2k Sconsa Candy -Storage Refresh project in October, no projects in September $7.4k Graceada Ptnrs. -2 projects closed in October -Enforce 2FA and Password Management Solutions no projects in September $6.4k DiMare-Site Moved completed in October, no projects in September - put on hold couple times by customer $6.2k Oliveira Wealth-Workstation Configuration & Set up project in October, no projects in September $4k Cranbrook Group-Oakland Server Restoration & SharePoint Migration project in October, no projects in September Partially offset by: ($11k) decrease City of Firebaugh-Switching Refresh project in September , no projects in October OH: Decrease primarily driven by the following: $11k Vital Care, USAC, River Gate HS, partially offset by ($5.9k) Imagine Great Western-no October business. | P37: =IFERROR(-VLOOKUP(B37,'Actual Billings'!$A$8:$C$26,3,FALSE),0) -> 46520 | Q37: =C37-P37 -> 4800 | R37: =IFERROR(-VLOOKUP(B37,'Actual Billings'!$H$8:$J$24,3,FALSE),0) -> 22171 | S37: =F37-R37 -> -5937 | T37: Also bring in Customer level variance analysis tab | U37: 67554 | V37: =U37-I37 -> 0
A38: Revenue - Project Services | B38: Revenue | C38: 51320 | D38: 24527 | E38: 26794 | F38: 16234 | G38: 21545 | H38: -5311 | I38: 67554 | J38: 46071 | K38: 21483 | L38: 511189 | M38: 277231 | N38: 788421 | U38: 67554 | V38: =U38-I38 -> 0
A39: Subcontracted Services | B39: Subcontracted | V39: =U39-I39 -> #VALUE!
A40: 41700 - Subcontracted Service Revenue | B40: 41700 | C40: 10863 | D40: 7030 | E40: 3832 | F40: 9125 | G40: 7449 | H40: 1677 | I40: 19989 | J40: 14480 | K40: 5509 | L40: 251649 | M40: 50731 | N40: 302380 | O40: See tab 41700-50500 | P40: =IFERROR(-VLOOKUP(B40,'Actual Billings'!$A$8:$C$26,3,FALSE),0) -> 10863.16 | Q40: =C40-P40 -> -0.16 | R40: =IFERROR(-VLOOKUP(B40,'Actual Billings'!$H$8:$J$24,3,FALSE),0) -> 9125.8 | S40: =F40-R40 -> -0.8 | U40: 19989 | V40: =U40-I40 -> 0
...

Sheet Payroll Breakdown - October
A1: August Payroll Breakdown | F1: P&L | H1: Payoll Cost | I1: Differences | J1: Notes
F2: IT Project Labor | G2: 55387 | H2: =ROUND(+H13,0) -> 57904 | I2: =+G2-H2 -> -2517
F3: Direct Labor | G3: 210696 | H3: =ROUND(+H50,0) -> 208629 | I3: =+G3-H3 -> 2067
A4: Dismissed | F4: Sales (includes commissions) | G4: 147904 | H4: =ROUND(+H64,0) -> 131474 | I4: =+G4-H4 -> 16430 | J4: CC transactions
A5: New Hires | F5: Admin | G5: 75369 | H5: =ROUND(+H76,0) -> 72670 | I5: =+G5-H5 -> 2699 | J5: Stop loss
A7: Last Day | B7: New Hire First Day | C7: Last Name | D7: First Name | E7: Full Name | F7: Department | G7: Financial Statement category | H7: Payroll Cost | I7: One time Payouts | J7: After- Hours On Call and Overtime | K7: Monthly Base Cost | L7: September Monthly Base Estimated | M7: Diff | N7: Commissions Current Month | O7: Commissions Previous Month | P7: Difference | Q7: Notes
C8: Bruce | D8: James | E8: James Bruce | F8: West Coast - Engineering | G8: 1-IT Project Labor | H8: 10476.994 | K8: =+H8-I8-J8 -> 10476.994 | L8: 10021.473 | M8: =+K8-L8 -> 455.52138
C9: Lampe | D9: Matthew | E9: Matthew Lampe | F9: West Coast - Engineering | G9: 1-IT Project Labor | H9: 8861.7975 | K9: =+H9-I9-J9 -> 8861.7975 | L9: 8476.5067 | M9: =+K9-L9 -> 385.29085
C10: Newson | D10: Keith | E10: Keith Newson | F10: West Coast - Engineering | G10: 1-IT Project Labor | H10: 11954.575 | K10: =+H10-I10-J10 -> 11954.575 | L10: 11434.835 | M10: =+K10-L10 -> 519.74008
C11: Walski | D11: Stephen | E11: Stephen Walski | F11: West Coast - Service Delivery | G11: 1-IT Project Labor | H11: 14940.796 | K11: =+H11-I11-J11 -> 14940.796 | L11: 14291.239 | M11: =+K11-L11 -> 649.557
C12: Gilmore | D12: Christopher | E12: Christopher Gilmore | F12: West Cost-Fresno Engineering | G12: 1-IT Project Labor | H12: 11669.737 | K12: =+H12-I12-J12 -> 11669.737 | L12: 11162.338 | M12: =+K12-L12 -> 507.39915
G13: 1-IT Project Labor Total | H13: =SUM(H8:H12) -> 57903.9 | I13: =SUM(I8:I12) -> 0 | J13: =SUM(J8:J12) -> 0 | K13: =SUM(K8:K12) -> 57903.9 | L13: =+SUM(L8:L12) -> 55386.392 | M13: =+K13-L13 -> 2517.5085 | Q13: =+M13/K13 -> 0.043477355
C14: Annabel | D14: Peter | E14: Peter Annabel | F14: Cloud Services | G14: 2-Direct Labor | H14: 12204.655 | K14: =+J14+I14+H14 -> 12204.655 | L14: 11674.037 | M14: =+K14-L14 -> 530.61846
C15: Barr | D15: Kevin | E15: Kevin Barr | F15: East Coast - Installation Services | G15: 2-Direct Labor | H15: 5566.2061 | K15: =+J15+I15+H15 -> 5566.2061 | L15: 5324.1974 | M15: =+K15-L15 -> 242.00869
C16: Bates | D16: Colin | E16: Colin Bates | F16: West Coast - Service Delivery | G16: 2-Direct Labor | H16: 2794.836 | K16: =+J16+I16+H16 -> 2794.836 | L16: 1908.104 | M16: =+K16-L16 -> 886.732 | Q16: Lower number of hours each payroll
C17: Blair | D17: Joshua | E17: Joshua Blair | F17: West Coast - Service Delivery | G17: 2-Direct Labor | H17: 1344.78 | K17: =+J17+I17+H17 -> 1344.78 | L17: 4379.028 | M17: =+K17-L17 -> -3034.248
A18: 45925 | C18: Brennan | D18: Thomas | E18: Thomas Brennan | F18: West Coast - Service Delivery | G18: 2-Direct Labor | H18: 2669.72 | K18: =+J18+I18+H18 -> 2669.72 | L18: 5498.33 | M18: =+K18-L18 -> -2828.61
C19: Brinovec | D19: Matthew | E19: Matthew Brinovec | F19: East Coast - Service Desk | G19: 2-Direct Labor | H19: 7755.0722 | K19: =+J19+I19+H19 -> 7755.0722 | L19: 7417.8848 | M19: =+K19-L19 -> 337.18738
C20: Chavez Soto | D20: Cristina | E20: Cristina Chavez Soto | F20: West Coast - Service Delivery | G20: 2-Direct Labor | H20: 5678.355 | K20: =+J20+I20+H20 -> 5678.355 | L20: 5115.1 | M20: =+K20-L20 -> 563.255
C21: Conkle | D21: Kerr | E21: Kerr Conkle | F21: East Coast - Service Desk | G21: 2-Direct Labor | H21: 8651.9532 | K21: =+J21+I21+H21 -> 8651.9532 | L21: 8275.7572 | M21: =+K21-L21 -> 376.19608
C22: Contreras | D22: Angela | E22: Angela Contreras | F22: West Coast - Service Delivery | G22: 2-Direct Labor | H22: 8122.963 | K22: =+J22+I22+H22 -> 8122.963 | L22: 7565.472 | M22: =+K22-L22 -> 557.491
C23: Contreras | D23: Oscar | E23: Oscar Contreras | F23: West Coast - Service Delivery | G23: 2-Direct Labor | H23: 4454.091 | K23: =+J23+I23+H23 -> 4454.091 | L23: 6111.799 | M23: =+K23-L23 -> -1657.708
B24: 45922 | C24: Darmstandler | D24: Hudson | E24: Hudson Darmstandler | F24: West Coast - Service Delivery | G24: 2-Direct Labor | H24: 3397.9 | K24: =+J24+I24+H24 -> 3397.9
C25: Dean | D25: Sam | E25: Sam Dean | F25: East Coast - Service Desk | G25: 2-Direct Labor | H25: 6809.689 | K25: =+J25+I25+H25 -> 6809.689 | L25: 6684.366 | M25: =+K25-L25 -> 125.323
C26: Dimson | D26: Hoover | E26: Hoover Dimson | F26: West Coast - Service Delivery | G26: 2-Direct Labor | H26: 1265.44 | K26: =+J26+I26+H26 -> 1265.44 | L26: 1218.71 | M26: =+K26-L26 -> 46.73
C27: Doyle | D27: William | E27: William Doyle | F27: West Coast - Service Delivery | G27: 2-Direct Labor | H27: 8698.385 | K27: =+J27+I27+H27 -> 8698.385 | L27: 6935.78 | M27: =+K27-L27 -> 1762.605
C28: Dupray | D28: Nathaniel | E28: Nathaniel Dupray | F28: East Coast - Service Desk | G28: 2-Direct Labor | H28: 5696.815 | K28: =+J28+I28+H28 -> 5696.815 | L28: 5564.28 | M28: =+K28-L28 -> 132.535
C29: Espinoza | D29: Gabriel | E29: Gabriel Espinoza | F29: West Coast - Service Delivery | G29: 2-Direct Labor | H29: 9442.185 | K29: =+J29+I29+H29 -> 9442.185 | L29: 6603.77 | M29: =+K29-L29 -> 2838.415
C30: Fajardo | D30: Franz Aram | E30: Franz Aram Fajardo | F30: West Coast - Service Delivery | G30: 2-Direct Labor | H30: 1039.8 | K30: =+J30+I30+H30 -> 1039.8 | L30: 1665.3 | M30: =+K30-L30 -> -625.5
C31: Hughes | D31: Michael | E31: Michael Hughes | F31: West Coast - Service Delivery | G31: 2-Direct Labor | H31: 6626.784 | K31: =+J31+I31+H31 -> 6626.784 | L31: 6092.471 | M31: =+K31-L31 -> 534.313
A32: 45926 | C32: Huizar | D32: Luis | E32: Luis Huizar | F32: West Coast - Service Delivery | G32: 2-Direct Labor | H32: -2083.957 | K32: =+J32+I32+H32 -> -2083.957 | L32: 8272.229 | M32: =+K32-L32 -> -10356.186
C33: Hulsey-Cedeno | D33: Brandon | E33: Brandon Hulsey-Cedeno | F33: West Coast - Service Delivery | G33: 2-Direct Labor | H33: 6006.198 | K33: =+J33+I33+H33 -> 6006.198 | L33: 4800.202 | M33: =+K33-L33 -> 1205.996
C34: Johnson | D34: Brandon | E34: Brandon Johnson | F34: West Coast - Service Delivery | G34: 2-Direct Labor | H34: 11503.135 | K34: =+J34+I34+H34 -> 11503.135 | L34: 11002.965 | M34: =+K34-L34 -> 500.16992
C35: Keim | D35: Colton | E35: Colton Keim | F35: East Coast - Service Desk | G35: 2-Direct Labor | H35: 6853.913 | K35: =+J35+I35+H35 -> 6853.913 | L35: 5542.592 | M35: =+K35-L35 -> 1311.321
C36: Lanning | D36: Nathan | E36: Nathan Lanning | F36: East Coast - Field Engineering | G36: 2-Direct Labor | H36: 9312.9098 | K36: =+J36+I36+H36 -> 9312.9098 | L36: 8908.0198 | M36: =+K36-L36 -> 404.88992
C37: Magcalayo | D37: Jenny Rose | E37: Jenny Rose Magcalayo | F37: West Coast - Service Delivery | G37: 2-Direct Labor | H37: 1322.96 | K37: =+J37+I37+H37 -> 1322.96
C38: Matuszynski | D38: Cole | E38: Cole Matuszynski | F38: East Coast - Service Desk | G38: 2-Direct Labor | H38: 2327.989 | K38: =+J38+I38+H38 -> 2327.989 | L38: 3738.606 | M38: =+K38-L38 -> -1410.617
C39: Mercer | D39: Mark | E39: Mark Mercer | F39: West Coast-Fresno Service | G39: 2-Direct Labor | H39: 7335.503 | K39: =+J39+I39+H39 -> 7335.503 | L39: 6633.957 | M39: =+K39-L39 -> 701.546
C40: Morozov | D40: Steve | E40: Steve Morozov | F40: West Coast - Service Delivery | G40: 2-Direct Labor | H40: 5527.16 | K40: =+J40+I40+H40 -> 5527.16 | L40: 4939.66 | M40: =+K40-L40 -> 587.5
C41: Pena | D41: Luis | E41: Luis Pena | F41: West Coast - Service Delivery | G41: 2-Direct Labor | H41: 8710.102 | K41: =+J41+I41+H41 -> 8710.102 | L41: 6475.793 | M41: =+K41-L41 -> 2234.309
...

Sheet Oct Agreement Compare OH
A1: Location | B1: Customer | C1: Agreement Type | D1: Agreement Name | E1: Invoice Number | F1: Invoice Date | G1: October Financials | H1: October Revenue | I1: September Clawback | J1: September Financials | K1: Difference October - September | L1: % Change | M1: Notes
B2: Albert Einstein Academy of Ohio | C2: Recurring Resale - MSP | D2: Recurring Resale - MSP 25/26 | E2: 180446OH | F2: 45931 | G2: 112.5 | H2: =+G2 -> 112.5 | J2: =SUMIFS('[1]Sept-August Comp OH'!$G$2:$G$154,'[1]Sept-August Comp OH'!$B$2:$B$154,'Oct Agreement Compare OH'!B2,'[1]Sept-August Comp OH'!$C$2:$C$154,'Oct Agreement Compare OH'!C2,'[1]Sept-August Comp OH'!$D$2:$D$154,'Oct Agreement Compare OH'!D2) -> 112.5 | K2: =+G2-J2 -> 0 | L2: =IFERROR(K2/J2,1) -> 0
B3: Albert Einstein Academy of Ohio | C3: T-Services-MSP | D3: T-Services-MSP | E3: 180446OH | F3: 45931 | G3: 2842.2 | H3: =+G3 -> 2842.2 | J3: =SUMIFS('[1]Sept-August Comp OH'!$G$2:$G$154,'[1]Sept-August Comp OH'!$B$2:$B$154,'Oct Agreement Compare OH'!B3,'[1]Sept-August Comp OH'!$C$2:$C$154,'Oct Agreement Compare OH'!C3,'[1]Sept-August Comp OH'!$D$2:$D$154,'Oct Agreement Compare OH'!D3) -> 2842.2 | K3: =+G3-J3 -> 0 | L3: =IFERROR(K3/J3,1) -> 0
B4: Albert Einstein Academy of Ohio Total | G4: =SUBTOTAL(9,G2:G3) -> 2954.7 | H4: =SUBTOTAL(9,H2:H3) -> 2954.7 | I4: =SUBTOTAL(9,I2:I3) -> 0 | J4: =SUBTOTAL(9,J2:J3) -> 2954.7
B5: Arcanum Butler Local School District | C5: T-Services-MSP | D5: T-Services-MSP | E5: 180447OH | F5: 45931 | G5: 1161 | H5: =+G5 -> 1161 | J5: =SUMIFS('[1]Sept-August Comp OH'!$G$2:$G$154,'[1]Sept-August Comp OH'!$B$2:$B$154,'Oct Agreement Compare OH'!B5,'[1]Sept-August Comp OH'!$C$2:$C$154,'Oct Agreement Compare OH'!C5,'[1]Sept-August Comp OH'!$D$2:$D$154,'Oct Agreement Compare OH'!D5) -> 1161 | K5: =+G5-J5 -> 0 | L5: =IFERROR(K5/J5,1) -> 0
B6: Arcanum Butler Local School District Total | G6: =SUBTOTAL(9,G5:G5) -> 1161 | H6: =SUBTOTAL(9,H5:H5) -> 1161 | I6: =SUBTOTAL(9,I5:I5) -> 0 | J6: =SUBTOTAL(9,J5:J5) -> 1161
B7: Arts and College Preparatory Academy | C7: Erate-MIBS-School Percentage | D7: Erate-MIBS-School Percentage 25/26 | E7: 180448OH | F7: 45931 | G7: 111.5 | H7: =+G7 -> 111.5 | J7: =SUMIFS('[1]Sept-August Comp OH'!$G$2:$G$154,'[1]Sept-August Comp OH'!$B$2:$B$154,'Oct Agreement Compare OH'!B7,'[1]Sept-August Comp OH'!$C$2:$C$154,'Oct Agreement Compare OH'!C7,'[1]Sept-August Comp OH'!$D$2:$D$154,'Oct Agreement Compare OH'!D7) -> 111.5 | K7: =+G7-J7 -> 0 | L7: =IFERROR(K7/J7,1) -> 0
B8: Arts and College Preparatory Academy | C8: Recurring Resale - MSP | D8: Recurring Resale - MSP 2025 | E8: 180449OH | F8: 45931 | G8: 280 | H8: =+G8 -> 280 | J8: =SUMIFS('[1]Sept-August Comp OH'!$G$2:$G$154,'[1]Sept-August Comp OH'!$B$2:$B$154,'Oct Agreement Compare OH'!B8,'[1]Sept-August Comp OH'!$C$2:$C$154,'Oct Agreement Compare OH'!C8,'[1]Sept-August Comp OH'!$D$2:$D$154,'Oct Agreement Compare OH'!D8) -> 280 | K8: =+G8-J8 -> 0 | L8: =IFERROR(K8/J8,1) -> 0
B9: Arts and College Preparatory Academy | C9: Recurring Resale - Security | D9: Recurring Resale - Security 2025 | E9: 180449OH | F9: 45931 | G9: 35 | H9: =+G9 -> 35 | J9: =SUMIFS('[1]Sept-August Comp OH'!$G$2:$G$154,'[1]Sept-August Comp OH'!$B$2:$B$154,'Oct Agreement Compare OH'!B9,'[1]Sept-August Comp OH'!$C$2:$C$154,'Oct Agreement Compare OH'!C9,'[1]Sept-August Comp OH'!$D$2:$D$154,'Oct Agreement Compare OH'!D9) -> 35 | K9: =+G9-J9 -> 0 | L9: =IFERROR(K9/J9,1) -> 0
B10: Arts and College Preparatory Academy | C10: T-Erate-MIBS-USAC Percentage | D10: T-Erate-MIBS-USAC Percentage 25/26 | E10: 180426OH | F10: 45932 | G10: 446 | H10: =+G10 -> 446 | J10: =SUMIFS('[1]Sept-August Comp OH'!$G$2:$G$154,'[1]Sept-August Comp OH'!$B$2:$B$154,'Oct Agreement Compare OH'!B10,'[1]Sept-August Comp OH'!$C$2:$C$154,'Oct Agreement Compare OH'!C10,'[1]Sept-August Comp OH'!$D$2:$D$154,'Oct Agreement Compare OH'!D10) -> 446 | K10: =+G10-J10 -> 0 | L10: =IFERROR(K10/J10,1) -> 0
B11: Arts and College Preparatory Academy | C11: T-Services-MSP | D11: T-Services-MSP 2025-Evergreen | E11: 180449OH | F11: 45931 | G11: 2658 | H11: =+G11 -> 2658 | J11: =SUMIFS('[1]Sept-August Comp OH'!$G$2:$G$154,'[1]Sept-August Comp OH'!$B$2:$B$154,'Oct Agreement Compare OH'!B11,'[1]Sept-August Comp OH'!$C$2:$C$154,'Oct Agreement Compare OH'!C11,'[1]Sept-August Comp OH'!$D$2:$D$154,'Oct Agreement Compare OH'!D11) -> 2658 | K11: =+G11-J11 -> 0 | L11: =IFERROR(K11/J11,1) -> 0
B12: Arts and College Preparatory Academy Total | G12: =SUBTOTAL(9,G7:G11) -> 3530.5 | H12: =SUBTOTAL(9,H7:H11) -> 3530.5 | I12: =SUBTOTAL(9,I7:I11) -> 0 | J12: =SUBTOTAL(9,J7:J11) -> 3530.5
B13: Caldwell Exempted Village | C13: Erate-MIBS-School Percentage | D13: Erate-MIBS-School Percentage | E13: 180450OH | F13: 45931 | G13: 288.6 | H13: =+G13 -> 288.6 | J13: =SUMIFS('[1]Sept-August Comp OH'!$G$2:$G$154,'[1]Sept-August Comp OH'!$B$2:$B$154,'Oct Agreement Compare OH'!B13,'[1]Sept-August Comp OH'!$C$2:$C$154,'Oct Agreement Compare OH'!C13,'[1]Sept-August Comp OH'!$D$2:$D$154,'Oct Agreement Compare OH'!D13) -> 288.6 | K13: =+G13-J13 -> 0 | L13: =IFERROR(K13/J13,1) -> 0
B14: Caldwell Exempted Village | C14: T-Erate-MIBS-USAC Percentage | D14: T-Erate-MIBS-USAC Percentage 25/26 | E14: 180427OH | F14: 45932 | G14: 673.4 | H14: =+G14 -> 673.4 | J14: =SUMIFS('[1]Sept-August Comp OH'!$G$2:$G$154,'[1]Sept-August Comp OH'!$B$2:$B$154,'Oct Agreement Compare OH'!B14,'[1]Sept-August Comp OH'!$C$2:$C$154,'Oct Agreement Compare OH'!C14,'[1]Sept-August Comp OH'!$D$2:$D$154,'Oct Agreement Compare OH'!D14) -> 673.4 | K14: =+G14-J14 -> 0 | L14: =IFERROR(K14/J14,1) -> 0
B15: Caldwell Exempted Village | C15: T-Services-MSP | D15: T-Services-MSP 2025 Camera | E15: 180451OH | F15: 45931 | G15: 1058 | H15: =+G15 -> 1058 | J15: =SUMIFS('[1]Sept-August Comp OH'!$G$2:$G$154,'[1]Sept-August Comp OH'!$B$2:$B$154,'Oct Agreement Compare OH'!B15,'[1]Sept-August Comp OH'!$C$2:$C$154,'Oct Agreement Compare OH'!C15,'[1]Sept-August Comp OH'!$D$2:$D$154,'Oct Agreement Compare OH'!D15) -> 1058 | K15: =+G15-J15 -> 0 | L15: =IFERROR(K15/J15,1) -> 0
B16: Caldwell Exempted Village | C16: T-Services-MSP | D16: T-Services-MSP VoIP | E16: 180452OH | F16: 45931 | G16: 530 | H16: =+G16 -> 530 | J16: =SUMIFS('[1]Sept-August Comp OH'!$G$2:$G$154,'[1]Sept-August Comp OH'!$B$2:$B$154,'Oct Agreement Compare OH'!B16,'[1]Sept-August Comp OH'!$C$2:$C$154,'Oct Agreement Compare OH'!C16,'[1]Sept-August Comp OH'!$D$2:$D$154,'Oct Agreement Compare OH'!D16) -> 530 | K16: =+G16-J16 -> 0 | L16: =IFERROR(K16/J16,1) -> 0
B17: Caldwell Exempted Village Total | G17: =SUBTOTAL(9,G13:G16) -> 2550 | H17: =SUBTOTAL(9,H13:H16) -> 2550 | I17: =SUBTOTAL(9,I13:I16) -> 0 | J17: =SUBTOTAL(9,J13:J16) -> 2550
B18: City Day Community School | C18: Erate-MIBS-School Percentage | D18: Erate-MIBS-School Percentage 25/26 | E18: 180454OH | F18: 45931 | G18: 40.1 | H18: =+G18 -> 40.1 | J18: =SUMIFS('[1]Sept-August Comp OH'!$G$2:$G$154,'[1]Sept-August Comp OH'!$B$2:$B$154,'Oct Agreement Compare OH'!B18,'[1]Sept-August Comp OH'!$C$2:$C$154,'Oct Agreement Compare OH'!C18,'[1]Sept-August Comp OH'!$D$2:$D$154,'Oct Agreement Compare OH'!D18) -> 40.1 | K18: =+G18-J18 -> 0 | L18: =IFERROR(K18/J18,1) -> 0
B19: City Day Community School | C19: Recurring Resale - MSP | D19: Recurring Resale - MSP 2024/27 | E19: 180453OH | F19: 45931 | G19: 272.44 | H19: =+G19 -> 272.44 | J19: =SUMIFS('[1]Sept-August Comp OH'!$G$2:$G$154,'[1]Sept-August Comp OH'!$B$2:$B$154,'Oct Agreement Compare OH'!B19,'[1]Sept-August Comp OH'!$C$2:$C$154,'Oct Agreement Compare OH'!C19,'[1]Sept-August Comp OH'!$D$2:$D$154,'Oct Agreement Compare OH'!D19) -> 272.44 | K19: =+G19-J19 -> 0 | L19: =IFERROR(K19/J19,1) -> 0
B20: City Day Community School | C20: Recurring Resale - Security | D20: Recurring Resale - Security 2024/27 | E20: 180453OH | F20: 45931 | G20: 217 | H20: =+G20 -> 217 | J20: =SUMIFS('[1]Sept-August Comp OH'!$G$2:$G$154,'[1]Sept-August Comp OH'!$B$2:$B$154,'Oct Agreement Compare OH'!B20,'[1]Sept-August Comp OH'!$C$2:$C$154,'Oct Agreement Compare OH'!C20,'[1]Sept-August Comp OH'!$D$2:$D$154,'Oct Agreement Compare OH'!D20) -> 217 | K20: =+G20-J20 -> 0 | L20: =IFERROR(K20/J20,1) -> 0
B21: City Day Community School | C21: T-Erate-MIBS-USAC Percentage | D21: T-Erate-MIBS-USAC Percentage 25/26 | E21: 180428OH | F21: 45932 | G21: 227.23 | H21: =+G21 -> 227.23 | J21: =SUMIFS('[1]Sept-August Comp OH'!$G$2:$G$154,'[1]Sept-August Comp OH'!$B$2:$B$154,'Oct Agreement Compare OH'!B21,'[1]Sept-August Comp OH'!$C$2:$C$154,'Oct Agreement Compare OH'!C21,'[1]Sept-August Comp OH'!$D$2:$D$154,'Oct Agreement Compare OH'!D21) -> 227.23 | K21: =+G21-J21 -> 0 | L21: =IFERROR(K21/J21,1) -> 0
B22: City Day Community School | C22: T-Services-MSP | D22: Managed Services 2024/27 | E22: 180453OH | F22: 45931 | G22: 2240.53 | H22: =+G22 -> 2240.53 | J22: =SUMIFS('[1]Sept-August Comp OH'!$G$2:$G$154,'[1]Sept-August Comp OH'!$B$2:$B$154,'Oct Agreement Compare OH'!B22,'[1]Sept-August Comp OH'!$C$2:$C$154,'Oct Agreement Compare OH'!C22,'[1]Sept-August Comp OH'!$D$2:$D$154,'Oct Agreement Compare OH'!D22) -> 2240.53 | K22: =+G22-J22 -> 0 | L22: =IFERROR(K22/J22,1) -> 0
B23: City Day Community School Total | G23: =SUBTOTAL(9,G18:G22) -> 2997.3 | H23: =SUBTOTAL(9,H18:H22) -> 2997.3 | I23: =SUBTOTAL(9,I18:I22) -> 0 | J23: =SUBTOTAL(9,J18:J22) -> 2997.3
B24: Columbus Preparatory Academy | C24: Recurring Resale - Microsoft 365 NCE | D24: Microsoft 365 | E24: 180455OH | F24: 45931 | G24: 67.1 | H24: =+G24 -> 67.1 | J24: =SUMIFS('[1]Sept-August Comp OH'!$G$2:$G$154,'[1]Sept-August Comp OH'!$B$2:$B$154,'Oct Agreement Compare OH'!B24,'[1]Sept-August Comp OH'!$C$2:$C$154,'Oct Agreement Compare OH'!C24,'[1]Sept-August Comp OH'!$D$2:$D$154,'Oct Agreement Compare OH'!D24) -> 67.1 | K24: =+G24-J24 -> 0 | L24: =IFERROR(K24/J24,1) -> 0
B25: Columbus Preparatory Academy Total | G25: =SUBTOTAL(9,G24:G24) -> 67.1 | H25: =SUBTOTAL(9,H24:H24) -> 67.1 | I25: =SUBTOTAL(9,I24:I24) -> 0 | J25: =SUBTOTAL(9,J24:J24) -> 67.1
B26: Cristo Rey High School | C26: Erate-MIBS-School Percentage | D26: Erate-MIBS-School Percentage 25/26 | E26: 180456OH | F26: 45931 | G26: 39.79 | H26: =+G26 -> 39.79 | J26: =SUMIFS('[1]Sept-August Comp OH'!$G$2:$G$154,'[1]Sept-August Comp OH'!$B$2:$B$154,'Oct Agreement Compare OH'!B26,'[1]Sept-August Comp OH'!$C$2:$C$154,'Oct Agreement Compare OH'!C26,'[1]Sept-August Comp OH'!$D$2:$D$154,'Oct Agreement Compare OH'!D26) -> 39.79 | K26: =+G26-J26 -> 0 | L26: =IFERROR(K26/J26,1) -> 0
B27: Cristo Rey High School | C27: Recurring Resale - MSP | D27: Recurring Resale - MSP 25/26 | E27: 180459OH | F27: 45931 | G27: 116.14 | H27: =+G27 -> 116.14 | J27: =SUMIFS('[1]Sept-August Comp OH'!$G$2:$G$154,'[1]Sept-August Comp OH'!$B$2:$B$154,'Oct Agreement Compare OH'!B27,'[1]Sept-August Comp OH'!$C$2:$C$154,'Oct Agreement Compare OH'!C27,'[1]Sept-August Comp OH'!$D$2:$D$154,'Oct Agreement Compare OH'!D27) -> 116.14 | K27: =+G27-J27 -> 0 | L27: =IFERROR(K27/J27,1) -> 0
B28: Cristo Rey High School | C28: Recurring Resale - Security | D28: Recurring Resale - Security 25/26 | E28: 180459OH | F28: 45931 | G28: 3489 | H28: =+G28 -> 3489 | J28: =SUMIFS('[1]Sept-August Comp OH'!$G$2:$G$154,'[1]Sept-August Comp OH'!$B$2:$B$154,'Oct Agreement Compare OH'!B28,'[1]Sept-August Comp OH'!$C$2:$C$154,'Oct Agreement Compare OH'!C28,'[1]Sept-August Comp OH'!$D$2:$D$154,'Oct Agreement Compare OH'!D28) -> 2968 | K28: =+G28-J28 -> 521 | L28: =IFERROR(K28/J28,1) -> 0.17553908
B29: Cristo Rey High School | C29: T-Erate-MIBS-USAC Percentage | D29: T-Erate-MIBS-USAC Percentage 25/26 | E29: 180429OH | F29: 45932 | G29: 225.41 | H29: =+G29 -> 225.41 | J29: =SUMIFS('[1]Sept-August Comp OH'!$G$2:$G$154,'[1]Sept-August Comp OH'!$B$2:$B$154,'Oct Agreement Compare OH'!B29,'[1]Sept-August Comp OH'!$C$2:$C$154,'Oct Agreement Compare OH'!C29,'[1]Sept-August Comp OH'!$D$2:$D$154,'Oct Agreement Compare OH'!D29) -> 225.41 | K29: =+G29-J29 -> 0 | L29: =IFERROR(K29/J29,1) -> 0
B30: Cristo Rey High School | C30: T-Services-MSP | D30: 2018/2026 VOIP | E30: 180457OH | F30: 45931 | G30: 379.5 | H30: =+G30 -> 379.5 | J30: =SUMIFS('[1]Sept-August Comp OH'!$G$2:$G$154,'[1]Sept-August Comp OH'!$B$2:$B$154,'Oct Agreement Compare OH'!B30,'[1]Sept-August Comp OH'!$C$2:$C$154,'Oct Agreement Compare OH'!C30,'[1]Sept-August Comp OH'!$D$2:$D$154,'Oct Agreement Compare OH'!D30) -> 379.5 | K30: =+G30-J30 -> 0 | L30: =IFERROR(K30/J30,1) -> 0
B31: Cristo Rey High School | C31: T-Services-MSP | D31: T-Services-MSP - Student Device Support 25/26 | E31: 180458OH | F31: 45931 | G31: 4416.67 | H31: =+G31 -> 4416.67 | J31: =SUMIFS('[1]Sept-August Comp OH'!$G$2:$G$154,'[1]Sept-August Comp OH'!$B$2:$B$154,'Oct Agreement Compare OH'!B31,'[1]Sept-August Comp OH'!$C$2:$C$154,'Oct Agreement Compare OH'!C31,'[1]Sept-August Comp OH'!$D$2:$D$154,'Oct Agreement Compare OH'!D31) -> 4416.67 | K31: =+G31-J31 -> 0 | L31: =IFERROR(K31/J31,1) -> 0
B32: Cristo Rey High School | C32: T-Services-MSP | D32: T-Services-MSP 25/26 | E32: 180459OH | F32: 45931 | G32: 4533.7 | H32: =+G32 -> 4533.7 | J32: =SUMIFS('[1]Sept-August Comp OH'!$G$2:$G$154,'[1]Sept-August Comp OH'!$B$2:$B$154,'Oct Agreement Compare OH'!B32,'[1]Sept-August Comp OH'!$C$2:$C$154,'Oct Agreement Compare OH'!C32,'[1]Sept-August Comp OH'!$D$2:$D$154,'Oct Agreement Compare OH'!D32) -> 4533.7 | K32: =+G32-J32 -> 0 | L32: =IFERROR(K32/J32,1) -> 0
B33: Cristo Rey High School Total | G33: =SUBTOTAL(9,G26:G32) -> 13200.21 | H33: =SUBTOTAL(9,H26:H32) -> 13200.21 | I33: =SUBTOTAL(9,I26:I32) -> 0 | J33: =SUBTOTAL(9,J26:J32) -> 12679.21
B34: Dayton SMART Elementary | C34: Recurring Resale - Security | D34: Recurring Resale - Security 25/26 | E34: 180460OH | F34: 45931 | G34: 105 | H34: =+G34 -> 105 | J34: =SUMIFS('[1]Sept-August Comp OH'!$G$2:$G$154,'[1]Sept-August Comp OH'!$B$2:$B$154,'Oct Agreement Compare OH'!B34,'[1]Sept-August Comp OH'!$C$2:$C$154,'Oct Agreement Compare OH'!C34,'[1]Sept-August Comp OH'!$D$2:$D$154,'Oct Agreement Compare OH'!D34) -> 91 | K34: =+G34-J34 -> 14 | L34: =IFERROR(K34/J34,1) -> 0.15384615
B35: Dayton SMART Elementary | C35: T-Services-MSP | D35: T-Services-MSP 25/26 | E35: 180460OH | F35: 45931 | G35: 1608 | H35: =+G35 -> 1608 | J35: =SUMIFS('[1]Sept-August Comp OH'!$G$2:$G$154,'[1]Sept-August Comp OH'!$B$2:$B$154,'Oct Agreement Compare OH'!B35,'[1]Sept-August Comp OH'!$C$2:$C$154,'Oct Agreement Compare OH'!C35,'[1]Sept-August Comp OH'!$D$2:$D$154,'Oct Agreement Compare OH'!D35) -> 1608 | K35: =+G35-J35 -> 0 | L35: =IFERROR(K35/J35,1) -> 0
B36: Dayton SMART Elementary Total | G36: =SUBTOTAL(9,G34:G35) -> 1713 | H36: =SUBTOTAL(9,H34:H35) -> 1713 | I36: =SUBTOTAL(9,I34:I35) -> 0 | J36: =SUBTOTAL(9,J34:J35) -> 1699
B37: East Muskingum School District | C37: Recurring Resale - MSP | D37: MSP -Recurring Resale | E37: 180462OH | F37: 45931 | G37: 173.5 | H37: =+G37 -> 173.5 | J37: =SUMIFS('[1]Sept-August Comp OH'!$G$2:$G$154,'[1]Sept-August Comp OH'!$B$2:$B$154,'Oct Agreement Compare OH'!B37,'[1]Sept-August Comp OH'!$C$2:$C$154,'Oct Agreement Compare OH'!C37,'[1]Sept-August Comp OH'!$D$2:$D$154,'Oct Agreement Compare OH'!D37) -> 178.5 | K37: =+G37-J37 -> -5 | L37: =IFERROR(K37/J37,1) -> -0.028011204
B38: East Muskingum School District | C38: T-Services-MSP | D38: T-Services-MSP | E38: 180461OH | F38: 45931 | G38: 1260 | H38: =+G38 -> 1260 | J38: =SUMIFS('[1]Sept-August Comp OH'!$G$2:$G$154,'[1]Sept-August Comp OH'!$B$2:$B$154,'Oct Agreement Compare OH'!B38,'[1]Sept-August Comp OH'!$C$2:$C$154,'Oct Agreement Compare OH'!C38,'[1]Sept-August Comp OH'!$D$2:$D$154,'Oct Agreement Compare OH'!D38) -> 1260 | K38: =+G38-J38 -> 0 | L38: =IFERROR(K38/J38,1) -> 0
B39: East Muskingum School District Total | G39: =SUBTOTAL(9,G37:G38) -> 1433.5 | H39: =SUBTOTAL(9,H37:H38) -> 1433.5 | I39: =SUBTOTAL(9,I37:I38) -> 0 | J39: =SUBTOTAL(9,J37:J38) -> 1438.5
B40: Energility LLC | C40: Recurring Resale - Security | D40: Recurring Resale - Security | E40: 180463OH | F40: 45931 | G40: 35 | H40: =+G40 -> 35 | J40: =SUMIFS('[1]Sept-August Comp OH'!$G$2:$G$154,'[1]Sept-August Comp OH'!$B$2:$B$154,'Oct Agreement Compare OH'!B40,'[1]Sept-August Comp OH'!$C$2:$C$154,'Oct Agreement Compare OH'!C40,'[1]Sept-August Comp OH'!$D$2:$D$154,'Oct Agreement Compare OH'!D40) -> 35 | K40: =+G40-J40 -> 0 | L40: =IFERROR(K40/J40,1) -> 0
...

Sheet Oct Agreement Compare CA
A1: Location | B1: Customer | C1: Agreement Type | D1: Agreement Name | E1: Invoice Number | F1: Invoice Date | G1: October Financials | H1: October Revenue | I1: September Clawback | J1: September Financials | K1: Difference October - September | L1: % Change | M1: Notes
B2: 24 Hour Home Care | C2: Recurring Resale - Microsoft 365 NCE | D2: Recurring Resale - Microsoft 365 NCE | E2: 180325 | F2: 45931 | G2: 31614.3 | H2: =+G2 -> 31614.3 | J2: =SUMIFS('[2]Sep-Aug Comp CA'!$G$1:$G$498,'[2]Sep-Aug Comp CA'!$B$1:$B$498,'Oct Agreement Compare CA'!B2,'[2]Sep-Aug Comp CA'!$C$1:$C$498,'Oct Agreement Compare CA'!C2,'[2]Sep-Aug Comp CA'!$D$1:$D$498,'Oct Agreement Compare CA'!D2) -> 0 | K2: =+G2-J2 -> 31614.3 | L2: =+K2/J2 -> #DIV/0!
B3: 24 Hour Home Care | C3: Recurring Resale - MSP | D3: Recurring Resale - MSP 2024/27 | E3: 180324 | F3: 45931 | G3: 1003.0806 | H3: =+G3 -> 1003.0806 | J3: =SUMIFS('[2]Sep-Aug Comp CA'!$G$1:$G$498,'[2]Sep-Aug Comp CA'!$B$1:$B$498,'Oct Agreement Compare CA'!B3,'[2]Sep-Aug Comp CA'!$C$1:$C$498,'Oct Agreement Compare CA'!C3,'[2]Sep-Aug Comp CA'!$D$1:$D$498,'Oct Agreement Compare CA'!D3) -> 989.6244 | K3: =+G3-J3 -> 13.4562 | L3: =+K3/J3 -> 0.01359728
B4: 24 Hour Home Care | C4: Recurring Resale - Security | D4: Recurring Resale - Security | E4: 180324 | F4: 45931 | G4: 11764 | H4: =+G4 -> 11764 | J4: =SUMIFS('[2]Sep-Aug Comp CA'!$G$1:$G$498,'[2]Sep-Aug Comp CA'!$B$1:$B$498,'Oct Agreement Compare CA'!B4,'[2]Sep-Aug Comp CA'!$C$1:$C$498,'Oct Agreement Compare CA'!C4,'[2]Sep-Aug Comp CA'!$D$1:$D$498,'Oct Agreement Compare CA'!D4) -> 11618 | K4: =+G4-J4 -> 146 | L4: =+K4/J4 -> 0.012566707
B5: 24 Hour Home Care | C5: T-Services-MSP | D5: T-Services-MSP | E5: 180324 | F5: 45931 | G5: 28950 | H5: =+G5 -> 28950 | J5: =SUMIFS('[2]Sep-Aug Comp CA'!$G$1:$G$498,'[2]Sep-Aug Comp CA'!$B$1:$B$498,'Oct Agreement Compare CA'!B5,'[2]Sep-Aug Comp CA'!$C$1:$C$498,'Oct Agreement Compare CA'!C5,'[2]Sep-Aug Comp CA'!$D$1:$D$498,'Oct Agreement Compare CA'!D5) -> 28675 | K5: =+G5-J5 -> 275 | L5: =+K5/J5 -> 0.0095902354
B6: 24 Hour Home Care Total | G6: =SUBTOTAL(9,G2:G5) -> 73331.381 | H6: =SUBTOTAL(9,H2:H5) -> 73331.381 | I6: =SUBTOTAL(9,I2:I5) -> 0 | J6: =SUBTOTAL(9,J2:J5) -> 41282.624 | K6: =+G6-J6 -> 32048.756 | L6: =+K6/J6 -> 0.77632555
B7: 7C Escrow | C7: Cloud - Private | D7: Cloud - Private | E7: 180748 | F7: 45945 | G7: 954.1 | H7: =+G7 -> 954.1 | J7: =SUMIFS('[2]Sep-Aug Comp CA'!$G$1:$G$498,'[2]Sep-Aug Comp CA'!$B$1:$B$498,'Oct Agreement Compare CA'!B7,'[2]Sep-Aug Comp CA'!$C$1:$C$498,'Oct Agreement Compare CA'!C7,'[2]Sep-Aug Comp CA'!$D$1:$D$498,'Oct Agreement Compare CA'!D7) -> 954.1 | K7: =+G7-J7 -> 0 | L7: =+K7/J7 -> 0
B8: 7C Escrow | C8: Recurring Resale - MSP | D8: Recurring Resale - MSP | E8: 180748 | F8: 45945 | G8: 28.38 | H8: =+G8 -> 28.38 | J8: =SUMIFS('[2]Sep-Aug Comp CA'!$G$1:$G$498,'[2]Sep-Aug Comp CA'!$B$1:$B$498,'Oct Agreement Compare CA'!B8,'[2]Sep-Aug Comp CA'!$C$1:$C$498,'Oct Agreement Compare CA'!C8,'[2]Sep-Aug Comp CA'!$D$1:$D$498,'Oct Agreement Compare CA'!D8) -> 28.38 | K8: =+G8-J8 -> 0 | L8: =+K8/J8 -> 0
B9: 7C Escrow | C9: Recurring Resale - Security | D9: Recurring Resale - Security | E9: 180748 | F9: 45945 | G9: 330.5 | H9: =+G9 -> 330.5 | J9: =SUMIFS('[2]Sep-Aug Comp CA'!$G$1:$G$498,'[2]Sep-Aug Comp CA'!$B$1:$B$498,'Oct Agreement Compare CA'!B9,'[2]Sep-Aug Comp CA'!$C$1:$C$498,'Oct Agreement Compare CA'!C9,'[2]Sep-Aug Comp CA'!$D$1:$D$498,'Oct Agreement Compare CA'!D9) -> 330.5 | K9: =+G9-J9 -> 0 | L9: =+K9/J9 -> 0
B10: 7C Escrow | C10: T-Services-MSP | D10: T-Services-MSP | E10: 180748 | F10: 45945 | G10: 351.5 | H10: =+G10 -> 351.5 | J10: =SUMIFS('[2]Sep-Aug Comp CA'!$G$1:$G$498,'[2]Sep-Aug Comp CA'!$B$1:$B$498,'Oct Agreement Compare CA'!B10,'[2]Sep-Aug Comp CA'!$C$1:$C$498,'Oct Agreement Compare CA'!C10,'[2]Sep-Aug Comp CA'!$D$1:$D$498,'Oct Agreement Compare CA'!D10) -> 351.5 | K10: =+G10-J10 -> 0 | L10: =+K10/J10 -> 0
B11: 7C Escrow Total | G11: =SUBTOTAL(9,G7:G10) -> 1664.48 | H11: =SUBTOTAL(9,H7:H10) -> 1664.48 | I11: =SUBTOTAL(9,I7:I10) -> 0 | J11: =SUBTOTAL(9,J7:J10) -> 1664.48 | K11: =+G11-J11 -> 0 | L11: =+K11/J11 -> 0
B12: Abest Professional Health Care | C12: Recurring Resale - Microsoft 365 NCE | D12: Recurring Resale - Microsoft 365 NCE | E12: 180326 | F12: 45931 | G12: 484 | H12: =+G12 -> 484 | J12: =SUMIFS('[2]Sep-Aug Comp CA'!$G$1:$G$498,'[2]Sep-Aug Comp CA'!$B$1:$B$498,'Oct Agreement Compare CA'!B12,'[2]Sep-Aug Comp CA'!$C$1:$C$498,'Oct Agreement Compare CA'!C12,'[2]Sep-Aug Comp CA'!$D$1:$D$498,'Oct Agreement Compare CA'!D12) -> 484 | K12: =+G12-J12 -> 0 | L12: =+K12/J12 -> 0
B13: Abest Professional Health Care | C13: Recurring Resale - MSP | D13: Recurring Resale - MSP 2025/27 | E13: 180326 | F13: 45931 | G13: 158 | H13: =+G13 -> 158 | J13: =SUMIFS('[2]Sep-Aug Comp CA'!$G$1:$G$498,'[2]Sep-Aug Comp CA'!$B$1:$B$498,'Oct Agreement Compare CA'!B13,'[2]Sep-Aug Comp CA'!$C$1:$C$498,'Oct Agreement Compare CA'!C13,'[2]Sep-Aug Comp CA'!$D$1:$D$498,'Oct Agreement Compare CA'!D13) -> 158 | K13: =+G13-J13 -> 0 | L13: =+K13/J13 -> 0
B14: Abest Professional Health Care | C14: Recurring Resale - MSP | D14: Temp Backups Agreement | E14: 180326 | F14: 45931 | G14: 289.356 | H14: =+G14 -> 289.356 | J14: =SUMIFS('[2]Sep-Aug Comp CA'!$G$1:$G$498,'[2]Sep-Aug Comp CA'!$B$1:$B$498,'Oct Agreement Compare CA'!B14,'[2]Sep-Aug Comp CA'!$C$1:$C$498,'Oct Agreement Compare CA'!C14,'[2]Sep-Aug Comp CA'!$D$1:$D$498,'Oct Agreement Compare CA'!D14) -> 292.7244 | K14: =+G14-J14 -> -3.3684 | L14: =+K14/J14 -> -0.011507069
B15: Abest Professional Health Care | C15: Recurring Resale - Security | D15: Recurring Resale - Security 2025/27 | E15: 180326 | F15: 45931 | G15: 117 | H15: =+G15 -> 117 | J15: =SUMIFS('[2]Sep-Aug Comp CA'!$G$1:$G$498,'[2]Sep-Aug Comp CA'!$B$1:$B$498,'Oct Agreement Compare CA'!B15,'[2]Sep-Aug Comp CA'!$C$1:$C$498,'Oct Agreement Compare CA'!C15,'[2]Sep-Aug Comp CA'!$D$1:$D$498,'Oct Agreement Compare CA'!D15) -> 133 | K15: =+G15-J15 -> -16 | L15: =+K15/J15 -> -0.12030075
B16: Abest Professional Health Care | C16: T-Services-MSP | D16: T-Services-MSP 2024/27 | E16: 180326 | F16: 45931 | G16: 615.004 | H16: =+G16 -> 615.004 | J16: =SUMIFS('[2]Sep-Aug Comp CA'!$G$1:$G$498,'[2]Sep-Aug Comp CA'!$B$1:$B$498,'Oct Agreement Compare CA'!B16,'[2]Sep-Aug Comp CA'!$C$1:$C$498,'Oct Agreement Compare CA'!C16,'[2]Sep-Aug Comp CA'!$D$1:$D$498,'Oct Agreement Compare CA'!D16) -> 560 | K16: =+G16-J16 -> 55.004 | L16: =+K16/J16 -> 0.098221429
B17: Abest Professional Health Care Total | G17: =SUBTOTAL(9,G12:G16) -> 1663.36 | H17: =SUBTOTAL(9,H12:H16) -> 1663.36 | I17: =SUBTOTAL(9,I12:I16) -> 0 | J17: =SUBTOTAL(9,J12:J16) -> 1627.7244 | K17: =+G17-J17 -> 35.6356 | L17: =+K17/J17 -> 0.021892895
B18: ABI Healthcare | C18: Recurring Resale - Microsoft 365 NCE | D18: Recurring Resale - Microsoft 365 NCE | E18: 180327 | F18: 45931 | G18: 3358.53 | H18: =+G18 -> 3358.53 | J18: =SUMIFS('[2]Sep-Aug Comp CA'!$G$1:$G$498,'[2]Sep-Aug Comp CA'!$B$1:$B$498,'Oct Agreement Compare CA'!B18,'[2]Sep-Aug Comp CA'!$C$1:$C$498,'Oct Agreement Compare CA'!C18,'[2]Sep-Aug Comp CA'!$D$1:$D$498,'Oct Agreement Compare CA'!D18) -> 3358.53 | K18: =+G18-J18 -> 0 | L18: =+K18/J18 -> 0
B19: ABI Healthcare | C19: Recurring Resale - MSP | D19: MSP -Recurring Resale | E19: 180327 | F19: 45931 | G19: 10.5 | H19: =+G19 -> 10.5 | J19: =SUMIFS('[2]Sep-Aug Comp CA'!$G$1:$G$498,'[2]Sep-Aug Comp CA'!$B$1:$B$498,'Oct Agreement Compare CA'!B19,'[2]Sep-Aug Comp CA'!$C$1:$C$498,'Oct Agreement Compare CA'!C19,'[2]Sep-Aug Comp CA'!$D$1:$D$498,'Oct Agreement Compare CA'!D19) -> 10.5 | K19: =+G19-J19 -> 0 | L19: =+K19/J19 -> 0
B20: ABI Healthcare | C20: Recurring Resale - Security | D20: Recurring Resale - Security | E20: 180327 | F20: 45931 | G20: 5357 | H20: =+G20 -> 5357 | J20: =SUMIFS('[2]Sep-Aug Comp CA'!$G$1:$G$498,'[2]Sep-Aug Comp CA'!$B$1:$B$498,'Oct Agreement Compare CA'!B20,'[2]Sep-Aug Comp CA'!$C$1:$C$498,'Oct Agreement Compare CA'!C20,'[2]Sep-Aug Comp CA'!$D$1:$D$498,'Oct Agreement Compare CA'!D20) -> 5390 | K20: =+G20-J20 -> -33 | L20: =+K20/J20 -> -0.006122449
B21: ABI Healthcare | C21: T-Services-MSP | D21: T-Services-MSP | E21: 180327 | F21: 45931 | G21: 9032 | H21: =+G21 -> 9032 | J21: =SUMIFS('[2]Sep-Aug Comp CA'!$G$1:$G$498,'[2]Sep-Aug Comp CA'!$B$1:$B$498,'Oct Agreement Compare CA'!B21,'[2]Sep-Aug Comp CA'!$C$1:$C$498,'Oct Agreement Compare CA'!C21,'[2]Sep-Aug Comp CA'!$D$1:$D$498,'Oct Agreement Compare CA'!D21) -> 9286 | K21: =+G21-J21 -> -254 | L21: =+K21/J21 -> -0.027353005
B22: ABI Healthcare Total | G22: =SUBTOTAL(9,G18:G21) -> 17758.03 | H22: =SUBTOTAL(9,H18:H21) -> 17758.03 | I22: =SUBTOTAL(9,I18:I21) -> 0 | J22: =SUBTOTAL(9,J18:J21) -> 18045.03 | K22: =+G22-J22 -> -287 | L22: =+K22/J22 -> -0.015904656
B23: ABIFI Professional Health Care | C23: Recurring Resale - Microsoft 365 NCE | D23: Recurring Resale - Microsoft 365 NCE | E23: 180328 | F23: 45931 | G23: 1219.2 | H23: =+G23 -> 1219.2 | J23: =SUMIFS('[2]Sep-Aug Comp CA'!$G$1:$G$498,'[2]Sep-Aug Comp CA'!$B$1:$B$498,'Oct Agreement Compare CA'!B23,'[2]Sep-Aug Comp CA'!$C$1:$C$498,'Oct Agreement Compare CA'!C23,'[2]Sep-Aug Comp CA'!$D$1:$D$498,'Oct Agreement Compare CA'!D23) -> 1598.4 | K23: =+G23-J23 -> -379.2 | L23: =+K23/J23 -> -0.23723724
B24: ABIFI Professional Health Care | C24: Recurring Resale - MSP | D24: Recurring Resale - MSP 2024/27 | E24: 180328 | F24: 45931 | G24: 380.4734 | H24: =+G24 -> 380.4734 | J24: =SUMIFS('[2]Sep-Aug Comp CA'!$G$1:$G$498,'[2]Sep-Aug Comp CA'!$B$1:$B$498,'Oct Agreement Compare CA'!B24,'[2]Sep-Aug Comp CA'!$C$1:$C$498,'Oct Agreement Compare CA'!C24,'[2]Sep-Aug Comp CA'!$D$1:$D$498,'Oct Agreement Compare CA'!D24) -> 370.0562 | K24: =+G24-J24 -> 10.4172 | L24: =+K24/J24 -> 0.028150319
B25: ABIFI Professional Health Care | C25: Recurring Resale - Security | D25: Recurring Resale - Security 2024/27 | E25: 180328 | F25: 45931 | G25: 1006 | H25: =+G25 -> 1006 | J25: =SUMIFS('[2]Sep-Aug Comp CA'!$G$1:$G$498,'[2]Sep-Aug Comp CA'!$B$1:$B$498,'Oct Agreement Compare CA'!B25,'[2]Sep-Aug Comp CA'!$C$1:$C$498,'Oct Agreement Compare CA'!C25,'[2]Sep-Aug Comp CA'!$D$1:$D$498,'Oct Agreement Compare CA'!D25) -> 1020 | K25: =+G25-J25 -> -14 | L25: =+K25/J25 -> -0.01372549
B26: ABIFI Professional Health Care | C26: T-Services-MSP | D26: T-Services-MSP | E26: 180328 | F26: 45931 | G26: 820 | H26: =+G26 -> 820 | J26: =SUMIFS('[2]Sep-Aug Comp CA'!$G$1:$G$498,'[2]Sep-Aug Comp CA'!$B$1:$B$498,'Oct Agreement Compare CA'!B26,'[2]Sep-Aug Comp CA'!$C$1:$C$498,'Oct Agreement Compare CA'!C26,'[2]Sep-Aug Comp CA'!$D$1:$D$498,'Oct Agreement Compare CA'!D26) -> 967.0038 | K26: =+G26-J26 -> -147.0038 | L26: =+K26/J26 -> -0.15201988
B27: ABIFI Professional Health Care Total | G27: =SUBTOTAL(9,G23:G26) -> 3425.6734 | H27: =SUBTOTAL(9,H23:H26) -> 3425.6734 | I27: =SUBTOTAL(9,I23:I26) -> 0 | J27: =SUBTOTAL(9,J23:J26) -> 3955.46 | K27: =+G27-J27 -> -529.7866 | L27: =+K27/J27 -> -0.13393805
B28: Ability Ambeck Mortgage | C28: Recurring Resale - Microsoft 365 NCE | D28: Ability Microsoft 365 | E28: 180330 | F28: 45931 | G28: 1016 | H28: =+G28 -> 1016 | J28: =SUMIFS('[2]Sep-Aug Comp CA'!$G$1:$G$498,'[2]Sep-Aug Comp CA'!$B$1:$B$498,'Oct Agreement Compare CA'!B28,'[2]Sep-Aug Comp CA'!$C$1:$C$498,'Oct Agreement Compare CA'!C28,'[2]Sep-Aug Comp CA'!$D$1:$D$498,'Oct Agreement Compare CA'!D28) -> 994 | K28: =+G28-J28 -> 22 | L28: =+K28/J28 -> 0.022132797
B29: Ability Ambeck Mortgage | C29: Recurring Resale - MSP | D29: Recurring Resale - MSP | E29: 180330 | F29: 45931 | G29: 625.51 | H29: =+G29 -> 625.51 | J29: =SUMIFS('[2]Sep-Aug Comp CA'!$G$1:$G$498,'[2]Sep-Aug Comp CA'!$B$1:$B$498,'Oct Agreement Compare CA'!B29,'[2]Sep-Aug Comp CA'!$C$1:$C$498,'Oct Agreement Compare CA'!C29,'[2]Sep-Aug Comp CA'!$D$1:$D$498,'Oct Agreement Compare CA'!D29) -> 625.51 | K29: =+G29-J29 -> 0 | L29: =+K29/J29 -> 0
B30: Ability Ambeck Mortgage | C30: Recurring Resale - MSP | D30: Recurring Resale - MSP 25/26 | E30: 180329 | F30: 45931 | G30: 7.4 | H30: =+G30 -> 7.4 | J30: =SUMIFS('[2]Sep-Aug Comp CA'!$G$1:$G$498,'[2]Sep-Aug Comp CA'!$B$1:$B$498,'Oct Agreement Compare CA'!B30,'[2]Sep-Aug Comp CA'!$C$1:$C$498,'Oct Agreement Compare CA'!C30,'[2]Sep-Aug Comp CA'!$D$1:$D$498,'Oct Agreement Compare CA'!D30) -> 7.4 | K30: =+G30-J30 -> 0 | L30: =+K30/J30 -> 0
B31: Ability Ambeck Mortgage | C31: Recurring Resale - Security | D31: Ability - Recurring Resale - Security | E31: 180330 | F31: 45931 | G31: 838 | H31: =+G31 -> 838 | J31: =SUMIFS('[2]Sep-Aug Comp CA'!$G$1:$G$498,'[2]Sep-Aug Comp CA'!$B$1:$B$498,'Oct Agreement Compare CA'!B31,'[2]Sep-Aug Comp CA'!$C$1:$C$498,'Oct Agreement Compare CA'!C31,'[2]Sep-Aug Comp CA'!$D$1:$D$498,'Oct Agreement Compare CA'!D31) -> 850 | K31: =+G31-J31 -> -12 | L31: =+K31/J31 -> -0.014117647
B32: Ability Ambeck Mortgage | C32: T-Services-MSP | D32: Ability-Managed | E32: 180330 | F32: 45931 | G32: 855.2 | H32: =+G32 -> 855.2 | J32: =SUMIFS('[2]Sep-Aug Comp CA'!$G$1:$G$498,'[2]Sep-Aug Comp CA'!$B$1:$B$498,'Oct Agreement Compare CA'!B32,'[2]Sep-Aug Comp CA'!$C$1:$C$498,'Oct Agreement Compare CA'!C32,'[2]Sep-Aug Comp CA'!$D$1:$D$498,'Oct Agreement Compare CA'!D32) -> 855.2 | K32: =+G32-J32 -> 0 | L32: =+K32/J32 -> 0
B33: Ability Ambeck Mortgage Total | G33: =SUBTOTAL(9,G28:G32) -> 3342.11 | H33: =SUBTOTAL(9,H28:H32) -> 3342.11 | I33: =SUBTOTAL(9,I28:I32) -> 0 | J33: =SUBTOTAL(9,J28:J32) -> 3332.11 | K33: =+G33-J33 -> 10 | L33: =+K33/J33 -> 0.0030011014
B34: Advantage Home Care | C34: Recurring Resale - Security | D34: Recurring Resale - Security | E34: 180331 | F34: 45931 | G34: 5298 | H34: =+G34 -> 5298 | J34: =SUMIFS('[2]Sep-Aug Comp CA'!$G$1:$G$498,'[2]Sep-Aug Comp CA'!$B$1:$B$498,'Oct Agreement Compare CA'!B34,'[2]Sep-Aug Comp CA'!$C$1:$C$498,'Oct Agreement Compare CA'!C34,'[2]Sep-Aug Comp CA'!$D$1:$D$498,'Oct Agreement Compare CA'!D34) -> 5312 | K34: =+G34-J34 -> -14 | L34: =+K34/J34 -> -0.0026355422
B35: Advantage Home Care | C35: T-Services-MSP | D35: T-Services-MSP | E35: 180331 | F35: 45931 | G35: 7176 | H35: =+G35 -> 7176 | J35: =SUMIFS('[2]Sep-Aug Comp CA'!$G$1:$G$498,'[2]Sep-Aug Comp CA'!$B$1:$B$498,'Oct Agreement Compare CA'!B35,'[2]Sep-Aug Comp CA'!$C$1:$C$498,'Oct Agreement Compare CA'!C35,'[2]Sep-Aug Comp CA'!$D$1:$D$498,'Oct Agreement Compare CA'!D35) -> 6600 | K35: =+G35-J35 -> 576 | L35: =+K35/J35 -> 0.087272727
B36: Advantage Home Care Total | G36: =SUBTOTAL(9,G34:G35) -> 12474 | H36: =SUBTOTAL(9,H34:H35) -> 12474 | I36: =SUBTOTAL(9,I34:I35) -> 0 | J36: =SUBTOTAL(9,J34:J35) -> 11912 | K36: =+G36-J36 -> 562 | L36: =+K36/J36 -> 0.047179315
B37: Agape Corporation WEB Du | C37: Recurring Resale - MSP | D37: Recurring Resale - MSP | E37: 180292 | F37: 45931 | G37: 250 | H37: =+G37 -> 250 | J37: =SUMIFS('[2]Sep-Aug Comp CA'!$G$1:$G$498,'[2]Sep-Aug Comp CA'!$B$1:$B$498,'Oct Agreement Compare CA'!B37,'[2]Sep-Aug Comp CA'!$C$1:$C$498,'Oct Agreement Compare CA'!C37,'[2]Sep-Aug Comp CA'!$D$1:$D$498,'Oct Agreement Compare CA'!D37) -> 250 | K37: =+G37-J37 -> 0 | L37: =+K37/J37 -> 0
B38: Agape Corporation WEB Du | C38: Recurring Resale - Security | D38: Recurring Resale - Security | E38: 180292 | F38: 45931 | G38: 1600 | H38: =+G38 -> 1600 | J38: =SUMIFS('[2]Sep-Aug Comp CA'!$G$1:$G$498,'[2]Sep-Aug Comp CA'!$B$1:$B$498,'Oct Agreement Compare CA'!B38,'[2]Sep-Aug Comp CA'!$C$1:$C$498,'Oct Agreement Compare CA'!C38,'[2]Sep-Aug Comp CA'!$D$1:$D$498,'Oct Agreement Compare CA'!D38) -> 1600 | K38: =+G38-J38 -> 0 | L38: =+K38/J38 -> 0
B39: Agape Corporation WEB Du | C39: T-Services-MSP | D39: T-Services-MSP | E39: 180292 | F39: 45931 | G39: 3288.79 | H39: =+G39 -> 3288.79 | J39: =SUMIFS('[2]Sep-Aug Comp CA'!$G$1:$G$498,'[2]Sep-Aug Comp CA'!$B$1:$B$498,'Oct Agreement Compare CA'!B39,'[2]Sep-Aug Comp CA'!$C$1:$C$498,'Oct Agreement Compare CA'!C39,'[2]Sep-Aug Comp CA'!$D$1:$D$498,'Oct Agreement Compare CA'!D39) -> 3288.79 | K39: =+G39-J39 -> 0 | L39: =+K39/J39 -> 0
B40: Agape Corporation WEB Du Total | G40: =SUBTOTAL(9,G37:G39) -> 5138.79 | H40: =SUBTOTAL(9,H37:H39) -> 5138.79 | I40: =SUBTOTAL(9,I37:I39) -> 0 | J40: =SUBTOTAL(9,J37:J39) -> 5138.79 | K40: =+G40-J40 -> 0 | L40: =+K40/J40 -> 0
...

Sheet Actual Billings
A1: Location name | B1: (Multiple Items) | H1: Location name | I1: (Multiple Items)
A2: Billing | B2: x | H2: Billing | I2: x
A4: Sum of Balance | B4: Column Labels | H4: Sum of Balance | I4: Column Labels
B5: Sep | C5: Oct | D5: Grand Total | I5: Sep | J5: Oct | K5: Grand Total
A7: Row Labels | H7: Row Labels
A8: 40000 | B8: -458333.46 | C8: -458920.03 | D8: -917253.49 | H8: 40000 | I8: -91841.37 | J8: -92188.25 | K8: -184029.62
A9: 40100 | B9: -5055.45 | C9: -5055.45 | D9: -10110.9 | H9: 40200 | I9: -5580.2 | J9: -5580.2 | K9: -11160.4
A10: 40200 | B10: -3141.33 | C10: -2826.33 | D10: -5967.66 | H10: 41200 | J10: -315 | K10: -315
A11: 41200 | B11: -26560.81 | C11: -26310.81 | D11: -52871.62 | H11: 41250 | I11: -562.5 | J11: -562.5 | K11: -1125
A12: 41300 | B12: -48266.91 | C12: -49744.37 | D12: -98011.28 | H12: 41300 | I12: -2064.91 | J12: -2010.85 | K12: -4075.76
A13: 41320 | B13: -8987.36 | C13: -8757.36 | D13: -17744.72 | H13: 41320 | I13: -2734.25 | J13: -2799.25 | K13: -5533.5
A14: 41350 | B14: -954.1 | C14: -898.87 | D14: -1852.97 | H14: 41400 | I14: -720.95 | J14: -1230.41 | K14: -1951.36
A15: 41360 | B15: -1144 | C15: -1144 | D15: -2288 | H15: 41450 | I15: -1310.97 | J15: -1377.37 | K15: -2688.34
A16: 41365 | B16: -25835.05 | C16: -25853.05 | D16: -51688.1 | H16: 42100 | I16: -13408.7 | J16: -14214.1 | K16: -27622.8
A17: 41400 | B17: -5584.21 | C17: -7877.69 | D17: -13461.9 | H17: 41500 | I17: -58058 | J17: -22171 | K17: -80229
A18: 41450 | B18: -92497.27 | C18: -121329.87 | D18: -213827.14 | H18: 42000 | I18: -228854.89 | J18: -441630.42 | K18: -670485.31
A19: 42100 | B19: -133948.08 | C19: -135011.8 | D19: -268959.88 | H19: 42300 | I19: -754 | J19: -754 | K19: -1508
A20: 41500 | B20: -24526.25 | C20: -46520 | D20: -71046.25 | H20: 44000 | I20: -1587.29 | J20: -17123.75 | K20: -18711.04
A21: 42000 | B21: -101632.12 | C21: -193347.56 | D21: -294979.68 | H21: 41700 | I21: -7449 | J21: -9125.8 | K21: -16574.8
A22: 42300 | B22: -1791.81 | C22: -1791.81 | D22: -3583.62 | H22: 42200 | I22: -1718.1 | J22: -1718.1 | K22: -3436.2
A23: 44000 | B23: -211.17 | C23: -551.15 | D23: -762.32 | H23: 41925 | I23: -5913.61 | J23: -5773.93 | K23: -11687.54
A24: 41700 | B24: -7030.76 | C24: -10863.16 | D24: -17893.92 | H24: Grand Total | I24: -422558.74 | J24: -618574.93 | K24: -1041133.7
A25: 42200 | B25: -1898.23 | C25: -1898.23 | D25: -3796.46
A26: Grand Total | B26: -947398.37 | C26: -1098701.5 | D26: -2046099.9

Sheet General Ledger report
A1: GL | B1: Posted dt. | C1: Doc dt. | D1: Doc | E1: Memo/Description | F1: Department | G1: Department name | H1: Vendor name | I1: Location name | J1: Item | K1: Customer name | L1: Item name | M1: Customer | N1: Product Type | O1: Txn No | P1: JNL | Q1: Debit | R1: Credit | S1: Balance | T1: Billing
A2: 40000 | B2: 45961 | C2: 45961 | E2: Accrual for Irvine Invoices- Oct REV Sept 2025 INV | I2: Irvine | K2: 7C Escrow | M2: C00002 | O2: 24186 | P2: ARJ | Q2: 351.5 | S2: 351.5
A3: 40000 | B3: 45961 | C3: 45961 | E3: Accrual for Irvine Invoices- Oct REV Sept 2025 INV | I3: Irvine | K3: Peak Real Estate Management LLC | M3: C00302 | O3: 24186 | P3: ARJ | Q3: 368.58 | S3: 368.58
A4: 40000 | B4: 45961 | C4: 45961 | E4: Accrual for Irvine Invoices- Oct REV Sept 2025 INV | I4: Irvine | K4: Your Escrow Company | M4: C-10008 | O4: 24186 | P4: ARJ | Q4: 449.4 | S4: 449.4
A5: 40000 | B5: 45961 | C5: 45961 | E5: Accrual for Irvine Invoices- Oct REV Sept 2025 INV | I5: Irvine | K5: Kaplan & Trombi | M5: C00165 | O5: 24186 | P5: ARJ | Q5: 614.25 | S5: 614.25
A6: 40000 | B6: 45961 | C6: 45961 | E6: Accrual for Irvine Invoices- Oct REV Sept 2025 INV | I6: Irvine | K6: Primetime Escrow | M6: C00215 | O6: 24186 | P6: ARJ | Q6: 653.38 | S6: 653.38
A7: 40000 | B7: 45961 | C7: 45961 | E7: Accrual for Irvine Invoices- Oct REV Sept 2025 INV | I7: Irvine | K7: Modiv | M7: C00224 | O7: 24186 | P7: ARJ | Q7: 843.6 | S7: 843.6
A8: 40000 | B8: 45961 | C8: 45961 | E8: Accrual for Irvine Invoices- Oct REV Sept 2025 INV | I8: Irvine | K8: Capital Financial Consultants Group | M8: C00060 | O8: 24186 | P8: ARJ | Q8: 1125.3 | S8: 1125.3
A9: 40000 | B9: 45961 | C9: 45961 | E9: Accrual for Irvine Invoices- Oct REV Sept 2025 INV | I9: Irvine | K9: Linwood Engineering Associates | M9: C00178 | O9: 24186 | P9: ARJ | Q9: 1378.95 | S9: 1378.95
A10: 40000 | B10: 45961 | C10: 45961 | E10: Accrual for Irvine Invoices- Oct REV Sept 2025 INV | I10: Irvine | K10: Project Hope Alliance | M10: C00216 | O10: 24186 | P10: ARJ | Q10: 1492.52 | S10: 1492.52
A11: 40000 | B11: 45961 | C11: 45961 | E11: Accrual for Irvine Invoices- Oct REV Sept 2025 INV | I11: Irvine | K11: Anonymous LLC | M11: C00020 | O11: 24186 | P11: ARJ | Q11: 2595.6 | S11: 2595.6
A12: 40000 | B12: 45961 | C12: 45961 | E12: Accrual for Irvine Invoices- Oct REV Sept 2025 INV | I12: Irvine | K12: Groundswell | M12: C00204 | O12: 24186 | P12: ARJ | Q12: 2648 | S12: 2648
A13: 40000 | B13: 45961 | C13: 45961 | E13: Accrual for Irvine Invoices- Oct REV Sept 2025 INV | I13: Irvine | K13: Free Wheelchair Mission | M13: C00116 | O13: 24186 | P13: ARJ | Q13: 2666.1 | S13: 2666.1
... A135: 42100 | B135: 45930 | C135: 45930 | E135: Accrual for Irvine Invoices- Sept REV Aug 2025 INV | I135: Irvine | K135: Hercules OEM Group | M135: C00139 | O135: 24080 | P135: ARJ | Q135: 1055 | S135: 1055
A136: 41500 | B136: 45925 | C136: 45925 | D136: 180271 | E136: Invoice - 24 Hour Home Care | F136: D-004 | G136: Projects | I136: Modesto | K136: 24 Hour Home Care | M136: 24hrcares | O136: 23658 | P136: ARJ | R136: 800 | S136: -800 | T136: x
A137: 42100 | B137: 45901 | C137: 45901 | D137: 179772 | E137: Invoice - 24 Hour Home Care: 24x7 Gateway Security Monitoring | F137: D-005 | G137: Security | I137: Modesto | J137: DPM-FWM-SM | K137: 24 Hour Home Care | L137: 24x7 Gateway Security Monitoring Small | M137: 24hrcares | O137: 23534 | P137: ARJ | R137: 1225 | S137: -1225 | T137: x
A138: 42100 | B138: 45931 | C138: 45931 | D138: 180324 | E138: Invoice - 24 Hour Home Care: 24x7 Gateway Security Monitoring | F138: D-005 | G138: Security | I138: Modesto | J138: DPM-FWM-SM | K138: 24 Hour Home Care | L138: 24x7 Gateway Security Monitoring Small | M138: 24hrcares | O138: 23749 | P138: ARJ | R138: 1225 | S138: -1225 | T138: x
A139: 42100 | B139: 45901 | C139: 45901 | D139: 179772 | E139: Invoice - 24 Hour Home Care: AI Powered Email Filtering and Phishing Protection | F139: D-005 | G139: Security | I139: Modesto | J139: IS-ESP-1 | K139: 24 Hour Home Care | L139: Email Security | M139: 24hrcares | O139: 23534 | P139: ARJ | R139: 2502 | S139: -2502 | T139: x
A140: 42100 | B140: 45931 | C140: 45931 | D140: 180324 | E140: Invoice - 24 Hour Home Care: AI Powered Email Filtering and Phishing Protection | F140: D-005 | G140: Security | I140: Modesto | J140: IS-ESP-1 | K140: 24 Hour Home Care | L140: Email Security | M140: 24hrcares | O140: 23749 | P140: ARJ | R140: 2502 | S140: -2502 | T140: x
