Workbook

Sheet 2023 to 2025 P&L
A1: Datapath
A2: P&L MTD with Previous Month Comparison
A3: Reporting Book:
A4: As of Date:
B6: Data Path - All Locations | C6: Data Path - All Locations | D6: Data Path - All Locations
B7: Year To Date | C7: Year To Date | D7: Year To Date
B8: 46022 | C8: 12/31/2024 | D8: 12/31/2023
B9: Actual | C9: Actual | D9: Actual
A10: Net Income- With DL above the line
A11: Operating Net Income- DL above the line
A12: Gross Profit with Direct Labor
A13: Revenue
A14: Monthly Recurring Services | B14: 6854056 | C14: 6936443 | D14: 8102462
A15: Monthly Recurring Private Cloud | B15: 293246 | C15: 249130 | D15: 501696
A16: Monthly Recurring Resale | B16: 3552126 | C16: 2690685 | D16: 3860762
A17: Revenue - Project Services | B17: 897286 | C17: 1636389 | D17: 1243556
A18: Subcontracted Services | B18: 320191 | C18: 665693 | D18: 578727
A19: Revenue - Product Sales | B19: 5748162 | C19: 9750353 | D19: 13238613
A20: Revenue - Other | B20: 89645 | C20: 135672 | D20: 215473
B21: 0 | C21: 0 | D21: 69
A22: Total Revenue | B22: 17754712 | C22: 22064365 | D22: 27741220
A23: Cost of Rev with Direct and IT Project Labor
A24: Managed IT Service Costs | B24: 308646 | C24: 244439 | D24: 384241
A25: Cost of Monthly Recurring Cloud | B25: 130837 | C25: 111211 | D25: 362537
A26: Cost of Monthly Recurring Resale | B26: 2209537 | C26: 1848460 | D26: 2081794
A27: Project Service Costs | B27: 2899 | C27: 28353 | D27: 10903
A28: Subcontractor Service Costs | B28: 290943 | C28: 556704 | D28: 491468
A29: Product Sales Cost | B29: 4849109 | C29: 8022086 | D29: 11092919
A30: IT Project Labor | B30: 692147 | C30: 0 | D30: 0
A31: Direct Labor Costs | B31: 2587557 | C31: 4111567 | D31: 0
A32: Total Cost of Rev with IT Project and Direct Labor | B32: 11071675 | C32: 14922820 | D32: 14423862
A33: Total Gross Profit with Direct Labor | B33: 6683037 | C33: 7141545 | D33: 13317358
A34: Sales Labor Costs | B34: 1661111 | C34: 1706643 | D34: 0
A35: Operating Expense- no Direct or Sales Labor
A36: Payroll and Related Expenses no Direct or Sales Labor | B36: 960566 | C36: 1417800 | D36: 7319360
A37: Utilities and Facilities | B37: 494644 | C37: 485563 | D37: 443737
A38: Operating and Maintenance Expenses | B38: 1453007 | C38: 857972 | D38: 769383
A39: Marketing and Advertising Expenses | B39: 118962 | C39: 132250 | D39: 75785
A40: General and Administrative Expenses | B40: 269759 | C40: 389429 | D40: 399339
A41: Taxes and Insurance | B41: 228578 | C41: 78090 | D41: 105668
...

Sheet Condensed P&L by Month
A1: Datapath
A2: P&L MTD with Previous Month Comparison
A3: Reporting Book:
A4: As of Date:
B6: Data Path - All Locations | F6: Data Path - All Locations | G6: Data Path - All Locations | H6: Data Path - All Locations | I6: Data Path - All Locations | J6: Data Path - All Locations | K6: Data Path - All Locations | L6: Data Path - All Locations | M6: Data Path - All Locations | N6: Data Path - All Locations | O6: Data Path - All Locations | P6: Data Path - All Locations | Q6: Data Path - All Locations
B7: Month Ending | D7: Unadjusted | F7: Month Ending | G7: Month Ending | H7: Month Ending | I7: Month Ending | J7: Month Ending | K7: Month Ending | L7: Month Ending | M7: Month Ending | N7: Month Ending | O7: Month Ending | P7: Month Ending | Q7: Month Ending
B8: 12/31/2025 | C8: YE Clean up | D8: 12/31/2025 | F8: 11/30/2025 | G8: 10/31/2025 | H8: 09/30/2025 | I8: 08/31/2025 | J8: 07/31/2025 | K8: 06/30/2025 | L8: 05/31/2025 | M8: 04/30/2025 | N8: 03/31/2025 | O8: 02/28/2025 | P8: 01/31/2025 | Q8: Total
A10: Net Income- With DL above the line
A11: Operating Net Income- DL above the line
A12: Gross Profit with Direct Labor
A13: Revenue
A14: Monthly Recurring Services | B14: =SUMIF('P&L by Month Detail'!$A:$A,'Condensed P&L by Month'!$A14,'P&L by Month Detail'!C:C) -> 586949 | C14: =SUMIF('P&L by Month Detail'!$A:$A,'Condensed P&L by Month'!$A14,'P&L by Month Detail'!D:D) -> 0 | D14: =+B14+C14 -> 586949 | F14: =SUMIF('P&L by Month Detail'!$A:$A,'Condensed P&L by Month'!$A14,'P&L by Month Detail'!G:G) -> 581869 | G14: =SUMIF('P&L by Month Detail'!$A:$A,'Condensed P&L by Month'!$A14,'P&L by Month Detail'!H:H) -> 578956 | H14: =SUMIF('P&L by Month Detail'!$A:$A,'Condensed P&L by Month'!$A14,'P&L by Month Detail'!I:I) -> 547217 | I14: =SUMIF('P&L by Month Detail'!$A:$A,'Condensed P&L by Month'!$A14,'P&L by Month Detail'!J:J) -> 587835 | J14: =SUMIF('P&L by Month Detail'!$A:$A,'Condensed P&L by Month'!$A14,'P&L by Month Detail'!K:K) -> 573925 | K14: =SUMIF('P&L by Month Detail'!$A:$A,'Condensed P&L by Month'!$A14,'P&L by Month Detail'!L:L) -> 595438 | L14: =SUMIF('P&L by Month Detail'!$A:$A,'Condensed P&L by Month'!$A14,'P&L by Month Detail'!M:M) -> 584502 | M14: =SUMIF('P&L by Month Detail'!$A:$A,'Condensed P&L by Month'!$A14,'P&L by Month Detail'!N:N) -> 587391 | N14: =SUMIF('P&L by Month Detail'!$A:$A,'Condensed P&L by Month'!$A14,'P&L by Month Detail'!O:O) -> 550648 | O14: =SUMIF('P&L by Month Detail'!$A:$A,'Condensed P&L by Month'!$A14,'P&L by Month Detail'!P:P) -> 541962 | P14: =SUMIF('P&L by Month Detail'!$A:$A,'Condensed P&L by Month'!$A14,'P&L by Month Detail'!Q:Q) -> 537364 | Q14: =+SUM(F14:P14)+B14 -> 6854056
A15: Monthly Recurring Private Cloud | B15: =SUMIF('P&L by Month Detail'!$A:$A,'Condensed P&L by Month'!$A15,'P&L by Month Detail'!C:C) -> 27201 | C15: =SUMIF('P&L by Month Detail'!$A:$A,'Condensed P&L by Month'!$A15,'P&L by Month Detail'!D:D) -> 0 | D15: =+B15+C15 -> 27201 | F15: =SUMIF('P&L by Month Detail'!$A:$A,'Condensed P&L by Month'!$A15,'P&L by Month Detail'!G:G) -> 27015 | G15: =SUMIF('P&L by Month Detail'!$A:$A,'Condensed P&L by Month'!$A15,'P&L by Month Detail'!H:H) -> 26997 | H15: =SUMIF('P&L by Month Detail'!$A:$A,'Condensed P&L by Month'!$A15,'P&L by Month Detail'!I:I) -> 21601 | I15: =SUMIF('P&L by Month Detail'!$A:$A,'Condensed P&L by Month'!$A15,'P&L by Month Detail'!J:J) -> 26424 | J15: =SUMIF('P&L by Month Detail'!$A:$A,'Condensed P&L by Month'!$A15,'P&L by Month Detail'!K:K) -> 26261 | K15: =SUMIF('P&L by Month Detail'!$A:$A,'Condensed P&L by Month'!$A15,'P&L by Month Detail'!L:L) -> 24486 | L15: =SUMIF('P&L by Month Detail'!$A:$A,'Condensed P&L by Month'!$A15,'P&L by Month Detail'!M:M) -> 24468 | M15: =SUMIF('P&L by Month Detail'!$A:$A,'Condensed P&L by Month'!$A15,'P&L by Month Detail'!N:N) -> 23204 | N15: =SUMIF('P&L by Month Detail'!$A:$A,'Condensed P&L by Month'!$A15,'P&L by Month Detail'!O:O) -> 22726 | O15: =SUMIF('P&L by Month Detail'!$A:$A,'Condensed P&L by Month'!$A15,'P&L by Month Detail'!P:P) -> 22726 | P15: =SUMIF('P&L by Month Detail'!$A:$A,'Condensed P&L by Month'!$A15,'P&L by Month Detail'!Q:Q) -> 20137 | Q15: =+SUM(F15:P15)+B15 -> 293246
A16: Monthly Recurring Resale | B16: =SUMIF('P&L by Month Detail'!$A:$A,'Condensed P&L by Month'!$A16,'P&L by Month Detail'!C:C) -> 293462 | C16: =SUMIF('P&L by Month Detail'!$A:$A,'Condensed P&L by Month'!$A16,'P&L by Month Detail'!D:D) -> -60357 | D16: =+B16+C16 -> 233105 | E16: 1 | F16: =SUMIF('P&L by Month Detail'!$A:$A,'Condensed P&L by Month'!$A16,'P&L by Month Detail'!G:G) -> 352224 | G16: =SUMIF('P&L by Month Detail'!$A:$A,'Condensed P&L by Month'!$A16,'P&L by Month Detail'!H:H) -> 356786 | H16: =SUMIF('P&L by Month Detail'!$A:$A,'Condensed P&L by Month'!$A16,'P&L by Month Detail'!I:I) -> 299709 | I16: =SUMIF('P&L by Month Detail'!$A:$A,'Condensed P&L by Month'!$A16,'P&L by Month Detail'!J:J) -> 308346 | J16: =SUMIF('P&L by Month Detail'!$A:$A,'Condensed P&L by Month'!$A16,'P&L by Month Detail'!K:K) -> 307801 | K16: =SUMIF('P&L by Month Detail'!$A:$A,'Condensed P&L by Month'!$A16,'P&L by Month Detail'!L:L) -> 301279 | L16: =SUMIF('P&L by Month Detail'!$A:$A,'Condensed P&L by Month'!$A16,'P&L by Month Detail'!M:M) -> 309155 | M16: =SUMIF('P&L by Month Detail'!$A:$A,'Condensed P&L by Month'!$A16,'P&L by Month Detail'!N:N) -> 271511 | N16: =SUMIF('P&L by Month Detail'!$A:$A,'Condensed P&L by Month'!$A16,'P&L by Month Detail'!O:O) -> 265320 | O16: =SUMIF('P&L by Month Detail'!$A:$A,'Condensed P&L by Month'!$A16,'P&L by Month Detail'!P:P) -> 247561 | P16: =SUMIF('P&L by Month Detail'!$A:$A,'Condensed P&L by Month'!$A16,'P&L by Month Detail'!Q:Q) -> 238972 | Q16: =+SUM(F16:P16)+B16 -> 3552126
A17: Revenue - Project Services | B17: =SUMIF('P&L by Month Detail'!$A:$A,'Condensed P&L by Month'!$A17,'P&L by Month Detail'!C:C) -> 61485 | C17: =SUMIF('P&L by Month Detail'!$A:$A,'Condensed P&L by Month'!$A17,'P&L by Month Detail'!D:D) -> 43058.14 | D17: =+B17+C17 -> 104543.14 | E17: 2 | F17: =SUMIF('P&L by Month Detail'!$A:$A,'Condensed P&L by Month'!$A17,'P&L by Month Detail'!G:G) -> 47381 | G17: =SUMIF('P&L by Month Detail'!$A:$A,'Condensed P&L by Month'!$A17,'P&L by Month Detail'!H:H) -> 67554 | H17: =SUMIF('P&L by Month Detail'!$A:$A,'Condensed P&L by Month'!$A17,'P&L by Month Detail'!I:I) -> 46071 | I17: =SUMIF('P&L by Month Detail'!$A:$A,'Condensed P&L by Month'!$A17,'P&L by Month Detail'!J:J) -> 104693 | J17: =SUMIF('P&L by Month Detail'!$A:$A,'Condensed P&L by Month'!$A17,'P&L by Month Detail'!K:K) -> 53462 | K17: =SUMIF('P&L by Month Detail'!$A:$A,'Condensed P&L by Month'!$A17,'P&L by Month Detail'!L:L) -> 120765 | L17: =SUMIF('P&L by Month Detail'!$A:$A,'Condensed P&L by Month'!$A17,'P&L by Month Detail'!M:M) -> 47201 | M17: =SUMIF('P&L by Month Detail'!$A:$A,'Condensed P&L by Month'!$A17,'P&L by Month Detail'!N:N) -> 99226 | N17: =SUMIF('P&L by Month Detail'!$A:$A,'Condensed P&L by Month'!$A17,'P&L by Month Detail'!O:O) -> 105235 | O17: =SUMIF('P&L by Month Detail'!$A:$A,'Condensed P&L by Month'!$A17,'P&L by Month Detail'!P:P) -> 92496 | P17: =SUMIF('P&L by Month Detail'!$A:$A,'Condensed P&L by Month'!$A17,'P&L by Month Detail'!Q:Q) -> 51717 | Q17: =+SUM(F17:P17)+B17 -> 897286
A18: Subcontracted Services | B18: =SUMIF('P&L by Month Detail'!$A:$A,'Condensed P&L by Month'!$A18,'P&L by Month Detail'!C:C) -> 4614 | C18: =SUMIF('P&L by Month Detail'!$A:$A,'Condensed P&L by Month'!$A18,'P&L by Month Detail'!D:D) -> 0 | D18: =+B18+C18 -> 4614 | F18: =SUMIF('P&L by Month Detail'!$A:$A,'Condensed P&L by Month'!$A18,'P&L by Month Detail'!G:G) -> 13197 | G18: =SUMIF('P&L by Month Detail'!$A:$A,'Condensed P&L by Month'!$A18,'P&L by Month Detail'!H:H) -> 19989 | H18: =SUMIF('P&L by Month Detail'!$A:$A,'Condensed P&L by Month'!$A18,'P&L by Month Detail'!I:I) -> 14480 | I18: =SUMIF('P&L by Month Detail'!$A:$A,'Condensed P&L by Month'!$A18,'P&L by Month Detail'!J:J) -> 36139 | J18: =SUMIF('P&L by Month Detail'!$A:$A,'Condensed P&L by Month'!$A18,'P&L by Month Detail'!K:K) -> 12686 | K18: =SUMIF('P&L by Month Detail'!$A:$A,'Condensed P&L by Month'!$A18,'P&L by Month Detail'!L:L) -> 8539 | L18: =SUMIF('P&L by Month Detail'!$A:$A,'Condensed P&L by Month'!$A18,'P&L by Month Detail'!M:M) -> 16341 | M18: =SUMIF('P&L by Month Detail'!$A:$A,'Condensed P&L by Month'!$A18,'P&L by Month Detail'!N:N) -> 14387 | N18: =SUMIF('P&L by Month Detail'!$A:$A,'Condensed P&L by Month'!$A18,'P&L by Month Detail'!O:O) -> 35020 | O18: =SUMIF('P&L by Month Detail'!$A:$A,'Condensed P&L by Month'!$A18,'P&L by Month Detail'!P:P) -> 58116 | P18: =SUMIF('P&L by Month Detail'!$A:$A,'Condensed P&L by Month'!$A18,'P&L by Month Detail'!Q:Q) -> 86683 | Q18: =+SUM(F18:P18)+B18 -> 320191
A19: Revenue - Product Sales | B19: =SUMIF('P&L by Month Detail'!$A:$A,'Condensed P&L by Month'!$A19,'P&L by Month Detail'!C:C) -> 157725 | C19: =SUMIF('P&L by Month Detail'!$A:$A,'Condensed P&L by Month'!$A19,'P&L by Month Detail'!D:D) -> 0 | D19: =+B19+C19 -> 157725 | F19: =SUMIF('P&L by Month Detail'!$A:$A,'Condensed P&L by Month'!$A19,'P&L by Month Detail'!G:G) -> 286085 | G19: =SUMIF('P&L by Month Detail'!$A:$A,'Condensed P&L by Month'!$A19,'P&L by Month Detail'!H:H) -> 578813 | H19: =SUMIF('P&L by Month Detail'!$A:$A,'Condensed P&L by Month'!$A19,'P&L by Month Detail'!I:I) -> 364070 | I19: =SUMIF('P&L by Month Detail'!$A:$A,'Condensed P&L by Month'!$A19,'P&L by Month Detail'!J:J) -> 667670 | J19: =SUMIF('P&L by Month Detail'!$A:$A,'Condensed P&L by Month'!$A19,'P&L by Month Detail'!K:K) -> 803455 | K19: =SUMIF('P&L by Month Detail'!$A:$A,'Condensed P&L by Month'!$A19,'P&L by Month Detail'!L:L) -> 598232 | L19: =SUMIF('P&L by Month Detail'!$A:$A,'Condensed P&L by Month'!$A19,'P&L by Month Detail'!M:M) -> 500988 | M19: =SUMIF('P&L by Month Detail'!$A:$A,'Condensed P&L by Month'!$A19,'P&L by Month Detail'!N:N) -> 584904 | N19: =SUMIF('P&L by Month Detail'!$A:$A,'Condensed P&L by Month'!$A19,'P&L by Month Detail'!O:O) -> 440383 | O19: =SUMIF('P&L by Month Detail'!$A:$A,'Condensed P&L by Month'!$A19,'P&L by Month Detail'!P:P) -> 554032 | P19: =SUMIF('P&L by Month Detail'!$A:$A,'Condensed P&L by Month'!$A19,'P&L by Month Detail'!Q:Q) -> 211805 | Q19: =+SUM(F19:P19)+B19 -> 5748162
A20: Revenue - Other | B20: =SUMIF('P&L by Month Detail'!$A:$A,'Condensed P&L by Month'!$A20,'P&L by Month Detail'!C:C) -> 4906 | C20: =SUMIF('P&L by Month Detail'!$A:$A,'Condensed P&L by Month'!$A20,'P&L by Month Detail'!D:D) -> 0 | D20: =+B20+C20 -> 4906 | F20: =SUMIF('P&L by Month Detail'!$A:$A,'Condensed P&L by Month'!$A20,'P&L by Month Detail'!G:G) -> 9277 | G20: =SUMIF('P&L by Month Detail'!$A:$A,'Condensed P&L by Month'!$A20,'P&L by Month Detail'!H:H) -> 9108 | H20: =SUMIF('P&L by Month Detail'!$A:$A,'Condensed P&L by Month'!$A20,'P&L by Month Detail'!I:I) -> 6305 | I20: =SUMIF('P&L by Month Detail'!$A:$A,'Condensed P&L by Month'!$A20,'P&L by Month Detail'!J:J) -> 6386 | J20: =SUMIF('P&L by Month Detail'!$A:$A,'Condensed P&L by Month'!$A20,'P&L by Month Detail'!K:K) -> 7049 | K20: =SUMIF('P&L by Month Detail'!$A:$A,'Condensed P&L by Month'!$A20,'P&L by Month Detail'!L:L) -> 3891 | L20: =SUMIF('P&L by Month Detail'!$A:$A,'Condensed P&L by Month'!$A20,'P&L by Month Detail'!M:M) -> 7133 | M20: =SUMIF('P&L by Month Detail'!$A:$A,'Condensed P&L by Month'!$A20,'P&L by Month Detail'!N:N) -> 11171 | N20: =SUMIF('P&L by Month Detail'!$A:$A,'Condensed P&L by Month'!$A20,'P&L by Month Detail'!O:O) -> 11139 | O20: =SUMIF('P&L by Month Detail'!$A:$A,'Condensed P&L by Month'!$A20,'P&L by Month Detail'!P:P) -> 7690 | P20: =SUMIF('P&L by Month Detail'!$A:$A,'Condensed P&L by Month'!$A20,'P&L by Month Detail'!Q:Q) -> 5590 | Q20: =+SUM(F20:P20)+B20 -> 89645
A21: Total Revenue | B21: =SUM(B14:B20) -> 1136342 | C21: =SUM(C14:C20) -> -17298.86 | D21: =SUM(D14:D20) -> 1119043.1 | F21: =SUM(F14:F20) -> 1317048 | G21: =SUM(G14:G20) -> 1638203 | H21: =SUM(H14:H20) -> 1299453 | I21: =SUM(I14:I20) -> 1737493 | J21: =SUM(J14:J20) -> 1784639 | K21: =SUM(K14:K20) -> 1652630 | L21: =SUM(L14:L20) -> 1489788 | M21: =SUM(M14:M20) -> 1591794 | ... Q21: =SUM(Q14:Q20) -> 17754712
A22: Cost of Rev with Direct and IT Project Labor
A23: Managed IT Service Costs | B23: =SUMIF('P&L by Month Detail'!$A:$A,'Condensed P&L by Month'!$A23,'P&L by Month Detail'!C:C) -> 28797 | C23: =SUMIF('P&L by Month Detail'!$A:$A,'Condensed P&L by Month'!$A23,'P&L by Month Detail'!D:D) -> 0 | D23: =+B23+C23 -> 28797 | F23: =SUMIF('P&L by Month Detail'!$A:$A,'Condensed P&L by Month'!$A23,'P&L by Month Detail'!G:G) -> 16754 | G23: =SUMIF('P&L by Month Detail'!$A:$A,'Condensed P&L by Month'!$A23,'P&L by Month Detail'!H:H) -> 38253 | H23: =SUMIF('P&L by Month Detail'!$A:$A,'Condensed P&L by Month'!$A23,'P&L by Month Detail'!I:I) -> 29904 | I23: =SUMIF('P&L by Month Detail'!$A:$A,'Condensed P&L by Month'!$A23,'P&L by Month Detail'!J:J) -> 28443 | J23: =SUMIF('P&L by Month Detail'!$A:$A,'Condensed P&L by Month'!$A23,'P&L by Month Detail'!K:K) -> 24465 | K23: =SUMIF('P&L by Month Detail'!$A:$A,'Condensed P&L by Month'!$A23,'P&L by Month Detail'!L:L) -> 22966 | L23: =SUMIF('P&L by Month Detail'!$A:$A,'Condensed P&L by Month'!$A23,'P&L by Month Detail'!M:M) -> 26243 | M23: =SUMIF('P&L by Month Detail'!$A:$A,'Condensed P&L by Month'!$A23,'P&L by Month Detail'!N:N) -> 23445 | N23: =SUMIF('P&L by Month Detail'!$A:$A,'Condensed P&L by Month'!$A23,'P&L by Month Detail'!O:O) -> 22148 | O23: =SUMIF('P&L by Month Detail'!$A:$A,'Condensed P&L by Month'!$A23,'P&L by Month Detail'!P:P) -> 24343 | P23: =SUMIF('P&L by Month Detail'!$A:$A,'Condensed P&L by Month'!$A23,'P&L by Month Detail'!Q:Q) -> 22885 | Q23: =+SUM(F23:P23)+B23 -> 308646
A24: Cost of Monthly Recurring Cloud | B24: =SUMIF('P&L by Month Detail'!$A:$A,'Condensed P&L by Month'!$A24,'P&L by Month Detail'!C:C) -> 11313 | C24: =SUMIF('P&L by Month Detail'!$A:$A,'Condensed P&L by Month'!$A24,'P&L by Month Detail'!D:D) -> 0 | D24: =+B24+C24 -> 11313 | F24: =SUMIF('P&L by Month Detail'!$A:$A,'Condensed P&L by Month'!$A24,'P&L by Month Detail'!G:G) -> 11740 | G24: =SUMIF('P&L by Month Detail'!$A:$A,'Condensed P&L by Month'!$A24,'P&L by Month Detail'!H:H) -> 11403 | H24: =SUMIF('P&L by Month Detail'!$A:$A,'Condensed P&L by Month'!$A24,'P&L by Month Detail'!I:I) -> 9013 | I24: =SUMIF('P&L by Month Detail'!$A:$A,'Condensed P&L by Month'!$A24,'P&L by Month Detail'!J:J) -> 11283 | J24: =SUMIF('P&L by Month Detail'!$A:$A,'Condensed P&L by Month'!$A24,'P&L by Month Detail'!K:K) -> 11187 | K24: =SUMIF('P&L by Month Detail'!$A:$A,'Condensed P&L by Month'!$A24,'P&L by Month Detail'!L:L) -> 11665 | L24: =SUMIF('P&L by Month Detail'!$A:$A,'Condensed P&L by Month'!$A24,'P&L by Month Detail'!M:M) -> 13395 | M24: =SUMIF('P&L by Month Detail'!$A:$A,'Condensed P&L by Month'!$A24,'P&L by Month Detail'!N:N) -> 10285 | N24: =SUMIF('P&L by Month Detail'!$A:$A,'Condensed P&L by Month'!$A24,'P&L by Month Detail'!O:O) -> 10286 | O24: =SUMIF('P&L by Month Detail'!$A:$A,'Condensed P&L by Month'!$A24,'P&L by Month Detail'!P:P) -> 10352 | P24: =SUMIF('P&L by Month Detail'!$A:$A,'Condensed P&L by Month'!$A24,'P&L by Month Detail'!Q:Q) -> 8915 | Q24: =+SUM(F24:P24)+B24 -> 130837
A25: Cost of Monthly Recurring Resale | B25: =SUMIF('P&L by Month Detail'!$A:$A,'Condensed P&L by Month'!$A25,'P&L by Month Detail'!C:C) -> 221137 | C25: =SUMIF('P&L by Month Detail'!$A:$A,'Condensed P&L by Month'!$A25,'P&L by Month Detail'!D:D) -> 0 | D25: =+B25+C25 -> 221137 | F25: =SUMIF('P&L by Month Detail'!$A:$A,'Condensed P&L by Month'!$A25,'P&L by Month Detail'!G:G) -> 224909 | G25: =SUMIF('P&L by Month Detail'!$A:$A,'Condensed P&L by Month'!$A25,'P&L by Month Detail'!H:H) -> 229434 | H25: =SUMIF('P&L by Month Detail'!$A:$A,'Condensed P&L by Month'!$A25,'P&L by Month Detail'!I:I) -> 177322 | I25: =SUMIF('P&L by Month Detail'!$A:$A,'Condensed P&L by Month'!$A25,'P&L by Month Detail'!J:J) -> 178977 | J25: =SUMIF('P&L by Month Detail'!$A:$A,'Condensed P&L by Month'!$A25,'P&L by Month Detail'!K:K) -> 177862 | K25: =SUMIF('P&L by Month Detail'!$A:$A,'Condensed P&L by Month'!$A25,'P&L by Month Detail'!L:L) -> 173126 | L25: =SUMIF('P&L by Month Detail'!$A:$A,'Condensed P&L by Month'!$A25,'P&L by Month Detail'!M:M) -> 166534 | M25: =SUMIF('P&L by Month Detail'!$A:$A,'Condensed P&L by Month'!$A25,'P&L by Month Detail'!N:N) -> 172048 | N25: =SUMIF('P&L by Month Detail'!$A:$A,'Condensed P&L by Month'!$A25,'P&L by Month Detail'!O:O) -> 171015 | O25: =SUMIF('P&L by Month Detail'!$A:$A,'Condensed P&L by Month'!$A25,'P&L by Month Detail'!P:P) -> 159224 | P25: =SUMIF('P&L by Month Detail'!$A:$A,'Condensed P&L by Month'!$A25,'P&L by Month Detail'!Q:Q) -> 157949 | Q25: =+SUM(F25:P25)+B25 -> 2209537
A26: Project Service Costs | B26: =SUMIF('P&L by Month Detail'!$A:$A,'Condensed P&L by Month'!$A26,'P&L by Month Detail'!C:C) -> 0 | C26: =SUMIF('P&L by Month Detail'!$A:$A,'Condensed P&L by Month'!$A26,'P&L by Month Detail'!D:D) -> 0 | D26: =+B26+C26 -> 0 | F26: =SUMIF('P&L by Month Detail'!$A:$A,'Condensed P&L by Month'!$A26,'P&L by Month Detail'!G:G) -> 0 | G26: =SUMIF('P&L by Month Detail'!$A:$A,'Condensed P&L by Month'!$A26,'P&L by Month Detail'!H:H) -> 0 | H26: =SUMIF('P&L by Month Detail'!$A:$A,'Condensed P&L by Month'!$A26,'P&L by Month Detail'!I:I) -> 0 | I26: =SUMIF('P&L by Month Detail'!$A:$A,'Condensed P&L by Month'!$A26,'P&L by Month Detail'!J:J) -> 0 | J26: =SUMIF('P&L by Month Detail'!$A:$A,'Condensed P&L by Month'!$A26,'P&L by Month Detail'!K:K) -> 1028 | K26: =SUMIF('P&L by Month Detail'!$A:$A,'Condensed P&L by Month'!$A26,'P&L by Month Detail'!L:L) -> 1215 | L26: =SUMIF('P&L by Month Detail'!$A:$A,'Condensed P&L by Month'!$A26,'P&L by Month Detail'!M:M) -> 632 | M26: =SUMIF('P&L by Month Detail'!$A:$A,'Condensed P&L by Month'!$A26,'P&L by Month Detail'!N:N) -> 0 | N26: =SUMIF('P&L by Month Detail'!$A:$A,'Condensed P&L by Month'!$A26,'P&L by Month Detail'!O:O) -> 24 | O26: =SUMIF('P&L by Month Detail'!$A:$A,'Condensed P&L by Month'!$A26,'P&L by Month Detail'!P:P) -> 0 | P26: =SUMIF('P&L by Month Detail'!$A:$A,'Condensed P&L by Month'!$A26,'P&L by Month Detail'!Q:Q) -> 0 | Q26: =+SUM(F26:P26)+B26 -> 2899
A27: Subcontractor Service Costs | B27: =SUMIF('P&L by Month Detail'!$A:$A,'Condensed P&L by Month'!$A27,'P&L by Month Detail'!C:C) -> 2305 | C27: =SUMIF('P&L by Month Detail'!$A:$A,'Condensed P&L by Month'!$A27,'P&L by Month Detail'!D:D) -> 0 | D27: =+B27+C27 -> 2305 | F27: =SUMIF('P&L by Month Detail'!$A:$A,'Condensed P&L by Month'!$A27,'P&L by Month Detail'!G:G) -> 23527 | G27: =SUMIF('P&L by Month Detail'!$A:$A,'Condensed P&L by Month'!$A27,'P&L by Month Detail'!H:H) -> 23040 | H27: =SUMIF('P&L by Month Detail'!$A:$A,'Condensed P&L by Month'!$A27,'P&L by Month Detail'!I:I) -> 13423 | I27: =SUMIF('P&L by Month Detail'!$A:$A,'Condensed P&L by Month'!$A27,'P&L by Month Detail'!J:J) -> 31339 | J27: =SUMIF('P&L by Month Detail'!$A:$A,'Condensed P&L by Month'!$A27,'P&L by Month Detail'!K:K) -> 11923 | K27: =SUMIF('P&L by Month Detail'!$A:$A,'Condensed P&L by Month'!$A27,'P&L by Month Detail'!L:L) -> 6946 | L27: =SUMIF('P&L by Month Detail'!$A:$A,'Condensed P&L by Month'!$A27,'P&L by Month Detail'!M:M) -> 13493 | M27: =SUMIF('P&L by Month Detail'!$A:$A,'Condensed P&L by Month'!$A27,'P&L by Month Detail'!N:N) -> 14836 | N27: =SUMIF('P&L by Month Detail'!$A:$A,'Condensed P&L by Month'!$A27,'P&L by Month Detail'!O:O) -> 29319 | O27: =SUMIF('P&L by Month Detail'!$A:$A,'Condensed P&L by Month'!$A27,'P&L by Month Detail'!P:P) -> 48356 | P27: =SUMIF('P&L by Month Detail'!$A:$A,'Condensed P&L by Month'!$A27,'P&L by Month Detail'!Q:Q) -> 72436 | Q27: =+SUM(F27:P27)+B27 -> 290943
A28: Product Sales Cost | B28: =SUMIF('P&L by Month Detail'!$A:$A,'Condensed P&L by Month'!$A28,'P&L by Month Detail'!C:C) -> 102255 | C28: =SUMIF('P&L by Month Detail'!$A:$A,'Condensed P&L by Month'!$A28,'P&L by Month Detail'!D:D) -> 42625.69 | D28: =+B28+C28 -> 144880.69 | E28: 3 | F28: =SUMIF('P&L by Month Detail'!$A:$A,'Condensed P&L by Month'!$A28,'P&L by Month Detail'!G:G) -> 240342 | G28: =SUMIF('P&L by Month Detail'!$A:$A,'Condensed P&L by Month'!$A28,'P&L by Month Detail'!H:H) -> 486006 | H28: =SUMIF('P&L by Month Detail'!$A:$A,'Condensed P&L by Month'!$A28,'P&L by Month Detail'!I:I) -> 321154 | I28: =SUMIF('P&L by Month Detail'!$A:$A,'Condensed P&L by Month'!$A28,'P&L by Month Detail'!J:J) -> 569431 | J28: =SUMIF('P&L by Month Detail'!$A:$A,'Condensed P&L by Month'!$A28,'P&L by Month Detail'!K:K) -> 694977 | K28: =SUMIF('P&L by Month Detail'!$A:$A,'Condensed P&L by Month'!$A28,'P&L by Month Detail'!L:L) -> 506712 | L28: =SUMIF('P&L by Month Detail'!$A:$A,'Condensed P&L by Month'!$A28,'P&L by Month Detail'!M:M) -> 409890 | M28: =SUMIF('P&L by Month Detail'!$A:$A,'Condensed P&L by Month'!$A28,'P&L by Month Detail'!N:N) -> 495271 | N28: =SUMIF('P&L by Month Detail'!$A:$A,'Condensed P&L by Month'!$A28,'P&L by Month Detail'!O:O) -> 370688 | O28: =SUMIF('P&L by Month Detail'!$A:$A,'Condensed P&L by Month'!$A28,'P&L by Month Detail'!P:P) -> 471991 | P28: =SUMIF('P&L by Month Detail'!$A:$A,'Condensed P&L by Month'!$A28,'P&L by Month Detail'!Q:Q) -> 180392 | Q28: =+SUM(F28:P28)+B28 -> 4849109
A29: IT Project Labor | B29: =SUMIF('P&L by Month Detail'!$A:$A,'Condensed P&L by Month'!$A29,'P&L by Month Detail'!C:C) -> -2116 | C29: =SUMIF('P&L by Month Detail'!$A:$A,'Condensed P&L by Month'!$A29,'P&L by Month Detail'!D:D) -> 68871.5 | D29: =+B29+C29 -> 66755.5 | E29: 5 | F29: =SUMIF('P&L by Month Detail'!$A:$A,'Condensed P&L by Month'!$A29,'P&L by Month Detail'!G:G) -> 51988 | G29: =SUMIF('P&L by Month Detail'!$A:$A,'Condensed P&L by Month'!$A29,'P&L by Month Detail'!H:H) -> 57904 | H29: =SUMIF('P&L by Month Detail'!$A:$A,'Condensed P&L by Month'!$A29,'P&L by Month Detail'!I:I) -> 55387 | I29: =SUMIF('P&L by Month Detail'!$A:$A,'Condensed P&L by Month'!$A29,'P&L by Month Detail'!J:J) -> 64553 | J29: =SUMIF('P&L by Month Detail'!$A:$A,'Condensed P&L by Month'!$A29,'P&L by Month Detail'!K:K) -> 65070 | K29: =SUMIF('P&L by Month Detail'!$A:$A,'Condensed P&L by Month'!$A29,'P&L by Month Detail'!L:L) -> 61677 | L29: =SUMIF('P&L by Month Detail'!$A:$A,'Condensed P&L by Month'!$A29,'P&L by Month Detail'!M:M) -> 64595 | M29: =SUMIF('P&L by Month Detail'!$A:$A,'Condensed P&L by Month'!$A29,'P&L by Month Detail'!N:N) -> 67481 | N29: =SUMIF('P&L by Month Detail'!$A:$A,'Condensed P&L by Month'!$A29,'P&L by Month Detail'!O:O) -> 71122 | O29: =SUMIF('P&L by Month Detail'!$A:$A,'Condensed P&L by Month'!$A29,'P&L by Month Detail'!P:P) -> 64602 | P29: =SUMIF('P&L by Month Detail'!$A:$A,'Condensed P&L by Month'!$A29,'P&L by Month Detail'!Q:Q) -> 69884 | Q29: =+SUM(F29:P29)+B29 -> 692147
A30: Direct Labor Costs | B30: =SUMIF('P&L by Month Detail'!$A:$A,'Condensed P&L by Month'!$A30,'P&L by Month Detail'!C:C) -> 325620 | C30: =SUMIF('P&L by Month Detail'!$A:$A,'Condensed P&L by Month'!$A30,'P&L by Month Detail'!D:D) -> -91087.33 | D30: =+B30+C30 -> 234532.67 | E30: 5 & 6 | F30: =SUMIF('P&L by Month Detail'!$A:$A,'Condensed P&L by Month'!$A30,'P&L by Month Detail'!G:G) -> 174861 | G30: =SUMIF('P&L by Month Detail'!$A:$A,'Condensed P&L by Month'!$A30,'P&L by Month Detail'!H:H) -> 206820 | H30: =SUMIF('P&L by Month Detail'!$A:$A,'Condensed P&L by Month'!$A30,'P&L by Month Detail'!I:I) -> 210696 | I30: =SUMIF('P&L by Month Detail'!$A:$A,'Condensed P&L by Month'!$A30,'P&L by Month Detail'!J:J) -> 189126 | J30: =SUMIF('P&L by Month Detail'!$A:$A,'Condensed P&L by Month'!$A30,'P&L by Month Detail'!K:K) -> 218508 | K30: =SUMIF('P&L by Month Detail'!$A:$A,'Condensed P&L by Month'!$A30,'P&L by Month Detail'!L:L) -> 205476 | L30: =SUMIF('P&L by Month Detail'!$A:$A,'Condensed P&L by Month'!$A30,'P&L by Month Detail'!M:M) -> 203541 | M30: =SUMIF('P&L by Month Detail'!$A:$A,'Condensed P&L by Month'!$A30,'P&L by Month Detail'!N:N) -> 194932 | N30: =SUMIF('P&L by Month Detail'!$A:$A,'Condensed P&L by Month'!$A30,'P&L by Month Detail'!O:O) -> 227117 | O30: =SUMIF('P&L by Month Detail'!$A:$A,'Condensed P&L by Month'!$A30,'P&L by Month Detail'!P:P) -> 203182 | P30: =SUMIF('P&L by Month Detail'!$A:$A,'Condensed P&L by Month'!$A30,'P&L by Month Detail'!Q:Q) -> 227678 | Q30: =+SUM(F30:P30)+B30 -> 2587557
A31: Total Cost of Rev with IT Project and Direct Labor | B31: =SUM(B23:B30) -> 689311 | C31: =SUM(C23:C30) -> 20409.86 | D31: =SUM(D23:D30) -> 709720.86 | F31: =SUM(F23:F30) -> 744121 | G31: =SUM(G23:G30) -> 1052860 | H31: =SUM(H23:H30) -> 816899 | I31: =SUM(I23:I30) -> 1073152 | J31: =SUM(J23:J30) -> 1205020 | K31: =SUM(K23:K30) -> 989783 | L31: =SUM(L23:L30) -> 898323 | M31: =SUM(M23:M30) -> 978298 | ... Q31: =SUM(Q23:Q30) -> 11071675
A32: Total Gross Profit with Direct Labor | B32: =SUMIF('P&L by Month Detail'!$A:$A,'Condensed P&L by Month'!$A32,'P&L by Month Detail'!C:C) -> 447031 | C32: =SUMIF('P&L by Month Detail'!$A:$A,'Condensed P&L by Month'!$A32,'P&L by Month Detail'!D:D) -> -37708.72 | D32: =+B32+C32 -> 409322.28 | F32: =SUMIF('P&L by Month Detail'!$A:$A,'Condensed P&L by Month'!$A32,'P&L by Month Detail'!G:G) -> 572927 | G32: =SUMIF('P&L by Month Detail'!$A:$A,'Condensed P&L by Month'!$A32,'P&L by Month Detail'!H:H) -> 585343 | H32: =SUMIF('P&L by Month Detail'!$A:$A,'Condensed P&L by Month'!$A32,'P&L by Month Detail'!I:I) -> 482554 | I32: =SUMIF('P&L by Month Detail'!$A:$A,'Condensed P&L by Month'!$A32,'P&L by Month Detail'!J:J) -> 664341 | J32: =SUMIF('P&L by Month Detail'!$A:$A,'Condensed P&L by Month'!$A32,'P&L by Month Detail'!K:K) -> 579619 | K32: =SUMIF('P&L by Month Detail'!$A:$A,'Condensed P&L by Month'!$A32,'P&L by Month Detail'!L:L) -> 662847 | L32: =SUMIF('P&L by Month Detail'!$A:$A,'Condensed P&L by Month'!$A32,'P&L by Month Detail'!M:M) -> 591465 | M32: =SUMIF('P&L by Month Detail'!$A:$A,'Condensed P&L by Month'!$A32,'P&L by Month Detail'!N:N) -> 613496 | N32: =SUMIF('P&L by Month Detail'!$A:$A,'Condensed P&L by Month'!$A32,'P&L by Month Detail'!O:O) -> 528752 | O32: =SUMIF('P&L by Month Detail'!$A:$A,'Condensed P&L by Month'!$A32,'P&L by Month Detail'!P:P) -> 542533 | P32: =SUMIF('P&L by Month Detail'!$A:$A,'Condensed P&L by Month'!$A32,'P&L by Month Detail'!Q:Q) -> 412129 | Q32: =+SUM(F32:P32)+B32 -> 6683037
A33: Sales Labor Costs | B33: =SUMIF('P&L by Month Detail'!$A:$A,'Condensed P&L by Month'!$A33,'P&L by Month Detail'!C:C) -> 31075 | C33: =SUMIF('P&L by Month Detail'!$A:$A,'Condensed P&L by Month'!$A33,'P&L by Month Detail'!D:D) -> 95959.63 | D33: =+B33+C33 -> 127034.63 | E33: 5 | F33: =SUMIF('P&L by Month Detail'!$A:$A,'Condensed P&L by Month'!$A33,'P&L by Month Detail'!G:G) -> 111629 | G33: =SUMIF('P&L by Month Detail'!$A:$A,'Condensed P&L by Month'!$A33,'P&L by Month Detail'!H:H) -> 197590 | H33: =SUMIF('P&L by Month Detail'!$A:$A,'Condensed P&L by Month'!$A33,'P&L by Month Detail'!I:I) -> 147595 | I33: =SUMIF('P&L by Month Detail'!$A:$A,'Condensed P&L by Month'!$A33,'P&L by Month Detail'!J:J) -> 145868 | J33: =SUMIF('P&L by Month Detail'!$A:$A,'Condensed P&L by Month'!$A33,'P&L by Month Detail'!K:K) -> 147139 | K33: =SUMIF('P&L by Month Detail'!$A:$A,'Condensed P&L by Month'!$A33,'P&L by Month Detail'!L:L) -> 129570 | L33: =SUMIF('P&L by Month Detail'!$A:$A,'Condensed P&L by Month'!$A33,'P&L by Month Detail'!M:M) -> 136510 | M33: =SUMIF('P&L by Month Detail'!$A:$A,'Condensed P&L by Month'!$A33,'P&L by Month Detail'!N:N) -> 128044 | N33: =SUMIF('P&L by Month Detail'!$A:$A,'Condensed P&L by Month'!$A33,'P&L by Month Detail'!O:O) -> 145044 | O33: =SUMIF('P&L by Month Detail'!$A:$A,'Condensed P&L by Month'!$A33,'P&L by Month Detail'!P:P) -> 166242 | P33: =SUMIF('P&L by Month Detail'!$A:$A,'Condensed P&L by Month'!$A33,'P&L by Month Detail'!Q:Q) -> 174805 | Q33: =+SUM(F33:P33)+B33 -> 1661111
A34: Operating Expense- no Direct or Sales Labor
A35: Payroll and Related Expenses no Direct or Sales Labor | B35: =SUMIF('P&L by Month Detail'!$A:$A,'Condensed P&L by Month'!$A35,'P&L by Month Detail'!C:C) -> 71324 | C35: =SUMIF('P&L by Month Detail'!$A:$A,'Condensed P&L by Month'!$A35,'P&L by Month Detail'!D:D) -> 14288.61 | D35: =+B35+C35 -> 85612.61 | E35: 5 | F35: =SUMIF('P&L by Month Detail'!$A:$A,'Condensed P&L by Month'!$A35,'P&L by Month Detail'!G:G) -> 54724 | G35: =SUMIF('P&L by Month Detail'!$A:$A,'Condensed P&L by Month'!$A35,'P&L by Month Detail'!H:H) -> 66012 | H35: =SUMIF('P&L by Month Detail'!$A:$A,'Condensed P&L by Month'!$A35,'P&L by Month Detail'!I:I) -> 75368 | I35: =SUMIF('P&L by Month Detail'!$A:$A,'Condensed P&L by Month'!$A35,'P&L by Month Detail'!J:J) -> 76247 | J35: =SUMIF('P&L by Month Detail'!$A:$A,'Condensed P&L by Month'!$A35,'P&L by Month Detail'!K:K) -> 88854 | K35: =SUMIF('P&L by Month Detail'!$A:$A,'Condensed P&L by Month'!$A35,'P&L by Month Detail'!L:L) -> 83226 | L35: =SUMIF('P&L by Month Detail'!$A:$A,'Condensed P&L by Month'!$A35,'P&L by Month Detail'!M:M) -> 85672 | M35: =SUMIF('P&L by Month Detail'!$A:$A,'Condensed P&L by Month'!$A35,'P&L by Month Detail'!N:N) -> 76476 | N35: =SUMIF('P&L by Month Detail'!$A:$A,'Condensed P&L by Month'!$A35,'P&L by Month Detail'!O:O) -> 86712 | O35: =SUMIF('P&L by Month Detail'!$A:$A,'Condensed P&L by Month'!$A35,'P&L by Month Detail'!P:P) -> 107567 | P35: =SUMIF('P&L by Month Detail'!$A:$A,'Condensed P&L by Month'!$A35,'P&L by Month Detail'!Q:Q) -> 88384 | Q35: =+SUM(F35:P35)+B35 -> 960566
A36: Utilities and Facilities | B36: =SUMIF('P&L by Month Detail'!$A:$A,'Condensed P&L by Month'!$A36,'P&L by Month Detail'!C:C) -> 46712 | C36: =SUMIF('P&L by Month Detail'!$A:$A,'Condensed P&L by Month'!$A36,'P&L by Month Detail'!D:D) -> 2773.88 | D36: =+B36+C36 -> 49485.88 | E36: 7 | F36: =SUMIF('P&L by Month Detail'!$A:$A,'Condensed P&L by Month'!$A36,'P&L by Month Detail'!G:G) -> 44444 | G36: =SUMIF('P&L by Month Detail'!$A:$A,'Condensed P&L by Month'!$A36,'P&L by Month Detail'!H:H) -> 32939 | H36: =SUMIF('P&L by Month Detail'!$A:$A,'Condensed P&L by Month'!$A36,'P&L by Month Detail'!I:I) -> 32562 | I36: =SUMIF('P&L by Month Detail'!$A:$A,'Condensed P&L by Month'!$A36,'P&L by Month Detail'!J:J) -> 43353 | J36: =SUMIF('P&L by Month Detail'!$A:$A,'Condensed P&L by Month'!$A36,'P&L by Month Detail'!K:K) -> 39315 | K36: =SUMIF('P&L by Month Detail'!$A:$A,'Condensed P&L by Month'!$A36,'P&L by Month Detail'!L:L) -> 38662 | L36: =SUMIF('P&L by Month Detail'!$A:$A,'Condensed P&L by Month'!$A36,'P&L by Month Detail'!M:M) -> 38240 | M36: =SUMIF('P&L by Month Detail'!$A:$A,'Condensed P&L by Month'!$A36,'P&L by Month Detail'!N:N) -> 39645 | N36: =SUMIF('P&L by Month Detail'!$A:$A,'Condensed P&L by Month'!$A36,'P&L by Month Detail'!O:O) -> 58379 | O36: =SUMIF('P&L by Month Detail'!$A:$A,'Condensed P&L by Month'!$A36,'P&L by Month Detail'!P:P) -> 40343 | P36: =SUMIF('P&L by Month Detail'!$A:$A,'Condensed P&L by Month'!$A36,'P&L by Month Detail'!Q:Q) -> 40050 | Q36: =+SUM(F36:P36)+B36 -> 494644
A37: Operating and Maintenance Expenses | B37: =SUMIF('P&L by Month Detail'!$A:$A,'Condensed P&L by Month'!$A37,'P&L by Month Detail'!C:C) -> 301681 | C37: =SUMIF('P&L by Month Detail'!$A:$A,'Condensed P&L by Month'!$A37,'P&L by Month Detail'!D:D) -> -245482.78 | D37: =+B37+C37 -> 56198.22 | E37: 8, 9 & 10 | F37: =SUMIF('P&L by Month Detail'!$A:$A,'Condensed P&L by Month'!$A37,'P&L by Month Detail'!G:G) -> 125361 | G37: =SUMIF('P&L by Month Detail'!$A:$A,'Condensed P&L by Month'!$A37,'P&L by Month Detail'!H:H) -> 93219 | H37: =SUMIF('P&L by Month Detail'!$A:$A,'Condensed P&L by Month'!$A37,'P&L by Month Detail'!I:I) -> 124862 | I37: =SUMIF('P&L by Month Detail'!$A:$A,'Condensed P&L by Month'!$A37,'P&L by Month Detail'!J:J) -> 127923 | J37: =SUMIF('P&L by Month Detail'!$A:$A,'Condensed P&L by Month'!$A37,'P&L by Month Detail'!K:K) -> 102371 | K37: =SUMIF('P&L by Month Detail'!$A:$A,'Condensed P&L by Month'!$A37,'P&L by Month Detail'!L:L) -> 97951 | L37: =SUMIF('P&L by Month Detail'!$A:$A,'Condensed P&L by Month'!$A37,'P&L by Month Detail'!M:M) -> 106192 | M37: =SUMIF('P&L by Month Detail'!$A:$A,'Condensed P&L by Month'!$A37,'P&L by Month Detail'!N:N) -> 94847 | N37: =SUMIF('P&L by Month Detail'!$A:$A,'Condensed P&L by Month'!$A37,'P&L by Month Detail'!O:O) -> 79928 | O37: =SUMIF('P&L by Month Detail'!$A:$A,'Condensed P&L by Month'!$A37,'P&L by Month Detail'!P:P) -> 109242 | P37: =SUMIF('P&L by Month Detail'!$A:$A,'Condensed P&L by Month'!$A37,'P&L by Month Detail'!Q:Q) -> 89430 | Q37: =+SUM(F37:P37)+B37 -> 1453007
A38: Marketing and Advertising Expenses | B38: =SUMIF('P&L by Month Detail'!$A:$A,'Condensed P&L by Month'!$A38,'P&L by Month Detail'!C:C) -> 13014 | C38: =SUMIF('P&L by Month Detail'!$A:$A,'Condensed P&L by Month'!$A38,'P&L by Month Detail'!D:D) -> -4000 | D38: =+B38+C38 -> 9014 | E38: 4 | F38: =SUMIF('P&L by Month Detail'!$A:$A,'Condensed P&L by Month'!$A38,'P&L by Month Detail'!G:G) -> 15176 | G38: =SUMIF('P&L by Month Detail'!$A:$A,'Condensed P&L by Month'!$A38,'P&L by Month Detail'!H:H) -> 14957 | H38: =SUMIF('P&L by Month Detail'!$A:$A,'Condensed P&L by Month'!$A38,'P&L by Month Detail'!I:I) -> 14315 | I38: =SUMIF('P&L by Month Detail'!$A:$A,'Condensed P&L by Month'!$A38,'P&L by Month Detail'!J:J) -> 9048 | J38: =SUMIF('P&L by Month Detail'!$A:$A,'Condensed P&L by Month'!$A38,'P&L by Month Detail'!K:K) -> 10887 | K38: =SUMIF('P&L by Month Detail'!$A:$A,'Condensed P&L by Month'!$A38,'P&L by Month Detail'!L:L) -> 10481 | L38: =SUMIF('P&L by Month Detail'!$A:$A,'Condensed P&L by Month'!$A38,'P&L by Month Detail'!M:M) -> 7303 | M38: =SUMIF('P&L by Month Detail'!$A:$A,'Condensed P&L by Month'!$A38,'P&L by Month Detail'!N:N) -> 8153 | N38: =SUMIF('P&L by Month Detail'!$A:$A,'Condensed P&L by Month'!$A38,'P&L by Month Detail'!O:O) -> 7987 | O38: =SUMIF('P&L by Month Detail'!$A:$A,'Condensed P&L by Month'!$A38,'P&L by Month Detail'!P:P) -> 3121 | P38: =SUMIF('P&L by Month Detail'!$A:$A,'Condensed P&L by Month'!$A38,'P&L by Month Detail'!Q:Q) -> 4520 | Q38: =+SUM(F38:P38)+B38 -> 118962
A39: General and Administrative Expenses | B39: =SUMIF('P&L by Month Detail'!$A:$A,'Condensed P&L by Month'!$A39,'P&L by Month Detail'!C:C) -> 33590 | C39: =SUMIF('P&L by Month Detail'!$A:$A,'Condensed P&L by Month'!$A39,'P&L by Month Detail'!D:D) -> 0 | D39: =+B39+C39 -> 33590 | F39: =SUMIF('P&L by Month Detail'!$A:$A,'Condensed P&L by Month'!$A39,'P&L by Month Detail'!G:G) -> 33809 | G39: =SUMIF('P&L by Month Detail'!$A:$A,'Condensed P&L by Month'!$A39,'P&L by Month Detail'!H:H) -> 25910 | H39: =SUMIF('P&L by Month Detail'!$A:$A,'Condensed P&L by Month'!$A39,'P&L by Month Detail'!I:I) -> 22849 | I39: =SUMIF('P&L by Month Detail'!$A:$A,'Condensed P&L by Month'!$A39,'P&L by Month Detail'!J:J) -> 16742 | J39: =SUMIF('P&L by Month Detail'!$A:$A,'Condensed P&L by Month'!$A39,'P&L by Month Detail'!K:K) -> 23977 | K39: =SUMIF('P&L by Month Detail'!$A:$A,'Condensed P&L by Month'!$A39,'P&L by Month Detail'!L:L) -> 17197 | L39: =SUMIF('P&L by Month Detail'!$A:$A,'Condensed P&L by Month'!$A39,'P&L by Month Detail'!M:M) -> 18050 | M39: =SUMIF('P&L by Month Detail'!$A:$A,'Condensed P&L by Month'!$A39,'P&L by Month Detail'!N:N) -> 15130 | N39: =SUMIF('P&L by Month Detail'!$A:$A,'Condensed P&L by Month'!$A39,'P&L by Month Detail'!O:O) -> 18959 | O39: =SUMIF('P&L by Month Detail'!$A:$A,'Condensed P&L by Month'!$A39,'P&L by Month Detail'!P:P) -> 23341 | P39: =SUMIF('P&L by Month Detail'!$A:$A,'Condensed P&L by Month'!$A39,'P&L by Month Detail'!Q:Q) -> 20205 | Q39: =+SUM(F39:P39)+B39 -> 269759
A40: Taxes and Insurance | B40: =SUMIF('P&L by Month Detail'!$A:$A,'Condensed P&L by Month'!$A40,'P&L by Month Detail'!C:C) -> 143390 | C40: =SUMIF('P&L by Month Detail'!$A:$A,'Condensed P&L by Month'!$A40,'P&L by Month Detail'!D:D) -> 0 | D40: =+B40+C40 -> 143390 | F40: =SUMIF('P&L by Month Detail'!$A:$A,'Condensed P&L by Month'!$A40,'P&L by Month Detail'!G:G) -> 7787 | G40: =SUMIF('P&L by Month Detail'!$A:$A,'Condensed P&L by Month'!$A40,'P&L by Month Detail'!H:H) -> 9950 | H40: =SUMIF('P&L by Month Detail'!$A:$A,'Condensed P&L by Month'!$A40,'P&L by Month Detail'!I:I) -> 14268 | I40: =SUMIF('P&L by Month Detail'!$A:$A,'Condensed P&L by Month'!$A40,'P&L by Month Detail'!J:J) -> 6091 | J40: =SUMIF('P&L by Month Detail'!$A:$A,'Condensed P&L by Month'!$A40,'P&L by Month Detail'!K:K) -> 6081 | K40: =SUMIF('P&L by Month Detail'!$A:$A,'Condensed P&L by Month'!$A40,'P&L by Month Detail'!L:L) -> 6826 | L40: =SUMIF('P&L by Month Detail'!$A:$A,'Condensed P&L by Month'!$A40,'P&L by Month Detail'!M:M) -> 5501 | M40: =SUMIF('P&L by Month Detail'!$A:$A,'Condensed P&L by Month'!$A40,'P&L by Month Detail'!N:N) -> 6410 | N40: =SUMIF('P&L by Month Detail'!$A:$A,'Condensed P&L by Month'!$A40,'P&L by Month Detail'!O:O) -> 7430 | O40: =SUMIF('P&L by Month Detail'!$A:$A,'Condensed P&L by Month'!$A40,'P&L by Month Detail'!P:P) -> 7419 | P40: =SUMIF('P&L by Month Detail'!$A:$A,'Condensed P&L by Month'!$A40,'P&L by Month Detail'!Q:Q) -> 7425 | Q40: =+SUM(F40:P40)+B40 -> 228578
A41: Total Operating Expense- no Direct or Sales Labor | B41: =SUM(B35:B40) -> 609711 | C41: =SUM(C35:C40) -> -232420.29 | D41: =SUM(D35:D40) -> 377290.71 | F41: =SUM(F35:F40) -> 281301 | G41: =SUM(G35:G40) -> 242987 | H41: =SUM(H35:H40) -> 284224 | I41: =SUM(I35:I40) -> 279404 | J41: =SUM(J35:J40) -> 271485 | K41: =SUM(K35:K40) -> 254343 | L41: =SUM(L35:L40) -> 260958 | M41: =SUM(M35:M40) -> 240661 | ... Q41: =SUM(Q35:Q40) -> 3525516
A42: Total Operating Net Income- DL above the line | B42: =+B32-B33-B41 -> -193755 | C42: =+C32-C33-C41 -> 98751.94 | D42: =+D32-D33-D41 -> -95003.06 | F42: =+F32-F33-F41 -> 179997 | G42: =+G32-G33-G41 -> 144766 | H42: =+H32-H33-H41 -> 50735 | I42: =+I32-I33-I41 -> 239069 | J42: =+J32-J33-J41 -> 160995 | K42: =+K32-K33-K41 -> 278934 | L42: =+L32-L33-L41 -> 193997 | M42: =+M32-M33-M41 -> 244791 | ... Q42: =+Q32-Q33-Q41 -> 1496410
...

Sheet P&L by Month Detail
A1: Datapath
A2: P&L MTD with Previous Month Comparison
A3: Reporting Book:
A4: As of Date:
C6: Data Path - All Locations | G6: Data Path - All Locations | H6: Data Path - All Locations | I6: Data Path - All Locations | J6: Data Path - All Locations | K6: Data Path - All Locations | L6: Data Path - All Locations | M6: Data Path - All Locations | N6: Data Path - All Locations | O6: Data Path - All Locations | P6: Data Path - All Locations | Q6: Data Path - All Locations | R6: Data Path - All Locations
C7: Month Ending | E7: Unadjusted | G7: Month Ending | H7: Month Ending | I7: Month Ending | J7: Month Ending | K7: Month Ending | L7: Month Ending | M7: Month Ending | N7: Month Ending | O7: Month Ending | P7: Month Ending | Q7: Month Ending | R7: Month Ending
C8: 12/31/2025 | D8: YE Clean up | E8: 12/31/2025 | G8: 11/30/2025 | H8: 10/31/2025 | I8: 09/30/2025 | J8: 08/31/2025 | K8: 07/31/2025 | L8: 06/30/2025 | M8: 05/31/2025 | N8: 04/30/2025 | O8: 03/31/2025 | P8: 02/28/2025 | Q8: 01/31/2025 | R8: Total
C9: Actual | G9: Actual | H9: Actual | I9: Actual | J9: Actual | K9: Actual | L9: Actual | M9: Actual | N9: Actual | O9: Actual | P9: Actual | Q9: Actual | R9: Actual
A10: Net Income- With DL above the line
A11: Operating Net Income- DL above the line
A12: Gross Profit with Direct Labor
A13: Revenue
A14: Monthly Recurring Services
A15: 40000 - Managed IT Revenue | B15: 40000 | C15: 558277 | D15: =-SUMIF(Sheet1!A:A,B15,Sheet1!Z:Z) -> 0 | E15: =+C15+D15 -> 558277 | G15: 551140 | H15: 548490 | I15: 515994 | J15: 556309 | K15: 540665 | L15: 553888 | M15: 542770 | N15: 546505 | O15: 508811 | P15: 500073 | Q15: 492103 | R15: =SUM(G15:Q15)+C15 -> 6415025
A16: 40100 - Managed Security Revenue | B16: 40100 | C16: 5055 | D16: =-SUMIF(Sheet1!A:A,B16,Sheet1!Z:Z) -> 0 | E16: =+C16+D16 -> 5055 | G16: 5055 | H16: 4729 | I16: 5056 | J16: 5162 | K16: 5162 | L16: 7797 | M16: 7797 | N16: 7797 | O16: 7797 | P16: 7797 | Q16: 9897 | R16: =SUM(G16:Q16)+C16 -> 79101
A17: 40200 - Managed Voice Revenue | B17: 40200 | C17: 8406 | D17: =-SUMIF(Sheet1!A:A,B17,Sheet1!Z:Z) -> 0 | E17: =+C17+D17 -> 8406 | G17: 8407 | H17: 8407 | I17: 8532 | J17: 8807 | K17: 9888 | L17: 10629 | M17: 10629 | N17: 10210 | O17: 11050 | P17: 11462 | Q17: 13253 | R17: =SUM(G17:Q17)+C17 -> 119680
A18: 41320 - Managed Back up Revenue | B18: 41320 | C18: 10531 | D18: =-SUMIF(Sheet1!A:A,B18,Sheet1!Z:Z) -> 0 | E18: =+C18+D18 -> 10531 | G18: 11493 | H18: 11556 | I18: 11722 | J18: 11417 | K18: 12099 | L18: 13052 | M18: 13234 | N18: 12807 | O18: 12918 | P18: 12558 | Q18: 12039 | R18: =SUM(G18:Q18)+C18 -> 145426
A19: 41925 - USAC ERATE BM Revenue | B19: 41925 | C19: 4680 | D19: =-SUMIF(Sheet1!A:A,B19,Sheet1!Z:Z) -> 0 | E19: =+C19+D19 -> 4680 | G19: 5774 | H19: 5774 | I19: 5913 | J19: 6140 | K19: 6111 | L19: 10072 | M19: 10072 | N19: 10072 | O19: 10072 | P19: 10072 | Q19: 10072 | R19: =SUM(G19:Q19)+C19 -> 94824
A20: Monthly Recurring Services | C20: =SUM(C15:C19) -> 586949 | D20: =SUM(D15:D19) -> 0 | E20: =SUM(E15:E19) -> 586949 | G20: =SUM(G15:G19) -> 581869 | H20: =SUM(H15:H19) -> 578956 | I20: =SUM(I15:I19) -> 547217 | J20: =SUM(J15:J19) -> 587835 | K20: =SUM(K15:K19) -> 573925 | L20: =SUM(L15:L19) -> 595438 | M20: =SUM(M15:M19) -> 584502 | N20: =SUM(N15:N19) -> 587391 | ... Q20: =SUM(Q15:Q19) -> 537364 | R20: =SUM(G20:Q20)+C20 -> 6854056
A21: Monthly Recurring Private Cloud
A22: 41360 - Public Cloud Revenue | B22: 41360 | C22: 1144 | D22: =-SUMIF(Sheet1!A:A,B22,Sheet1!Z:Z) -> 0 | E22: =+C22+D22 -> 1144 | G22: 1144 | H22: 1144 | I22: 1144 | J22: 1144 | K22: 1144 | L22: 1144 | M22: 1144 | N22: 1144 | O22: 1144 | P22: 1144 | Q22: 1144 | R22: =SUM(G22:Q22)+C22 -> 13728
A23: 41365 - Private Cloud Revenue | B23: 41365 | C23: 26057 | D23: =-SUMIF(Sheet1!A:A,B23,Sheet1!Z:Z) -> 0 | E23: =+C23+D23 -> 26057 | G23: 25871 | H23: 25853 | I23: 20457 | J23: 25280 | K23: 25117 | L23: 23342 | M23: 23324 | N23: 22060 | O23: 21582 | P23: 21582 | Q23: 18993 | R23: =SUM(G23:Q23)+C23 -> 279518
A24: Monthly Recurring Private Cloud | C24: =SUM(C22:C23) -> 27201 | D24: =SUM(D22:D23) -> 0 | E24: =SUM(E22:E23) -> 27201 | G24: =SUM(G22:G23) -> 27015 | H24: =SUM(H22:H23) -> 26997 | I24: =SUM(I22:I23) -> 21601 | J24: =SUM(J22:J23) -> 26424 | K24: =SUM(K22:K23) -> 26261 | L24: =SUM(L22:L23) -> 24486 | M24: =SUM(M22:M23) -> 24468 | N24: =SUM(N22:N23) -> 23204 | ... Q24: =SUM(Q22:Q23) -> 20137 | R24: =SUM(G24:Q24)+C24 -> 293246
A25: Monthly Recurring Resale
A26: 41200 - HaaS Revenue | B26: 41200 | C26: 27131 | D26: =-SUMIF(Sheet1!A:A,B26,Sheet1!Z:Z) -> 0 | E26: =+C26+D26 -> 27131 | G26: 26941 | H26: 26390 | I26: 20854 | J26: 22102 | K26: 26229 | L26: 26479 | M26: 26155 | N26: 24655 | O26: 24654 | P26: 24795 | Q26: 25121 | R26: =SUM(G26:Q26)+C26 -> 301506
A27: 41250 - Chromebook ADP Revenue | B27: 41250 | C27: 562 | D27: =-SUMIF(Sheet1!A:A,B27,Sheet1!Z:Z) -> 0 | E27: =+C27+D27 -> 562 | G27: 563 | H27: 562 | I27: 563 | J27: 563 | K27: 562 | L27: 563 | M27: 562 | N27: 562 | O27: 563 | P27: 562 | Q27: 562 | R27: =SUM(G27:Q27)+C27 -> 6749
A28: 41300 - Cloud SAAS Revenue | B28: 41300 | C28: -15338 | D28: =-SUMIF(Sheet1!A:A,B28,Sheet1!Z:Z) -> -60357 | E28: =+C28+D28 -> -75695 | F28: 1 | G28: 46534 | H28: 51519 | I28: 45616 | J28: 50092 | K28: 50221 | L28: 49375 | M28: 49594 | N28: 39052 | O28: 38905 | P28: 38181 | Q28: 31136 | R28: =SUM(G28:Q28)+C28 -> 474887
A29: 41350 - Managed Spam Filtering Revenue | B29: 41350 | C29: 896 | D29: =-SUMIF(Sheet1!A:A,B29,Sheet1!Z:Z) -> 0 | E29: =+C29+D29 -> 896 | G29: 902 | H29: 899 | I29: 954 | J29: 952 | K29: 949 | L29: 952 | M29: 949 | N29: 756 | O29: 770 | P29: 974 | Q29: 974 | R29: =SUM(G29:Q29)+C29 -> 10927
A30: 41450 - Microsoft 365 Revenue | B30: 41450 | C30: 126918 | D30: =-SUMIF(Sheet1!A:A,B30,Sheet1!Z:Z) -> 0 | E30: =+C30+D30 -> 126918 | G30: 124569 | H30: 122540 | I30: 82195 | J30: 89934 | K30: 87546 | L30: 84100 | M30: 95660 | N30: 93187 | O30: 88758 | P30: 80232 | Q30: 81227 | R30: =SUM(G30:Q30)+C30 -> 1156866
A31: 42100 - Security Resale Revenue | B31: 42100 | C31: 147131 | D31: =-SUMIF(Sheet1!A:A,B31,Sheet1!Z:Z) -> 0 | E31: =+C31+D31 -> 147131 | G31: 146553 | H31: 148714 | I31: 143365 | J31: 138622 | K31: 136209 | L31: 133413 | M31: 129838 | N31: 106277 | O31: 104647 | P31: 96967 | Q31: 94782 | R31: =SUM(G31:Q31)+C31 -> 1526518
A32: 42200 - Tool Resale Revenue | B32: 42200 | C32: 3617 | D32: =-SUMIF(Sheet1!A:A,B32,Sheet1!Z:Z) -> 0 | E32: =+C32+D32 -> 3617 | G32: 3616 | H32: 3616 | I32: 3616 | J32: 3647 | K32: 3652 | L32: 3963 | M32: 3963 | N32: 4589 | O32: 4589 | P32: 4589 | Q32: 4529 | R32: =SUM(G32:Q32)+C32 -> 47986
A33: 42300 - Voice Resale Revenue | B33: 42300 | C33: 2545 | D33: =-SUMIF(Sheet1!A:A,B33,Sheet1!Z:Z) -> 0 | E33: =+C33+D33 -> 2545 | G33: 2546 | H33: 2546 | I33: 2546 | J33: 2434 | K33: 2433 | L33: 2434 | M33: 2434 | N33: 2433 | O33: 2434 | P33: 1261 | Q33: 641 | R33: =SUM(G33:Q33)+C33 -> 26687
A34: Monthly Recurring Resale | C34: =SUM(C26:C33) -> 293462 | D34: =SUM(D26:D33) -> -60357 | E34: =SUM(E26:E33) -> 233105 | G34: =SUM(G26:G33) -> 352224 | H34: =SUM(H26:H33) -> 356786 | I34: =SUM(I26:I33) -> 299709 | J34: =SUM(J26:J33) -> 308346 | K34: =SUM(K26:K33) -> 307801 | L34: =SUM(L26:L33) -> 301279 | M34: =SUM(M26:M33) -> 309155 | N34: =SUM(N26:N33) -> 271511 | ... Q34: =SUM(Q26:Q33) -> 238972 | R34: =SUM(G34:Q34)+C34 -> 3552126
A35: Project Services
A36: 41500 - Project Service Revenue | B36: 41500 | C36: 61485 | D36: =-SUMIF(Sheet1!A:A,B36,Sheet1!Z:Z) -> 43058.14 | E36: =+C36+D36 -> 104543.14 | F36: 2 | G36: 47381 | H36: 67554 | I36: 46071 | J36: 104693 | K36: 53462 | L36: 120765 | M36: 47201 | N36: 99226 | O36: 105235 | P36: 92496 | Q36: 51717 | R36: =SUM(G36:Q36)+C36 -> 897286
A37: Revenue - Project Services | C37: =+C36 -> 61485 | D37: =+D36 -> 43058.14 | E37: =+E36 -> 104543.14 | G37: =+G36 -> 47381 | H37: =+H36 -> 67554 | I37: =+I36 -> 46071 | J37: =+J36 -> 104693 | K37: =+K36 -> 53462 | L37: =+L36 -> 120765 | M37: =+M36 -> 47201 | N37: =+N36 -> 99226 | ... Q37: =+Q36 -> 51717 | R37: =SUM(G37:Q37)+C37 -> 897286
A38: Subcontracted Services
A39: 41700 - Subcontracted Service Revenue | B39: 41700 | C39: 4614 | D39: =-SUMIF(Sheet1!A:A,B39,Sheet1!Z:Z) -> 0 | E39: =+C39+D39 -> 4614 | G39: 13197 | H39: 19989 | I39: 14480 | J39: 36139 | K39: 12686 | L39: 8539 | M39: 16341 | N39: 14387 | O39: 35020 | P39: 58116 | Q39: 86683 | R39: =SUM(G39:Q39)+C39 -> 320191
A40: Subcontracted Services | C40: =+C39 -> 4614 | D40: =+D39 -> 0 | E40: =+E39 -> 4614 | G40: =+G39 -> 13197 | H40: =+H39 -> 19989 | I40: =+I39 -> 14480 | J40: =+J39 -> 36139 | K40: =+K39 -> 12686 | L40: =+L39 -> 8539 | M40: =+M39 -> 16341 | N40: =+N39 -> 14387 | ... Q40: =+Q39 -> 86683 | R40: =SUM(G40:Q40)+C40 -> 320191
A41: Product Sales
...

Sheet Sheet1
A1: GL Code | B1: Posted dt. | C1: Doc dt. | D1: Doc | E1: Memo/Description | F1: Department | G1: Location | H1: Department name | I1: Location name | J1: Customer name | K1: Customer | L1: Vendor name | M1: Vendor | N1: Item name | O1: Item | P1: Class name | Q1: Class | R1: Product Type | S1: Revenue Type | T1: Employee name | U1: Employee | V1: Txn No | W1: JNL | X1: Debit | Y1: Credit | Z1: Balance
A2: 41300 | B2: 46022 | C2: 46022 | E2: HHHC Overbilling correction | G2: DP | I2: Datapath, Inc. | V2: 2677 | W2: GJ | X2: 60357 | Z2: 60357
A3: 41500 | B3: 46022 | C3: 46022 | E3: Reverse WIP booking for 2024 | G3: DP | I3: Datapath, Inc. | V3: 2646 | W3: GJ | Y3: 1745.14 | Z3: -1745.14
A4: 41500 | B4: 46022 | C4: 46022 | E4: WIP Accrual 2025 | G4: DP | I4: Datapath, Inc. | V4: 2668 | W4: GJ | Y4: 13000 | Z4: -13000
A5: 41500 | B5: 46022 | C5: 46022 | E5: WIP Accrual 2025 | G5: DP | I5: Datapath, Inc. | V5: 2668 | W5: GJ | Y5: 15900 | Z5: -15900
A6: 41500 | B6: 46022 | C6: 46022 | E6: WIP Accrual 2025 | G6: DP | I6: Datapath, Inc. | V6: 2668 | W6: GJ | Y6: 18913.5 | Z6: -18913.5
A7: 41500 | B7: 46022 | C7: 46022 | E7: Reverse WIP booking for 2024 | G7: OHIO | I7: Data Path OHIO LLC | V7: 2646 | W7: GJ | X7: 6500.5 | Z7: 6500.5
A8: 50600 | B8: 46022 | C8: 46022 | E8: To correct payroll and accruals | G8: DP | I8: Datapath, Inc. | V8: 2681 | W8: GJ | Y8: 56839.74 | Z8: -56839.74
A9: 50600 | B9: 46022 | C9: 46022 | E9: To correct payroll and accruals | G9: DPF | I9: Datapath Fresno, LC | V9: 2681 | W9: GJ | Y9: 268.24 | Z9: -268.24
A10: 50600 | B10: 46022 | C10: 46022 | E10: To correct payroll and accruals | G10: OHIO | I10: Data Path OHIO LLC | V10: 2681 | W10: GJ | X10: 4679.26 | Z10: 4679.26
A11: 50605 | B11: 46022 | C11: 46022 | E11: To correct payroll and accruals | F11: D-002 | G11: DP | H11: Administration | I11: Datapath, Inc. | V11: 2681 | W11: GJ | X11: 14434.6 | Z11: 14434.6
A12: 50605 | B12: 46022 | C12: 46022 | E12: To correct payroll and accruals | F12: D-002 | G12: DPF | H12: Administration | I12: Datapath Fresno, LC | V12: 2681 | W12: GJ | X12: 3596.96 | Z12: 3596.96
A13: 50605 | B13: 46022 | C13: 46022 | E13: To correct payroll and accruals | F13: D-002 | G13: OHIO | H13: Administration | I13: Data Path OHIO LLC | V13: 2681 | W13: GJ | Y13: 82377 | Z13: -82377
A14: 50610 | B14: 46022 | C14: 46022 | E14: To correct payroll and accruals | F14: D-002 | G14: DP | H14: Administration | I14: Datapath, Inc. | V14: 2681 | W14: GJ | X14: 71686 | Z14: 71686
A15: 50610 | B15: 46022 | C15: 46022 | E15: To correct payroll and accruals | F15: D-002 | G15: DPF | H15: Administration | I15: Datapath Fresno, LC | V15: 2681 | W15: GJ | X15: 6868.02 | Z15: 6868.02
A16: 50610 | B16: 46022 | C16: 46022 | E16: To correct payroll and accruals | F16: D-002 | G16: OHIO | H16: Administration | I16: Data Path OHIO LLC | V16: 2681 | W16: GJ | X16: 82134.58 | Z16: 82134.58
A17: 50620 | B17: 46022 | C17: 46022 | E17: To correct payroll and accruals | F17: D-002 | G17: DP | H17: Administration | I17: Datapath, Inc. | V17: 2681 | W17: GJ | X17: 14922.8 | Z17: 14922.8
A18: 50620 | B18: 46022 | C18: 46022 | E18: To correct payroll and accruals | F18: D-002 | G18: OHIO | H18: Administration | I18: Data Path OHIO LLC | V18: 2681 | W18: GJ | X18: 4462.76 | Z18: 4462.76
A19: 50625 | B19: 46022 | C19: 46022 | E19: To correct payroll and accruals | F19: D-002 | G19: DP | H19: Administration | I19: Datapath, Inc. | V19: 2681 | W19: GJ | Y19: 135262.26 | Z19: -135262.26
A20: 50625 | B20: 46022 | C20: 46022 | E20: To correct payroll and accruals | F20: D-002 | G20: OHIO | H20: Administration | I20: Data Path OHIO LLC | V20: 2681 | W20: GJ | X20: 15442.83 | Z20: 15442.83
A21: 50661 | B21: 46022 | C21: 46022 | E21: To post internal use software. | G21: DP | I21: Datapath, Inc. | V21: 2721 | W21: GJ | Y21: 90648.14 | Z21: -90648.14
A22: 50700 | B22: 46022 | C22: 46022 | E22: To correct payroll and accruals | G22: DP | I22: Datapath, Inc. | V22: 2681 | W22: GJ | Y22: 15331.32 | Z22: -15331.32
A23: 50700 | B23: 46022 | C23: 46022 | E23: To correct payroll and accruals | G23: DPF | I23: Datapath Fresno, LC | V23: 2681 | W23: GJ | X23: 399.41 | Z23: 399.41
A24: 50700 | B24: 46022 | C24: 46022 | E24: To correct payroll and accruals | G24: OHIO | I24: Data Path OHIO LLC | V24: 2681 | W24: GJ | X24: 357.08 | Z24: 357.08
A25: 50705 | B25: 46022 | C25: 46022 | E25: To correct payroll and accruals | F25: D-002 | G25: DP | H25: Administration | I25: Datapath, Inc. | V25: 2681 | W25: GJ | X25: 3029.84 | Z25: 3029.84
A26: 50705 | B26: 46022 | C26: 46022 | E26: To correct payroll and accruals | F26: D-002 | G26: DPF | H26: Administration | I26: Datapath Fresno, LC | V26: 2681 | W26: GJ | X26: 920.97 | Z26: 920.97
A27: 50705 | B27: 46022 | C27: 46022 | E27: To correct payroll and accruals | F27: D-002 | G27: OHIO | H27: Administration | I27: Data Path OHIO LLC | V27: 2681 | W27: GJ | Y27: 6542 | Z27: -6542
A28: 50710 | B28: 46022 | C28: 46022 | E28: To correct payroll and accruals | F28: D-002 | G28: DP | H28: Administration | I28: Datapath, Inc. | V28: 2681 | W28: GJ | X28: 10631.43 | Z28: 10631.43
A29: 50710 | B29: 46022 | C29: 46022 | E29: To correct payroll and accruals | F29: D-002 | G29: DPF | H29: Administration | I29: Datapath Fresno, LC | V29: 2681 | W29: GJ | X29: 1178.99 | Z29: 1178.99
A30: 50710 | B30: 46022 | C30: 46022 | E30: To correct payroll and accruals | F30: D-002 | G30: OHIO | H30: Administration | I30: Data Path OHIO LLC | V30: 2681 | W30: GJ | X30: 7402.03 | Z30: 7402.03
A31: 50720 | B31: 46022 | C31: 46022 | E31: To correct payroll and accruals | F31: D-002 | G31: DP | H31: Administration | I31: Datapath, Inc. | V31: 2681 | W31: GJ | Y31: 758.42 | Z31: -758.42
A32: 50720 | B32: 46022 | C32: 46022 | E32: To correct payroll and accruals | F32: D-002 | G32: OHIO | H32: Administration | I32: Data Path OHIO LLC | V32: 2681 | W32: GJ | X32: 3882.41 | Z32: 3882.41
A33: 50801 | B33: 46022 | C33: 46022 | E33: To correct payroll and accruals | G33: DP | I33: Datapath, Inc. | V33: 2681 | W33: GJ | Y33: 1189.39 | Z33: -1189.39
A34: 50801 | B34: 46022 | C34: 46022 | E34: To correct payroll and accruals | G34: DPF | I34: Datapath Fresno, LC | V34: 2681 | W34: GJ | Y34: 9.43 | Z34: -9.43
A35: 50805 | B35: 46022 | C35: 46022 | E35: To correct payroll and accruals | F35: D-002 | G35: DP | H35: Administration | I35: Datapath, Inc. | V35: 2681 | W35: GJ | X35: 428.63 | Z35: 428.63
A36: 50805 | B36: 46022 | C36: 46022 | E36: To correct payroll and accruals | F36: D-002 | G36: DPF | H36: Administration | I36: Datapath Fresno, LC | V36: 2681 | W36: GJ | X36: 107.5 | Z36: 107.5
A37: 50805 | B37: 46022 | C37: 46022 | E37: To correct payroll and accruals | F37: D-002 | G37: OHIO | H37: Administration | I37: Data Path OHIO LLC | V37: 2681 | W37: GJ | Y37: 2471 | Z37: -2471
A38: 50811 | B38: 46022 | C38: 46022 | E38: To correct payroll and accruals | F38: D-002 | G38: DP | H38: Administration | I38: Datapath, Inc. | V38: 2681 | W38: GJ | Y38: 820.77 | Z38: -820.77
A39: 50811 | B39: 46022 | C39: 46022 | E39: To correct payroll and accruals | F39: D-002 | G39: DPF | H39: Administration | I39: Datapath Fresno, LC | V39: 2681 | W39: GJ | X39: 169.16 | Z39: 169.16
A40: 50811 | B40: 46022 | C40: 46022 | E40: To correct payroll and accruals | F40: D-002 | G40: OHIO | H40: Administration | I40: Data Path OHIO LLC | V40: 2681 | W40: GJ | X40: 2486.03 | Z40: 2486.03
...
